Workbook

Sheet PinNo
A1: 1 | B1: AVDD09[1] | C1: =A1 -> 1
A2: 2 | B2: INH | C2: =A2 -> 2
A3: 3 | B3: V33 | C3: =A3 -> 3
A4: 4 | B4: WAKE | C4: =A4 -> 4
A5: 5 | B5: DVDD09[01] | C5: =A5 -> 5
A6: 6 | B6: DVDD09[02] | C6: =A6 -> 6
A7: 7 | B7: XMII_1_CRS | C7: =A7 -> 7
A8: 8 | B8: XMII_1_COL | C8: =A8 -> 8
A9: 9 | B9: XMII_1_RXER | C9: =A9 -> 9
A10: 10 | B10: XMII_1_RXDV | C10: =A10 -> 10
A11: 11 | B11: XMII_1_RXD0 | C11: =A11 -> 11
A12: 12 | B12: XMII_1_RXD1 | C12: =A12 -> 12
... A176: 88 | B176: AVDD09_TRX[4] | C176: =A176 -> 88
A177: GH1 | B177: GH1 | C177: =A177 -> GH1
A178: GH2 | B178: GH2 | C178: =A178 -> GH2
A179: NUT1 | B179: NUT1 | C179: =A179 -> NUT1
A180: NUT2 | B180: NUT2 | C180: =A180 -> NUT2
A181: EP | B181: EP | C181: =A181 -> EP
A182: G1 | B182: G1 | C182: =A182 -> G1
A183: G2 | B183: G2 | C183: =A183 -> G2
A184: G3 | B184: G3 | C184: =A184 -> G3
A185: G4 | B185: G4 | C185: =A185 -> G4
A186: G5 | B186: G5 | C186: =A186 -> G5
A187: G6 | B187: G6 | C187: =A187 -> G6
A188: G7 | B188: G7 | C188: =A188 -> G7
... A210: G25 | B210: G25 | C210: =A210 -> G25

Sheet Netlist_VTable
C1: refer | E1: Name | F1: Number | G1: Net Name | H1: =CONCATENATE(C1,".",F1) -> refer.Number | I1: =G1 -> Net Name
A2: SCHEMATIC1 | B2: P000A_S0_BRPHY_P1_2_3_4 | C2: C197 | D2: 1 | E2: 1 | F2: 1 | G2: S0_U3_P1_RC | H2: =CONCATENATE(C2,".",F2) -> C197.1 | I2: =G2 -> S0_U3_P1_RC
A3: SCHEMATIC1 | B3: P000A_S0_BRPHY_P1_2_3_4 | C3: C197 | D3: 2 | E3: 2 | F3: 2 | G3: DGND | H3: =CONCATENATE(C3,".",F3) -> C197.2 | I3: =G3 -> DGND
A4: SCHEMATIC1 | B4: P000A_S0_BRPHY_P1_2_3_4 | C4: C198 | D4: 1 | E4: 1 | F4: 1 | G4: S0_U2_P1_MDI+ | H4: =CONCATENATE(C4,".",F4) -> C198.1 | I4: =G4 -> S0_U2_P1_MDI+
A5: SCHEMATIC1 | B5: P000A_S0_BRPHY_P1_2_3_4 | C5: C198 | D5: 2 | E5: 2 | F5: 2 | G5: S0_U3_P1_MDI+ | H5: =CONCATENATE(C5,".",F5) -> C198.2 | I5: =G5 -> S0_U3_P1_MDI+
A6: SCHEMATIC1 | B6: P000A_S0_BRPHY_P1_2_3_4 | C6: C199 | D6: 1 | E6: 1 | F6: 1 | G6: S0_U2_P1_MDI- | H6: =CONCATENATE(C6,".",F6) -> C199.1 | I6: =G6 -> S0_U2_P1_MDI-
A7: SCHEMATIC1 | B7: P000A_S0_BRPHY_P1_2_3_4 | C7: C199 | D7: 2 | E7: 2 | F7: 2 | G7: S0_U3_P1_MDI- | H7: =CONCATENATE(C7,".",F7) -> C199.2 | I7: =G7 -> S0_U3_P1_MDI-
A8: SCHEMATIC1 | B8: P000A_S0_BRPHY_P1_2_3_4 | C8: C200 | D8: 1 | E8: 1 | F8: 1 | G8: S0_U3_P2_RC | H8: =CONCATENATE(C8,".",F8) -> C200.1 | I8: =G8 -> S0_U3_P2_RC
A9: SCHEMATIC1 | B9: P000A_S0_BRPHY_P1_2_3_4 | C9: C200 | D9: 2 | E9: 2 | F9: 2 | G9: DGND | H9: =CONCATENATE(C9,".",F9) -> C200.2 | I9: =G9 -> DGND
A10: SCHEMATIC1 | B10: P000A_S0_BRPHY_P1_2_3_4 | C10: C201 | D10: 1 | E10: 1 | F10: 1 | G10: S0_U2_P2_MDI+ | H10: =CONCATENATE(C10,".",F10) -> C201.1 | I10: =G10 -> S0_U2_P2_MDI+
A11: SCHEMATIC1 | B11: P000A_S0_BRPHY_P1_2_3_4 | C11: C201 | D11: 2 | E11: 2 | F11: 2 | G11: S0_U3_P2_MDI+ | H11: =CONCATENATE(C11,".",F11) -> C201.2 | I11: =G11 -> S0_U3_P2_MDI+
A12: SCHEMATIC1 | B12: P000A_S0_BRPHY_P1_2_3_4 | C12: C202 | D12: 1 | E12: 1 | F12: 1 | G12: S0_U2_P2_MDI- | H12: =CONCATENATE(C12,".",F12) -> C202.1 | I12: =G12 -> S0_U2_P2_MDI-
A13: SCHEMATIC1 | B13: P000A_S0_BRPHY_P1_2_3_4 | C13: C202 | D13: 2 | E13: 2 | F13: 2 | G13: S0_U3_P2_MDI- | H13: =CONCATENATE(C13,".",F13) -> C202.2 | I13: =G13 -> S0_U3_P2_MDI-
... A31: SCHEMATIC1 | B31: P000A_S0_BRPHY_P1_2_3_4 | C31: K64 | D31: 7 | E31: 7 | F31: 7 | G31: S0_HSD006- | H31: =CONCATENATE(C31,".",F31) -> K64.7 | I31: =G31 -> S0_HSD006-
A32: SCHEMATIC1 | B32: P000A_S0_BRPHY_P1_2_3_4 | C32: K64 | D32: V+ | E32: V+ | F32: 1 | G32: VP12 | H32: =CONCATENATE(C32,".",F32) -> K64.1 | I32: =G32 -> VP12
A33: SCHEMATIC1 | B33: P000A_S0_BRPHY_P1_2_3_4 | C33: K64 | D33: V- | E33: V- | F33: 8 | G33: SC_UDB064 | H33: =CONCATENATE(C33,".",F33) -> K64.8 | I33: =G33 -> SC_UDB064
A34: SCHEMATIC1 | B34: P000A_S0_BRPHY_P1_2_3_4 | C34: K68 | D34: 2 | E34: 2 | F34: 2 | G34: S0_HSD038+ | H34: =CONCATENATE(C34,".",F34) -> K68.2 | I34: =G34 -> S0_HSD038+
A35: SCHEMATIC1 | B35: P000A_S0_BRPHY_P1_2_3_4 | C35: K68 | D35: 3 | E35: 3 | F35: 3 | G35: S0_P2_MDI+ | H35: =CONCATENATE(C35,".",F35) -> K68.3 | I35: =G35 -> S0_P2_MDI+
A36: SCHEMATIC1 | B36: P000A_S0_BRPHY_P1_2_3_4 | C36: K68 | D36: 4 | E36: 4 | F36: 4 | G36: S0_U1_P2_MDI+ | H36: =CONCATENATE(C36,".",F36) -> K68.4 | I36: =G36 -> S0_U1_P2_MDI+
A37: SCHEMATIC1 | B37: P000A_S0_BRPHY_P1_2_3_4 | C37: K68 | D37: 5 | E37: 5 | F37: 5 | G37: S0_U1_P2_MDI- | H37: =CONCATENATE(C37,".",F37) -> K68.5 | I37: =G37 -> S0_U1_P2_MDI-
A38: SCHEMATIC1 | B38: P000A_S0_BRPHY_P1_2_3_4 | C38: K68 | D38: 6 | E38: 6 | F38: 6 | G38: S0_P2_MDI- | H38: =CONCATENATE(C38,".",F38) -> K68.6 | I38: =G38 -> S0_P2_MDI-
A39: SCHEMATIC1 | B39: P000A_S0_BRPHY_P1_2_3_4 | C39: K68 | D39: 7 | E39: 7 | F39: 7 | G39: S0_HSD038- | H39: =CONCATENATE(C39,".",F39) -> K68.7 | I39: =G39 -> S0_HSD038-
A40: SCHEMATIC1 | B40: P000A_S0_BRPHY_P1_2_3_4 | C40: K68 | D40: V+ | E40: V+ | F40: 1 | G40: VP12 | H40: =CONCATENATE(C40,".",F40) -> K68.1 | I40: =G40 -> VP12
A41: SCHEMATIC1 | B41: P000A_S0_BRPHY_P1_2_3_4 | C41: K68 | D41: V- | E41: V- | F41: 8 | G41: SC_UDB068 | H41: =CONCATENATE(C41,".",F41) -> K68.8 | I41: =G41 -> SC_UDB068
A42: SCHEMATIC1 | B42: P000A_S0_BRPHY_P1_2_3_4 | C42: K72 | D42: 2 | E42: 2 | F42: 2 | G42: S0_HSD016+ | H42: =CONCATENATE(C42,".",F42) -> K72.2 | I42: =G42 -> S0_HSD016+
A43: SCHEMATIC1 | B43: P000A_S0_BRPHY_P1_2_3_4 | C43: K72 | D43: 3 | E43: 3 | F43: 3 | G43: S0_P3_MDI+ | H43: =CONCATENATE(C43,".",F43) -> K72.3 | I43: =G43 -> S0_P3_MDI+
A44: SCHEMATIC1 | B44: P000A_S0_BRPHY_P1_2_3_4 | C44: K72 | D44: 4 | E44: 4 | F44: 4 | G44: S0_U1_P3_MDI+ | H44: =CONCATENATE(C44,".",F44) -> K72.4 | I44: =G44 -> S0_U1_P3_MDI+
A45: SCHEMATIC1 | B45: P000A_S0_BRPHY_P1_2_3_4 | C45: K72 | D45: 5 | E45: 5 | F45: 5 | G45: S0_U1_P3_MDI- | H45: =CONCATENATE(C45,".",F45) -> K72.5 | I45: =G45 -> S0_U1_P3_MDI-
A46: SCHEMATIC1 | B46: P000A_S0_BRPHY_P1_2_3_4 | C46: K72 | D46: 6 | E46: 6 | F46: 6 | G46: S0_P3_MDI- | H46: =CONCATENATE(C46,".",F46) -> K72.6 | I46: =G46 -> S0_P3_MDI-
A47: SCHEMATIC1 | B47: P000A_S0_BRPHY_P1_2_3_4 | C47: K72 | D47: 7 | E47: 7 | F47: 7 | G47: S0_HSD016- | H47: =CONCATENATE(C47,".",F47) -> K72.7 | I47: =G47 -> S0_HSD016-
A48: SCHEMATIC1 | B48: P000A_S0_BRPHY_P1_2_3_4 | C48: K72 | D48: V+ | E48: V+ | F48: 1 | G48: VP12 | H48: =CONCATENATE(C48,".",F48) -> K72.1 | I48: =G48 -> VP12
A49: SCHEMATIC1 | B49: P000A_S0_BRPHY_P1_2_3_4 | C49: K72 | D49: V- | E49: V- | F49: 8 | G49: SC_UDB072 | H49: =CONCATENATE(C49,".",F49) -> K72.8 | I49: =G49 -> SC_UDB072
A50: SCHEMATIC1 | B50: P000A_S0_BRPHY_P1_2_3_4 | C50: K76 | D50: 2 | E50: 2 | F50: 2 | G50: S0_HSD026+ | H50: =CONCATENATE(C50,".",F50) -> K76.2 | I50: =G50 -> S0_HSD026+
A51: SCHEMATIC1 | B51: P000A_S0_BRPHY_P1_2_3_4 | C51: K76 | D51: 3 | E51: 3 | F51: 3 | G51: S0_P4_MDI+ | H51: =CONCATENATE(C51,".",F51) -> K76.3 | I51: =G51 -> S0_P4_MDI+
A52: SCHEMATIC1 | B52: P000A_S0_BRPHY_P1_2_3_4 | C52: K76 | D52: 4 | E52: 4 | F52: 4 | G52: S0_U1_P4_MDI+ | H52: =CONCATENATE(C52,".",F52) -> K76.4 | I52: =G52 -> S0_U1_P4_MDI+
A53: SCHEMATIC1 | B53: P000A_S0_BRPHY_P1_2_3_4 | C53: K76 | D53: 5 | E53: 5 | F53: 5 | G53: S0_U1_P4_MDI- | H53: =CONCATENATE(C53,".",F53) -> K76.5 | I53: =G53 -> S0_U1_P4_MDI-
A54: SCHEMATIC1 | B54: P000A_S0_BRPHY_P1_2_3_4 | C54: K76 | D54: 6 | E54: 6 | F54: 6 | G54: S0_P4_MDI- | H54: =CONCATENATE(C54,".",F54) -> K76.6 | I54: =G54 -> S0_P4_MDI-
A55: SCHEMATIC1 | B55: P000A_S0_BRPHY_P1_2_3_4 | C55: K76 | D55: 7 | E55: 7 | F55: 7 | G55: S0_HSD026- | H55: =CONCATENATE(C55,".",F55) -> K76.7 | I55: =G55 -> S0_HSD026-
A56: SCHEMATIC1 | B56: P000A_S0_BRPHY_P1_2_3_4 | C56: K76 | D56: V+ | E56: V+ | F56: 1 | G56: VP12 | H56: =CONCATENATE(C56,".",F56) -> K76.1 | I56: =G56 -> VP12
A57: SCHEMATIC1 | B57: P000A_S0_BRPHY_P1_2_3_4 | C57: K76 | D57: V- | E57: V- | F57: 8 | G57: SC_UDB076 | H57: =CONCATENATE(C57,".",F57) -> K76.8 | I57: =G57 -> SC_UDB076
...

Sheet EtchLengthFromLayout
A1: Design Name C:/Users/rick.kuo/Desktop/9071/038RT-9071CJ_0904_1.brd
A2: Date Tue Sep 22 20:36:12 2026
A3: Net Name | B3: Etch Length (mils) | C3: Manhattan Length (mils) | D3: Percent Manhattan (mils)
A4: AGND | B4: 7916.28 | C4: 28322.72 | D4: 27.95
A5: ATX_P3_3V | B5: 0 | C5: 2725.19 | D5: 0
A6: ATX_P5V | B6: 0 | C6: 1893.38 | D6: 0
A7: ATX_P12V | B7: 0 | C7: 732.93 | D7: 0
A8: CTO_DGS00 | B8: 67.9 | C8: 72.94 | D8: 93.09
A9: CTO_DGS01 | B9: 67.9 | C9: 72.94 | D9: 93.09
A10: CTO_DGS02 | B10: 67.9 | C10: 72.94 | D10: 93.09
A11: CTO_DGS03 | B11: 67.9 | C11: 72.94 | D11: 93.09
A12: CTO_DGS04 | B12: 67.9 | C12: 72.94 | D12: 93.09
A13: CTO_DGS05 | B13: 67.9 | C13: 72.94 | D13: 93.09
A14: CTO_DGS06 | B14: 67.9 | C14: 72.94 | D14: 93.09
A15: CTO_DGS07 | B15: 67.9 | C15: 72.94 | D15: 93.09
... A2825: VR24 | B2825: 78.74 | C2825: 78.74 | D2825: 100

Sheet Assigned_Channel
A1: S0_BPMUINH_HSD141 | B1: SLOT2.CH118
A2: S0_DS_GP_HSD303 | B2: SLOT0.CH58
A3: S0_DS_GP_HSD304 | B3: SLOT0.CH47
A4: S0_DS_HSD085 | B4: SLOT0.CH62
A5: S0_DS_HSD089 | B5: SLOT0.CH59
A6: S0_DS_HSD998 | B6: SLOT0.CH49
A7: S0_DS_HSD999 | B7: SLOT0.CH52
A8: S0_HSD006- | B8: SLOT0.CH55
A9: S0_HSD006+ | B9: SLOT0.CH54
A10: S0_HSD016- | B10: SLOT0.CH127
A11: S0_HSD016+ | B11: SLOT0.CH126
A12: S0_HSD026- | B12: SLOT2.CH55
... A482: SC_PWCT_HSD995 | B482: SLOT0.CH74

Sheet BRPHY
A1: DUT Port [ 1 : 4 ] to Golden | I1: All Site All Port 等長 誤差 1000 mils | M1: 等長調此線段
A2: Site | B2: Pin No | C2: Pin Name | D2: Net | E2: Length | F2: Net | G2: Length | H2: DUT-> Choke ( E + G ) 此處為最短距離 | I2: Net | J2: Length | K2: Net | L2: Length | M2: Net | N2: Length | O2: Net | P2: Length | Q2: Net | R2: Length | S2: Net | T2: Length | V2: Golden -> Choke Net (此處為最短距離) | W2: Length | X2: Total Length (mils) | Y2: P/N Difference (mils) | Z2: Golden | AA2: Pin No | AB2: Pin Name | AC2: Note
A3: SITE0 | B3: =VLOOKUP(C3,PinNo!$B:$C,2,0) -> 175 | C3: P1_MDIN | D3: =VLOOKUP(CONCATENATE($A3,".",$B3),Netlist_VTable!$H:$I,2,0) -> S0_P1_MDI- | E3: =VLOOKUP(D3,EtchLengthFromLayout!$A:$B,2,0) -> 2372.75 | F3: =CONCATENATE("S",MID($A3,5,1),"_U1_",SUBSTITUTE($C3,"IN","I-") ) -> S0_U1_P1_MDI- | G3: =VLOOKUP(F3,EtchLengthFromLayout!$A:$B,2,0) -> 487.03 | H3: =E3+G3 -> 2859.78 | I3: =CONCATENATE("S",MID($A3,5,1),"_U2_",SUBSTITUTE($C3,"IN","I-") ) -> S0_U2_P1_MDI- | J3: =VLOOKUP(I3,EtchLengthFromLayout!$A:$B,2,0) -> 104.67 | K3: =CONCATENATE("S",MID($A3,5,1),"_U3_",SUBSTITUTE($C3,"IN","I-") ) -> S0_U3_P1_MDI- | L3: =VLOOKUP(K3,EtchLengthFromLayout!$A:$B,2,0) -> 9372.74 | M3: =CONCATENATE("S",MID($A3,5,1),"_U4PILB_",SUBSTITUTE($C3,"IN","I-") ) -> S0_U4PILB_P1_MDI- | N3: =VLOOKUP(M3,EtchLengthFromLayout!$A:$B,2,0) -> 8552.4 | Q3: =SUBSTITUTE($V3,"_P","_2_P") -> SG0_2_P1_MDI- | R3: =VLOOKUP(Q3,EtchLengthFromLayout!$A:$B,2,0) -> 3375.36 | S3: =SUBSTITUTE($V3,"_P","_1_P") -> SG0_1_P1_MDI- | T3: =VLOOKUP(S3,EtchLengthFromLayout!$A:$B,2,0) -> 104.67 | V3: =VLOOKUP(CONCATENATE($Z3,".",$AA3),Netlist_VTable!$H:$I,2,0) -> SG0_P1_MDI- | W3: =VLOOKUP(V3,EtchLengthFromLayout!$A:$B,2,0) -> 1215.88 | X3: =E3+G3+J3+L3+N3+P3+R3+T3+W3 -> 25585.5 | Y3: =ABS(X3-X4) -> 0.07 | Z3: GOLD0 | AA3: =VLOOKUP(AB3,PinNo!$B:$C,2,0) -> 175 | AB3: =C3 -> P1_MDIN | AC3: DUT to Golden Port P1
A4: SITE0 | B4: =VLOOKUP(C4,PinNo!$B:$C,2,0) -> 174 | C4: P1_MDIP | D4: =VLOOKUP(CONCATENATE($A4,".",$B4),Netlist_VTable!$H:$I,2,0) -> S0_P1_MDI+ | E4: =VLOOKUP(D4,EtchLengthFromLayout!$A:$B,2,0) -> 2372.77 | F4: =CONCATENATE("S",MID($A4,5,1),"_U1_",SUBSTITUTE($C4,"IP","I+") ) -> S0_U1_P1_MDI+ | G4: =VLOOKUP(F4,EtchLengthFromLayout!$A:$B,2,0) -> 487.03 | H4: =E4+G4 -> 2859.8 | I4: =CONCATENATE("S",MID($A4,5,1),"_U2_",SUBSTITUTE($C4,"IP","I+") ) -> S0_U2_P1_MDI+ | J4: =VLOOKUP(I4,EtchLengthFromLayout!$A:$B,2,0) -> 104.67 | K4: =CONCATENATE("S",MID($A4,5,1),"_U3_",SUBSTITUTE($C4,"IP","I+") ) -> S0_U3_P1_MDI+ | L4: =VLOOKUP(K4,EtchLengthFromLayout!$A:$B,2,0) -> 9372.74 | M4: =CONCATENATE("S",MID($A4,5,1),"_U4PILB_",SUBSTITUTE($C4,"IP","I+") ) -> S0_U4PILB_P1_MDI+ | N4: =VLOOKUP(M4,EtchLengthFromLayout!$A:$B,2,0) -> 8552.41 | Q4: =SUBSTITUTE($V4,"_P","_2_P") -> SG0_2_P1_MDI+ | R4: =VLOOKUP(Q4,EtchLengthFromLayout!$A:$B,2,0) -> 3375.37 | S4: =SUBSTITUTE($V4,"_P","_1_P") -> SG0_1_P1_MDI+ | T4: =VLOOKUP(S4,EtchLengthFromLayout!$A:$B,2,0) -> 104.67 | V4: =VLOOKUP(CONCATENATE($Z4,".",$AA4),Netlist_VTable!$H:$I,2,0) -> SG0_P1_MDI+ | W4: =VLOOKUP(V4,EtchLengthFromLayout!$A:$B,2,0) -> 1215.91 | X4: =E4+G4+J4+L4+N4+P4+R4+T4+W4 -> 25585.57 | Y4: =IF(Y3<=5,"OK, Tolerance<= 5 mils", "Fail, Tolerance > 5 mils") -> OK, Tolerance<= 5 mils | Z4: GOLD0 | AA4: =VLOOKUP(AB4,PinNo!$B:$C,2,0) -> 174 | AB4: =C4 -> P1_MDIP
A5: SITE1 | B5: =VLOOKUP(C5,PinNo!$B:$C,2,0) -> 175 | C5: P1_MDIN | D5: =VLOOKUP(CONCATENATE($A5,".",$B5),Netlist_VTable!$H:$I,2,0) -> S1_P1_MDI- | E5: =VLOOKUP(D5,EtchLengthFromLayout!$A:$B,2,0) -> 1569.13 | F5: =CONCATENATE("S",MID($A5,5,1),"_U1_",SUBSTITUTE($C5,"IN","I-") ) -> S1_U1_P1_MDI- | G5: =VLOOKUP(F5,EtchLengthFromLayout!$A:$B,2,0) -> 487.03 | H5: =E5+G5 -> 2056.16 | I5: =CONCATENATE("S",MID($A5,5,1),"_U2_",SUBSTITUTE($C5,"IN","I-") ) -> S1_U2_P1_MDI- | J5: =VLOOKUP(I5,EtchLengthFromLayout!$A:$B,2,0) -> 104.67 | K5: =CONCATENATE("S",MID($A5,5,1),"_U3_",SUBSTITUTE($C5,"IN","I-") ) -> S1_U3_P1_MDI- | L5: =VLOOKUP(K5,EtchLengthFromLayout!$A:$B,2,0) -> 14139.99 | M5: =CONCATENATE("S",MID($A5,5,1),"_U4PILB_",SUBSTITUTE($C5,"IN","I-") ) -> S1_U4PILB_P1_MDI- | N5: =VLOOKUP(M5,EtchLengthFromLayout!$A:$B,2,0) -> 1541.46 | Q5: =SUBSTITUTE($V5,"_P","_2_P") -> SG1_2_P1_MDI- | R5: =VLOOKUP(Q5,EtchLengthFromLayout!$A:$B,2,0) -> 5161.89 | S5: =SUBSTITUTE($V5,"_P","_1_P") -> SG1_1_P1_MDI- | T5: =VLOOKUP(S5,EtchLengthFromLayout!$A:$B,2,0) -> 104.67 | V5: =VLOOKUP(CONCATENATE($Z5,".",$AA5),Netlist_VTable!$H:$I,2,0) -> SG1_P1_MDI- | W5: =VLOOKUP(V5,EtchLengthFromLayout!$A:$B,2,0) -> 2476.73 | X5: =E5+G5+J5+L5+N5+P5+R5+T5+W5 -> 25585.57 | Y5: =ABS(X5-X6) -> 0.07 | Z5: GOLD1 | AA5: =VLOOKUP(AB5,PinNo!$B:$C,2,0) -> 175 | AB5: =C5 -> P1_MDIN
A6: SITE1 | B6: =VLOOKUP(C6,PinNo!$B:$C,2,0) -> 174 | C6: P1_MDIP | D6: =VLOOKUP(CONCATENATE($A6,".",$B6),Netlist_VTable!$H:$I,2,0) -> S1_P1_MDI+ | E6: =VLOOKUP(D6,EtchLengthFromLayout!$A:$B,2,0) -> 1569.16 | F6: =CONCATENATE("S",MID($A6,5,1),"_U1_",SUBSTITUTE($C6,"IP","I+") ) -> S1_U1_P1_MDI+ | G6: =VLOOKUP(F6,EtchLengthFromLayout!$A:$B,2,0) -> 487.03 | H6: =E6+G6 -> 2056.19 | I6: =CONCATENATE("S",MID($A6,5,1),"_U2_",SUBSTITUTE($C6,"IP","I+") ) -> S1_U2_P1_MDI+ | J6: =VLOOKUP(I6,EtchLengthFromLayout!$A:$B,2,0) -> 104.67 | K6: =CONCATENATE("S",MID($A6,5,1),"_U3_",SUBSTITUTE($C6,"IP","I+") ) -> S1_U3_P1_MDI+ | L6: =VLOOKUP(K6,EtchLengthFromLayout!$A:$B,2,0) -> 14139.95 | M6: =CONCATENATE("S",MID($A6,5,1),"_U4PILB_",SUBSTITUTE($C6,"IP","I+") ) -> S1_U4PILB_P1_MDI+ | N6: =VLOOKUP(M6,EtchLengthFromLayout!$A:$B,2,0) -> 1541.47 | Q6: =SUBSTITUTE($V6,"_P","_2_P") -> SG1_2_P1_MDI+ | R6: =VLOOKUP(Q6,EtchLengthFromLayout!$A:$B,2,0) -> 5161.88 | S6: =SUBSTITUTE($V6,"_P","_1_P") -> SG1_1_P1_MDI+ | T6: =VLOOKUP(S6,EtchLengthFromLayout!$A:$B,2,0) -> 104.67 | V6: =VLOOKUP(CONCATENATE($Z6,".",$AA6),Netlist_VTable!$H:$I,2,0) -> SG1_P1_MDI+ | W6: =VLOOKUP(V6,EtchLengthFromLayout!$A:$B,2,0) -> 2476.67 | X6: =E6+G6+J6+L6+N6+P6+R6+T6+W6 -> 25585.5 | Y6: =IF(Y5<=5,"OK, Tolerance<= 5 mils", "Fail, Tolerance > 5 mils") -> OK, Tolerance<= 5 mils | Z6: GOLD1 | AA6: =VLOOKUP(AB6,PinNo!$B:$C,2,0) -> 174 | AB6: =C6 -> P1_MDIP
A7: SITE2 | B7: =VLOOKUP(C7,PinNo!$B:$C,2,0) -> 175 | C7: P1_MDIN | D7: =VLOOKUP(CONCATENATE($A7,".",$B7),Netlist_VTable!$H:$I,2,0) -> S2_P1_MDI- | E7: =VLOOKUP(D7,EtchLengthFromLayout!$A:$B,2,0) -> 2375.98 | F7: =CONCATENATE("S",MID($A7,5,1),"_U1_",SUBSTITUTE($C7,"IN","I-") ) -> S2_U1_P1_MDI- | G7: =VLOOKUP(F7,EtchLengthFromLayout!$A:$B,2,0) -> 487.03 | H7: =E7+G7 -> 2863.01 | I7: =CONCATENATE("S",MID($A7,5,1),"_U2_",SUBSTITUTE($C7,"IN","I-") ) -> S2_U2_P1_MDI- | J7: =VLOOKUP(I7,EtchLengthFromLayout!$A:$B,2,0) -> 104.67 | K7: =CONCATENATE("S",MID($A7,5,1),"_U3_",SUBSTITUTE($C7,"IN","I-") ) -> S2_U3_P1_MDI- | L7: =VLOOKUP(K7,EtchLengthFromLayout!$A:$B,2,0) -> 10379.47 | M7: =CONCATENATE("S",MID($A7,5,1),"_U4PILB_",SUBSTITUTE($C7,"IN","I-") ) -> S2_U4PILB_P1_MDI- | N7: =VLOOKUP(M7,EtchLengthFromLayout!$A:$B,2,0) -> 4929.91 | Q7: =SUBSTITUTE($V7,"_P","_2_P") -> SG2_2_P1_MDI- | R7: =VLOOKUP(Q7,EtchLengthFromLayout!$A:$B,2,0) -> 4884.37 | S7: =SUBSTITUTE($V7,"_P","_1_P") -> SG2_1_P1_MDI- | T7: =VLOOKUP(S7,EtchLengthFromLayout!$A:$B,2,0) -> 104.67 | V7: =VLOOKUP(CONCATENATE($Z7,".",$AA7),Netlist_VTable!$H:$I,2,0) -> SG2_P1_MDI- | W7: =VLOOKUP(V7,EtchLengthFromLayout!$A:$B,2,0) -> 2319.5 | X7: =E7+G7+J7+L7+N7+P7+R7+T7+W7 -> 25585.6 | Y7: =ABS(X7-X8) -> 0.12 | Z7: GOLD2 | AA7: =VLOOKUP(AB7,PinNo!$B:$C,2,0) -> 175 | AB7: =C7 -> P1_MDIN
A8: SITE2 | B8: =VLOOKUP(C8,PinNo!$B:$C,2,0) -> 174 | C8: P1_MDIP | D8: =VLOOKUP(CONCATENATE($A8,".",$B8),Netlist_VTable!$H:$I,2,0) -> S2_P1_MDI+ | E8: =VLOOKUP(D8,EtchLengthFromLayout!$A:$B,2,0) -> 2375.95 | F8: =CONCATENATE("S",MID($A8,5,1),"_U1_",SUBSTITUTE($C8,"IP","I+") ) -> S2_U1_P1_MDI+ | G8: =VLOOKUP(F8,EtchLengthFromLayout!$A:$B,2,0) -> 487.03 | H8: =E8+G8 -> 2862.98 | I8: =CONCATENATE("S",MID($A8,5,1),"_U2_",SUBSTITUTE($C8,"IP","I+") ) -> S2_U2_P1_MDI+ | J8: =VLOOKUP(I8,EtchLengthFromLayout!$A:$B,2,0) -> 104.67 | K8: =CONCATENATE("S",MID($A8,5,1),"_U3_",SUBSTITUTE($C8,"IP","I+") ) -> S2_U3_P1_MDI+ | L8: =VLOOKUP(K8,EtchLengthFromLayout!$A:$B,2,0) -> 10379.4 | M8: =CONCATENATE("S",MID($A8,5,1),"_U4PILB_",SUBSTITUTE($C8,"IP","I+") ) -> S2_U4PILB_P1_MDI+ | N8: =VLOOKUP(M8,EtchLengthFromLayout!$A:$B,2,0) -> 4929.89 | Q8: =SUBSTITUTE($V8,"_P","_2_P") -> SG2_2_P1_MDI+ | R8: =VLOOKUP(Q8,EtchLengthFromLayout!$A:$B,2,0) -> 4884.36 | S8: =SUBSTITUTE($V8,"_P","_1_P") -> SG2_1_P1_MDI+ | T8: =VLOOKUP(S8,EtchLengthFromLayout!$A:$B,2,0) -> 104.67 | V8: =VLOOKUP(CONCATENATE($Z8,".",$AA8),Netlist_VTable!$H:$I,2,0) -> SG2_P1_MDI+ | W8: =VLOOKUP(V8,EtchLengthFromLayout!$A:$B,2,0) -> 2319.51 | X8: =E8+G8+J8+L8+N8+P8+R8+T8+W8 -> 25585.48 | Y8: =IF(Y7<=5,"OK, Tolerance<= 5 mils", "Fail, Tolerance > 5 mils") -> OK, Tolerance<= 5 mils | Z8: GOLD2 | AA8: =VLOOKUP(AB8,PinNo!$B:$C,2,0) -> 174 | AB8: =C8 -> P1_MDIP
A9: SITE3 | B9: =VLOOKUP(C9,PinNo!$B:$C,2,0) -> 175 | C9: P1_MDIN | D9: =VLOOKUP(CONCATENATE($A9,".",$B9),Netlist_VTable!$H:$I,2,0) -> S3_P1_MDI- | E9: =VLOOKUP(D9,EtchLengthFromLayout!$A:$B,2,0) -> 1569.13 | F9: =CONCATENATE("S",MID($A9,5,1),"_U1_",SUBSTITUTE($C9,"IN","I-") ) -> S3_U1_P1_MDI- | G9: =VLOOKUP(F9,EtchLengthFromLayout!$A:$B,2,0) -> 487.03 | H9: =E9+G9 -> 2056.16 | I9: =CONCATENATE("S",MID($A9,5,1),"_U2_",SUBSTITUTE($C9,"IN","I-") ) -> S3_U2_P1_MDI- | J9: =VLOOKUP(I9,EtchLengthFromLayout!$A:$B,2,0) -> 104.67 | K9: =CONCATENATE("S",MID($A9,5,1),"_U3_",SUBSTITUTE($C9,"IN","I-") ) -> S3_U3_P1_MDI- | L9: =VLOOKUP(K9,EtchLengthFromLayout!$A:$B,2,0) -> 14542.03 | M9: =CONCATENATE("S",MID($A9,5,1),"_U4PILB_",SUBSTITUTE($C9,"IN","I-") ) -> S3_U4PILB_P1_MDI- | N9: =VLOOKUP(M9,EtchLengthFromLayout!$A:$B,2,0) -> 4041.43 | Q9: =SUBSTITUTE($V9,"_P","_2_P") -> SG3_2_P1_MDI- | R9: =VLOOKUP(Q9,EtchLengthFromLayout!$A:$B,2,0) -> 3226.2 | S9: =SUBSTITUTE($V9,"_P","_1_P") -> SG3_1_P1_MDI- | T9: =VLOOKUP(S9,EtchLengthFromLayout!$A:$B,2,0) -> 104.67 | V9: =VLOOKUP(CONCATENATE($Z9,".",$AA9),Netlist_VTable!$H:$I,2,0) -> SG3_P1_MDI- | W9: =VLOOKUP(V9,EtchLengthFromLayout!$A:$B,2,0) -> 1510.29 | X9: =E9+G9+J9+L9+N9+P9+R9+T9+W9 -> 25585.45 | Y9: =ABS(X9-X10) -> 0.12 | Z9: GOLD3 | AA9: =VLOOKUP(AB9,PinNo!$B:$C,2,0) -> 175 | AB9: =C9 -> P1_MDIN
A10: SITE3 | B10: =VLOOKUP(C10,PinNo!$B:$C,2,0) -> 174 | C10: P1_MDIP | D10: =VLOOKUP(CONCATENATE($A10,".",$B10),Netlist_VTable!$H:$I,2,0) -> S3_P1_MDI+ | E10: =VLOOKUP(D10,EtchLengthFromLayout!$A:$B,2,0) -> 1569.16 | F10: =CONCATENATE("S",MID($A10,5,1),"_U1_",SUBSTITUTE($C10,"IP","I+") ) -> S3_U1_P1_MDI+ | G10: =VLOOKUP(F10,EtchLengthFromLayout!$A:$B,2,0) -> 487.03 | H10: =E10+G10 -> 2056.19 | I10: =CONCATENATE("S",MID($A10,5,1),"_U2_",SUBSTITUTE($C10,"IP","I+") ) -> S3_U2_P1_MDI+ | J10: =VLOOKUP(I10,EtchLengthFromLayout!$A:$B,2,0) -> 104.67 | K10: =CONCATENATE("S",MID($A10,5,1),"_U3_",SUBSTITUTE($C10,"IP","I+") ) -> S3_U3_P1_MDI+ | L10: =VLOOKUP(K10,EtchLengthFromLayout!$A:$B,2,0) -> 14542.05 | M10: =CONCATENATE("S",MID($A10,5,1),"_U4PILB_",SUBSTITUTE($C10,"IP","I+") ) -> S3_U4PILB_P1_MDI+ | N10: =VLOOKUP(M10,EtchLengthFromLayout!$A:$B,2,0) -> 4041.44 | Q10: =SUBSTITUTE($V10,"_P","_2_P") -> SG3_2_P1_MDI+ | R10: =VLOOKUP(Q10,EtchLengthFromLayout!$A:$B,2,0) -> 3226.24 | S10: =SUBSTITUTE($V10,"_P","_1_P") -> SG3_1_P1_MDI+ | T10: =VLOOKUP(S10,EtchLengthFromLayout!$A:$B,2,0) -> 104.67 | V10: =VLOOKUP(CONCATENATE($Z10,".",$AA10),Netlist_VTable!$H:$I,2,0) -> SG3_P1_MDI+ | W10: =VLOOKUP(V10,EtchLengthFromLayout!$A:$B,2,0) -> 1510.31 | X10: =E10+G10+J10+L10+N10+P10+R10+T10+W10 -> 25585.57 | Y10: =IF(Y9<=5,"OK, Tolerance<= 5 mils", "Fail, Tolerance > 5 mils") -> OK, Tolerance<= 5 mils | Z10: GOLD3 | AA10: =VLOOKUP(AB10,PinNo!$B:$C,2,0) -> 174 | AB10: =C10 -> P1_MDIP
F11: Max | H11: =MAX(H3:H10) -> 2863.01 | V11: Max | X11: =MAX(X3:X10) -> 25585.6
F12: Min | H12: =MIN(H3:H10) -> 2056.16 | V12: Min | X12: =MIN(X3:X10) -> 25585.45
F13: Max-Min | H13: =ABS(H11-H12) -> 806.85 | V13: Max-Min | X13: =ABS(X11-X12) -> 0.15
A16: Site | B16: Pin No | C16: Pin Name | D16: Net | E16: Length | F16: Net | G16: Length | H16: DUT-> Choke ( E + G ) 此處為最短距離 | I16: Net | J16: Length | K16: Net | L16: Length | M16: Net | N16: Length | O16: Net | P16: Length | Q16: Net | R16: Length | S16: Net | T16: Length | V16: Golden -> Choke Net (此處為最短距離) | W16: Length | X16: Total Length (mils) | Y16: P/N Difference (mils) | Z16: Golden | AA16: Pin No | AB16: Pin Name | AC16: Note
A17: SITE0 | B17: =VLOOKUP(C17,PinNo!$B:$C,2,0) -> 172 | C17: P2_MDIN | D17: =VLOOKUP(CONCATENATE($A17,".",$B17),Netlist_VTable!$H:$I,2,0) -> S0_P2_MDI- | E17: =VLOOKUP(D17,EtchLengthFromLayout!$A:$B,2,0) -> 2539.18 | F17: =CONCATENATE("S",MID($A17,5,1),"_U1_",SUBSTITUTE($C17,"IN","I-") ) -> S0_U1_P2_MDI- | G17: =VLOOKUP(F17,EtchLengthFromLayout!$A:$B,2,0) -> 487.03 | H17: =E17+G17 -> 3026.21 | I17: =CONCATENATE("S",MID($A17,5,1),"_U2_",SUBSTITUTE($C17,"IN","I-") ) -> S0_U2_P2_MDI- | J17: =VLOOKUP(I17,EtchLengthFromLayout!$A:$B,2,0) -> 104.67 | K17: =CONCATENATE("S",MID($A17,5,1),"_U3_",SUBSTITUTE($C17,"IN","I-") ) -> S0_U3_P2_MDI- | L17: =VLOOKUP(K17,EtchLengthFromLayout!$A:$B,2,0) -> 9673.1 | M17: =CONCATENATE("S",MID($A17,5,1),"_U4PILB_",SUBSTITUTE($C17,"IN","I-") ) -> S0_U4PILB_P2_MDI- | N17: =VLOOKUP(M17,EtchLengthFromLayout!$A:$B,2,0) -> 7918.85 | Q17: =SUBSTITUTE($V17,"_P","_2_P") -> SG0_2_P2_MDI- | R17: =VLOOKUP(Q17,EtchLengthFromLayout!$A:$B,2,0) -> 3571.19 | S17: =SUBSTITUTE($V17,"_P","_1_P") -> SG0_1_P2_MDI- | T17: =VLOOKUP(S17,EtchLengthFromLayout!$A:$B,2,0) -> 104.67 | V17: =VLOOKUP(CONCATENATE($Z17,".",$AA17),Netlist_VTable!$H:$I,2,0) -> SG0_P2_MDI- | W17: =VLOOKUP(V17,EtchLengthFromLayout!$A:$B,2,0) -> 1186.77 | X17: =E17+G17+J17+L17+N17+P17+R17+T17+W17 -> 25585.46 | Y17: =ABS(X17-X18) -> 0.04 | Z17: GOLD0 | AA17: =VLOOKUP(AB17,PinNo!$B:$C,2,0) -> 172 | AB17: =C17 -> P2_MDIN | AC17: DUT to Golden Port P2
A18: SITE0 | B18: =VLOOKUP(C18,PinNo!$B:$C,2,0) -> 171 | C18: P2_MDIP | D18: =VLOOKUP(CONCATENATE($A18,".",$B18),Netlist_VTable!$H:$I,2,0) -> S0_P2_MDI+ | E18: =VLOOKUP(D18,EtchLengthFromLayout!$A:$B,2,0) -> 2539.13 | F18: =CONCATENATE("S",MID($A18,5,1),"_U1_",SUBSTITUTE($C18,"IP","I+") ) -> S0_U1_P2_MDI+ | G18: =VLOOKUP(F18,EtchLengthFromLayout!$A:$B,2,0) -> 487.03 | H18: =E18+G18 -> 3026.16 | I18: =CONCATENATE("S",MID($A18,5,1),"_U2_",SUBSTITUTE($C18,"IP","I+") ) -> S0_U2_P2_MDI+ | J18: =VLOOKUP(I18,EtchLengthFromLayout!$A:$B,2,0) -> 104.67 | K18: =CONCATENATE("S",MID($A18,5,1),"_U3_",SUBSTITUTE($C18,"IP","I+") ) -> S0_U3_P2_MDI+ | L18: =VLOOKUP(K18,EtchLengthFromLayout!$A:$B,2,0) -> 9673.06 | M18: =CONCATENATE("S",MID($A18,5,1),"_U4PILB_",SUBSTITUTE($C18,"IP","I+") ) -> S0_U4PILB_P2_MDI+ | N18: =VLOOKUP(M18,EtchLengthFromLayout!$A:$B,2,0) -> 7918.85 | Q18: =SUBSTITUTE($V18,"_P","_2_P") -> SG0_2_P2_MDI+ | R18: =VLOOKUP(Q18,EtchLengthFromLayout!$A:$B,2,0) -> 3571.22 | S18: =SUBSTITUTE($V18,"_P","_1_P") -> SG0_1_P2_MDI+ | T18: =VLOOKUP(S18,EtchLengthFromLayout!$A:$B,2,0) -> 104.67 | V18: =VLOOKUP(CONCATENATE($Z18,".",$AA18),Netlist_VTable!$H:$I,2,0) -> SG0_P2_MDI+ | W18: =VLOOKUP(V18,EtchLengthFromLayout!$A:$B,2,0) -> 1186.79 | X18: =E18+G18+J18+L18+N18+P18+R18+T18+W18 -> 25585.42 | Y18: =IF(Y17<=5,"OK, Tolerance<= 5 mils", "Fail, Tolerance > 5 mils") -> OK, Tolerance<= 5 mils | Z18: GOLD0 | AA18: =VLOOKUP(AB18,PinNo!$B:$C,2,0) -> 171 | AB18: =C18 -> P2_MDIP
A19: SITE1 | B19: =VLOOKUP(C19,PinNo!$B:$C,2,0) -> 172 | C19: P2_MDIN | D19: =VLOOKUP(CONCATENATE($A19,".",$B19),Netlist_VTable!$H:$I,2,0) -> S1_P2_MDI- | E19: =VLOOKUP(D19,EtchLengthFromLayout!$A:$B,2,0) -> 1739.8 | F19: =CONCATENATE("S",MID($A19,5,1),"_U1_",SUBSTITUTE($C19,"IN","I-") ) -> S1_U1_P2_MDI- | G19: =VLOOKUP(F19,EtchLengthFromLayout!$A:$B,2,0) -> 487.03 | H19: =E19+G19 -> 2226.83 | I19: =CONCATENATE("S",MID($A19,5,1),"_U2_",SUBSTITUTE($C19,"IN","I-") ) -> S1_U2_P2_MDI- | J19: =VLOOKUP(I19,EtchLengthFromLayout!$A:$B,2,0) -> 104.67 | K19: =CONCATENATE("S",MID($A19,5,1),"_U3_",SUBSTITUTE($C19,"IN","I-") ) -> S1_U3_P2_MDI- | L19: =VLOOKUP(K19,EtchLengthFromLayout!$A:$B,2,0) -> 14140.83 | M19: =CONCATENATE("S",MID($A19,5,1),"_U4PILB_",SUBSTITUTE($C19,"IN","I-") ) -> S1_U4PILB_P2_MDI- | N19: =VLOOKUP(M19,EtchLengthFromLayout!$A:$B,2,0) -> 1848.6 | Q19: =SUBSTITUTE($V19,"_P","_2_P") -> SG1_2_P2_MDI- | R19: =VLOOKUP(Q19,EtchLengthFromLayout!$A:$B,2,0) -> 4698.68 | S19: =SUBSTITUTE($V19,"_P","_1_P") -> SG1_1_P2_MDI- | T19: =VLOOKUP(S19,EtchLengthFromLayout!$A:$B,2,0) -> 104.67 | V19: =VLOOKUP(CONCATENATE($Z19,".",$AA19),Netlist_VTable!$H:$I,2,0) -> SG1_P2_MDI- | W19: =VLOOKUP(V19,EtchLengthFromLayout!$A:$B,2,0) -> 2461.23 | X19: =E19+G19+J19+L19+N19+P19+R19+T19+W19 -> 25585.51 | Y19: =ABS(X19-X20) -> 0.08 | Z19: GOLD1 | AA19: =VLOOKUP(AB19,PinNo!$B:$C,2,0) -> 172 | AB19: =C19 -> P2_MDIN
A20: SITE1 | B20: =VLOOKUP(C20,PinNo!$B:$C,2,0) -> 171 | C20: P2_MDIP | D20: =VLOOKUP(CONCATENATE($A20,".",$B20),Netlist_VTable!$H:$I,2,0) -> S1_P2_MDI+ | E20: =VLOOKUP(D20,EtchLengthFromLayout!$A:$B,2,0) -> 1739.83 | F20: =CONCATENATE("S",MID($A20,5,1),"_U1_",SUBSTITUTE($C20,"IP","I+") ) -> S1_U1_P2_MDI+ | G20: =VLOOKUP(F20,EtchLengthFromLayout!$A:$B,2,0) -> 487.03 | H20: =E20+G20 -> 2226.86 | I20: =CONCATENATE("S",MID($A20,5,1),"_U2_",SUBSTITUTE($C20,"IP","I+") ) -> S1_U2_P2_MDI+ | J20: =VLOOKUP(I20,EtchLengthFromLayout!$A:$B,2,0) -> 104.67 | K20: =CONCATENATE("S",MID($A20,5,1),"_U3_",SUBSTITUTE($C20,"IP","I+") ) -> S1_U3_P2_MDI+ | L20: =VLOOKUP(K20,EtchLengthFromLayout!$A:$B,2,0) -> 14140.91 | M20: =CONCATENATE("S",MID($A20,5,1),"_U4PILB_",SUBSTITUTE($C20,"IP","I+") ) -> S1_U4PILB_P2_MDI+ | N20: =VLOOKUP(M20,EtchLengthFromLayout!$A:$B,2,0) -> 1848.6 | Q20: =SUBSTITUTE($V20,"_P","_2_P") -> SG1_2_P2_MDI+ | R20: =VLOOKUP(Q20,EtchLengthFromLayout!$A:$B,2,0) -> 4698.65 | S20: =SUBSTITUTE($V20,"_P","_1_P") -> SG1_1_P2_MDI+ | T20: =VLOOKUP(S20,EtchLengthFromLayout!$A:$B,2,0) -> 104.67 | V20: =VLOOKUP(CONCATENATE($Z20,".",$AA20),Netlist_VTable!$H:$I,2,0) -> SG1_P2_MDI+ | W20: =VLOOKUP(V20,EtchLengthFromLayout!$A:$B,2,0) -> 2461.23 | X20: =E20+G20+J20+L20+N20+P20+R20+T20+W20 -> 25585.59 | Y20: =IF(Y19<=5,"OK, Tolerance<= 5 mils", "Fail, Tolerance > 5 mils") -> OK, Tolerance<= 5 mils | Z20: GOLD1 | AA20: =VLOOKUP(AB20,PinNo!$B:$C,2,0) -> 171 | AB20: =C20 -> P2_MDIP
A21: SITE2 | B21: =VLOOKUP(C21,PinNo!$B:$C,2,0) -> 172 | C21: P2_MDIN | D21: =VLOOKUP(CONCATENATE($A21,".",$B21),Netlist_VTable!$H:$I,2,0) -> S2_P2_MDI- | E21: =VLOOKUP(D21,EtchLengthFromLayout!$A:$B,2,0) -> 2539.18 | F21: =CONCATENATE("S",MID($A21,5,1),"_U1_",SUBSTITUTE($C21,"IN","I-") ) -> S2_U1_P2_MDI- | G21: =VLOOKUP(F21,EtchLengthFromLayout!$A:$B,2,0) -> 487.03 | H21: =E21+G21 -> 3026.21 | I21: =CONCATENATE("S",MID($A21,5,1),"_U2_",SUBSTITUTE($C21,"IN","I-") ) -> S2_U2_P2_MDI- | J21: =VLOOKUP(I21,EtchLengthFromLayout!$A:$B,2,0) -> 104.67 | K21: =CONCATENATE("S",MID($A21,5,1),"_U3_",SUBSTITUTE($C21,"IN","I-") ) -> S2_U3_P2_MDI- | L21: =VLOOKUP(K21,EtchLengthFromLayout!$A:$B,2,0) -> 9810.3 | M21: =CONCATENATE("S",MID($A21,5,1),"_U4PILB_",SUBSTITUTE($C21,"IN","I-") ) -> S2_U4PILB_P2_MDI- | N21: =VLOOKUP(M21,EtchLengthFromLayout!$A:$B,2,0) -> 5849.14 | Q21: =SUBSTITUTE($V21,"_P","_2_P") -> SG2_2_P2_MDI- | R21: =VLOOKUP(Q21,EtchLengthFromLayout!$A:$B,2,0) -> 4362.56 | S21: =SUBSTITUTE($V21,"_P","_1_P") -> SG2_1_P2_MDI- | T21: =VLOOKUP(S21,EtchLengthFromLayout!$A:$B,2,0) -> 104.67 | V21: =VLOOKUP(CONCATENATE($Z21,".",$AA21),Netlist_VTable!$H:$I,2,0) -> SG2_P2_MDI- | W21: =VLOOKUP(V21,EtchLengthFromLayout!$A:$B,2,0) -> 2328.06 | X21: =E21+G21+J21+L21+N21+P21+R21+T21+W21 -> 25585.61 | Y21: =ABS(X21-X22) -> 0.11 | Z21: GOLD2 | AA21: =VLOOKUP(AB21,PinNo!$B:$C,2,0) -> 172 | AB21: =C21 -> P2_MDIN
A22: SITE2 | B22: =VLOOKUP(C22,PinNo!$B:$C,2,0) -> 171 | C22: P2_MDIP | D22: =VLOOKUP(CONCATENATE($A22,".",$B22),Netlist_VTable!$H:$I,2,0) -> S2_P2_MDI+ | E22: =VLOOKUP(D22,EtchLengthFromLayout!$A:$B,2,0) -> 2539.13 | F22: =CONCATENATE("S",MID($A22,5,1),"_U1_",SUBSTITUTE($C22,"IP","I+") ) -> S2_U1_P2_MDI+ | G22: =VLOOKUP(F22,EtchLengthFromLayout!$A:$B,2,0) -> 487.03 | H22: =E22+G22 -> 3026.16 | I22: =CONCATENATE("S",MID($A22,5,1),"_U2_",SUBSTITUTE($C22,"IP","I+") ) -> S2_U2_P2_MDI+ | J22: =VLOOKUP(I22,EtchLengthFromLayout!$A:$B,2,0) -> 104.67 | K22: =CONCATENATE("S",MID($A22,5,1),"_U3_",SUBSTITUTE($C22,"IP","I+") ) -> S2_U3_P2_MDI+ | L22: =VLOOKUP(K22,EtchLengthFromLayout!$A:$B,2,0) -> 9810.27 | M22: =CONCATENATE("S",MID($A22,5,1),"_U4PILB_",SUBSTITUTE($C22,"IP","I+") ) -> S2_U4PILB_P2_MDI+ | N22: =VLOOKUP(M22,EtchLengthFromLayout!$A:$B,2,0) -> 5849.13 | Q22: =SUBSTITUTE($V22,"_P","_2_P") -> SG2_2_P2_MDI+ | R22: =VLOOKUP(Q22,EtchLengthFromLayout!$A:$B,2,0) -> 4362.52 | S22: =SUBSTITUTE($V22,"_P","_1_P") -> SG2_1_P2_MDI+ | T22: =VLOOKUP(S22,EtchLengthFromLayout!$A:$B,2,0) -> 104.67 | V22: =VLOOKUP(CONCATENATE($Z22,".",$AA22),Netlist_VTable!$H:$I,2,0) -> SG2_P2_MDI+ | W22: =VLOOKUP(V22,EtchLengthFromLayout!$A:$B,2,0) -> 2328.08 | X22: =E22+G22+J22+L22+N22+P22+R22+T22+W22 -> 25585.5 | Y22: =IF(Y21<=5,"OK, Tolerance<= 5 mils", "Fail, Tolerance > 5 mils") -> OK, Tolerance<= 5 mils | Z22: GOLD2 | AA22: =VLOOKUP(AB22,PinNo!$B:$C,2,0) -> 171 | AB22: =C22 -> P2_MDIP
A23: SITE3 | B23: =VLOOKUP(C23,PinNo!$B:$C,2,0) -> 172 | C23: P2_MDIN | D23: =VLOOKUP(CONCATENATE($A23,".",$B23),Netlist_VTable!$H:$I,2,0) -> S3_P2_MDI- | E23: =VLOOKUP(D23,EtchLengthFromLayout!$A:$B,2,0) -> 1739.8 | F23: =CONCATENATE("S",MID($A23,5,1),"_U1_",SUBSTITUTE($C23,"IN","I-") ) -> S3_U1_P2_MDI- | G23: =VLOOKUP(F23,EtchLengthFromLayout!$A:$B,2,0) -> 487.03 | H23: =E23+G23 -> 2226.83 | I23: =CONCATENATE("S",MID($A23,5,1),"_U2_",SUBSTITUTE($C23,"IN","I-") ) -> S3_U2_P2_MDI- | J23: =VLOOKUP(I23,EtchLengthFromLayout!$A:$B,2,0) -> 104.67 | K23: =CONCATENATE("S",MID($A23,5,1),"_U3_",SUBSTITUTE($C23,"IN","I-") ) -> S3_U3_P2_MDI- | L23: =VLOOKUP(K23,EtchLengthFromLayout!$A:$B,2,0) -> 14204.14 | M23: =CONCATENATE("S",MID($A23,5,1),"_U4PILB_",SUBSTITUTE($C23,"IN","I-") ) -> S3_U4PILB_P2_MDI- | N23: =VLOOKUP(M23,EtchLengthFromLayout!$A:$B,2,0) -> 4063.18 | Q23: =SUBSTITUTE($V23,"_P","_2_P") -> SG3_2_P2_MDI- | R23: =VLOOKUP(Q23,EtchLengthFromLayout!$A:$B,2,0) -> 3427.8 | S23: =SUBSTITUTE($V23,"_P","_1_P") -> SG3_1_P2_MDI- | T23: =VLOOKUP(S23,EtchLengthFromLayout!$A:$B,2,0) -> 104.67 | V23: =VLOOKUP(CONCATENATE($Z23,".",$AA23),Netlist_VTable!$H:$I,2,0) -> SG3_P2_MDI- | W23: =VLOOKUP(V23,EtchLengthFromLayout!$A:$B,2,0) -> 1454.2 | X23: =E23+G23+J23+L23+N23+P23+R23+T23+W23 -> 25585.49 | Y23: =ABS(X23-X24) -> 0.06 | Z23: GOLD3 | AA23: =VLOOKUP(AB23,PinNo!$B:$C,2,0) -> 172 | AB23: =C23 -> P2_MDIN
A24: SITE3 | B24: =VLOOKUP(C24,PinNo!$B:$C,2,0) -> 171 | C24: P2_MDIP | D24: =VLOOKUP(CONCATENATE($A24,".",$B24),Netlist_VTable!$H:$I,2,0) -> S3_P2_MDI+ | E24: =VLOOKUP(D24,EtchLengthFromLayout!$A:$B,2,0) -> 1739.83 | F24: =CONCATENATE("S",MID($A24,5,1),"_U1_",SUBSTITUTE($C24,"IP","I+") ) -> S3_U1_P2_MDI+ | G24: =VLOOKUP(F24,EtchLengthFromLayout!$A:$B,2,0) -> 487.03 | H24: =E24+G24 -> 2226.86 | I24: =CONCATENATE("S",MID($A24,5,1),"_U2_",SUBSTITUTE($C24,"IP","I+") ) -> S3_U2_P2_MDI+ | J24: =VLOOKUP(I24,EtchLengthFromLayout!$A:$B,2,0) -> 104.67 | K24: =CONCATENATE("S",MID($A24,5,1),"_U3_",SUBSTITUTE($C24,"IP","I+") ) -> S3_U3_P2_MDI+ | L24: =VLOOKUP(K24,EtchLengthFromLayout!$A:$B,2,0) -> 14204.12 | M24: =CONCATENATE("S",MID($A24,5,1),"_U4PILB_",SUBSTITUTE($C24,"IP","I+") ) -> S3_U4PILB_P2_MDI+ | N24: =VLOOKUP(M24,EtchLengthFromLayout!$A:$B,2,0) -> 4063.18 | Q24: =SUBSTITUTE($V24,"_P","_2_P") -> SG3_2_P2_MDI+ | R24: =VLOOKUP(Q24,EtchLengthFromLayout!$A:$B,2,0) -> 3427.73 | S24: =SUBSTITUTE($V24,"_P","_1_P") -> SG3_1_P2_MDI+ | T24: =VLOOKUP(S24,EtchLengthFromLayout!$A:$B,2,0) -> 104.67 | V24: =VLOOKUP(CONCATENATE($Z24,".",$AA24),Netlist_VTable!$H:$I,2,0) -> SG3_P2_MDI+ | W24: =VLOOKUP(V24,EtchLengthFromLayout!$A:$B,2,0) -> 1454.2 | X24: =E24+G24+J24+L24+N24+P24+R24+T24+W24 -> 25585.43 | Y24: =IF(Y23<=5,"OK, Tolerance<= 5 mils", "Fail, Tolerance > 5 mils") -> OK, Tolerance<= 5 mils | Z24: GOLD3 | AA24: =VLOOKUP(AB24,PinNo!$B:$C,2,0) -> 171 | AB24: =C24 -> P2_MDIP
F25: Max | H25: =MAX(H17:H24) -> 3026.21 | V25: Max | X25: =MAX(X17:X24) -> 25585.61
F26: Min | H26: =MIN(H17:H24) -> 2226.83 | V26: Min | X26: =MIN(X17:X24) -> 25585.42
F27: Max-Min | H27: =ABS(H25-H26) -> 799.38 | V27: Max-Min | X27: =ABS(X25-X26) -> 0.19
A30: Site | B30: Pin No | C30: Pin Name | D30: Net | E30: Length | F30: Net | G30: Length | H30: DUT-> Choke ( E + G ) 此處為最短距離 | I30: Net | J30: Length | K30: Net | L30: Length | M30: Net | N30: Length | O30: Net | P30: Length | Q30: Net | R30: Length | S30: Net | T30: Length | V30: Golden -> Choke Net (此處為最短距離) | W30: Length | X30: Total Length (mils) | Y30: P/N Difference (mils) | Z30: Golden | AA30: Pin No | AB30: Pin Name | AC30: Note
A31: SITE0 | B31: =VLOOKUP(C31,PinNo!$B:$C,2,0) -> 168 | C31: P3_MDIN | D31: =VLOOKUP(CONCATENATE($A31,".",$B31),Netlist_VTable!$H:$I,2,0) -> S0_P3_MDI- | E31: =VLOOKUP(D31,EtchLengthFromLayout!$A:$B,2,0) -> 2588.65 | F31: =CONCATENATE("S",MID($A31,5,1),"_U1_",SUBSTITUTE($C31,"IN","I-") ) -> S0_U1_P3_MDI- | G31: =VLOOKUP(F31,EtchLengthFromLayout!$A:$B,2,0) -> 487.03 | H31: =E31+G31 -> 3075.68 | I31: =CONCATENATE("S",MID($A31,5,1),"_U2_",SUBSTITUTE($C31,"IN","I-") ) -> S0_U2_P3_MDI- | J31: =VLOOKUP(I31,EtchLengthFromLayout!$A:$B,2,0) -> 104.67 | K31: =CONCATENATE("S",MID($A31,5,1),"_U3_",SUBSTITUTE($C31,"IN","I-") ) -> S0_U3_P3_MDI- | L31: =VLOOKUP(K31,EtchLengthFromLayout!$A:$B,2,0) -> 10350.43 | M31: =CONCATENATE("S",MID($A31,5,1),"_U4PILB_",SUBSTITUTE($C31,"IN","I-") ) -> S0_U4PILB_P3_MDI- | N31: =VLOOKUP(M31,EtchLengthFromLayout!$A:$B,2,0) -> 7040.09 | Q31: =SUBSTITUTE($V31,"_P","_2_P") -> SG0_2_P3_MDI- | R31: =VLOOKUP(Q31,EtchLengthFromLayout!$A:$B,2,0) -> 3799.67 | S31: =SUBSTITUTE($V31,"_P","_1_P") -> SG0_1_P3_MDI- | T31: =VLOOKUP(S31,EtchLengthFromLayout!$A:$B,2,0) -> 104.67 | V31: =VLOOKUP(CONCATENATE($Z31,".",$AA31),Netlist_VTable!$H:$I,2,0) -> SG0_P3_MDI- | W31: =VLOOKUP(V31,EtchLengthFromLayout!$A:$B,2,0) -> 1110.21 | X31: =E31+G31+J31+L31+N31+P31+R31+T31+W31 -> 25585.42 | Y31: =ABS(X31-X32) -> 0.1 | Z31: GOLD0 | AA31: =VLOOKUP(AB31,PinNo!$B:$C,2,0) -> 168 | AB31: =C31 -> P3_MDIN | AC31: DUT to Golden Port P3
A32: SITE0 | B32: =VLOOKUP(C32,PinNo!$B:$C,2,0) -> 167 | C32: P3_MDIP | D32: =VLOOKUP(CONCATENATE($A32,".",$B32),Netlist_VTable!$H:$I,2,0) -> S0_P3_MDI+ | E32: =VLOOKUP(D32,EtchLengthFromLayout!$A:$B,2,0) -> 2588.66 | F32: =CONCATENATE("S",MID($A32,5,1),"_U1_",SUBSTITUTE($C32,"IP","I+") ) -> S0_U1_P3_MDI+ | G32: =VLOOKUP(F32,EtchLengthFromLayout!$A:$B,2,0) -> 487.03 | H32: =E32+G32 -> 3075.69 | I32: =CONCATENATE("S",MID($A32,5,1),"_U2_",SUBSTITUTE($C32,"IP","I+") ) -> S0_U2_P3_MDI+ | J32: =VLOOKUP(I32,EtchLengthFromLayout!$A:$B,2,0) -> 104.67 | K32: =CONCATENATE("S",MID($A32,5,1),"_U3_",SUBSTITUTE($C32,"IP","I+") ) -> S0_U3_P3_MDI+ | L32: =VLOOKUP(K32,EtchLengthFromLayout!$A:$B,2,0) -> 10350.52 | M32: =CONCATENATE("S",MID($A32,5,1),"_U4PILB_",SUBSTITUTE($C32,"IP","I+") ) -> S0_U4PILB_P3_MDI+ | N32: =VLOOKUP(M32,EtchLengthFromLayout!$A:$B,2,0) -> 7040.07 | Q32: =SUBSTITUTE($V32,"_P","_2_P") -> SG0_2_P3_MDI+ | R32: =VLOOKUP(Q32,EtchLengthFromLayout!$A:$B,2,0) -> 3799.66 | S32: =SUBSTITUTE($V32,"_P","_1_P") -> SG0_1_P3_MDI+ | T32: =VLOOKUP(S32,EtchLengthFromLayout!$A:$B,2,0) -> 104.67 | V32: =VLOOKUP(CONCATENATE($Z32,".",$AA32),Netlist_VTable!$H:$I,2,0) -> SG0_P3_MDI+ | W32: =VLOOKUP(V32,EtchLengthFromLayout!$A:$B,2,0) -> 1110.24 | X32: =E32+G32+J32+L32+N32+P32+R32+T32+W32 -> 25585.52 | Y32: =IF(Y31<=5,"OK, Tolerance<= 5 mils", "Fail, Tolerance > 5 mils") -> OK, Tolerance<= 5 mils | Z32: GOLD0 | AA32: =VLOOKUP(AB32,PinNo!$B:$C,2,0) -> 167 | AB32: =C32 -> P3_MDIP
A33: SITE1 | B33: =VLOOKUP(C33,PinNo!$B:$C,2,0) -> 168 | C33: P3_MDIN | D33: =VLOOKUP(CONCATENATE($A33,".",$B33),Netlist_VTable!$H:$I,2,0) -> S1_P3_MDI- | E33: =VLOOKUP(D33,EtchLengthFromLayout!$A:$B,2,0) -> 1671.04 | F33: =CONCATENATE("S",MID($A33,5,1),"_U1_",SUBSTITUTE($C33,"IN","I-") ) -> S1_U1_P3_MDI- | G33: =VLOOKUP(F33,EtchLengthFromLayout!$A:$B,2,0) -> 487.03 | H33: =E33+G33 -> 2158.07 | I33: =CONCATENATE("S",MID($A33,5,1),"_U2_",SUBSTITUTE($C33,"IN","I-") ) -> S1_U2_P3_MDI- | J33: =VLOOKUP(I33,EtchLengthFromLayout!$A:$B,2,0) -> 104.67 | K33: =CONCATENATE("S",MID($A33,5,1),"_U3_",SUBSTITUTE($C33,"IN","I-") ) -> S1_U3_P3_MDI- | L33: =VLOOKUP(K33,EtchLengthFromLayout!$A:$B,2,0) -> 14414.03 | M33: =CONCATENATE("S",MID($A33,5,1),"_U4PILB_",SUBSTITUTE($C33,"IN","I-") ) -> S1_U4PILB_P3_MDI- | N33: =VLOOKUP(M33,EtchLengthFromLayout!$A:$B,2,0) -> 1743.8 | Q33: =SUBSTITUTE($V33,"_P","_2_P") -> SG1_2_P3_MDI- | R33: =VLOOKUP(Q33,EtchLengthFromLayout!$A:$B,2,0) -> 4608.36 | S33: =SUBSTITUTE($V33,"_P","_1_P") -> SG1_1_P3_MDI- | T33: =VLOOKUP(S33,EtchLengthFromLayout!$A:$B,2,0) -> 104.67 | V33: =VLOOKUP(CONCATENATE($Z33,".",$AA33),Netlist_VTable!$H:$I,2,0) -> SG1_P3_MDI- | W33: =VLOOKUP(V33,EtchLengthFromLayout!$A:$B,2,0) -> 2451.82 | X33: =E33+G33+J33+L33+N33+P33+R33+T33+W33 -> 25585.42 | Y33: =ABS(X33-X34) -> 0.02 | Z33: GOLD1 | AA33: =VLOOKUP(AB33,PinNo!$B:$C,2,0) -> 168 | AB33: =C33 -> P3_MDIN
A34: SITE1 | B34: =VLOOKUP(C34,PinNo!$B:$C,2,0) -> 167 | C34: P3_MDIP | D34: =VLOOKUP(CONCATENATE($A34,".",$B34),Netlist_VTable!$H:$I,2,0) -> S1_P3_MDI+ | E34: =VLOOKUP(D34,EtchLengthFromLayout!$A:$B,2,0) -> 1671.04 | F34: =CONCATENATE("S",MID($A34,5,1),"_U1_",SUBSTITUTE($C34,"IP","I+") ) -> S1_U1_P3_MDI+ | G34: =VLOOKUP(F34,EtchLengthFromLayout!$A:$B,2,0) -> 487.03 | H34: =E34+G34 -> 2158.07 | I34: =CONCATENATE("S",MID($A34,5,1),"_U2_",SUBSTITUTE($C34,"IP","I+") ) -> S1_U2_P3_MDI+ | J34: =VLOOKUP(I34,EtchLengthFromLayout!$A:$B,2,0) -> 104.67 | K34: =CONCATENATE("S",MID($A34,5,1),"_U3_",SUBSTITUTE($C34,"IP","I+") ) -> S1_U3_P3_MDI+ | L34: =VLOOKUP(K34,EtchLengthFromLayout!$A:$B,2,0) -> 14414.02 | M34: =CONCATENATE("S",MID($A34,5,1),"_U4PILB_",SUBSTITUTE($C34,"IP","I+") ) -> S1_U4PILB_P3_MDI+ | N34: =VLOOKUP(M34,EtchLengthFromLayout!$A:$B,2,0) -> 1743.79 | Q34: =SUBSTITUTE($V34,"_P","_2_P") -> SG1_2_P3_MDI+ | R34: =VLOOKUP(Q34,EtchLengthFromLayout!$A:$B,2,0) -> 4608.38 | S34: =SUBSTITUTE($V34,"_P","_1_P") -> SG1_1_P3_MDI+ | T34: =VLOOKUP(S34,EtchLengthFromLayout!$A:$B,2,0) -> 104.67 | V34: =VLOOKUP(CONCATENATE($Z34,".",$AA34),Netlist_VTable!$H:$I,2,0) -> SG1_P3_MDI+ | W34: =VLOOKUP(V34,EtchLengthFromLayout!$A:$B,2,0) -> 2451.8 | X34: =E34+G34+J34+L34+N34+P34+R34+T34+W34 -> 25585.4 | Y34: =IF(Y33<=5,"OK, Tolerance<= 5 mils", "Fail, Tolerance > 5 mils") -> OK, Tolerance<= 5 mils | Z34: GOLD1 | AA34: =VLOOKUP(AB34,PinNo!$B:$C,2,0) -> 167 | AB34: =C34 -> P3_MDIP
A35: SITE2 | B35: =VLOOKUP(C35,PinNo!$B:$C,2,0) -> 168 | C35: P3_MDIN | D35: =VLOOKUP(CONCATENATE($A35,".",$B35),Netlist_VTable!$H:$I,2,0) -> S2_P3_MDI- | E35: =VLOOKUP(D35,EtchLengthFromLayout!$A:$B,2,0) -> 2593.96 | F35: =CONCATENATE("S",MID($A35,5,1),"_U1_",SUBSTITUTE($C35,"IN","I-") ) -> S2_U1_P3_MDI- | G35: =VLOOKUP(F35,EtchLengthFromLayout!$A:$B,2,0) -> 487.03 | H35: =E35+G35 -> 3080.99 | I35: =CONCATENATE("S",MID($A35,5,1),"_U2_",SUBSTITUTE($C35,"IN","I-") ) -> S2_U2_P3_MDI- | J35: =VLOOKUP(I35,EtchLengthFromLayout!$A:$B,2,0) -> 104.67 | K35: =CONCATENATE("S",MID($A35,5,1),"_U3_",SUBSTITUTE($C35,"IN","I-") ) -> S2_U3_P3_MDI- | L35: =VLOOKUP(K35,EtchLengthFromLayout!$A:$B,2,0) -> 9524.45 | M35: =CONCATENATE("S",MID($A35,5,1),"_U4PILB_",SUBSTITUTE($C35,"IN","I-") ) -> S2_U4PILB_P3_MDI- | N35: =VLOOKUP(M35,EtchLengthFromLayout!$A:$B,2,0) -> 6051.26 | Q35: =SUBSTITUTE($V35,"_P","_2_P") -> SG2_2_P3_MDI- | R35: =VLOOKUP(Q35,EtchLengthFromLayout!$A:$B,2,0) -> 4342.97 | S35: =SUBSTITUTE($V35,"_P","_1_P") -> SG2_1_P3_MDI- | T35: =VLOOKUP(S35,EtchLengthFromLayout!$A:$B,2,0) -> 104.67 | V35: =VLOOKUP(CONCATENATE($Z35,".",$AA35),Netlist_VTable!$H:$I,2,0) -> SG2_P3_MDI- | W35: =VLOOKUP(V35,EtchLengthFromLayout!$A:$B,2,0) -> 2376.57 | X35: =E35+G35+J35+L35+N35+P35+R35+T35+W35 -> 25585.58 | Y35: =ABS(X35-X36) -> 0.03 | Z35: GOLD2 | AA35: =VLOOKUP(AB35,PinNo!$B:$C,2,0) -> 168 | AB35: =C35 -> P3_MDIN
A36: SITE2 | B36: =VLOOKUP(C36,PinNo!$B:$C,2,0) -> 167 | C36: P3_MDIP | D36: =VLOOKUP(CONCATENATE($A36,".",$B36),Netlist_VTable!$H:$I,2,0) -> S2_P3_MDI+ | E36: =VLOOKUP(D36,EtchLengthFromLayout!$A:$B,2,0) -> 2593.96 | F36: =CONCATENATE("S",MID($A36,5,1),"_U1_",SUBSTITUTE($C36,"IP","I+") ) -> S2_U1_P3_MDI+ | G36: =VLOOKUP(F36,EtchLengthFromLayout!$A:$B,2,0) -> 487.03 | H36: =E36+G36 -> 3080.99 | I36: =CONCATENATE("S",MID($A36,5,1),"_U2_",SUBSTITUTE($C36,"IP","I+") ) -> S2_U2_P3_MDI+ | J36: =VLOOKUP(I36,EtchLengthFromLayout!$A:$B,2,0) -> 104.67 | K36: =CONCATENATE("S",MID($A36,5,1),"_U3_",SUBSTITUTE($C36,"IP","I+") ) -> S2_U3_P3_MDI+ | L36: =VLOOKUP(K36,EtchLengthFromLayout!$A:$B,2,0) -> 9524.5 | M36: =CONCATENATE("S",MID($A36,5,1),"_U4PILB_",SUBSTITUTE($C36,"IP","I+") ) -> S2_U4PILB_P3_MDI+ | N36: =VLOOKUP(M36,EtchLengthFromLayout!$A:$B,2,0) -> 6051.24 | Q36: =SUBSTITUTE($V36,"_P","_2_P") -> SG2_2_P3_MDI+ | R36: =VLOOKUP(Q36,EtchLengthFromLayout!$A:$B,2,0) -> 4342.98 | S36: =SUBSTITUTE($V36,"_P","_1_P") -> SG2_1_P3_MDI+ | T36: =VLOOKUP(S36,EtchLengthFromLayout!$A:$B,2,0) -> 104.67 | V36: =VLOOKUP(CONCATENATE($Z36,".",$AA36),Netlist_VTable!$H:$I,2,0) -> SG2_P3_MDI+ | W36: =VLOOKUP(V36,EtchLengthFromLayout!$A:$B,2,0) -> 2376.56 | X36: =E36+G36+J36+L36+N36+P36+R36+T36+W36 -> 25585.61 | Y36: =IF(Y35<=5,"OK, Tolerance<= 5 mils", "Fail, Tolerance > 5 mils") -> OK, Tolerance<= 5 mils | Z36: GOLD2 | AA36: =VLOOKUP(AB36,PinNo!$B:$C,2,0) -> 167 | AB36: =C36 -> P3_MDIP
A37: SITE3 | B37: =VLOOKUP(C37,PinNo!$B:$C,2,0) -> 168 | C37: P3_MDIN | D37: =VLOOKUP(CONCATENATE($A37,".",$B37),Netlist_VTable!$H:$I,2,0) -> S3_P3_MDI- | E37: =VLOOKUP(D37,EtchLengthFromLayout!$A:$B,2,0) -> 1671.04 | F37: =CONCATENATE("S",MID($A37,5,1),"_U1_",SUBSTITUTE($C37,"IN","I-") ) -> S3_U1_P3_MDI- | G37: =VLOOKUP(F37,EtchLengthFromLayout!$A:$B,2,0) -> 487.03 | H37: =E37+G37 -> 2158.07 | I37: =CONCATENATE("S",MID($A37,5,1),"_U2_",SUBSTITUTE($C37,"IN","I-") ) -> S3_U2_P3_MDI- | J37: =VLOOKUP(I37,EtchLengthFromLayout!$A:$B,2,0) -> 104.67 | K37: =CONCATENATE("S",MID($A37,5,1),"_U3_",SUBSTITUTE($C37,"IN","I-") ) -> S3_U3_P3_MDI- | L37: =VLOOKUP(K37,EtchLengthFromLayout!$A:$B,2,0) -> 14275.72 | M37: =CONCATENATE("S",MID($A37,5,1),"_U4PILB_",SUBSTITUTE($C37,"IN","I-") ) -> S3_U4PILB_P3_MDI- | N37: =VLOOKUP(M37,EtchLengthFromLayout!$A:$B,2,0) -> 3885.98 | Q37: =SUBSTITUTE($V37,"_P","_2_P") -> SG3_2_P3_MDI- | R37: =VLOOKUP(Q37,EtchLengthFromLayout!$A:$B,2,0) -> 3651.65 | S37: =SUBSTITUTE($V37,"_P","_1_P") -> SG3_1_P3_MDI- | T37: =VLOOKUP(S37,EtchLengthFromLayout!$A:$B,2,0) -> 104.67 | V37: =VLOOKUP(CONCATENATE($Z37,".",$AA37),Netlist_VTable!$H:$I,2,0) -> SG3_P3_MDI- | W37: =VLOOKUP(V37,EtchLengthFromLayout!$A:$B,2,0) -> 1404.62 | X37: =E37+G37+J37+L37+N37+P37+R37+T37+W37 -> 25585.38 | Y37: =ABS(X37-X38) -> 0.02 | Z37: GOLD3 | AA37: =VLOOKUP(AB37,PinNo!$B:$C,2,0) -> 168 | AB37: =C37 -> P3_MDIN
A38: SITE3 | B38: =VLOOKUP(C38,PinNo!$B:$C,2,0) -> 167 | C38: P3_MDIP | D38: =VLOOKUP(CONCATENATE($A38,".",$B38),Netlist_VTable!$H:$I,2,0) -> S3_P3_MDI+ | E38: =VLOOKUP(D38,EtchLengthFromLayout!$A:$B,2,0) -> 1671.04 | F38: =CONCATENATE("S",MID($A38,5,1),"_U1_",SUBSTITUTE($C38,"IP","I+") ) -> S3_U1_P3_MDI+ | G38: =VLOOKUP(F38,EtchLengthFromLayout!$A:$B,2,0) -> 487.03 | H38: =E38+G38 -> 2158.07 | I38: =CONCATENATE("S",MID($A38,5,1),"_U2_",SUBSTITUTE($C38,"IP","I+") ) -> S3_U2_P3_MDI+ | J38: =VLOOKUP(I38,EtchLengthFromLayout!$A:$B,2,0) -> 104.67 | K38: =CONCATENATE("S",MID($A38,5,1),"_U3_",SUBSTITUTE($C38,"IP","I+") ) -> S3_U3_P3_MDI+ | L38: =VLOOKUP(K38,EtchLengthFromLayout!$A:$B,2,0) -> 14275.73 | M38: =CONCATENATE("S",MID($A38,5,1),"_U4PILB_",SUBSTITUTE($C38,"IP","I+") ) -> S3_U4PILB_P3_MDI+ | N38: =VLOOKUP(M38,EtchLengthFromLayout!$A:$B,2,0) -> 3885.96 | Q38: =SUBSTITUTE($V38,"_P","_2_P") -> SG3_2_P3_MDI+ | R38: =VLOOKUP(Q38,EtchLengthFromLayout!$A:$B,2,0) -> 3651.71 | S38: =SUBSTITUTE($V38,"_P","_1_P") -> SG3_1_P3_MDI+ | T38: =VLOOKUP(S38,EtchLengthFromLayout!$A:$B,2,0) -> 104.67 | V38: =VLOOKUP(CONCATENATE($Z38,".",$AA38),Netlist_VTable!$H:$I,2,0) -> SG3_P3_MDI+ | W38: =VLOOKUP(V38,EtchLengthFromLayout!$A:$B,2,0) -> 1404.59 | X38: =E38+G38+J38+L38+N38+P38+R38+T38+W38 -> 25585.4 | Y38: =IF(Y37<=5,"OK, Tolerance<= 5 mils", "Fail, Tolerance > 5 mils") -> OK, Tolerance<= 5 mils | Z38: GOLD3 | AA38: =VLOOKUP(AB38,PinNo!$B:$C,2,0) -> 167 | AB38: =C38 -> P3_MDIP
F39: Max | H39: =MAX(H31:H38) -> 3080.99 | V39: Max | X39: =MAX(X31:X38) -> 25585.61
F40: Min | H40: =MIN(H31:H38) -> 2158.07 | V40: Min | X40: =MIN(X31:X38) -> 25585.38
F41: Max-Min | H41: =ABS(H39-H40) -> 922.92 | V41: Max-Min | X41: =ABS(X39-X40) -> 0.23
A44: Site | B44: Pin No | C44: Pin Name | D44: Net | E44: Length | F44: Net | G44: Length | H44: DUT-> Choke ( E + G ) 此處為最短距離 | I44: Net | J44: Length | K44: Net | L44: Length | M44: Net | N44: Length | O44: Net | P44: Length | Q44: Net | R44: Length | S44: Net | T44: Length | V44: Golden -> Choke Net (此處為最短距離) | W44: Length | X44: Total Length (mils) | Y44: P/N Difference (mils) | Z44: Golden | AA44: Pin No | AB44: Pin Name | AC44: Note
A45: SITE0 | B45: =VLOOKUP(C45,PinNo!$B:$C,2,0) -> 165 | C45: P4_MDIN | D45: =VLOOKUP(CONCATENATE($A45,".",$B45),Netlist_VTable!$H:$I,2,0) -> S0_P4_MDI- | E45: =VLOOKUP(D45,EtchLengthFromLayout!$A:$B,2,0) -> 2730.04 | F45: =CONCATENATE("S",MID($A45,5,1),"_U1_",SUBSTITUTE($C45,"IN","I-") ) -> S0_U1_P4_MDI- | G45: =VLOOKUP(F45,EtchLengthFromLayout!$A:$B,2,0) -> 487.03 | H45: =E45+G45 -> 3217.07 | I45: =CONCATENATE("S",MID($A45,5,1),"_U2_",SUBSTITUTE($C45,"IN","I-") ) -> S0_U2_P4_MDI- | J45: =VLOOKUP(I45,EtchLengthFromLayout!$A:$B,2,0) -> 104.67 | K45: =CONCATENATE("S",MID($A45,5,1),"_U3_",SUBSTITUTE($C45,"IN","I-") ) -> S0_U3_P4_MDI- | L45: =VLOOKUP(K45,EtchLengthFromLayout!$A:$B,2,0) -> 11098.88 | M45: =CONCATENATE("S",MID($A45,5,1),"_U4PILB_",SUBSTITUTE($C45,"IN","I-") ) -> S0_U4PILB_P4_MDI- | N45: =VLOOKUP(M45,EtchLengthFromLayout!$A:$B,2,0) -> 5878.63 | Q45: =SUBSTITUTE($V45,"_P","_2_P") -> SG0_2_P4_MDI- | R45: =VLOOKUP(Q45,EtchLengthFromLayout!$A:$B,2,0) -> 4072.44 | S45: =SUBSTITUTE($V45,"_P","_1_P") -> SG0_1_P4_MDI- | T45: =VLOOKUP(S45,EtchLengthFromLayout!$A:$B,2,0) -> 104.67 | V45: =VLOOKUP(CONCATENATE($Z45,".",$AA45),Netlist_VTable!$H:$I,2,0) -> SG0_P4_MDI- | W45: =VLOOKUP(V45,EtchLengthFromLayout!$A:$B,2,0) -> 1109.19 | X45: =E45+G45+J45+L45+N45+P45+R45+T45+W45 -> 25585.55 | Y45: =ABS(X45-X46) -> 0.06 | Z45: GOLD0 | AA45: =VLOOKUP(AB45,PinNo!$B:$C,2,0) -> 165 | AB45: =C45 -> P4_MDIN | AC45: DUT to Golden Port P4
A46: SITE0 | B46: =VLOOKUP(C46,PinNo!$B:$C,2,0) -> 164 | C46: P4_MDIP | D46: =VLOOKUP(CONCATENATE($A46,".",$B46),Netlist_VTable!$H:$I,2,0) -> S0_P4_MDI+ | E46: =VLOOKUP(D46,EtchLengthFromLayout!$A:$B,2,0) -> 2730.06 | F46: =CONCATENATE("S",MID($A46,5,1),"_U1_",SUBSTITUTE($C46,"IP","I+") ) -> S0_U1_P4_MDI+ | G46: =VLOOKUP(F46,EtchLengthFromLayout!$A:$B,2,0) -> 487.03 | H46: =E46+G46 -> 3217.09 | I46: =CONCATENATE("S",MID($A46,5,1),"_U2_",SUBSTITUTE($C46,"IP","I+") ) -> S0_U2_P4_MDI+ | J46: =VLOOKUP(I46,EtchLengthFromLayout!$A:$B,2,0) -> 104.67 | K46: =CONCATENATE("S",MID($A46,5,1),"_U3_",SUBSTITUTE($C46,"IP","I+") ) -> S0_U3_P4_MDI+ | L46: =VLOOKUP(K46,EtchLengthFromLayout!$A:$B,2,0) -> 11098.82 | M46: =CONCATENATE("S",MID($A46,5,1),"_U4PILB_",SUBSTITUTE($C46,"IP","I+") ) -> S0_U4PILB_P4_MDI+ | N46: =VLOOKUP(M46,EtchLengthFromLayout!$A:$B,2,0) -> 5878.63 | Q46: =SUBSTITUTE($V46,"_P","_2_P") -> SG0_2_P4_MDI+ | R46: =VLOOKUP(Q46,EtchLengthFromLayout!$A:$B,2,0) -> 4072.4 | S46: =SUBSTITUTE($V46,"_P","_1_P") -> SG0_1_P4_MDI+ | T46: =VLOOKUP(S46,EtchLengthFromLayout!$A:$B,2,0) -> 104.67 | V46: =VLOOKUP(CONCATENATE($Z46,".",$AA46),Netlist_VTable!$H:$I,2,0) -> SG0_P4_MDI+ | W46: =VLOOKUP(V46,EtchLengthFromLayout!$A:$B,2,0) -> 1109.21 | X46: =E46+G46+J46+L46+N46+P46+R46+T46+W46 -> 25585.49 | Y46: =IF(Y45<=5,"OK, Tolerance<= 5 mils", "Fail, Tolerance > 5 mils") -> OK, Tolerance<= 5 mils | Z46: GOLD0 | AA46: =VLOOKUP(AB46,PinNo!$B:$C,2,0) -> 164 | AB46: =C46 -> P4_MDIP
...

Sheet GIGAPHY
A1: DUT Port [ 5 : 6 ] to Golden | O1: 等長調此線段 | AB1: All Site All Port 等長 誤差 1000 mils
A2: Site | B2: Pin No | C2: Pin Name | D2: Net | E2: Length | F2: Net | G2: Length | H2: DUT-> Choke ( E + G ) 此處為最短距離 | I2: Net | J2: Length | K2: Net | L2: Length | M2: Net | N2: Length | O2: Net | P2: Length | Q2: Net | R2: Length | S2: Net | T2: Length | U2: Net | V2: Length | W2: Net | X2: Length | Z2: Golden -> Choke Net (此處為最短距離) | AA2: Length | AB2: Total Length (mils) | AC2: P/N Difference (mils) | AD2: Golden | AE2: Pin No | AF2: Pin Name | AG2: Note
A3: SITE0 | B3: =VLOOKUP(C3,PinNo!$B:$C,2,0) -> 148 | C3: P5_GIGA_MDIN | D3: =VLOOKUP(CONCATENATE($A3,".",$B3),Netlist_VTable!$H:$I,2,0) -> S0_P5_GIGA_MDI- | E3: =VLOOKUP(D3,EtchLengthFromLayout!$A:$B,2,0) -> 1653.57 | F3: =CONCATENATE("S",MID($A3,5,1),"_U1_",SUBSTITUTE($C3,"IN","I-") ) -> S0_U1_P5_GIGA_MDI- | G3: =VLOOKUP(F3,EtchLengthFromLayout!$A:$B,2,0) -> 324.18 | H3: =E3+G3 -> 1977.75 | I3: =CONCATENATE("S",MID($A3,5,1),"_U2_",SUBSTITUTE($C3,"IN","I-") ) -> S0_U2_P5_GIGA_MDI- | J3: =VLOOKUP(I3,EtchLengthFromLayout!$A:$B,2,0) -> 100.55 | K3: =CONCATENATE("S",MID($A3,5,1),"_U3_",SUBSTITUTE($C3,"IN","I-") ) -> S0_U3_P5_GIGA_MDI- | L3: =VLOOKUP(K3,EtchLengthFromLayout!$A:$B,2,0) -> 8857.16 | O3: =CONCATENATE("S",MID($A3,5,1),"_LB_",SUBSTITUTE($C3,"IN","I-") ) -> S0_LB_P5_GIGA_MDI- | P3: =VLOOKUP(O3,EtchLengthFromLayout!$A:$B,2,0) -> 563.2 | U3: =SUBSTITUTE($Z3,"_P","_2_P") -> SG0_2_P5_GIGA_MDI- | V3: =VLOOKUP(U3,EtchLengthFromLayout!$A:$B,2,0) -> 673.97 | W3: =SUBSTITUTE($Z3,"_P","_1_P") -> SG0_1_P5_GIGA_MDI- | X3: =VLOOKUP(W3,EtchLengthFromLayout!$A:$B,2,0) -> 100.55 | Z3: =VLOOKUP(CONCATENATE($AD3,".",$AE3),Netlist_VTable!$H:$I,2,0) -> SG0_P5_GIGA_MDI- | AA3: =VLOOKUP(Z3,EtchLengthFromLayout!$A:$B,2,0) -> 1173.76 | AB3: =E3+G3+J3+L3+N3+P3+R3+T3+V3+X3+AA3 -> 13446.94 | AC3: =ABS(AB3-AB4) -> 0.04 | AD3: GOLD0 | AE3: =VLOOKUP(AF3,PinNo!$B:$C,2,0) -> 148 | AF3: =C3 -> P5_GIGA_MDIN | AG3: DUT to Golden Port P5
A4: SITE0 | B4: =VLOOKUP(C4,PinNo!$B:$C,2,0) -> 147 | C4: P5_GIGA_MDIP | D4: =VLOOKUP(CONCATENATE($A4,".",$B4),Netlist_VTable!$H:$I,2,0) -> S0_P5_GIGA_MDI+ | E4: =VLOOKUP(D4,EtchLengthFromLayout!$A:$B,2,0) -> 1653.57 | F4: =CONCATENATE("S",MID($A4,5,1),"_U1_",SUBSTITUTE($C4,"IP","I+") ) -> S0_U1_P5_GIGA_MDI+ | G4: =VLOOKUP(F4,EtchLengthFromLayout!$A:$B,2,0) -> 324.17 | H4: =E4+G4 -> 1977.74 | I4: =CONCATENATE("S",MID($A4,5,1),"_U2_",SUBSTITUTE($C4,"IP","I+") ) -> S0_U2_P5_GIGA_MDI+ | J4: =VLOOKUP(I4,EtchLengthFromLayout!$A:$B,2,0) -> 100.55 | K4: =CONCATENATE("S",MID($A4,5,1),"_U3_",SUBSTITUTE($C4,"IP","I+") ) -> S0_U3_P5_GIGA_MDI+ | L4: =VLOOKUP(K4,EtchLengthFromLayout!$A:$B,2,0) -> 8857.16 | O4: =CONCATENATE("S",MID($A4,5,1),"_LB_",SUBSTITUTE($C4,"IP","I+") ) -> S0_LB_P5_GIGA_MDI+ | P4: =VLOOKUP(O4,EtchLengthFromLayout!$A:$B,2,0) -> 563.18 | U4: =SUBSTITUTE($Z4,"_P","_2_P") -> SG0_2_P5_GIGA_MDI+ | V4: =VLOOKUP(U4,EtchLengthFromLayout!$A:$B,2,0) -> 673.97 | W4: =SUBSTITUTE($Z4,"_P","_1_P") -> SG0_1_P5_GIGA_MDI+ | X4: =VLOOKUP(W4,EtchLengthFromLayout!$A:$B,2,0) -> 100.55 | Z4: =VLOOKUP(CONCATENATE($AD4,".",$AE4),Netlist_VTable!$H:$I,2,0) -> SG0_P5_GIGA_MDI+ | AA4: =VLOOKUP(Z4,EtchLengthFromLayout!$A:$B,2,0) -> 1173.75 | AB4: =E4+G4+J4+L4+N4+P4+R4+T4+V4+X4+AA4 -> 13446.9 | AC4: =IF(AC3<=5,"OK, Tolerance<= 5 mils", "Fail, Tolerance > 5 mils") -> OK, Tolerance<= 5 mils | AD4: GOLD0 | AE4: =VLOOKUP(AF4,PinNo!$B:$C,2,0) -> 147 | AF4: =C4 -> P5_GIGA_MDIP
A5: SITE1 | B5: =VLOOKUP(C5,PinNo!$B:$C,2,0) -> 148 | C5: P5_GIGA_MDIN | D5: =VLOOKUP(CONCATENATE($A5,".",$B5),Netlist_VTable!$H:$I,2,0) -> S1_P5_GIGA_MDI- | E5: =VLOOKUP(D5,EtchLengthFromLayout!$A:$B,2,0) -> 1513.31 | F5: =CONCATENATE("S",MID($A5,5,1),"_U1_",SUBSTITUTE($C5,"IN","I-") ) -> S1_U1_P5_GIGA_MDI- | G5: =VLOOKUP(F5,EtchLengthFromLayout!$A:$B,2,0) -> 324.18 | H5: =E5+G5 -> 1837.49 | I5: =CONCATENATE("S",MID($A5,5,1),"_U2_",SUBSTITUTE($C5,"IN","I-") ) -> S1_U2_P5_GIGA_MDI- | J5: =VLOOKUP(I5,EtchLengthFromLayout!$A:$B,2,0) -> 100.55 | K5: =CONCATENATE("S",MID($A5,5,1),"_U3_",SUBSTITUTE($C5,"IN","I-") ) -> S1_U3_P5_GIGA_MDI- | L5: =VLOOKUP(K5,EtchLengthFromLayout!$A:$B,2,0) -> 8754.6 | O5: =CONCATENATE("S",MID($A5,5,1),"_LB_",SUBSTITUTE($C5,"IN","I-") ) -> S1_LB_P5_GIGA_MDI- | P5: =VLOOKUP(O5,EtchLengthFromLayout!$A:$B,2,0) -> 563.2 | U5: =SUBSTITUTE($Z5,"_P","_2_P") -> SG1_2_P5_GIGA_MDI- | V5: =VLOOKUP(U5,EtchLengthFromLayout!$A:$B,2,0) -> 961.85 | W5: =SUBSTITUTE($Z5,"_P","_1_P") -> SG1_1_P5_GIGA_MDI- | X5: =VLOOKUP(W5,EtchLengthFromLayout!$A:$B,2,0) -> 100.55 | Z5: =VLOOKUP(CONCATENATE($AD5,".",$AE5),Netlist_VTable!$H:$I,2,0) -> SG1_P5_GIGA_MDI- | AA5: =VLOOKUP(Z5,EtchLengthFromLayout!$A:$B,2,0) -> 1184.87 | AB5: =E5+G5+J5+L5+N5+P5+R5+T5+V5+X5+AA5 -> 13503.11 | AC5: =ABS(AB5-AB6) -> 0.1 | AD5: GOLD1 | AE5: =VLOOKUP(AF5,PinNo!$B:$C,2,0) -> 148 | AF5: =C5 -> P5_GIGA_MDIN
A6: SITE1 | B6: =VLOOKUP(C6,PinNo!$B:$C,2,0) -> 147 | C6: P5_GIGA_MDIP | D6: =VLOOKUP(CONCATENATE($A6,".",$B6),Netlist_VTable!$H:$I,2,0) -> S1_P5_GIGA_MDI+ | E6: =VLOOKUP(D6,EtchLengthFromLayout!$A:$B,2,0) -> 1513.33 | F6: =CONCATENATE("S",MID($A6,5,1),"_U1_",SUBSTITUTE($C6,"IP","I+") ) -> S1_U1_P5_GIGA_MDI+ | G6: =VLOOKUP(F6,EtchLengthFromLayout!$A:$B,2,0) -> 324.17 | H6: =E6+G6 -> 1837.5 | I6: =CONCATENATE("S",MID($A6,5,1),"_U2_",SUBSTITUTE($C6,"IP","I+") ) -> S1_U2_P5_GIGA_MDI+ | J6: =VLOOKUP(I6,EtchLengthFromLayout!$A:$B,2,0) -> 100.55 | K6: =CONCATENATE("S",MID($A6,5,1),"_U3_",SUBSTITUTE($C6,"IP","I+") ) -> S1_U3_P5_GIGA_MDI+ | L6: =VLOOKUP(K6,EtchLengthFromLayout!$A:$B,2,0) -> 8754.61 | O6: =CONCATENATE("S",MID($A6,5,1),"_LB_",SUBSTITUTE($C6,"IP","I+") ) -> S1_LB_P5_GIGA_MDI+ | P6: =VLOOKUP(O6,EtchLengthFromLayout!$A:$B,2,0) -> 563.18 | U6: =SUBSTITUTE($Z6,"_P","_2_P") -> SG1_2_P5_GIGA_MDI+ | V6: =VLOOKUP(U6,EtchLengthFromLayout!$A:$B,2,0) -> 961.8 | W6: =SUBSTITUTE($Z6,"_P","_1_P") -> SG1_1_P5_GIGA_MDI+ | X6: =VLOOKUP(W6,EtchLengthFromLayout!$A:$B,2,0) -> 100.55 | Z6: =VLOOKUP(CONCATENATE($AD6,".",$AE6),Netlist_VTable!$H:$I,2,0) -> SG1_P5_GIGA_MDI+ | AA6: =VLOOKUP(Z6,EtchLengthFromLayout!$A:$B,2,0) -> 1184.82 | AB6: =E6+G6+J6+L6+N6+P6+R6+T6+V6+X6+AA6 -> 13503.01 | AC6: =IF(AC5<=5,"OK, Tolerance<= 5 mils", "Fail, Tolerance > 5 mils") -> OK, Tolerance<= 5 mils | AD6: GOLD1 | AE6: =VLOOKUP(AF6,PinNo!$B:$C,2,0) -> 147 | AF6: =C6 -> P5_GIGA_MDIP
A7: SITE2 | B7: =VLOOKUP(C7,PinNo!$B:$C,2,0) -> 148 | C7: P5_GIGA_MDIN | D7: =VLOOKUP(CONCATENATE($A7,".",$B7),Netlist_VTable!$H:$I,2,0) -> S2_P5_GIGA_MDI- | E7: =VLOOKUP(D7,EtchLengthFromLayout!$A:$B,2,0) -> 1653.57 | F7: =CONCATENATE("S",MID($A7,5,1),"_U1_",SUBSTITUTE($C7,"IN","I-") ) -> S2_U1_P5_GIGA_MDI- | G7: =VLOOKUP(F7,EtchLengthFromLayout!$A:$B,2,0) -> 324.18 | H7: =E7+G7 -> 1977.75 | I7: =CONCATENATE("S",MID($A7,5,1),"_U2_",SUBSTITUTE($C7,"IN","I-") ) -> S2_U2_P5_GIGA_MDI- | J7: =VLOOKUP(I7,EtchLengthFromLayout!$A:$B,2,0) -> 100.55 | K7: =CONCATENATE("S",MID($A7,5,1),"_U3_",SUBSTITUTE($C7,"IN","I-") ) -> S2_U3_P5_GIGA_MDI- | L7: =VLOOKUP(K7,EtchLengthFromLayout!$A:$B,2,0) -> 8632.48 | O7: =CONCATENATE("S",MID($A7,5,1),"_LB_",SUBSTITUTE($C7,"IN","I-") ) -> S2_LB_P5_GIGA_MDI- | P7: =VLOOKUP(O7,EtchLengthFromLayout!$A:$B,2,0) -> 563.2 | U7: =SUBSTITUTE($Z7,"_P","_2_P") -> SG2_2_P5_GIGA_MDI- | V7: =VLOOKUP(U7,EtchLengthFromLayout!$A:$B,2,0) -> 954.7 | W7: =SUBSTITUTE($Z7,"_P","_1_P") -> SG2_1_P5_GIGA_MDI- | X7: =VLOOKUP(W7,EtchLengthFromLayout!$A:$B,2,0) -> 100.55 | Z7: =VLOOKUP(CONCATENATE($AD7,".",$AE7),Netlist_VTable!$H:$I,2,0) -> SG2_P5_GIGA_MDI- | AA7: =VLOOKUP(Z7,EtchLengthFromLayout!$A:$B,2,0) -> 1184.87 | AB7: =E7+G7+J7+L7+N7+P7+R7+T7+V7+X7+AA7 -> 13514.1 | AC7: =ABS(AB7-AB8) -> 0.06 | AD7: GOLD2 | AE7: =VLOOKUP(AF7,PinNo!$B:$C,2,0) -> 148 | AF7: =C7 -> P5_GIGA_MDIN
A8: SITE2 | B8: =VLOOKUP(C8,PinNo!$B:$C,2,0) -> 147 | C8: P5_GIGA_MDIP | D8: =VLOOKUP(CONCATENATE($A8,".",$B8),Netlist_VTable!$H:$I,2,0) -> S2_P5_GIGA_MDI+ | E8: =VLOOKUP(D8,EtchLengthFromLayout!$A:$B,2,0) -> 1653.57 | F8: =CONCATENATE("S",MID($A8,5,1),"_U1_",SUBSTITUTE($C8,"IP","I+") ) -> S2_U1_P5_GIGA_MDI+ | G8: =VLOOKUP(F8,EtchLengthFromLayout!$A:$B,2,0) -> 324.17 | H8: =E8+G8 -> 1977.74 | I8: =CONCATENATE("S",MID($A8,5,1),"_U2_",SUBSTITUTE($C8,"IP","I+") ) -> S2_U2_P5_GIGA_MDI+ | J8: =VLOOKUP(I8,EtchLengthFromLayout!$A:$B,2,0) -> 100.55 | K8: =CONCATENATE("S",MID($A8,5,1),"_U3_",SUBSTITUTE($C8,"IP","I+") ) -> S2_U3_P5_GIGA_MDI+ | L8: =VLOOKUP(K8,EtchLengthFromLayout!$A:$B,2,0) -> 8632.48 | O8: =CONCATENATE("S",MID($A8,5,1),"_LB_",SUBSTITUTE($C8,"IP","I+") ) -> S2_LB_P5_GIGA_MDI+ | P8: =VLOOKUP(O8,EtchLengthFromLayout!$A:$B,2,0) -> 563.18 | U8: =SUBSTITUTE($Z8,"_P","_2_P") -> SG2_2_P5_GIGA_MDI+ | V8: =VLOOKUP(U8,EtchLengthFromLayout!$A:$B,2,0) -> 954.68 | W8: =SUBSTITUTE($Z8,"_P","_1_P") -> SG2_1_P5_GIGA_MDI+ | X8: =VLOOKUP(W8,EtchLengthFromLayout!$A:$B,2,0) -> 100.55 | Z8: =VLOOKUP(CONCATENATE($AD8,".",$AE8),Netlist_VTable!$H:$I,2,0) -> SG2_P5_GIGA_MDI+ | AA8: =VLOOKUP(Z8,EtchLengthFromLayout!$A:$B,2,0) -> 1184.86 | AB8: =E8+G8+J8+L8+N8+P8+R8+T8+V8+X8+AA8 -> 13514.04 | AC8: =IF(AC7<=5,"OK, Tolerance<= 5 mils", "Fail, Tolerance > 5 mils") -> OK, Tolerance<= 5 mils | AD8: GOLD2 | AE8: =VLOOKUP(AF8,PinNo!$B:$C,2,0) -> 147 | AF8: =C8 -> P5_GIGA_MDIP
A9: SITE3 | B9: =VLOOKUP(C9,PinNo!$B:$C,2,0) -> 148 | C9: P5_GIGA_MDIN | D9: =VLOOKUP(CONCATENATE($A9,".",$B9),Netlist_VTable!$H:$I,2,0) -> S3_P5_GIGA_MDI- | E9: =VLOOKUP(D9,EtchLengthFromLayout!$A:$B,2,0) -> 1513.31 | F9: =CONCATENATE("S",MID($A9,5,1),"_U1_",SUBSTITUTE($C9,"IN","I-") ) -> S3_U1_P5_GIGA_MDI- | G9: =VLOOKUP(F9,EtchLengthFromLayout!$A:$B,2,0) -> 324.18 | H9: =E9+G9 -> 1837.49 | I9: =CONCATENATE("S",MID($A9,5,1),"_U2_",SUBSTITUTE($C9,"IN","I-") ) -> S3_U2_P5_GIGA_MDI- | J9: =VLOOKUP(I9,EtchLengthFromLayout!$A:$B,2,0) -> 100.55 | K9: =CONCATENATE("S",MID($A9,5,1),"_U3_",SUBSTITUTE($C9,"IN","I-") ) -> S3_U3_P5_GIGA_MDI- | L9: =VLOOKUP(K9,EtchLengthFromLayout!$A:$B,2,0) -> 8825 | O9: =CONCATENATE("S",MID($A9,5,1),"_LB_",SUBSTITUTE($C9,"IN","I-") ) -> S3_LB_P5_GIGA_MDI- | P9: =VLOOKUP(O9,EtchLengthFromLayout!$A:$B,2,0) -> 563.2 | U9: =SUBSTITUTE($Z9,"_P","_2_P") -> SG3_2_P5_GIGA_MDI- | V9: =VLOOKUP(U9,EtchLengthFromLayout!$A:$B,2,0) -> 845.76 | W9: =SUBSTITUTE($Z9,"_P","_1_P") -> SG3_1_P5_GIGA_MDI- | X9: =VLOOKUP(W9,EtchLengthFromLayout!$A:$B,2,0) -> 100.55 | Z9: =VLOOKUP(CONCATENATE($AD9,".",$AE9),Netlist_VTable!$H:$I,2,0) -> SG3_P5_GIGA_MDI- | AA9: =VLOOKUP(Z9,EtchLengthFromLayout!$A:$B,2,0) -> 1169.82 | AB9: =E9+G9+J9+L9+N9+P9+R9+T9+V9+X9+AA9 -> 13442.37 | AC9: =ABS(AB9-AB10) -> 0.03 | AD9: GOLD3 | AE9: =VLOOKUP(AF9,PinNo!$B:$C,2,0) -> 148 | AF9: =C9 -> P5_GIGA_MDIN
