Workbook

Sheet PinNo
A1: G8 | B1: DVDD09[01] | C1: =A1 -> G8 | E1: 1
A2: H9 | B2: DVDD09[02] | C2: =A2 -> H9 | E2: 1
A3: J9 | B3: DVDD09[03] | C3: =A3 -> J9 | E3: 1
A4: K9 | B4: DVDD09[04] | C4: =A4 -> K9 | E4: 1
A5: L9 | B5: DVDD09[05] | C5: =A5 -> L9 | E5: 1
A6: M10 | B6: DVDD09[06] | C6: =A6 -> M10 | E6: 1
A7: M11 | B7: DVDD09[07] | C7: =A7 -> M11 | E7: 1
A8: M12 | B8: DVDD09[08] | C8: =A8 -> M12 | E8: 1
A9: N10 | B9: DVDD09[09] | C9: =A9 -> N10 | E9: 1
A10: N11 | B10: DVDD09[10] | C10: =A10 -> N11 | E10: 1
A11: N12 | B11: DVDD09[11] | C11: =A11 -> N12 | E11: 1
A12: E4 | B12: AVDD09[01] | C12: =A12 -> E4 | E12: 2
... A281: NUT4 | B281: NUT4 | C281: =A281 -> NUT4 | E281: 68
A285: 1 | B285: PCIE_AVCC33 | C285: =A285 -> 1
A286: 2 | B286: PCIE_AVDD11[1] | C286: =A286 -> 2
A287: 3 | B287: RST_INPIN | C287: =A287 -> 3
A288: 4 | B288: VDD33[1] | C288: =A288 -> 4
A289: 5 | B289: UART_RXD/SJTCLK/GPIO4 | C289: =A289 -> 5
A290: 6 | B290: UART_TXD/SJTTDI/GPIO5 | C290: =A290 -> 6
A291: 7 | B291: TESTENPIN | C291: =A291 -> 7
A292: 8 | B292: GPIO6/SJTMS | C292: =A292 -> 8
A293: 9 | B293: GPIO7/SJTDO/LED0 | C293: =A293 -> 9
A294: 10 | B294: GPIO8/HOT_PLUG/I2C_DATA/SPIO2 | C294: =A294 -> 10
A295: 11 | B295: DVDD11[1] | C295: =A295 -> 11
A296: 12 | B296: ISOLATEBPIN | C296: =A296 -> 12
... A352: 34 | B352: LDO_5TO3_OUT | C352: =A352 -> 34
A353: GH1 | B353: GH1 | C353: =A353 -> GH1
A354: GH2 | B354: GH2 | C354: =A354 -> GH2
A355: NUT1 | B355: NUT1 | C355: =A355 -> NUT1
A356: NUT2 | B356: NUT2 | C356: =A356 -> NUT2
A357: EP | B357: EPAD | C357: =A357 -> EP
A358: G1 | B358: G1 | C358: =A358 -> G1
A359: G2 | B359: G2 | C359: =A359 -> G2
A360: G3 | B360: G3 | C360: =A360 -> G3
A361: G4 | B361: G4 | C361: =A361 -> G4
A362: G5 | B362: G5 | C362: =A362 -> G5
A363: G6 | B363: G6 | C363: =A363 -> G6
A364: G7 | B364: G7 | C364: =A364 -> G7
... A385: G24 | B385: G24 | C385: =A385 -> G24

Sheet Netlist_VTable
C1: refer | E1: Net Name | F1: Number | G1: Name | H1: =CONCATENATE(C1,".",F1) -> refer.Number | I1: =E1 -> Net Name
A2: SCHEMATIC1 | B2: P000A_S0_BRPHY_P0_1_5_6 | C2: C194 | D2: 1 | E2: S0_U3_P0_RC | F2: 1 | G2: 1 | H2: =CONCATENATE(C2,".",F2) -> C194.1 | I2: =E2 -> S0_U3_P0_RC
A3: SCHEMATIC1 | B3: P000A_S0_BRPHY_P0_1_5_6 | C3: C194 | D3: 2 | E3: DGND | F3: 2 | G3: 2 | H3: =CONCATENATE(C3,".",F3) -> C194.2 | I3: =E3 -> DGND
A4: SCHEMATIC1 | B4: P000A_S0_BRPHY_P0_1_5_6 | C4: C195 | D4: 1 | E4: S0_U2_P0_MDI+ | F4: 1 | G4: 1 | H4: =CONCATENATE(C4,".",F4) -> C195.1 | I4: =E4 -> S0_U2_P0_MDI+
A5: SCHEMATIC1 | B5: P000A_S0_BRPHY_P0_1_5_6 | C5: C195 | D5: 2 | E5: S0_U3_P0_MDI+ | F5: 2 | G5: 2 | H5: =CONCATENATE(C5,".",F5) -> C195.2 | I5: =E5 -> S0_U3_P0_MDI+
A6: SCHEMATIC1 | B6: P000A_S0_BRPHY_P0_1_5_6 | C6: C196 | D6: 1 | E6: S0_U2_P0_MDI- | F6: 1 | G6: 1 | H6: =CONCATENATE(C6,".",F6) -> C196.1 | I6: =E6 -> S0_U2_P0_MDI-
A7: SCHEMATIC1 | B7: P000A_S0_BRPHY_P0_1_5_6 | C7: C196 | D7: 2 | E7: S0_U3_P0_MDI- | F7: 2 | G7: 2 | H7: =CONCATENATE(C7,".",F7) -> C196.2 | I7: =E7 -> S0_U3_P0_MDI-
A8: SCHEMATIC1 | B8: P000A_S0_BRPHY_P0_1_5_6 | C8: C197 | D8: 1 | E8: S0_U3_P1_RC | F8: 1 | G8: 1 | H8: =CONCATENATE(C8,".",F8) -> C197.1 | I8: =E8 -> S0_U3_P1_RC
A9: SCHEMATIC1 | B9: P000A_S0_BRPHY_P0_1_5_6 | C9: C197 | D9: 2 | E9: DGND | F9: 2 | G9: 2 | H9: =CONCATENATE(C9,".",F9) -> C197.2 | I9: =E9 -> DGND
A10: SCHEMATIC1 | B10: P000A_S0_BRPHY_P0_1_5_6 | C10: C198 | D10: 1 | E10: S0_U2_P1_MDI+ | F10: 1 | G10: 1 | H10: =CONCATENATE(C10,".",F10) -> C198.1 | I10: =E10 -> S0_U2_P1_MDI+
A11: SCHEMATIC1 | B11: P000A_S0_BRPHY_P0_1_5_6 | C11: C198 | D11: 2 | E11: S0_U3_P1_MDI+ | F11: 2 | G11: 2 | H11: =CONCATENATE(C11,".",F11) -> C198.2 | I11: =E11 -> S0_U3_P1_MDI+
A12: SCHEMATIC1 | B12: P000A_S0_BRPHY_P0_1_5_6 | C12: C199 | D12: 1 | E12: S0_U2_P1_MDI- | F12: 1 | G12: 1 | H12: =CONCATENATE(C12,".",F12) -> C199.1 | I12: =E12 -> S0_U2_P1_MDI-
A13: SCHEMATIC1 | B13: P000A_S0_BRPHY_P0_1_5_6 | C13: C199 | D13: 2 | E13: S0_U3_P1_MDI- | F13: 2 | G13: 2 | H13: =CONCATENATE(C13,".",F13) -> C199.2 | I13: =E13 -> S0_U3_P1_MDI-
... A31: SCHEMATIC1 | B31: P000A_S0_BRPHY_P0_1_5_6 | C31: K60 | D31: 7 | E31: S0_HSD018- | F31: 7 | G31: 7 | H31: =CONCATENATE(C31,".",F31) -> K60.7 | I31: =E31 -> S0_HSD018-
A32: SCHEMATIC1 | B32: P000A_S0_BRPHY_P0_1_5_6 | C32: K60 | D32: V+ | E32: VP12 | F32: 1 | G32: V+ | H32: =CONCATENATE(C32,".",F32) -> K60.1 | I32: =E32 -> VP12
A33: SCHEMATIC1 | B33: P000A_S0_BRPHY_P0_1_5_6 | C33: K60 | D33: V- | E33: SC_UDB060 | F33: 8 | G33: V- | H33: =CONCATENATE(C33,".",F33) -> K60.8 | I33: =E33 -> SC_UDB060
A34: SCHEMATIC1 | B34: P000A_S0_BRPHY_P0_1_5_6 | C34: K64 | D34: 2 | E34: S0_HSD006+ | F34: 2 | G34: 2 | H34: =CONCATENATE(C34,".",F34) -> K64.2 | I34: =E34 -> S0_HSD006+
A35: SCHEMATIC1 | B35: P000A_S0_BRPHY_P0_1_5_6 | C35: K64 | D35: 3 | E35: S0_P1_MDI+ | F35: 3 | G35: 3 | H35: =CONCATENATE(C35,".",F35) -> K64.3 | I35: =E35 -> S0_P1_MDI+
A36: SCHEMATIC1 | B36: P000A_S0_BRPHY_P0_1_5_6 | C36: K64 | D36: 4 | E36: S0_U1_P1_MDI+ | F36: 4 | G36: 4 | H36: =CONCATENATE(C36,".",F36) -> K64.4 | I36: =E36 -> S0_U1_P1_MDI+
A37: SCHEMATIC1 | B37: P000A_S0_BRPHY_P0_1_5_6 | C37: K64 | D37: 5 | E37: S0_U1_P1_MDI- | F37: 5 | G37: 5 | H37: =CONCATENATE(C37,".",F37) -> K64.5 | I37: =E37 -> S0_U1_P1_MDI-
A38: SCHEMATIC1 | B38: P000A_S0_BRPHY_P0_1_5_6 | C38: K64 | D38: 6 | E38: S0_P1_MDI- | F38: 6 | G38: 6 | H38: =CONCATENATE(C38,".",F38) -> K64.6 | I38: =E38 -> S0_P1_MDI-
A39: SCHEMATIC1 | B39: P000A_S0_BRPHY_P0_1_5_6 | C39: K64 | D39: 7 | E39: S0_HSD006- | F39: 7 | G39: 7 | H39: =CONCATENATE(C39,".",F39) -> K64.7 | I39: =E39 -> S0_HSD006-
A40: SCHEMATIC1 | B40: P000A_S0_BRPHY_P0_1_5_6 | C40: K64 | D40: V+ | E40: VP12 | F40: 1 | G40: V+ | H40: =CONCATENATE(C40,".",F40) -> K64.1 | I40: =E40 -> VP12
A41: SCHEMATIC1 | B41: P000A_S0_BRPHY_P0_1_5_6 | C41: K64 | D41: V- | E41: SC_UDB064 | F41: 8 | G41: V- | H41: =CONCATENATE(C41,".",F41) -> K64.8 | I41: =E41 -> SC_UDB064
A42: SCHEMATIC1 | B42: P000A_S0_BRPHY_P0_1_5_6 | C42: K130 | D42: 2 | E42: S0_HSD165+ | F42: 2 | G42: 2 | H42: =CONCATENATE(C42,".",F42) -> K130.2 | I42: =E42 -> S0_HSD165+
A43: SCHEMATIC1 | B43: P000A_S0_BRPHY_P0_1_5_6 | C43: K130 | D43: 3 | E43: S0_P5_MDI+ | F43: 3 | G43: 3 | H43: =CONCATENATE(C43,".",F43) -> K130.3 | I43: =E43 -> S0_P5_MDI+
A44: SCHEMATIC1 | B44: P000A_S0_BRPHY_P0_1_5_6 | C44: K130 | D44: 4 | E44: S0_U1_P5_MDI+ | F44: 4 | G44: 4 | H44: =CONCATENATE(C44,".",F44) -> K130.4 | I44: =E44 -> S0_U1_P5_MDI+
A45: SCHEMATIC1 | B45: P000A_S0_BRPHY_P0_1_5_6 | C45: K130 | D45: 5 | E45: S0_U1_P5_MDI- | F45: 5 | G45: 5 | H45: =CONCATENATE(C45,".",F45) -> K130.5 | I45: =E45 -> S0_U1_P5_MDI-
A46: SCHEMATIC1 | B46: P000A_S0_BRPHY_P0_1_5_6 | C46: K130 | D46: 6 | E46: S0_P5_MDI- | F46: 6 | G46: 6 | H46: =CONCATENATE(C46,".",F46) -> K130.6 | I46: =E46 -> S0_P5_MDI-
A47: SCHEMATIC1 | B47: P000A_S0_BRPHY_P0_1_5_6 | C47: K130 | D47: 7 | E47: S0_HSD165- | F47: 7 | G47: 7 | H47: =CONCATENATE(C47,".",F47) -> K130.7 | I47: =E47 -> S0_HSD165-
A48: SCHEMATIC1 | B48: P000A_S0_BRPHY_P0_1_5_6 | C48: K130 | D48: V+ | E48: VP12 | F48: 1 | G48: V+ | H48: =CONCATENATE(C48,".",F48) -> K130.1 | I48: =E48 -> VP12
A49: SCHEMATIC1 | B49: P000A_S0_BRPHY_P0_1_5_6 | C49: K130 | D49: V- | E49: SC_UDB130 | F49: 8 | G49: V- | H49: =CONCATENATE(C49,".",F49) -> K130.8 | I49: =E49 -> SC_UDB130
A50: SCHEMATIC1 | B50: P000A_S0_BRPHY_P0_1_5_6 | C50: K140 | D50: 2 | E50: S0_HSD161+ | F50: 2 | G50: 2 | H50: =CONCATENATE(C50,".",F50) -> K140.2 | I50: =E50 -> S0_HSD161+
A51: SCHEMATIC1 | B51: P000A_S0_BRPHY_P0_1_5_6 | C51: K140 | D51: 3 | E51: S0_P6_MDI+ | F51: 3 | G51: 3 | H51: =CONCATENATE(C51,".",F51) -> K140.3 | I51: =E51 -> S0_P6_MDI+
A52: SCHEMATIC1 | B52: P000A_S0_BRPHY_P0_1_5_6 | C52: K140 | D52: 4 | E52: S0_U1_P6_MDI+ | F52: 4 | G52: 4 | H52: =CONCATENATE(C52,".",F52) -> K140.4 | I52: =E52 -> S0_U1_P6_MDI+
A53: SCHEMATIC1 | B53: P000A_S0_BRPHY_P0_1_5_6 | C53: K140 | D53: 5 | E53: S0_U1_P6_MDI- | F53: 5 | G53: 5 | H53: =CONCATENATE(C53,".",F53) -> K140.5 | I53: =E53 -> S0_U1_P6_MDI-
A54: SCHEMATIC1 | B54: P000A_S0_BRPHY_P0_1_5_6 | C54: K140 | D54: 6 | E54: S0_P6_MDI- | F54: 6 | G54: 6 | H54: =CONCATENATE(C54,".",F54) -> K140.6 | I54: =E54 -> S0_P6_MDI-
A55: SCHEMATIC1 | B55: P000A_S0_BRPHY_P0_1_5_6 | C55: K140 | D55: 7 | E55: S0_HSD161- | F55: 7 | G55: 7 | H55: =CONCATENATE(C55,".",F55) -> K140.7 | I55: =E55 -> S0_HSD161-
A56: SCHEMATIC1 | B56: P000A_S0_BRPHY_P0_1_5_6 | C56: K140 | D56: V+ | E56: VP12 | F56: 1 | G56: V+ | H56: =CONCATENATE(C56,".",F56) -> K140.1 | I56: =E56 -> VP12
A57: SCHEMATIC1 | B57: P000A_S0_BRPHY_P0_1_5_6 | C57: K140 | D57: V- | E57: SC_UDB140 | F57: 8 | G57: V- | H57: =CONCATENATE(C57,".",F57) -> K140.8 | I57: =E57 -> SC_UDB140
...

Sheet EtchLengthFromLayout
A1: Design Name D:/iTest/homeoffice/Test Hardware/Gowtham/68/038RT-9068CJK0E-A100_0928_1.brd
A2: Date Mon Sep 28 15:48:48 2026
A3: Net Name | B3: Etch Length (mils) | C3: Manhattan Length (mils) | D3: Percent Manhattan (mils)
A4: ATX_P12V | B4: 0 | C4: 732.93 | D4: 0
A5: ATX_P3_3V | B5: 0 | C5: 2725.19 | D5: 0
A6: ATX_P5V | B6: 0 | C6: 1893.38 | D6: 0
A7: CTO_DGS00 | B7: 51.6 | C7: 56.29 | D7: 91.67
A8: CTO_DGS01 | B8: 51.52 | C8: 56.21 | D8: 91.66
A9: CTO_DGS02 | B9: 51.54 | C9: 56.23 | D9: 91.67
A10: CTO_DGS03 | B10: 51.56 | C10: 56.25 | D10: 91.67
A11: CTO_DGS04 | B11: 51.58 | C11: 56.27 | D11: 91.67
A12: CTO_DGS05 | B12: 51.6 | C12: 56.29 | D12: 91.67
A13: CTO_DGS06 | B13: 51.52 | C13: 56.21 | D13: 91.66
A14: CTO_DGS07 | B14: 51.54 | C14: 56.23 | D14: 91.67
A15: CTO_DGS08 | B15: 51.6 | C15: 56.29 | D15: 91.67
... A3452: VR24 | B3452: 0 | C3452: 78.74 | D3452: 0

Sheet Assigned_Channel
A1: S0_Hsd006- | B1: Slot2.Ch43
A2: S0_Hsd006+ | B2: Slot2.Ch42
A3: S0_Hsd018- | B3: Slot0.Ch107
A4: S0_Hsd018+ | B4: Slot0.Ch106
A5: S0_Hsd122- | B5: Slot2.Ch109
A6: S0_Hsd122+ | B6: Slot2.Ch108
A7: S0_Hsd126- | B7: Slot2.Ch119
A8: S0_Hsd126+ | B8: Slot2.Ch118
A9: S0_Hsd161- | B9: Slot2.Ch47
A10: S0_Hsd161+ | B10: Slot2.Ch46
A11: S0_Hsd165- | B11: Slot2.Ch51
A12: S0_Hsd165+ | B12: Slot2.Ch50
... A512: Sh32_Hsd027 | B512: SLOT3.CH84

Sheet SGMII
A1: SGMII Port 4 / 5 DUT RX to Golden TX | E1: Each Site Length Matching, P/N Length Matching, When matching the length, Component Pin Fanout Route Symmetrically, Please refer to the picture next to the chart if you want apply Serpertine Routing | Q1: Each Site Length Matching, P/N Length Matching
A2: Site | B2: Pin No | C2: Pin Name | D2: Net | E2: Length | F2: Net | G2: Length | H2: Net | I2: Length | J2: Net | K2: Length | L2: Total Length (mils) | M2: P/N Difference (mils) | N2: Golden / Host | O2: Pin No | P2: Pin Name | Q2: Path
A3: SITE0 | B3: =VLOOKUP(C3,PinNo!$B:$C,2,0) -> V13 | C3: P4_HSIN | D3: =VLOOKUP(CONCATENATE($A3,".",$B3),Netlist_VTable!$H:$I,2,0) -> S0_P4_HSI- | E3: =VLOOKUP(D3,EtchLengthFromLayout!$A:$B,2,0) -> 7342.51 | H3: =SUBSTITUTE($J3,"_P","_C_P") -> SG0_C_P4_HSO- | I3: =VLOOKUP(H3,EtchLengthFromLayout!$A:$B,2,0) -> 303.81 | J3: =VLOOKUP(CONCATENATE($N3,".",$O3),Netlist_VTable!$H:$I,2,0) -> SG0_P4_HSO- | K3: =VLOOKUP(J3,EtchLengthFromLayout!$A:$B,2,0) -> 1817.76 | L3: =E3+G3+I3+K3 -> 9464.08 | M3: =ABS(L3-L4) -> 0.35 | N3: GOLD0 | O3: =VLOOKUP(P3,PinNo!$B:$C,2,0) -> W14 | P3: P4_HSON | Q3: SGMII Port 4 / 5 DUT RX to Golden TX
A4: SITE0 | B4: =VLOOKUP(C4,PinNo!$B:$C,2,0) -> V12 | C4: P4_HSIP | D4: =VLOOKUP(CONCATENATE($A4,".",$B4),Netlist_VTable!$H:$I,2,0) -> S0_P4_HSI+ | E4: =VLOOKUP(D4,EtchLengthFromLayout!$A:$B,2,0) -> 7342.51 | H4: =SUBSTITUTE($J4,"_P","_C_P") -> SG0_C_P4_HSO+ | I4: =VLOOKUP(H4,EtchLengthFromLayout!$A:$B,2,0) -> 303.81 | J4: =VLOOKUP(CONCATENATE($N4,".",$O4),Netlist_VTable!$H:$I,2,0) -> SG0_P4_HSO+ | K4: =VLOOKUP(J4,EtchLengthFromLayout!$A:$B,2,0) -> 1818.11 | L4: =E4+G4+I4+K4 -> 9464.43 | M4: =IF(M3<=20,"OK, Tolerance<= 20 mil", "Not OK, Tolerance > 20 mil") -> OK, Tolerance<= 20 mil | N4: GOLD0 | O4: =VLOOKUP(P4,PinNo!$B:$C,2,0) -> W13 | P4: P4_HSOP
A5: SITE0 | B5: =VLOOKUP(C5,PinNo!$B:$C,2,0) -> V15 | C5: P5_HSIN | D5: =VLOOKUP(CONCATENATE($A5,".",$B5),Netlist_VTable!$H:$I,2,0) -> S0_P5_HSI- | E5: =VLOOKUP(D5,EtchLengthFromLayout!$A:$B,2,0) -> 7444.91 | H5: =SUBSTITUTE($J5,"_P","_C_P") -> SG0_C_P5_HSO- | I5: =VLOOKUP(H5,EtchLengthFromLayout!$A:$B,2,0) -> 198.56 | J5: =VLOOKUP(CONCATENATE($N5,".",$O5),Netlist_VTable!$H:$I,2,0) -> SG0_P5_HSO- | K5: =VLOOKUP(J5,EtchLengthFromLayout!$A:$B,2,0) -> 1474.69 | L5: =E5+G5+I5+K5 -> 9118.16 | M5: =ABS(L5-L6) -> 0.17 | N5: GOLD0 | O5: =VLOOKUP(P5,PinNo!$B:$C,2,0) -> W16 | P5: P5_HSON
A6: SITE0 | B6: =VLOOKUP(C6,PinNo!$B:$C,2,0) -> V14 | C6: P5_HSIP | D6: =VLOOKUP(CONCATENATE($A6,".",$B6),Netlist_VTable!$H:$I,2,0) -> S0_P5_HSI+ | E6: =VLOOKUP(D6,EtchLengthFromLayout!$A:$B,2,0) -> 7444.91 | H6: =SUBSTITUTE($J6,"_P","_C_P") -> SG0_C_P5_HSO+ | I6: =VLOOKUP(H6,EtchLengthFromLayout!$A:$B,2,0) -> 198.56 | J6: =VLOOKUP(CONCATENATE($N6,".",$O6),Netlist_VTable!$H:$I,2,0) -> SG0_P5_HSO+ | K6: =VLOOKUP(J6,EtchLengthFromLayout!$A:$B,2,0) -> 1474.52 | L6: =E6+G6+I6+K6 -> 9117.99 | M6: =IF(M5<=20,"OK, Tolerance<= 20 mil", "Not OK, Tolerance > 20 mil") -> OK, Tolerance<= 20 mil | N6: GOLD0 | O6: =VLOOKUP(P6,PinNo!$B:$C,2,0) -> W15 | P6: P5_HSOP
A8: SITE1 | B8: =VLOOKUP(C8,PinNo!$B:$C,2,0) -> V13 | C8: P4_HSIN | D8: =VLOOKUP(CONCATENATE($A8,".",$B8),Netlist_VTable!$H:$I,2,0) -> S1_P4_HSI- | E8: =VLOOKUP(D8,EtchLengthFromLayout!$A:$B,2,0) -> 6324.96 | H8: =SUBSTITUTE($J8,"_P","_C_P") -> SG1_C_P4_HSO- | I8: =VLOOKUP(H8,EtchLengthFromLayout!$A:$B,2,0) -> 303.81 | J8: =VLOOKUP(CONCATENATE($N8,".",$O8),Netlist_VTable!$H:$I,2,0) -> SG1_P4_HSO- | K8: =VLOOKUP(J8,EtchLengthFromLayout!$A:$B,2,0) -> 1817.76 | L8: =E8+G8+I8+K8 -> 8446.53 | M8: =ABS(L8-L9) -> 0.37 | N8: GOLD1 | O8: =VLOOKUP(P8,PinNo!$B:$C,2,0) -> W14 | P8: P4_HSON
A9: SITE1 | B9: =VLOOKUP(C9,PinNo!$B:$C,2,0) -> V12 | C9: P4_HSIP | D9: =VLOOKUP(CONCATENATE($A9,".",$B9),Netlist_VTable!$H:$I,2,0) -> S1_P4_HSI+ | E9: =VLOOKUP(D9,EtchLengthFromLayout!$A:$B,2,0) -> 6324.98 | H9: =SUBSTITUTE($J9,"_P","_C_P") -> SG1_C_P4_HSO+ | I9: =VLOOKUP(H9,EtchLengthFromLayout!$A:$B,2,0) -> 303.81 | J9: =VLOOKUP(CONCATENATE($N9,".",$O9),Netlist_VTable!$H:$I,2,0) -> SG1_P4_HSO+ | K9: =VLOOKUP(J9,EtchLengthFromLayout!$A:$B,2,0) -> 1818.11 | L9: =E9+G9+I9+K9 -> 8446.9 | M9: =IF(M8<=20,"OK, Tolerance<= 20 mil", "Not OK, Tolerance > 20 mil") -> OK, Tolerance<= 20 mil | N9: GOLD1 | O9: =VLOOKUP(P9,PinNo!$B:$C,2,0) -> W13 | P9: P4_HSOP
A10: SITE1 | B10: =VLOOKUP(C10,PinNo!$B:$C,2,0) -> V15 | C10: P5_HSIN | D10: =VLOOKUP(CONCATENATE($A10,".",$B10),Netlist_VTable!$H:$I,2,0) -> S1_P5_HSI- | E10: =VLOOKUP(D10,EtchLengthFromLayout!$A:$B,2,0) -> 6151.46 | H10: =SUBSTITUTE($J10,"_P","_C_P") -> SG1_C_P5_HSO- | I10: =VLOOKUP(H10,EtchLengthFromLayout!$A:$B,2,0) -> 198.56 | J10: =VLOOKUP(CONCATENATE($N10,".",$O10),Netlist_VTable!$H:$I,2,0) -> SG1_P5_HSO- | K10: =VLOOKUP(J10,EtchLengthFromLayout!$A:$B,2,0) -> 1474.69 | L10: =E10+G10+I10+K10 -> 7824.71 | M10: =ABS(L10-L11) -> 0.17 | N10: GOLD1 | O10: =VLOOKUP(P10,PinNo!$B:$C,2,0) -> W16 | P10: P5_HSON
A11: SITE1 | B11: =VLOOKUP(C11,PinNo!$B:$C,2,0) -> V14 | C11: P5_HSIP | D11: =VLOOKUP(CONCATENATE($A11,".",$B11),Netlist_VTable!$H:$I,2,0) -> S1_P5_HSI+ | E11: =VLOOKUP(D11,EtchLengthFromLayout!$A:$B,2,0) -> 6151.46 | H11: =SUBSTITUTE($J11,"_P","_C_P") -> SG1_C_P5_HSO+ | I11: =VLOOKUP(H11,EtchLengthFromLayout!$A:$B,2,0) -> 198.56 | J11: =VLOOKUP(CONCATENATE($N11,".",$O11),Netlist_VTable!$H:$I,2,0) -> SG1_P5_HSO+ | K11: =VLOOKUP(J11,EtchLengthFromLayout!$A:$B,2,0) -> 1474.52 | L11: =E11+G11+I11+K11 -> 7824.54 | M11: =IF(M10<=20,"OK, Tolerance<= 20 mil", "Not OK, Tolerance > 20 mil") -> OK, Tolerance<= 20 mil | N11: GOLD1 | O11: =VLOOKUP(P11,PinNo!$B:$C,2,0) -> W15 | P11: P5_HSOP
A13: SITE2 | B13: =VLOOKUP(C13,PinNo!$B:$C,2,0) -> V13 | C13: P4_HSIN | D13: =VLOOKUP(CONCATENATE($A13,".",$B13),Netlist_VTable!$H:$I,2,0) -> S2_P4_HSI- | E13: =VLOOKUP(D13,EtchLengthFromLayout!$A:$B,2,0) -> 7437.24 | H13: =SUBSTITUTE($J13,"_P","_C_P") -> SG2_C_P4_HSO- | I13: =VLOOKUP(H13,EtchLengthFromLayout!$A:$B,2,0) -> 303.81 | J13: =VLOOKUP(CONCATENATE($N13,".",$O13),Netlist_VTable!$H:$I,2,0) -> SG2_P4_HSO- | K13: =VLOOKUP(J13,EtchLengthFromLayout!$A:$B,2,0) -> 1817.76 | L13: =E13+G13+I13+K13 -> 9558.81 | M13: =ABS(L13-L14) -> 0.27 | N13: GOLD2 | O13: =VLOOKUP(P13,PinNo!$B:$C,2,0) -> W14 | P13: P4_HSON
A14: SITE2 | B14: =VLOOKUP(C14,PinNo!$B:$C,2,0) -> V12 | C14: P4_HSIP | D14: =VLOOKUP(CONCATENATE($A14,".",$B14),Netlist_VTable!$H:$I,2,0) -> S2_P4_HSI+ | E14: =VLOOKUP(D14,EtchLengthFromLayout!$A:$B,2,0) -> 7437.16 | H14: =SUBSTITUTE($J14,"_P","_C_P") -> SG2_C_P4_HSO+ | I14: =VLOOKUP(H14,EtchLengthFromLayout!$A:$B,2,0) -> 303.81 | J14: =VLOOKUP(CONCATENATE($N14,".",$O14),Netlist_VTable!$H:$I,2,0) -> SG2_P4_HSO+ | K14: =VLOOKUP(J14,EtchLengthFromLayout!$A:$B,2,0) -> 1818.11 | L14: =E14+G14+I14+K14 -> 9559.08 | M14: =IF(M13<=20,"OK, Tolerance<= 20 mil", "Not OK, Tolerance > 20 mil") -> OK, Tolerance<= 20 mil | N14: GOLD2 | O14: =VLOOKUP(P14,PinNo!$B:$C,2,0) -> W13 | P14: P4_HSOP
A15: SITE2 | B15: =VLOOKUP(C15,PinNo!$B:$C,2,0) -> V15 | C15: P5_HSIN | D15: =VLOOKUP(CONCATENATE($A15,".",$B15),Netlist_VTable!$H:$I,2,0) -> S2_P5_HSI- | E15: =VLOOKUP(D15,EtchLengthFromLayout!$A:$B,2,0) -> 7498.58 | H15: =SUBSTITUTE($J15,"_P","_C_P") -> SG2_C_P5_HSO- | I15: =VLOOKUP(H15,EtchLengthFromLayout!$A:$B,2,0) -> 198.56 | J15: =VLOOKUP(CONCATENATE($N15,".",$O15),Netlist_VTable!$H:$I,2,0) -> SG2_P5_HSO- | K15: =VLOOKUP(J15,EtchLengthFromLayout!$A:$B,2,0) -> 1474.69 | L15: =E15+G15+I15+K15 -> 9171.83 | M15: =ABS(L15-L16) -> 0.17 | N15: GOLD2 | O15: =VLOOKUP(P15,PinNo!$B:$C,2,0) -> W16 | P15: P5_HSON
A16: SITE2 | B16: =VLOOKUP(C16,PinNo!$B:$C,2,0) -> V14 | C16: P5_HSIP | D16: =VLOOKUP(CONCATENATE($A16,".",$B16),Netlist_VTable!$H:$I,2,0) -> S2_P5_HSI+ | E16: =VLOOKUP(D16,EtchLengthFromLayout!$A:$B,2,0) -> 7498.58 | H16: =SUBSTITUTE($J16,"_P","_C_P") -> SG2_C_P5_HSO+ | I16: =VLOOKUP(H16,EtchLengthFromLayout!$A:$B,2,0) -> 198.56 | J16: =VLOOKUP(CONCATENATE($N16,".",$O16),Netlist_VTable!$H:$I,2,0) -> SG2_P5_HSO+ | K16: =VLOOKUP(J16,EtchLengthFromLayout!$A:$B,2,0) -> 1474.52 | L16: =E16+G16+I16+K16 -> 9171.66 | M16: =IF(M15<=20,"OK, Tolerance<= 20 mil", "Not OK, Tolerance > 20 mil") -> OK, Tolerance<= 20 mil | N16: GOLD2 | O16: =VLOOKUP(P16,PinNo!$B:$C,2,0) -> W15 | P16: P5_HSOP
A18: SITE3 | B18: =VLOOKUP(C18,PinNo!$B:$C,2,0) -> V13 | C18: P4_HSIN | D18: =VLOOKUP(CONCATENATE($A18,".",$B18),Netlist_VTable!$H:$I,2,0) -> S3_P4_HSI- | E18: =VLOOKUP(D18,EtchLengthFromLayout!$A:$B,2,0) -> 6308.14 | H18: =SUBSTITUTE($J18,"_P","_C_P") -> SG3_C_P4_HSO- | I18: =VLOOKUP(H18,EtchLengthFromLayout!$A:$B,2,0) -> 303.81 | J18: =VLOOKUP(CONCATENATE($N18,".",$O18),Netlist_VTable!$H:$I,2,0) -> SG3_P4_HSO- | K18: =VLOOKUP(J18,EtchLengthFromLayout!$A:$B,2,0) -> 1817.76 | L18: =E18+G18+I18+K18 -> 8429.71 | M18: =ABS(L18-L19) -> 0.38 | N18: GOLD3 | O18: =VLOOKUP(P18,PinNo!$B:$C,2,0) -> W14 | P18: P4_HSON
A19: SITE3 | B19: =VLOOKUP(C19,PinNo!$B:$C,2,0) -> V12 | C19: P4_HSIP | D19: =VLOOKUP(CONCATENATE($A19,".",$B19),Netlist_VTable!$H:$I,2,0) -> S3_P4_HSI+ | E19: =VLOOKUP(D19,EtchLengthFromLayout!$A:$B,2,0) -> 6308.17 | H19: =SUBSTITUTE($J19,"_P","_C_P") -> SG3_C_P4_HSO+ | I19: =VLOOKUP(H19,EtchLengthFromLayout!$A:$B,2,0) -> 303.81 | J19: =VLOOKUP(CONCATENATE($N19,".",$O19),Netlist_VTable!$H:$I,2,0) -> SG3_P4_HSO+ | K19: =VLOOKUP(J19,EtchLengthFromLayout!$A:$B,2,0) -> 1818.11 | L19: =E19+G19+I19+K19 -> 8430.09 | M19: =IF(M18<=20,"OK, Tolerance<= 20 mil", "Not OK, Tolerance > 20 mil") -> OK, Tolerance<= 20 mil | N19: GOLD3 | O19: =VLOOKUP(P19,PinNo!$B:$C,2,0) -> W13 | P19: P4_HSOP
A20: SITE3 | B20: =VLOOKUP(C20,PinNo!$B:$C,2,0) -> V15 | C20: P5_HSIN | D20: =VLOOKUP(CONCATENATE($A20,".",$B20),Netlist_VTable!$H:$I,2,0) -> S3_P5_HSI- | E20: =VLOOKUP(D20,EtchLengthFromLayout!$A:$B,2,0) -> 6137.52 | H20: =SUBSTITUTE($J20,"_P","_C_P") -> SG3_C_P5_HSO- | I20: =VLOOKUP(H20,EtchLengthFromLayout!$A:$B,2,0) -> 198.56 | J20: =VLOOKUP(CONCATENATE($N20,".",$O20),Netlist_VTable!$H:$I,2,0) -> SG3_P5_HSO- | K20: =VLOOKUP(J20,EtchLengthFromLayout!$A:$B,2,0) -> 1474.69 | L20: =E20+G20+I20+K20 -> 7810.77 | M20: =ABS(L20-L21) -> 0.32 | N20: GOLD3 | O20: =VLOOKUP(P20,PinNo!$B:$C,2,0) -> W16 | P20: P5_HSON
A21: SITE3 | B21: =VLOOKUP(C21,PinNo!$B:$C,2,0) -> V14 | C21: P5_HSIP | D21: =VLOOKUP(CONCATENATE($A21,".",$B21),Netlist_VTable!$H:$I,2,0) -> S3_P5_HSI+ | E21: =VLOOKUP(D21,EtchLengthFromLayout!$A:$B,2,0) -> 6137.37 | H21: =SUBSTITUTE($J21,"_P","_C_P") -> SG3_C_P5_HSO+ | I21: =VLOOKUP(H21,EtchLengthFromLayout!$A:$B,2,0) -> 198.56 | J21: =VLOOKUP(CONCATENATE($N21,".",$O21),Netlist_VTable!$H:$I,2,0) -> SG3_P5_HSO+ | K21: =VLOOKUP(J21,EtchLengthFromLayout!$A:$B,2,0) -> 1474.52 | L21: =E21+G21+I21+K21 -> 7810.45 | M21: =IF(M20<=20,"OK, Tolerance<= 20 mil", "Not OK, Tolerance > 20 mil") -> OK, Tolerance<= 20 mil | N21: GOLD3 | O21: =VLOOKUP(P21,PinNo!$B:$C,2,0) -> W15 | P21: P5_HSOP
J22: Max | L22: =MAX(L3:L21) -> 9559.08
J23: Min | L23: =MIN(L3:L21) -> 7810.45
J24: Max-Min | L24: =ABS(L22-L23) -> 1748.63
A27: SGMII Port 4 / 5 DUT TX to Golden RX | E27: Each Site Length Matching, P/N Length Matching, When matching the length, Component Pin Fanout Route Symmetrically, Please refer to the picture next to the chart if you want apply Serpertine Routing | Q27: Each Site Length Matching, P/N Length Matching
A28: Site | B28: Pin No | C28: Pin Name | D28: Net | E28: Length | F28: Net | G28: Length | H28: Net | I28: Length | J28: Net | K28: Length | L28: Total Length (mils) | M28: P/N Difference (mils) | N28: Golden / Host | O28: Pin No | P28: Pin Name | Q28: Path
A29: SITE0 | B29: =VLOOKUP(C29,PinNo!$B:$C,2,0) -> W14 | C29: P4_HSON | D29: =VLOOKUP(CONCATENATE($A29,".",$B29),Netlist_VTable!$H:$I,2,0) -> S0_P4_HSO- | E29: =VLOOKUP(D29,EtchLengthFromLayout!$A:$B,2,0) -> 6858.69 | H29: =SUBSTITUTE($J29,"_P","_C_P") -> SG0_C_P4_HSI- | I29: =VLOOKUP(H29,EtchLengthFromLayout!$A:$B,2,0) -> 253.74 | J29: =VLOOKUP(CONCATENATE($N29,".",$O29),Netlist_VTable!$H:$I,2,0) -> SG0_P4_HSI- | K29: =VLOOKUP(J29,EtchLengthFromLayout!$A:$B,2,0) -> 1723.67 | L29: =E29+G29+I29+K29 -> 8836.1 | M29: =ABS(L29-L30) -> 0.02 | N29: GOLD0 | O29: =VLOOKUP(P29,PinNo!$B:$C,2,0) -> V13 | P29: P4_HSIN | Q29: SGMII Port 4 / 5 DUT TX to Golden RX
A30: SITE0 | B30: =VLOOKUP(C30,PinNo!$B:$C,2,0) -> W13 | C30: P4_HSOP | D30: =VLOOKUP(CONCATENATE($A30,".",$B30),Netlist_VTable!$H:$I,2,0) -> S0_P4_HSO+ | E30: =VLOOKUP(D30,EtchLengthFromLayout!$A:$B,2,0) -> 6858.69 | H30: =SUBSTITUTE($J30,"_P","_C_P") -> SG0_C_P4_HSI+ | I30: =VLOOKUP(H30,EtchLengthFromLayout!$A:$B,2,0) -> 253.74 | J30: =VLOOKUP(CONCATENATE($N30,".",$O30),Netlist_VTable!$H:$I,2,0) -> SG0_P4_HSI+ | K30: =VLOOKUP(J30,EtchLengthFromLayout!$A:$B,2,0) -> 1723.65 | L30: =E30+G30+I30+K30 -> 8836.08 | M30: =IF(M29<=20,"OK, Tolerance<= 20 mil", "Not OK, Tolerance > 20 mil") -> OK, Tolerance<= 20 mil | N30: GOLD0 | O30: =VLOOKUP(P30,PinNo!$B:$C,2,0) -> V12 | P30: P4_HSIP
A31: SITE0 | B31: =VLOOKUP(C31,PinNo!$B:$C,2,0) -> W16 | C31: P5_HSON | D31: =VLOOKUP(CONCATENATE($A31,".",$B31),Netlist_VTable!$H:$I,2,0) -> S0_P5_HSO- | E31: =VLOOKUP(D31,EtchLengthFromLayout!$A:$B,2,0) -> 6737.44 | H31: =SUBSTITUTE($J31,"_P","_C_P") -> SG0_C_P5_HSI- | I31: =VLOOKUP(H31,EtchLengthFromLayout!$A:$B,2,0) -> 223.16 | J31: =VLOOKUP(CONCATENATE($N31,".",$O31),Netlist_VTable!$H:$I,2,0) -> SG0_P5_HSI- | K31: =VLOOKUP(J31,EtchLengthFromLayout!$A:$B,2,0) -> 1332.5 | L31: =E31+G31+I31+K31 -> 8293.1 | M31: =ABS(L31-L32) -> 0.03 | N31: GOLD0 | O31: =VLOOKUP(P31,PinNo!$B:$C,2,0) -> V15 | P31: P5_HSIN
A32: SITE0 | B32: =VLOOKUP(C32,PinNo!$B:$C,2,0) -> W15 | C32: P5_HSOP | D32: =VLOOKUP(CONCATENATE($A32,".",$B32),Netlist_VTable!$H:$I,2,0) -> S0_P5_HSO+ | E32: =VLOOKUP(D32,EtchLengthFromLayout!$A:$B,2,0) -> 6737.48 | H32: =SUBSTITUTE($J32,"_P","_C_P") -> SG0_C_P5_HSI+ | I32: =VLOOKUP(H32,EtchLengthFromLayout!$A:$B,2,0) -> 223.16 | J32: =VLOOKUP(CONCATENATE($N32,".",$O32),Netlist_VTable!$H:$I,2,0) -> SG0_P5_HSI+ | K32: =VLOOKUP(J32,EtchLengthFromLayout!$A:$B,2,0) -> 1332.49 | L32: =E32+G32+I32+K32 -> 8293.13 | M32: =IF(M31<=20,"OK, Tolerance<= 20 mil", "Not OK, Tolerance > 20 mil") -> OK, Tolerance<= 20 mil | N32: GOLD0 | O32: =VLOOKUP(P32,PinNo!$B:$C,2,0) -> V14 | P32: P5_HSIP
A34: SITE1 | B34: =VLOOKUP(C34,PinNo!$B:$C,2,0) -> W14 | C34: P4_HSON | D34: =VLOOKUP(CONCATENATE($A34,".",$B34),Netlist_VTable!$H:$I,2,0) -> S1_P4_HSO- | E34: =VLOOKUP(D34,EtchLengthFromLayout!$A:$B,2,0) -> 6522.8 | H34: =SUBSTITUTE($J34,"_P","_C_P") -> SG1_C_P4_HSI- | I34: =VLOOKUP(H34,EtchLengthFromLayout!$A:$B,2,0) -> 253.74 | J34: =VLOOKUP(CONCATENATE($N34,".",$O34),Netlist_VTable!$H:$I,2,0) -> SG1_P4_HSI- | K34: =VLOOKUP(J34,EtchLengthFromLayout!$A:$B,2,0) -> 1723.67 | L34: =E34+G34+I34+K34 -> 8500.21 | M34: =ABS(L34-L35) -> 0.01 | N34: GOLD1 | O34: =VLOOKUP(P34,PinNo!$B:$C,2,0) -> V13 | P34: P4_HSIN
A35: SITE1 | B35: =VLOOKUP(C35,PinNo!$B:$C,2,0) -> W13 | C35: P4_HSOP | D35: =VLOOKUP(CONCATENATE($A35,".",$B35),Netlist_VTable!$H:$I,2,0) -> S1_P4_HSO+ | E35: =VLOOKUP(D35,EtchLengthFromLayout!$A:$B,2,0) -> 6522.81 | H35: =SUBSTITUTE($J35,"_P","_C_P") -> SG1_C_P4_HSI+ | I35: =VLOOKUP(H35,EtchLengthFromLayout!$A:$B,2,0) -> 253.74 | J35: =VLOOKUP(CONCATENATE($N35,".",$O35),Netlist_VTable!$H:$I,2,0) -> SG1_P4_HSI+ | K35: =VLOOKUP(J35,EtchLengthFromLayout!$A:$B,2,0) -> 1723.65 | L35: =E35+G35+I35+K35 -> 8500.2 | M35: =IF(M34<=20,"OK, Tolerance<= 20 mil", "Not OK, Tolerance > 20 mil") -> OK, Tolerance<= 20 mil | N35: GOLD1 | O35: =VLOOKUP(P35,PinNo!$B:$C,2,0) -> V12 | P35: P4_HSIP
A36: SITE1 | B36: =VLOOKUP(C36,PinNo!$B:$C,2,0) -> W16 | C36: P5_HSON | D36: =VLOOKUP(CONCATENATE($A36,".",$B36),Netlist_VTable!$H:$I,2,0) -> S1_P5_HSO- | E36: =VLOOKUP(D36,EtchLengthFromLayout!$A:$B,2,0) -> 6152.95 | H36: =SUBSTITUTE($J36,"_P","_C_P") -> SG1_C_P5_HSI- | I36: =VLOOKUP(H36,EtchLengthFromLayout!$A:$B,2,0) -> 223.16 | J36: =VLOOKUP(CONCATENATE($N36,".",$O36),Netlist_VTable!$H:$I,2,0) -> SG1_P5_HSI- | K36: =VLOOKUP(J36,EtchLengthFromLayout!$A:$B,2,0) -> 1332.5 | L36: =E36+G36+I36+K36 -> 7708.61 | M36: =ABS(L36-L37) -> 0.41 | N36: GOLD1 | O36: =VLOOKUP(P36,PinNo!$B:$C,2,0) -> V15 | P36: P5_HSIN
A37: SITE1 | B37: =VLOOKUP(C37,PinNo!$B:$C,2,0) -> W15 | C37: P5_HSOP | D37: =VLOOKUP(CONCATENATE($A37,".",$B37),Netlist_VTable!$H:$I,2,0) -> S1_P5_HSO+ | E37: =VLOOKUP(D37,EtchLengthFromLayout!$A:$B,2,0) -> 6152.55 | H37: =SUBSTITUTE($J37,"_P","_C_P") -> SG1_C_P5_HSI+ | I37: =VLOOKUP(H37,EtchLengthFromLayout!$A:$B,2,0) -> 223.16 | J37: =VLOOKUP(CONCATENATE($N37,".",$O37),Netlist_VTable!$H:$I,2,0) -> SG1_P5_HSI+ | K37: =VLOOKUP(J37,EtchLengthFromLayout!$A:$B,2,0) -> 1332.49 | L37: =E37+G37+I37+K37 -> 7708.2 | M37: =IF(M36<=20,"OK, Tolerance<= 20 mil", "Not OK, Tolerance > 20 mil") -> OK, Tolerance<= 20 mil | N37: GOLD1 | O37: =VLOOKUP(P37,PinNo!$B:$C,2,0) -> V14 | P37: P5_HSIP
A39: SITE2 | B39: =VLOOKUP(C39,PinNo!$B:$C,2,0) -> W14 | C39: P4_HSON | D39: =VLOOKUP(CONCATENATE($A39,".",$B39),Netlist_VTable!$H:$I,2,0) -> S2_P4_HSO- | E39: =VLOOKUP(D39,EtchLengthFromLayout!$A:$B,2,0) -> 8062.27 | H39: =SUBSTITUTE($J39,"_P","_C_P") -> SG2_C_P4_HSI- | I39: =VLOOKUP(H39,EtchLengthFromLayout!$A:$B,2,0) -> 253.74 | J39: =VLOOKUP(CONCATENATE($N39,".",$O39),Netlist_VTable!$H:$I,2,0) -> SG2_P4_HSI- | K39: =VLOOKUP(J39,EtchLengthFromLayout!$A:$B,2,0) -> 1723.67 | L39: =E39+G39+I39+K39 -> 10039.68 | M39: =ABS(L39-L40) -> 0.04 | N39: GOLD2 | O39: =VLOOKUP(P39,PinNo!$B:$C,2,0) -> V13 | P39: P4_HSIN
A40: SITE2 | B40: =VLOOKUP(C40,PinNo!$B:$C,2,0) -> W13 | C40: P4_HSOP | D40: =VLOOKUP(CONCATENATE($A40,".",$B40),Netlist_VTable!$H:$I,2,0) -> S2_P4_HSO+ | E40: =VLOOKUP(D40,EtchLengthFromLayout!$A:$B,2,0) -> 8062.33 | H40: =SUBSTITUTE($J40,"_P","_C_P") -> SG2_C_P4_HSI+ | I40: =VLOOKUP(H40,EtchLengthFromLayout!$A:$B,2,0) -> 253.74 | J40: =VLOOKUP(CONCATENATE($N40,".",$O40),Netlist_VTable!$H:$I,2,0) -> SG2_P4_HSI+ | K40: =VLOOKUP(J40,EtchLengthFromLayout!$A:$B,2,0) -> 1723.65 | L40: =E40+G40+I40+K40 -> 10039.72 | M40: =IF(M39<=20,"OK, Tolerance<= 20 mil", "Not OK, Tolerance > 20 mil") -> OK, Tolerance<= 20 mil | N40: GOLD2 | O40: =VLOOKUP(P40,PinNo!$B:$C,2,0) -> V12 | P40: P4_HSIP
A41: SITE2 | B41: =VLOOKUP(C41,PinNo!$B:$C,2,0) -> W16 | C41: P5_HSON | D41: =VLOOKUP(CONCATENATE($A41,".",$B41),Netlist_VTable!$H:$I,2,0) -> S2_P5_HSO- | E41: =VLOOKUP(D41,EtchLengthFromLayout!$A:$B,2,0) -> 7980.97 | H41: =SUBSTITUTE($J41,"_P","_C_P") -> SG2_C_P5_HSI- | I41: =VLOOKUP(H41,EtchLengthFromLayout!$A:$B,2,0) -> 223.16 | J41: =VLOOKUP(CONCATENATE($N41,".",$O41),Netlist_VTable!$H:$I,2,0) -> SG2_P5_HSI- | K41: =VLOOKUP(J41,EtchLengthFromLayout!$A:$B,2,0) -> 1332.5 | L41: =E41+G41+I41+K41 -> 9536.63 | M41: =ABS(L41-L42) -> 0.03 | N41: GOLD2 | O41: =VLOOKUP(P41,PinNo!$B:$C,2,0) -> V15 | P41: P5_HSIN
A42: SITE2 | B42: =VLOOKUP(C42,PinNo!$B:$C,2,0) -> W15 | C42: P5_HSOP | D42: =VLOOKUP(CONCATENATE($A42,".",$B42),Netlist_VTable!$H:$I,2,0) -> S2_P5_HSO+ | E42: =VLOOKUP(D42,EtchLengthFromLayout!$A:$B,2,0) -> 7980.95 | H42: =SUBSTITUTE($J42,"_P","_C_P") -> SG2_C_P5_HSI+ | I42: =VLOOKUP(H42,EtchLengthFromLayout!$A:$B,2,0) -> 223.16 | J42: =VLOOKUP(CONCATENATE($N42,".",$O42),Netlist_VTable!$H:$I,2,0) -> SG2_P5_HSI+ | K42: =VLOOKUP(J42,EtchLengthFromLayout!$A:$B,2,0) -> 1332.49 | L42: =E42+G42+I42+K42 -> 9536.6 | M42: =IF(M41<=20,"OK, Tolerance<= 20 mil", "Not OK, Tolerance > 20 mil") -> OK, Tolerance<= 20 mil | N42: GOLD2 | O42: =VLOOKUP(P42,PinNo!$B:$C,2,0) -> V14 | P42: P5_HSIP
A44: SITE3 | B44: =VLOOKUP(C44,PinNo!$B:$C,2,0) -> W14 | C44: P4_HSON | D44: =VLOOKUP(CONCATENATE($A44,".",$B44),Netlist_VTable!$H:$I,2,0) -> S3_P4_HSO- | E44: =VLOOKUP(D44,EtchLengthFromLayout!$A:$B,2,0) -> 6829.88 | H44: =SUBSTITUTE($J44,"_P","_C_P") -> SG3_C_P4_HSI- | I44: =VLOOKUP(H44,EtchLengthFromLayout!$A:$B,2,0) -> 253.74 | J44: =VLOOKUP(CONCATENATE($N44,".",$O44),Netlist_VTable!$H:$I,2,0) -> SG3_P4_HSI- | K44: =VLOOKUP(J44,EtchLengthFromLayout!$A:$B,2,0) -> 1723.67 | L44: =E44+G44+I44+K44 -> 8807.29 | M44: =ABS(L44-L45) -> 0.03 | N44: GOLD3 | O44: =VLOOKUP(P44,PinNo!$B:$C,2,0) -> V13 | P44: P4_HSIN
A45: SITE3 | B45: =VLOOKUP(C45,PinNo!$B:$C,2,0) -> W13 | C45: P4_HSOP | D45: =VLOOKUP(CONCATENATE($A45,".",$B45),Netlist_VTable!$H:$I,2,0) -> S3_P4_HSO+ | E45: =VLOOKUP(D45,EtchLengthFromLayout!$A:$B,2,0) -> 6829.87 | H45: =SUBSTITUTE($J45,"_P","_C_P") -> SG3_C_P4_HSI+ | I45: =VLOOKUP(H45,EtchLengthFromLayout!$A:$B,2,0) -> 253.74 | J45: =VLOOKUP(CONCATENATE($N45,".",$O45),Netlist_VTable!$H:$I,2,0) -> SG3_P4_HSI+ | K45: =VLOOKUP(J45,EtchLengthFromLayout!$A:$B,2,0) -> 1723.65 | L45: =E45+G45+I45+K45 -> 8807.26 | M45: =IF(M44<=20,"OK, Tolerance<= 20 mil", "Not OK, Tolerance > 20 mil") -> OK, Tolerance<= 20 mil | N45: GOLD3 | O45: =VLOOKUP(P45,PinNo!$B:$C,2,0) -> V12 | P45: P4_HSIP
A46: SITE3 | B46: =VLOOKUP(C46,PinNo!$B:$C,2,0) -> W16 | C46: P5_HSON | D46: =VLOOKUP(CONCATENATE($A46,".",$B46),Netlist_VTable!$H:$I,2,0) -> S3_P5_HSO- | E46: =VLOOKUP(D46,EtchLengthFromLayout!$A:$B,2,0) -> 6824.23 | H46: =SUBSTITUTE($J46,"_P","_C_P") -> SG3_C_P5_HSI- | I46: =VLOOKUP(H46,EtchLengthFromLayout!$A:$B,2,0) -> 223.16 | J46: =VLOOKUP(CONCATENATE($N46,".",$O46),Netlist_VTable!$H:$I,2,0) -> SG3_P5_HSI- | K46: =VLOOKUP(J46,EtchLengthFromLayout!$A:$B,2,0) -> 1332.5 | L46: =E46+G46+I46+K46 -> 8379.89 | M46: =ABS(L46-L47) -> 0.59 | N46: GOLD3 | O46: =VLOOKUP(P46,PinNo!$B:$C,2,0) -> V15 | P46: P5_HSIN
A47: SITE3 | B47: =VLOOKUP(C47,PinNo!$B:$C,2,0) -> W15 | C47: P5_HSOP | D47: =VLOOKUP(CONCATENATE($A47,".",$B47),Netlist_VTable!$H:$I,2,0) -> S3_P5_HSO+ | E47: =VLOOKUP(D47,EtchLengthFromLayout!$A:$B,2,0) -> 6823.65 | H47: =SUBSTITUTE($J47,"_P","_C_P") -> SG3_C_P5_HSI+ | I47: =VLOOKUP(H47,EtchLengthFromLayout!$A:$B,2,0) -> 223.16 | J47: =VLOOKUP(CONCATENATE($N47,".",$O47),Netlist_VTable!$H:$I,2,0) -> SG3_P5_HSI+ | K47: =VLOOKUP(J47,EtchLengthFromLayout!$A:$B,2,0) -> 1332.49 | L47: =E47+G47+I47+K47 -> 8379.3 | M47: =IF(M46<=20,"OK, Tolerance<= 20 mil", "Not OK, Tolerance > 20 mil") -> OK, Tolerance<= 20 mil | N47: GOLD3 | O47: =VLOOKUP(P47,PinNo!$B:$C,2,0) -> V14 | P47: P5_HSIP
J48: Max | L48: =MAX(L29:L47) -> 10039.72
...

Sheet BRPHY
A1: DUT Port [ 0 : 1, 5 : 6 ] to Golden | I1: All Site All Port Length Matching Error 1000 mils | M1: Adjust this Net for Length Matching
A2: Site | B2: Pin No | C2: Pin Name | D2: Net | E2: Length | F2: Net | G2: Length | H2: DUT-> Choke ( E + G ) 此處為最短距離 | I2: Net | J2: Length | K2: Net | L2: Length | M2: Net | N2: Length | O2: Net | P2: Length | Q2: Net | R2: Length | S2: Net | T2: Length | V2: Golden -> Choke Net (此處為最短距離) | W2: Length | X2: Total Length (mils) | Y2: P/N Difference (mils) | Z2: Golden | AA2: Pin No | AB2: Pin Name | AC2: Note
A3: SITE0 | B3: =VLOOKUP(C3,PinNo!$B:$C,2,0) -> A2 | C3: P0_MDIN | D3: =VLOOKUP(CONCATENATE($A3,".",$B3),Netlist_VTable!$H:$I,2,0) -> S0_P0_MDI- | E3: =VLOOKUP(D3,EtchLengthFromLayout!$A:$B,2,0) -> 1134.84 | F3: =CONCATENATE("S",MID($A3,5,1),"_U1_",SUBSTITUTE($C3,"IN","I-") ) -> S0_U1_P0_MDI- | G3: =VLOOKUP(F3,EtchLengthFromLayout!$A:$B,2,0) -> 522.65 | H3: =E3+G3 -> 1657.49 | I3: =CONCATENATE("S",MID($A3,5,1),"_U2_",SUBSTITUTE($C3,"IN","I-") ) -> S0_U2_P0_MDI- | J3: =VLOOKUP(I3,EtchLengthFromLayout!$A:$B,2,0) -> 105.98 | K3: =CONCATENATE("S",MID($A3,5,1),"_U3_",SUBSTITUTE($C3,"IN","I-") ) -> S0_U3_P0_MDI- | L3: =VLOOKUP(K3,EtchLengthFromLayout!$A:$B,2,0) -> 11501.22 | M3: =CONCATENATE("S",MID($A3,5,1),"_U4PILB_",SUBSTITUTE($C3,"IN","I-") ) -> S0_U4PILB_P0_MDI- | N3: =VLOOKUP(M3,EtchLengthFromLayout!$A:$B,2,0) -> 8741.28 | Q3: =SUBSTITUTE($V3,"_P","_2_P") -> SG0_2_P0_MDI- | R3: =VLOOKUP(Q3,EtchLengthFromLayout!$A:$B,2,0) -> 3643.12 | S3: =SUBSTITUTE($V3,"_P","_1_P") -> SG0_1_P0_MDI- | T3: =VLOOKUP(S3,EtchLengthFromLayout!$A:$B,2,0) -> 102.2 | V3: =VLOOKUP(CONCATENATE($Z3,".",$AA3),Netlist_VTable!$H:$I,2,0) -> SG0_P0_MDI- | W3: =VLOOKUP(V3,EtchLengthFromLayout!$A:$B,2,0) -> 919.84 | X3: =E3+G3+J3+L3+N3+P3+R3+T3+W3 -> 26671.13 | Y3: =ABS(X3-X4) -> 2.04 | Z3: GOLD0 | AA3: =VLOOKUP(AB3,PinNo!$B:$C,2,0) -> A2 | AB3: =C3 -> P0_MDIN | AC3: DUT to Golden Port P0
A4: SITE0 | B4: =VLOOKUP(C4,PinNo!$B:$C,2,0) -> A3 | C4: P0_MDIP | D4: =VLOOKUP(CONCATENATE($A4,".",$B4),Netlist_VTable!$H:$I,2,0) -> S0_P0_MDI+ | E4: =VLOOKUP(D4,EtchLengthFromLayout!$A:$B,2,0) -> 1134.85 | F4: =CONCATENATE("S",MID($A4,5,1),"_U1_",SUBSTITUTE($C4,"IP","I+") ) -> S0_U1_P0_MDI+ | G4: =VLOOKUP(F4,EtchLengthFromLayout!$A:$B,2,0) -> 522.6 | H4: =E4+G4 -> 1657.45 | I4: =CONCATENATE("S",MID($A4,5,1),"_U2_",SUBSTITUTE($C4,"IP","I+") ) -> S0_U2_P0_MDI+ | J4: =VLOOKUP(I4,EtchLengthFromLayout!$A:$B,2,0) -> 105.79 | K4: =CONCATENATE("S",MID($A4,5,1),"_U3_",SUBSTITUTE($C4,"IP","I+") ) -> S0_U3_P0_MDI+ | L4: =VLOOKUP(K4,EtchLengthFromLayout!$A:$B,2,0) -> 11501.22 | M4: =CONCATENATE("S",MID($A4,5,1),"_U4PILB_",SUBSTITUTE($C4,"IP","I+") ) -> S0_U4PILB_P0_MDI+ | N4: =VLOOKUP(M4,EtchLengthFromLayout!$A:$B,2,0) -> 8741.28 | Q4: =SUBSTITUTE($V4,"_P","_2_P") -> SG0_2_P0_MDI+ | R4: =VLOOKUP(Q4,EtchLengthFromLayout!$A:$B,2,0) -> 3643.12 | S4: =SUBSTITUTE($V4,"_P","_1_P") -> SG0_1_P0_MDI+ | T4: =VLOOKUP(S4,EtchLengthFromLayout!$A:$B,2,0) -> 100.38 | V4: =VLOOKUP(CONCATENATE($Z4,".",$AA4),Netlist_VTable!$H:$I,2,0) -> SG0_P0_MDI+ | W4: =VLOOKUP(V4,EtchLengthFromLayout!$A:$B,2,0) -> 919.85 | X4: =E4+G4+J4+L4+N4+P4+R4+T4+W4 -> 26669.09 | Y4: =IF(Y3<=5,"OK, Tolerance<= 5 mil", "Not OK, Tolerance > 5 mil") -> OK, Tolerance<= 5 mil | Z4: GOLD0 | AA4: =VLOOKUP(AB4,PinNo!$B:$C,2,0) -> A3 | AB4: =C4 -> P0_MDIP
A5: SITE1 | B5: =VLOOKUP(C5,PinNo!$B:$C,2,0) -> A2 | C5: P0_MDIN | D5: =VLOOKUP(CONCATENATE($A5,".",$B5),Netlist_VTable!$H:$I,2,0) -> S1_P0_MDI- | E5: =VLOOKUP(D5,EtchLengthFromLayout!$A:$B,2,0) -> 1134.84 | F5: =CONCATENATE("S",MID($A5,5,1),"_U1_",SUBSTITUTE($C5,"IN","I-") ) -> S1_U1_P0_MDI- | G5: =VLOOKUP(F5,EtchLengthFromLayout!$A:$B,2,0) -> 522.65 | H5: =E5+G5 -> 1657.49 | I5: =CONCATENATE("S",MID($A5,5,1),"_U2_",SUBSTITUTE($C5,"IN","I-") ) -> S1_U2_P0_MDI- | J5: =VLOOKUP(I5,EtchLengthFromLayout!$A:$B,2,0) -> 105.98 | K5: =CONCATENATE("S",MID($A5,5,1),"_U3_",SUBSTITUTE($C5,"IN","I-") ) -> S1_U3_P0_MDI- | L5: =VLOOKUP(K5,EtchLengthFromLayout!$A:$B,2,0) -> 14717.28 | M5: =CONCATENATE("S",MID($A5,5,1),"_U4PILB_",SUBSTITUTE($C5,"IN","I-") ) -> S1_U4PILB_P0_MDI- | N5: =VLOOKUP(M5,EtchLengthFromLayout!$A:$B,2,0) -> 3460.43 | Q5: =SUBSTITUTE($V5,"_P","_2_P") -> SG1_2_P0_MDI- | R5: =VLOOKUP(Q5,EtchLengthFromLayout!$A:$B,2,0) -> 5782.96 | S5: =SUBSTITUTE($V5,"_P","_1_P") -> SG1_1_P0_MDI- | T5: =VLOOKUP(S5,EtchLengthFromLayout!$A:$B,2,0) -> 102.2 | V5: =VLOOKUP(CONCATENATE($Z5,".",$AA5),Netlist_VTable!$H:$I,2,0) -> SG1_P0_MDI- | W5: =VLOOKUP(V5,EtchLengthFromLayout!$A:$B,2,0) -> 919.84 | X5: =E5+G5+J5+L5+N5+P5+R5+T5+W5 -> 26746.18 | Y5: =ABS(X5-X6) -> 2.05 | Z5: GOLD1 | AA5: =VLOOKUP(AB5,PinNo!$B:$C,2,0) -> A2 | AB5: =C5 -> P0_MDIN
A6: SITE1 | B6: =VLOOKUP(C6,PinNo!$B:$C,2,0) -> A3 | C6: P0_MDIP | D6: =VLOOKUP(CONCATENATE($A6,".",$B6),Netlist_VTable!$H:$I,2,0) -> S1_P0_MDI+ | E6: =VLOOKUP(D6,EtchLengthFromLayout!$A:$B,2,0) -> 1134.85 | F6: =CONCATENATE("S",MID($A6,5,1),"_U1_",SUBSTITUTE($C6,"IP","I+") ) -> S1_U1_P0_MDI+ | G6: =VLOOKUP(F6,EtchLengthFromLayout!$A:$B,2,0) -> 522.6 | H6: =E6+G6 -> 1657.45 | I6: =CONCATENATE("S",MID($A6,5,1),"_U2_",SUBSTITUTE($C6,"IP","I+") ) -> S1_U2_P0_MDI+ | J6: =VLOOKUP(I6,EtchLengthFromLayout!$A:$B,2,0) -> 105.79 | K6: =CONCATENATE("S",MID($A6,5,1),"_U3_",SUBSTITUTE($C6,"IP","I+") ) -> S1_U3_P0_MDI+ | L6: =VLOOKUP(K6,EtchLengthFromLayout!$A:$B,2,0) -> 14717.28 | M6: =CONCATENATE("S",MID($A6,5,1),"_U4PILB_",SUBSTITUTE($C6,"IP","I+") ) -> S1_U4PILB_P0_MDI+ | N6: =VLOOKUP(M6,EtchLengthFromLayout!$A:$B,2,0) -> 3460.43 | Q6: =SUBSTITUTE($V6,"_P","_2_P") -> SG1_2_P0_MDI+ | R6: =VLOOKUP(Q6,EtchLengthFromLayout!$A:$B,2,0) -> 5782.96 | S6: =SUBSTITUTE($V6,"_P","_1_P") -> SG1_1_P0_MDI+ | T6: =VLOOKUP(S6,EtchLengthFromLayout!$A:$B,2,0) -> 100.38 | V6: =VLOOKUP(CONCATENATE($Z6,".",$AA6),Netlist_VTable!$H:$I,2,0) -> SG1_P0_MDI+ | W6: =VLOOKUP(V6,EtchLengthFromLayout!$A:$B,2,0) -> 919.84 | X6: =E6+G6+J6+L6+N6+P6+R6+T6+W6 -> 26744.13 | Y6: =IF(Y5<=5,"OK, Tolerance<= 5 mil", "Not OK, Tolerance > 5 mil") -> OK, Tolerance<= 5 mil | Z6: GOLD1 | AA6: =VLOOKUP(AB6,PinNo!$B:$C,2,0) -> A3 | AB6: =C6 -> P0_MDIP
A7: SITE2 | B7: =VLOOKUP(C7,PinNo!$B:$C,2,0) -> A2 | C7: P0_MDIN | D7: =VLOOKUP(CONCATENATE($A7,".",$B7),Netlist_VTable!$H:$I,2,0) -> S2_P0_MDI- | E7: =VLOOKUP(D7,EtchLengthFromLayout!$A:$B,2,0) -> 1134.84 | F7: =CONCATENATE("S",MID($A7,5,1),"_U1_",SUBSTITUTE($C7,"IN","I-") ) -> S2_U1_P0_MDI- | G7: =VLOOKUP(F7,EtchLengthFromLayout!$A:$B,2,0) -> 522.65 | H7: =E7+G7 -> 1657.49 | I7: =CONCATENATE("S",MID($A7,5,1),"_U2_",SUBSTITUTE($C7,"IN","I-") ) -> S2_U2_P0_MDI- | J7: =VLOOKUP(I7,EtchLengthFromLayout!$A:$B,2,0) -> 105.98 | K7: =CONCATENATE("S",MID($A7,5,1),"_U3_",SUBSTITUTE($C7,"IN","I-") ) -> S2_U3_P0_MDI- | L7: =VLOOKUP(K7,EtchLengthFromLayout!$A:$B,2,0) -> 10446.9 | M7: =CONCATENATE("S",MID($A7,5,1),"_U4PILB_",SUBSTITUTE($C7,"IN","I-") ) -> S2_U4PILB_P0_MDI- | N7: =VLOOKUP(M7,EtchLengthFromLayout!$A:$B,2,0) -> 8789.83 | Q7: =SUBSTITUTE($V7,"_P","_2_P") -> SG2_2_P0_MDI- | R7: =VLOOKUP(Q7,EtchLengthFromLayout!$A:$B,2,0) -> 4788.86 | S7: =SUBSTITUTE($V7,"_P","_1_P") -> SG2_1_P0_MDI- | T7: =VLOOKUP(S7,EtchLengthFromLayout!$A:$B,2,0) -> 102.2 | V7: =VLOOKUP(CONCATENATE($Z7,".",$AA7),Netlist_VTable!$H:$I,2,0) -> SG2_P0_MDI- | W7: =VLOOKUP(V7,EtchLengthFromLayout!$A:$B,2,0) -> 919.84 | X7: =E7+G7+J7+L7+N7+P7+R7+T7+W7 -> 26811.1 | Y7: =ABS(X7-X8) -> 2.05 | Z7: GOLD2 | AA7: =VLOOKUP(AB7,PinNo!$B:$C,2,0) -> A2 | AB7: =C7 -> P0_MDIN
A8: SITE2 | B8: =VLOOKUP(C8,PinNo!$B:$C,2,0) -> A3 | C8: P0_MDIP | D8: =VLOOKUP(CONCATENATE($A8,".",$B8),Netlist_VTable!$H:$I,2,0) -> S2_P0_MDI+ | E8: =VLOOKUP(D8,EtchLengthFromLayout!$A:$B,2,0) -> 1134.85 | F8: =CONCATENATE("S",MID($A8,5,1),"_U1_",SUBSTITUTE($C8,"IP","I+") ) -> S2_U1_P0_MDI+ | G8: =VLOOKUP(F8,EtchLengthFromLayout!$A:$B,2,0) -> 522.6 | H8: =E8+G8 -> 1657.45 | I8: =CONCATENATE("S",MID($A8,5,1),"_U2_",SUBSTITUTE($C8,"IP","I+") ) -> S2_U2_P0_MDI+ | J8: =VLOOKUP(I8,EtchLengthFromLayout!$A:$B,2,0) -> 105.79 | K8: =CONCATENATE("S",MID($A8,5,1),"_U3_",SUBSTITUTE($C8,"IP","I+") ) -> S2_U3_P0_MDI+ | L8: =VLOOKUP(K8,EtchLengthFromLayout!$A:$B,2,0) -> 10446.9 | M8: =CONCATENATE("S",MID($A8,5,1),"_U4PILB_",SUBSTITUTE($C8,"IP","I+") ) -> S2_U4PILB_P0_MDI+ | N8: =VLOOKUP(M8,EtchLengthFromLayout!$A:$B,2,0) -> 8789.83 | Q8: =SUBSTITUTE($V8,"_P","_2_P") -> SG2_2_P0_MDI+ | R8: =VLOOKUP(Q8,EtchLengthFromLayout!$A:$B,2,0) -> 4788.86 | S8: =SUBSTITUTE($V8,"_P","_1_P") -> SG2_1_P0_MDI+ | T8: =VLOOKUP(S8,EtchLengthFromLayout!$A:$B,2,0) -> 100.38 | V8: =VLOOKUP(CONCATENATE($Z8,".",$AA8),Netlist_VTable!$H:$I,2,0) -> SG2_P0_MDI+ | W8: =VLOOKUP(V8,EtchLengthFromLayout!$A:$B,2,0) -> 919.84 | X8: =E8+G8+J8+L8+N8+P8+R8+T8+W8 -> 26809.05 | Y8: =IF(Y7<=5,"OK, Tolerance<= 5 mil", "Not OK, Tolerance > 5 mil") -> OK, Tolerance<= 5 mil | Z8: GOLD2 | AA8: =VLOOKUP(AB8,PinNo!$B:$C,2,0) -> A3 | AB8: =C8 -> P0_MDIP
A9: SITE3 | B9: =VLOOKUP(C9,PinNo!$B:$C,2,0) -> A2 | C9: P0_MDIN | D9: =VLOOKUP(CONCATENATE($A9,".",$B9),Netlist_VTable!$H:$I,2,0) -> S3_P0_MDI- | E9: =VLOOKUP(D9,EtchLengthFromLayout!$A:$B,2,0) -> 1134.84 | F9: =CONCATENATE("S",MID($A9,5,1),"_U1_",SUBSTITUTE($C9,"IN","I-") ) -> S3_U1_P0_MDI- | G9: =VLOOKUP(F9,EtchLengthFromLayout!$A:$B,2,0) -> 522.65 | H9: =E9+G9 -> 1657.49 | I9: =CONCATENATE("S",MID($A9,5,1),"_U2_",SUBSTITUTE($C9,"IN","I-") ) -> S3_U2_P0_MDI- | J9: =VLOOKUP(I9,EtchLengthFromLayout!$A:$B,2,0) -> 105.98 | K9: =CONCATENATE("S",MID($A9,5,1),"_U3_",SUBSTITUTE($C9,"IN","I-") ) -> S3_U3_P0_MDI- | L9: =VLOOKUP(K9,EtchLengthFromLayout!$A:$B,2,0) -> 15854.55 | M9: =CONCATENATE("S",MID($A9,5,1),"_U4PILB_",SUBSTITUTE($C9,"IN","I-") ) -> S3_U4PILB_P0_MDI- | N9: =VLOOKUP(M9,EtchLengthFromLayout!$A:$B,2,0) -> 6035.07 | Q9: =SUBSTITUTE($V9,"_P","_2_P") -> SG3_2_P0_MDI- | R9: =VLOOKUP(Q9,EtchLengthFromLayout!$A:$B,2,0) -> 2500.46 | S9: =SUBSTITUTE($V9,"_P","_1_P") -> SG3_1_P0_MDI- | T9: =VLOOKUP(S9,EtchLengthFromLayout!$A:$B,2,0) -> 102.2 | V9: =VLOOKUP(CONCATENATE($Z9,".",$AA9),Netlist_VTable!$H:$I,2,0) -> SG3_P0_MDI- | W9: =VLOOKUP(V9,EtchLengthFromLayout!$A:$B,2,0) -> 919.84 | X9: =E9+G9+J9+L9+N9+P9+R9+T9+W9 -> 27175.59 | Y9: =ABS(X9-X10) -> 2.1 | Z9: GOLD3 | AA9: =VLOOKUP(AB9,PinNo!$B:$C,2,0) -> A2 | AB9: =C9 -> P0_MDIN
A10: SITE3 | B10: =VLOOKUP(C10,PinNo!$B:$C,2,0) -> A3 | C10: P0_MDIP | D10: =VLOOKUP(CONCATENATE($A10,".",$B10),Netlist_VTable!$H:$I,2,0) -> S3_P0_MDI+ | E10: =VLOOKUP(D10,EtchLengthFromLayout!$A:$B,2,0) -> 1134.85 | F10: =CONCATENATE("S",MID($A10,5,1),"_U1_",SUBSTITUTE($C10,"IP","I+") ) -> S3_U1_P0_MDI+ | G10: =VLOOKUP(F10,EtchLengthFromLayout!$A:$B,2,0) -> 522.6 | H10: =E10+G10 -> 1657.45 | I10: =CONCATENATE("S",MID($A10,5,1),"_U2_",SUBSTITUTE($C10,"IP","I+") ) -> S3_U2_P0_MDI+ | J10: =VLOOKUP(I10,EtchLengthFromLayout!$A:$B,2,0) -> 105.79 | K10: =CONCATENATE("S",MID($A10,5,1),"_U3_",SUBSTITUTE($C10,"IP","I+") ) -> S3_U3_P0_MDI+ | L10: =VLOOKUP(K10,EtchLengthFromLayout!$A:$B,2,0) -> 15854.51 | M10: =CONCATENATE("S",MID($A10,5,1),"_U4PILB_",SUBSTITUTE($C10,"IP","I+") ) -> S3_U4PILB_P0_MDI+ | N10: =VLOOKUP(M10,EtchLengthFromLayout!$A:$B,2,0) -> 6035.07 | Q10: =SUBSTITUTE($V10,"_P","_2_P") -> SG3_2_P0_MDI+ | R10: =VLOOKUP(Q10,EtchLengthFromLayout!$A:$B,2,0) -> 2500.45 | S10: =SUBSTITUTE($V10,"_P","_1_P") -> SG3_1_P0_MDI+ | T10: =VLOOKUP(S10,EtchLengthFromLayout!$A:$B,2,0) -> 100.38 | V10: =VLOOKUP(CONCATENATE($Z10,".",$AA10),Netlist_VTable!$H:$I,2,0) -> SG3_P0_MDI+ | W10: =VLOOKUP(V10,EtchLengthFromLayout!$A:$B,2,0) -> 919.84 | X10: =E10+G10+J10+L10+N10+P10+R10+T10+W10 -> 27173.49 | Y10: =IF(Y9<=5,"OK, Tolerance<= 5 mil", "Not OK, Tolerance > 5 mil") -> OK, Tolerance<= 5 mil | Z10: GOLD3 | AA10: =VLOOKUP(AB10,PinNo!$B:$C,2,0) -> A3 | AB10: =C10 -> P0_MDIP
F11: Max | H11: =MAX(H3:H10) -> 1657.49 | V11: Max | X11: =MAX(X3:X10) -> 27175.59
F12: Min | H12: =MIN(H3:H10) -> 1657.45 | V12: Min | X12: =MIN(X3:X10) -> 26669.09
F13: Max-Min | H13: =ABS(H11-H12) -> 0.04 | V13: Max-Min | X13: =ABS(X11-X12) -> 506.5
A16: Site | B16: Pin No | C16: Pin Name | D16: Net | E16: Length | F16: Net | G16: Length | H16: DUT-> Choke ( E + G ) 此處為最短距離 | I16: Net | J16: Length | K16: Net | L16: Length | M16: Net | N16: Length | O16: Net | P16: Length | Q16: Net | R16: Length | S16: Net | T16: Length | V16: Golden -> Choke Net (此處為最短距離) | W16: Length | X16: Total Length (mils) | Y16: P/N Difference (mils) | Z16: Golden | AA16: Pin No | AB16: Pin Name | AC16: Note
A17: SITE0 | B17: =VLOOKUP(C17,PinNo!$B:$C,2,0) -> B3 | C17: P1_MDIN | D17: =VLOOKUP(CONCATENATE($A17,".",$B17),Netlist_VTable!$H:$I,2,0) -> S0_P1_MDI- | E17: =VLOOKUP(D17,EtchLengthFromLayout!$A:$B,2,0) -> 2642.63 | F17: =CONCATENATE("S",MID($A17,5,1),"_U1_",SUBSTITUTE($C17,"IN","I-") ) -> S0_U1_P1_MDI- | G17: =VLOOKUP(F17,EtchLengthFromLayout!$A:$B,2,0) -> 550.79 | H17: =E17+G17 -> 3193.42 | I17: =CONCATENATE("S",MID($A17,5,1),"_U2_",SUBSTITUTE($C17,"IN","I-") ) -> S0_U2_P1_MDI- | J17: =VLOOKUP(I17,EtchLengthFromLayout!$A:$B,2,0) -> 105.98 | K17: =CONCATENATE("S",MID($A17,5,1),"_U3_",SUBSTITUTE($C17,"IN","I-") ) -> S0_U3_P1_MDI- | L17: =VLOOKUP(K17,EtchLengthFromLayout!$A:$B,2,0) -> 11123.43 | M17: =CONCATENATE("S",MID($A17,5,1),"_U4PILB_",SUBSTITUTE($C17,"IN","I-") ) -> S0_U4PILB_P1_MDI- | N17: =VLOOKUP(M17,EtchLengthFromLayout!$A:$B,2,0) -> 7616.07 | Q17: =SUBSTITUTE($V17,"_P","_2_P") -> SG0_2_P1_MDI- | R17: =VLOOKUP(Q17,EtchLengthFromLayout!$A:$B,2,0) -> 3739.06 | S17: =SUBSTITUTE($V17,"_P","_1_P") -> SG0_1_P1_MDI- | T17: =VLOOKUP(S17,EtchLengthFromLayout!$A:$B,2,0) -> 102.2 | V17: =VLOOKUP(CONCATENATE($Z17,".",$AA17),Netlist_VTable!$H:$I,2,0) -> SG0_P1_MDI- | W17: =VLOOKUP(V17,EtchLengthFromLayout!$A:$B,2,0) -> 1188.31 | X17: =E17+G17+J17+L17+N17+P17+R17+T17+W17 -> 27068.47 | Y17: =ABS(X17-X18) -> 2.24 | Z17: GOLD0 | AA17: =VLOOKUP(AB17,PinNo!$B:$C,2,0) -> B3 | AB17: =C17 -> P1_MDIN | AC17: DUT to Golden Port P1
A18: SITE0 | B18: =VLOOKUP(C18,PinNo!$B:$C,2,0) -> B4 | C18: P1_MDIP | D18: =VLOOKUP(CONCATENATE($A18,".",$B18),Netlist_VTable!$H:$I,2,0) -> S0_P1_MDI+ | E18: =VLOOKUP(D18,EtchLengthFromLayout!$A:$B,2,0) -> 2642.59 | F18: =CONCATENATE("S",MID($A18,5,1),"_U1_",SUBSTITUTE($C18,"IP","I+") ) -> S0_U1_P1_MDI+ | G18: =VLOOKUP(F18,EtchLengthFromLayout!$A:$B,2,0) -> 550.6 | H18: =E18+G18 -> 3193.19 | I18: =CONCATENATE("S",MID($A18,5,1),"_U2_",SUBSTITUTE($C18,"IP","I+") ) -> S0_U2_P1_MDI+ | J18: =VLOOKUP(I18,EtchLengthFromLayout!$A:$B,2,0) -> 105.79 | K18: =CONCATENATE("S",MID($A18,5,1),"_U3_",SUBSTITUTE($C18,"IP","I+") ) -> S0_U3_P1_MDI+ | L18: =VLOOKUP(K18,EtchLengthFromLayout!$A:$B,2,0) -> 11123.43 | M18: =CONCATENATE("S",MID($A18,5,1),"_U4PILB_",SUBSTITUTE($C18,"IP","I+") ) -> S0_U4PILB_P1_MDI+ | N18: =VLOOKUP(M18,EtchLengthFromLayout!$A:$B,2,0) -> 7616.07 | Q18: =SUBSTITUTE($V18,"_P","_2_P") -> SG0_2_P1_MDI+ | R18: =VLOOKUP(Q18,EtchLengthFromLayout!$A:$B,2,0) -> 3739.06 | S18: =SUBSTITUTE($V18,"_P","_1_P") -> SG0_1_P1_MDI+ | T18: =VLOOKUP(S18,EtchLengthFromLayout!$A:$B,2,0) -> 100.38 | V18: =VLOOKUP(CONCATENATE($Z18,".",$AA18),Netlist_VTable!$H:$I,2,0) -> SG0_P1_MDI+ | W18: =VLOOKUP(V18,EtchLengthFromLayout!$A:$B,2,0) -> 1188.31 | X18: =E18+G18+J18+L18+N18+P18+R18+T18+W18 -> 27066.23 | Y18: =IF(Y17<=5,"OK, Tolerance<= 5 mil", "Not OK, Tolerance > 5 mil") -> OK, Tolerance<= 5 mil | Z18: GOLD0 | AA18: =VLOOKUP(AB18,PinNo!$B:$C,2,0) -> B4 | AB18: =C18 -> P1_MDIP
A19: SITE1 | B19: =VLOOKUP(C19,PinNo!$B:$C,2,0) -> B3 | C19: P1_MDIN | D19: =VLOOKUP(CONCATENATE($A19,".",$B19),Netlist_VTable!$H:$I,2,0) -> S1_P1_MDI- | E19: =VLOOKUP(D19,EtchLengthFromLayout!$A:$B,2,0) -> 2642.63 | F19: =CONCATENATE("S",MID($A19,5,1),"_U1_",SUBSTITUTE($C19,"IN","I-") ) -> S1_U1_P1_MDI- | G19: =VLOOKUP(F19,EtchLengthFromLayout!$A:$B,2,0) -> 550.79 | H19: =E19+G19 -> 3193.42 | I19: =CONCATENATE("S",MID($A19,5,1),"_U2_",SUBSTITUTE($C19,"IN","I-") ) -> S1_U2_P1_MDI- | J19: =VLOOKUP(I19,EtchLengthFromLayout!$A:$B,2,0) -> 105.98 | K19: =CONCATENATE("S",MID($A19,5,1),"_U3_",SUBSTITUTE($C19,"IN","I-") ) -> S1_U3_P1_MDI- | L19: =VLOOKUP(K19,EtchLengthFromLayout!$A:$B,2,0) -> 13396.34 | M19: =CONCATENATE("S",MID($A19,5,1),"_U4PILB_",SUBSTITUTE($C19,"IN","I-") ) -> S1_U4PILB_P1_MDI- | N19: =VLOOKUP(M19,EtchLengthFromLayout!$A:$B,2,0) -> 3014.57 | Q19: =SUBSTITUTE($V19,"_P","_2_P") -> SG1_2_P1_MDI- | R19: =VLOOKUP(Q19,EtchLengthFromLayout!$A:$B,2,0) -> 6079.93 | S19: =SUBSTITUTE($V19,"_P","_1_P") -> SG1_1_P1_MDI- | T19: =VLOOKUP(S19,EtchLengthFromLayout!$A:$B,2,0) -> 102.2 | V19: =VLOOKUP(CONCATENATE($Z19,".",$AA19),Netlist_VTable!$H:$I,2,0) -> SG1_P1_MDI- | W19: =VLOOKUP(V19,EtchLengthFromLayout!$A:$B,2,0) -> 1188.31 | X19: =E19+G19+J19+L19+N19+P19+R19+T19+W19 -> 27080.75 | Y19: =ABS(X19-X20) -> 2.23 | Z19: GOLD1 | AA19: =VLOOKUP(AB19,PinNo!$B:$C,2,0) -> B3 | AB19: =C19 -> P1_MDIN
A20: SITE1 | B20: =VLOOKUP(C20,PinNo!$B:$C,2,0) -> B4 | C20: P1_MDIP | D20: =VLOOKUP(CONCATENATE($A20,".",$B20),Netlist_VTable!$H:$I,2,0) -> S1_P1_MDI+ | E20: =VLOOKUP(D20,EtchLengthFromLayout!$A:$B,2,0) -> 2642.59 | F20: =CONCATENATE("S",MID($A20,5,1),"_U1_",SUBSTITUTE($C20,"IP","I+") ) -> S1_U1_P1_MDI+ | G20: =VLOOKUP(F20,EtchLengthFromLayout!$A:$B,2,0) -> 550.6 | H20: =E20+G20 -> 3193.19 | I20: =CONCATENATE("S",MID($A20,5,1),"_U2_",SUBSTITUTE($C20,"IP","I+") ) -> S1_U2_P1_MDI+ | J20: =VLOOKUP(I20,EtchLengthFromLayout!$A:$B,2,0) -> 105.79 | K20: =CONCATENATE("S",MID($A20,5,1),"_U3_",SUBSTITUTE($C20,"IP","I+") ) -> S1_U3_P1_MDI+ | L20: =VLOOKUP(K20,EtchLengthFromLayout!$A:$B,2,0) -> 13396.34 | M20: =CONCATENATE("S",MID($A20,5,1),"_U4PILB_",SUBSTITUTE($C20,"IP","I+") ) -> S1_U4PILB_P1_MDI+ | N20: =VLOOKUP(M20,EtchLengthFromLayout!$A:$B,2,0) -> 3014.57 | Q20: =SUBSTITUTE($V20,"_P","_2_P") -> SG1_2_P1_MDI+ | R20: =VLOOKUP(Q20,EtchLengthFromLayout!$A:$B,2,0) -> 6079.94 | S20: =SUBSTITUTE($V20,"_P","_1_P") -> SG1_1_P1_MDI+ | T20: =VLOOKUP(S20,EtchLengthFromLayout!$A:$B,2,0) -> 100.38 | V20: =VLOOKUP(CONCATENATE($Z20,".",$AA20),Netlist_VTable!$H:$I,2,0) -> SG1_P1_MDI+ | W20: =VLOOKUP(V20,EtchLengthFromLayout!$A:$B,2,0) -> 1188.31 | X20: =E20+G20+J20+L20+N20+P20+R20+T20+W20 -> 27078.52 | Y20: =IF(Y19<=5,"OK, Tolerance<= 5 mil", "Not OK, Tolerance > 5 mil") -> OK, Tolerance<= 5 mil | Z20: GOLD1 | AA20: =VLOOKUP(AB20,PinNo!$B:$C,2,0) -> B4 | AB20: =C20 -> P1_MDIP
A21: SITE2 | B21: =VLOOKUP(C21,PinNo!$B:$C,2,0) -> B3 | C21: P1_MDIN | D21: =VLOOKUP(CONCATENATE($A21,".",$B21),Netlist_VTable!$H:$I,2,0) -> S2_P1_MDI- | E21: =VLOOKUP(D21,EtchLengthFromLayout!$A:$B,2,0) -> 2642.63 | F21: =CONCATENATE("S",MID($A21,5,1),"_U1_",SUBSTITUTE($C21,"IN","I-") ) -> S2_U1_P1_MDI- | G21: =VLOOKUP(F21,EtchLengthFromLayout!$A:$B,2,0) -> 550.79 | H21: =E21+G21 -> 3193.42 | I21: =CONCATENATE("S",MID($A21,5,1),"_U2_",SUBSTITUTE($C21,"IN","I-") ) -> S2_U2_P1_MDI- | J21: =VLOOKUP(I21,EtchLengthFromLayout!$A:$B,2,0) -> 105.98 | K21: =CONCATENATE("S",MID($A21,5,1),"_U3_",SUBSTITUTE($C21,"IN","I-") ) -> S2_U3_P1_MDI- | L21: =VLOOKUP(K21,EtchLengthFromLayout!$A:$B,2,0) -> 10258.76 | M21: =CONCATENATE("S",MID($A21,5,1),"_U4PILB_",SUBSTITUTE($C21,"IN","I-") ) -> S2_U4PILB_P1_MDI- | N21: =VLOOKUP(M21,EtchLengthFromLayout!$A:$B,2,0) -> 7309.59 | Q21: =SUBSTITUTE($V21,"_P","_2_P") -> SG2_2_P1_MDI- | R21: =VLOOKUP(Q21,EtchLengthFromLayout!$A:$B,2,0) -> 5101.48 | S21: =SUBSTITUTE($V21,"_P","_1_P") -> SG2_1_P1_MDI- | T21: =VLOOKUP(S21,EtchLengthFromLayout!$A:$B,2,0) -> 102.2 | V21: =VLOOKUP(CONCATENATE($Z21,".",$AA21),Netlist_VTable!$H:$I,2,0) -> SG2_P1_MDI- | W21: =VLOOKUP(V21,EtchLengthFromLayout!$A:$B,2,0) -> 1188.31 | X21: =E21+G21+J21+L21+N21+P21+R21+T21+W21 -> 27259.74 | Y21: =ABS(X21-X22) -> 2.24 | Z21: GOLD2 | AA21: =VLOOKUP(AB21,PinNo!$B:$C,2,0) -> B3 | AB21: =C21 -> P1_MDIN
A22: SITE2 | B22: =VLOOKUP(C22,PinNo!$B:$C,2,0) -> B4 | C22: P1_MDIP | D22: =VLOOKUP(CONCATENATE($A22,".",$B22),Netlist_VTable!$H:$I,2,0) -> S2_P1_MDI+ | E22: =VLOOKUP(D22,EtchLengthFromLayout!$A:$B,2,0) -> 2642.59 | F22: =CONCATENATE("S",MID($A22,5,1),"_U1_",SUBSTITUTE($C22,"IP","I+") ) -> S2_U1_P1_MDI+ | G22: =VLOOKUP(F22,EtchLengthFromLayout!$A:$B,2,0) -> 550.6 | H22: =E22+G22 -> 3193.19 | I22: =CONCATENATE("S",MID($A22,5,1),"_U2_",SUBSTITUTE($C22,"IP","I+") ) -> S2_U2_P1_MDI+ | J22: =VLOOKUP(I22,EtchLengthFromLayout!$A:$B,2,0) -> 105.79 | K22: =CONCATENATE("S",MID($A22,5,1),"_U3_",SUBSTITUTE($C22,"IP","I+") ) -> S2_U3_P1_MDI+ | L22: =VLOOKUP(K22,EtchLengthFromLayout!$A:$B,2,0) -> 10258.75 | M22: =CONCATENATE("S",MID($A22,5,1),"_U4PILB_",SUBSTITUTE($C22,"IP","I+") ) -> S2_U4PILB_P1_MDI+ | N22: =VLOOKUP(M22,EtchLengthFromLayout!$A:$B,2,0) -> 7309.59 | Q22: =SUBSTITUTE($V22,"_P","_2_P") -> SG2_2_P1_MDI+ | R22: =VLOOKUP(Q22,EtchLengthFromLayout!$A:$B,2,0) -> 5101.49 | S22: =SUBSTITUTE($V22,"_P","_1_P") -> SG2_1_P1_MDI+ | T22: =VLOOKUP(S22,EtchLengthFromLayout!$A:$B,2,0) -> 100.38 | V22: =VLOOKUP(CONCATENATE($Z22,".",$AA22),Netlist_VTable!$H:$I,2,0) -> SG2_P1_MDI+ | W22: =VLOOKUP(V22,EtchLengthFromLayout!$A:$B,2,0) -> 1188.31 | X22: =E22+G22+J22+L22+N22+P22+R22+T22+W22 -> 27257.5 | Y22: =IF(Y21<=5,"OK, Tolerance<= 5 mil", "Not OK, Tolerance > 5 mil") -> OK, Tolerance<= 5 mil | Z22: GOLD2 | AA22: =VLOOKUP(AB22,PinNo!$B:$C,2,0) -> B4 | AB22: =C22 -> P1_MDIP
A23: SITE3 | B23: =VLOOKUP(C23,PinNo!$B:$C,2,0) -> B3 | C23: P1_MDIN | D23: =VLOOKUP(CONCATENATE($A23,".",$B23),Netlist_VTable!$H:$I,2,0) -> S3_P1_MDI- | E23: =VLOOKUP(D23,EtchLengthFromLayout!$A:$B,2,0) -> 2642.63 | F23: =CONCATENATE("S",MID($A23,5,1),"_U1_",SUBSTITUTE($C23,"IN","I-") ) -> S3_U1_P1_MDI- | G23: =VLOOKUP(F23,EtchLengthFromLayout!$A:$B,2,0) -> 550.79 | H23: =E23+G23 -> 3193.42 | I23: =CONCATENATE("S",MID($A23,5,1),"_U2_",SUBSTITUTE($C23,"IN","I-") ) -> S3_U2_P1_MDI- | J23: =VLOOKUP(I23,EtchLengthFromLayout!$A:$B,2,0) -> 105.98 | K23: =CONCATENATE("S",MID($A23,5,1),"_U3_",SUBSTITUTE($C23,"IN","I-") ) -> S3_U3_P1_MDI- | L23: =VLOOKUP(K23,EtchLengthFromLayout!$A:$B,2,0) -> 14910.24 | M23: =CONCATENATE("S",MID($A23,5,1),"_U4PILB_",SUBSTITUTE($C23,"IN","I-") ) -> S3_U4PILB_P1_MDI- | N23: =VLOOKUP(M23,EtchLengthFromLayout!$A:$B,2,0) -> 5461.53 | Q23: =SUBSTITUTE($V23,"_P","_2_P") -> SG3_2_P1_MDI- | R23: =VLOOKUP(Q23,EtchLengthFromLayout!$A:$B,2,0) -> 2598.12 | S23: =SUBSTITUTE($V23,"_P","_1_P") -> SG3_1_P1_MDI- | T23: =VLOOKUP(S23,EtchLengthFromLayout!$A:$B,2,0) -> 102.2 | V23: =VLOOKUP(CONCATENATE($Z23,".",$AA23),Netlist_VTable!$H:$I,2,0) -> SG3_P1_MDI- | W23: =VLOOKUP(V23,EtchLengthFromLayout!$A:$B,2,0) -> 1188.31 | X23: =E23+G23+J23+L23+N23+P23+R23+T23+W23 -> 27559.8 | Y23: =ABS(X23-X24) -> 2.23 | Z23: GOLD3 | AA23: =VLOOKUP(AB23,PinNo!$B:$C,2,0) -> B3 | AB23: =C23 -> P1_MDIN
A24: SITE3 | B24: =VLOOKUP(C24,PinNo!$B:$C,2,0) -> B4 | C24: P1_MDIP | D24: =VLOOKUP(CONCATENATE($A24,".",$B24),Netlist_VTable!$H:$I,2,0) -> S3_P1_MDI+ | E24: =VLOOKUP(D24,EtchLengthFromLayout!$A:$B,2,0) -> 2642.59 | F24: =CONCATENATE("S",MID($A24,5,1),"_U1_",SUBSTITUTE($C24,"IP","I+") ) -> S3_U1_P1_MDI+ | G24: =VLOOKUP(F24,EtchLengthFromLayout!$A:$B,2,0) -> 550.6 | H24: =E24+G24 -> 3193.19 | I24: =CONCATENATE("S",MID($A24,5,1),"_U2_",SUBSTITUTE($C24,"IP","I+") ) -> S3_U2_P1_MDI+ | J24: =VLOOKUP(I24,EtchLengthFromLayout!$A:$B,2,0) -> 105.79 | K24: =CONCATENATE("S",MID($A24,5,1),"_U3_",SUBSTITUTE($C24,"IP","I+") ) -> S3_U3_P1_MDI+ | L24: =VLOOKUP(K24,EtchLengthFromLayout!$A:$B,2,0) -> 14910.24 | M24: =CONCATENATE("S",MID($A24,5,1),"_U4PILB_",SUBSTITUTE($C24,"IP","I+") ) -> S3_U4PILB_P1_MDI+ | N24: =VLOOKUP(M24,EtchLengthFromLayout!$A:$B,2,0) -> 5461.53 | Q24: =SUBSTITUTE($V24,"_P","_2_P") -> SG3_2_P1_MDI+ | R24: =VLOOKUP(Q24,EtchLengthFromLayout!$A:$B,2,0) -> 2598.13 | S24: =SUBSTITUTE($V24,"_P","_1_P") -> SG3_1_P1_MDI+ | T24: =VLOOKUP(S24,EtchLengthFromLayout!$A:$B,2,0) -> 100.38 | V24: =VLOOKUP(CONCATENATE($Z24,".",$AA24),Netlist_VTable!$H:$I,2,0) -> SG3_P1_MDI+ | W24: =VLOOKUP(V24,EtchLengthFromLayout!$A:$B,2,0) -> 1188.31 | X24: =E24+G24+J24+L24+N24+P24+R24+T24+W24 -> 27557.57 | Y24: =IF(Y23<=5,"OK, Tolerance<= 5 mil", "Not OK, Tolerance > 5 mil") -> OK, Tolerance<= 5 mil | Z24: GOLD3 | AA24: =VLOOKUP(AB24,PinNo!$B:$C,2,0) -> B4 | AB24: =C24 -> P1_MDIP
F25: Max | H25: =MAX(H17:H24) -> 3193.42 | V25: Max | X25: =MAX(X17:X24) -> 27559.8
F26: Min | H26: =MIN(H17:H24) -> 3193.19 | V26: Min | X26: =MIN(X17:X24) -> 27066.23
F27: Max-Min | H27: =ABS(H25-H26) -> 0.23 | V27: Max-Min | X27: =ABS(X25-X26) -> 493.57
A30: Site | B30: Pin No | C30: Pin Name | D30: Net | E30: Length | F30: Net | G30: Length | H30: DUT-> Choke ( E + G ) 此處為最短距離 | I30: Net | J30: Length | K30: Net | L30: Length | M30: Net | N30: Length | O30: Net | P30: Length | Q30: Net | R30: Length | S30: Net | T30: Length | V30: Golden -> Choke Net (此處為最短距離) | W30: Length | X30: Total Length (mils) | Y30: P/N Difference (mils) | Z30: Golden | AA30: Pin No | AB30: Pin Name | AC30: Note
A31: SITE0 | B31: =VLOOKUP(C31,PinNo!$B:$C,2,0) -> A4 | C31: P5_MDIN | D31: =VLOOKUP(CONCATENATE($A31,".",$B31),Netlist_VTable!$H:$I,2,0) -> S0_P5_MDI- | E31: =VLOOKUP(D31,EtchLengthFromLayout!$A:$B,2,0) -> 1170.74 | F31: =CONCATENATE("S",MID($A31,5,1),"_U1_",SUBSTITUTE($C31,"IN","I-") ) -> S0_U1_P5_MDI- | G31: =VLOOKUP(F31,EtchLengthFromLayout!$A:$B,2,0) -> 542.65 | H31: =E31+G31 -> 1713.39 | I31: =CONCATENATE("S",MID($A31,5,1),"_U2_",SUBSTITUTE($C31,"IN","I-") ) -> S0_U2_P5_MDI- | J31: =VLOOKUP(I31,EtchLengthFromLayout!$A:$B,2,0) -> 105.98 | K31: =CONCATENATE("S",MID($A31,5,1),"_U3_",SUBSTITUTE($C31,"IN","I-") ) -> S0_U3_P5_MDI- | L31: =VLOOKUP(K31,EtchLengthFromLayout!$A:$B,2,0) -> 11458.28 | M31: =CONCATENATE("S",MID($A31,5,1),"_U4PILB_",SUBSTITUTE($C31,"IN","I-") ) -> S0_U4PILB_P5_MDI- | N31: =VLOOKUP(M31,EtchLengthFromLayout!$A:$B,2,0) -> 8603.78 | Q31: =SUBSTITUTE($V31,"_P","_2_P") -> SG0_2_P5_MDI- | R31: =VLOOKUP(Q31,EtchLengthFromLayout!$A:$B,2,0) -> 4457.14 | S31: =SUBSTITUTE($V31,"_P","_1_P") -> SG0_1_P5_MDI- | T31: =VLOOKUP(S31,EtchLengthFromLayout!$A:$B,2,0) -> 102.2 | V31: =VLOOKUP(CONCATENATE($Z31,".",$AA31),Netlist_VTable!$H:$I,2,0) -> SG0_P5_MDI- | W31: =VLOOKUP(V31,EtchLengthFromLayout!$A:$B,2,0) -> 262.05 | X31: =E31+G31+J31+L31+N31+P31+R31+T31+W31 -> 26702.82 | Y31: =ABS(X31-X32) -> 2.07 | Z31: GOLD0 | AA31: =VLOOKUP(AB31,PinNo!$B:$C,2,0) -> A4 | AB31: =C31 -> P5_MDIN | AC31: DUT to Golden Port P5
A32: SITE0 | B32: =VLOOKUP(C32,PinNo!$B:$C,2,0) -> A5 | C32: P5_MDIP | D32: =VLOOKUP(CONCATENATE($A32,".",$B32),Netlist_VTable!$H:$I,2,0) -> S0_P5_MDI+ | E32: =VLOOKUP(D32,EtchLengthFromLayout!$A:$B,2,0) -> 1170.75 | F32: =CONCATENATE("S",MID($A32,5,1),"_U1_",SUBSTITUTE($C32,"IP","I+") ) -> S0_U1_P5_MDI+ | G32: =VLOOKUP(F32,EtchLengthFromLayout!$A:$B,2,0) -> 542.6 | H32: =E32+G32 -> 1713.35 | I32: =CONCATENATE("S",MID($A32,5,1),"_U2_",SUBSTITUTE($C32,"IP","I+") ) -> S0_U2_P5_MDI+ | J32: =VLOOKUP(I32,EtchLengthFromLayout!$A:$B,2,0) -> 105.79 | K32: =CONCATENATE("S",MID($A32,5,1),"_U3_",SUBSTITUTE($C32,"IP","I+") ) -> S0_U3_P5_MDI+ | L32: =VLOOKUP(K32,EtchLengthFromLayout!$A:$B,2,0) -> 11458.27 | M32: =CONCATENATE("S",MID($A32,5,1),"_U4PILB_",SUBSTITUTE($C32,"IP","I+") ) -> S0_U4PILB_P5_MDI+ | N32: =VLOOKUP(M32,EtchLengthFromLayout!$A:$B,2,0) -> 8603.78 | Q32: =SUBSTITUTE($V32,"_P","_2_P") -> SG0_2_P5_MDI+ | R32: =VLOOKUP(Q32,EtchLengthFromLayout!$A:$B,2,0) -> 4457.13 | S32: =SUBSTITUTE($V32,"_P","_1_P") -> SG0_1_P5_MDI+ | T32: =VLOOKUP(S32,EtchLengthFromLayout!$A:$B,2,0) -> 100.38 | V32: =VLOOKUP(CONCATENATE($Z32,".",$AA32),Netlist_VTable!$H:$I,2,0) -> SG0_P5_MDI+ | W32: =VLOOKUP(V32,EtchLengthFromLayout!$A:$B,2,0) -> 262.05 | X32: =E32+G32+J32+L32+N32+P32+R32+T32+W32 -> 26700.75 | Y32: =IF(Y31<=5,"OK, Tolerance<= 5 mil", "Not OK, Tolerance > 5 mil") -> OK, Tolerance<= 5 mil | Z32: GOLD0 | AA32: =VLOOKUP(AB32,PinNo!$B:$C,2,0) -> A5 | AB32: =C32 -> P5_MDIP
