Workbook

Sheet PinNo
A1: 1 | B1: LX_OUT | C1: =A1 -> 1
A2: 2 | B2: VDD33[1] | C2: =A2 -> 2
A3: 3 | B3: VDD33[2] | C3: =A3 -> 3
A4: 4 | B4: INTB | C4: =A4 -> 4
A5: 5 | B5: PHYRSTB | C5: =A5 -> 5
A6: 6 | B6: DVDD09 | C6: =A6 -> 6
A7: 7 | B7: XTAL_OUT | C7: =A7 -> 7
A8: 8 | B8: XTAL_IN | C8: =A8 -> 8
A9: 9 | B9: AVDD33[1] | C9: =A9 -> 9
A10: 10 | B10: WAKE | C10: =A10 -> 10
A11: 11 | B11: VBAT | C11: =A11 -> 11
A12: 12 | B12: INH | C12: =A12 -> 12
... A48: 24 | B48: DVDD[1] | C48: =A48 -> 24
A49: GH1 | B49: GH1 | C49: =A49 -> GH1
A50: GH2 | B50: GH2 | C50: =A50 -> GH2
A51: NUT1 | B51: NUT1 | C51: =A51 -> NUT1
A52: NUT2 | B52: NUT2 | C52: =A52 -> NUT2
A53: EP1 | B53: EP1 | C53: =A53 -> EP1
A54: EP2 | B54: EP2 | C54: =A54 -> EP2
A55: EP3 | B55: EP3 | C55: =A55 -> EP3
A56: EP4 | B56: EP4 | C56: =A56 -> EP4
A57: EP5 | B57: EP5 | C57: =A57 -> EP5
A58: EP6 | B58: EP6 | C58: =A58 -> EP6
A59: EP7 | B59: EP7 | C59: =A59 -> EP7
A60: EP8 | B60: EP8 | C60: =A60 -> EP8
... A96: EP40 | B96: EP40 | C96: =A96 -> EP40
C97: =A97 -> 0
C98: =A98 -> 0
C99: =A99 -> 0
C100: =A100 -> 0
C101: =A101 -> 0
C102: =A102 -> 0
C103: =A103 -> 0
C104: =A104 -> 0
C105: =A105 -> 0
C106: =A106 -> 0
C107: =A107 -> 0
C108: =A108 -> 0
... C225: =A225 -> 0

Sheet Netlist_VTable
C1: refer | E1: Net Name | F1: Number | G1: Name | H1: =CONCATENATE(C1,".",F1) -> refer.Number | I1: =E1 -> Net Name
A2: SCHEMATIC1 | B2: P000Z_SD0_SD1_DB_ACR | C2: DSP1 | D2: 1 | E2: SD1_HSD048 | F2: 1 | G2: 1 | H2: =CONCATENATE(C2,".",F2) -> DSP1.1 | I2: =E2 -> SD1_HSD048
A3: SCHEMATIC1 | B3: P000Z_SD0_SD1_DB_ACR | C3: DSP1 | D3: 2 | E3: SD0_HSD048 | F3: 2 | G3: 2 | H3: =CONCATENATE(C3,".",F3) -> DSP1.2 | I3: =E3 -> SD0_HSD048
A4: SCHEMATIC1 | B4: P000Z_SD0_SD1_DB_ACR | C4: DSP1 | D4: 3 | E4: SD1_HSD049 | F4: 3 | G4: 3 | H4: =CONCATENATE(C4,".",F4) -> DSP1.3 | I4: =E4 -> SD1_HSD049
A5: SCHEMATIC1 | B5: P000Z_SD0_SD1_DB_ACR | C5: DSP1 | D5: 4 | E5: SD0_HSD049 | F5: 4 | G5: 4 | H5: =CONCATENATE(C5,".",F5) -> DSP1.4 | I5: =E5 -> SD0_HSD049
A6: SCHEMATIC1 | B6: P000Z_SD0_SD1_DB_ACR | C6: DSP1 | D6: 5 | E6: SD1_HSD050 | F6: 5 | G6: 5 | H6: =CONCATENATE(C6,".",F6) -> DSP1.5 | I6: =E6 -> SD1_HSD050
A7: SCHEMATIC1 | B7: P000Z_SD0_SD1_DB_ACR | C7: DSP1 | D7: 6 | E7: SD0_HSD050 | F7: 6 | G7: 6 | H7: =CONCATENATE(C7,".",F7) -> DSP1.6 | I7: =E7 -> SD0_HSD050
A8: SCHEMATIC1 | B8: P000Z_SD0_SD1_DB_ACR | C8: DSP1 | D8: 7 | E8: SD1_HSD051 | F8: 7 | G8: 7 | H8: =CONCATENATE(C8,".",F8) -> DSP1.7 | I8: =E8 -> SD1_HSD051
A9: SCHEMATIC1 | B9: P000Z_SD0_SD1_DB_ACR | C9: DSP1 | D9: 8 | E9: SD0_HSD051 | F9: 8 | G9: 8 | H9: =CONCATENATE(C9,".",F9) -> DSP1.8 | I9: =E9 -> SD0_HSD051
A10: SCHEMATIC1 | B10: P000Z_SD0_SD1_DB_ACR | C10: DSP1 | D10: 9 | E10: SD1_HSD052 | F10: 9 | G10: 9 | H10: =CONCATENATE(C10,".",F10) -> DSP1.9 | I10: =E10 -> SD1_HSD052
A11: SCHEMATIC1 | B11: P000Z_SD0_SD1_DB_ACR | C11: DSP1 | D11: 10 | E11: SD0_HSD052 | F11: 10 | G11: 10 | H11: =CONCATENATE(C11,".",F11) -> DSP1.10 | I11: =E11 -> SD0_HSD052
A12: SCHEMATIC1 | B12: P000Z_SD0_SD1_DB_ACR | C12: DSP1 | D12: 11 | E12: SD1_HSD053 | F12: 11 | G12: 11 | H12: =CONCATENATE(C12,".",F12) -> DSP1.11 | I12: =E12 -> SD1_HSD053
A13: SCHEMATIC1 | B13: P000Z_SD0_SD1_DB_ACR | C13: DSP1 | D13: 12 | E13: SD0_HSD053 | F13: 12 | G13: 12 | H13: =CONCATENATE(C13,".",F13) -> DSP1.12 | I13: =E13 -> SD0_HSD053
... A75: SCHEMATIC1 | B75: P000Z_SD0_SD1_DB_ACR | C75: DSP1 | D75: 74 | E75: DGND | F75: 74 | G75: 74 | H75: =CONCATENATE(C75,".",F75) -> DSP1.74 | I75: =E75 -> DGND
A76: SCHEMATIC1 | B76: P000Z_SD0_SD1_DB_ACR | C76: DSP1 | D76: 75 | F76: 75 | G76: 75 | H76: =CONCATENATE(C76,".",F76) -> DSP1.75 | I76: =E76 -> 0
A77: SCHEMATIC1 | B77: P000Z_SD0_SD1_DB_ACR | C77: DSP1 | D77: 76 | F77: 76 | G77: 76 | H77: =CONCATENATE(C77,".",F77) -> DSP1.76 | I77: =E77 -> 0
A78: SCHEMATIC1 | B78: P000Z_SD0_SD1_DB_ACR | C78: DSP1 | D78: 77 | E78: DGND | F78: 77 | G78: 77 | H78: =CONCATENATE(C78,".",F78) -> DSP1.77 | I78: =E78 -> DGND
A79: SCHEMATIC1 | B79: P000Z_SD0_SD1_DB_ACR | C79: DSP1 | D79: 78 | E79: DGND | F79: 78 | G79: 78 | H79: =CONCATENATE(C79,".",F79) -> DSP1.78 | I79: =E79 -> DGND
A80: SCHEMATIC1 | B80: P000Z_SD0_SD1_DB_ACR | C80: DSP1 | D80: 79 | F80: 79 | G80: 79 | H80: =CONCATENATE(C80,".",F80) -> DSP1.79 | I80: =E80 -> 0
A81: SCHEMATIC1 | B81: P000Z_SD0_SD1_DB_ACR | C81: DSP1 | D81: 80 | F81: 80 | G81: 80 | H81: =CONCATENATE(C81,".",F81) -> DSP1.80 | I81: =E81 -> 0
A82: SCHEMATIC1 | B82: P000Z_SD0_SD1_DB_ACR | C82: DSP1 | D82: G1 | E82: DGND | F82: G1 | G82: G1 | H82: =CONCATENATE(C82,".",F82) -> DSP1.G1 | I82: =E82 -> DGND
A83: SCHEMATIC1 | B83: P000Z_SD0_SD1_DB_ACR | C83: DSP1 | D83: G2 | E83: DGND | F83: G2 | G83: G2 | H83: =CONCATENATE(C83,".",F83) -> DSP1.G2 | I83: =E83 -> DGND
A84: SCHEMATIC1 | B84: P000Z_SD0_SD1_DB_ACR | C84: DSP1 | D84: G3 | E84: DGND | F84: G3 | G84: G3 | H84: =CONCATENATE(C84,".",F84) -> DSP1.G3 | I84: =E84 -> DGND
A85: SCHEMATIC1 | B85: P000Z_SD0_SD1_DB_ACR | C85: DSP1 | D85: G4 | E85: DGND | F85: G4 | G85: G4 | H85: =CONCATENATE(C85,".",F85) -> DSP1.G4 | I85: =E85 -> DGND
A86: SCHEMATIC1 | B86: P000Z_SD0_SD1_DB_ACR | C86: DSP1 | D86: G5 | E86: DGND | F86: G5 | G86: G5 | H86: =CONCATENATE(C86,".",F86) -> DSP1.G5 | I86: =E86 -> DGND
A87: SCHEMATIC1 | B87: P000Z_SD0_SD1_DB_ACR | C87: DSP1 | D87: G6 | E87: DGND | F87: G6 | G87: G6 | H87: =CONCATENATE(C87,".",F87) -> DSP1.G6 | I87: =E87 -> DGND
A88: SCHEMATIC1 | B88: P000Z_SD0_SD1_DB_ACR | C88: DSP1 | D88: G7 | E88: DGND | F88: G7 | G88: G7 | H88: =CONCATENATE(C88,".",F88) -> DSP1.G7 | I88: =E88 -> DGND
A89: SCHEMATIC1 | B89: P000Z_SD0_SD1_DB_ACR | C89: DSP1 | D89: G8 | E89: DGND | F89: G8 | G89: G8 | H89: =CONCATENATE(C89,".",F89) -> DSP1.G8 | I89: =E89 -> DGND
A90: SCHEMATIC1 | B90: P000Z_SD0_SD1_DB_ACR | C90: DSP1 | D90: GH1 | F90: GH1 | G90: GH1 | H90: =CONCATENATE(C90,".",F90) -> DSP1.GH1 | I90: =E90 -> 0
A91: SCHEMATIC1 | B91: P000Z_SD0_SD1_DB_ACR | C91: DSP1 | D91: GH2 | F91: GH2 | G91: GH2 | H91: =CONCATENATE(C91,".",F91) -> DSP1.GH2 | I91: =E91 -> 0
A92: SCHEMATIC1 | B92: P000Z_SD0_SD1_DB_ACR | C92: DSP1 | D92: NUT1 | F92: NUT1 | G92: NUT1 | H92: =CONCATENATE(C92,".",F92) -> DSP1.NUT1 | I92: =E92 -> 0
A93: SCHEMATIC1 | B93: P000Z_SD0_SD1_DB_ACR | C93: DSP1 | D93: NUT2 | F93: NUT2 | G93: NUT2 | H93: =CONCATENATE(C93,".",F93) -> DSP1.NUT2 | I93: =E93 -> 0
A94: SCHEMATIC1 | B94: P000Z_SD0_SD1_DB_ACR | C94: DSP1 | D94: NUT3 | F94: NUT3 | G94: NUT3 | H94: =CONCATENATE(C94,".",F94) -> DSP1.NUT3 | I94: =E94 -> 0
A95: SCHEMATIC1 | B95: P000Z_SD0_SD1_DB_ACR | C95: DSP1 | D95: NUT4 | F95: NUT4 | G95: NUT4 | H95: =CONCATENATE(C95,".",F95) -> DSP1.NUT4 | I95: =E95 -> 0
A96: SCHEMATIC1 | B96: P000Z_SD0_SD1_DB_ACR | C96: DSP1 | D96: NUT5 | F96: NUT5 | G96: NUT5 | H96: =CONCATENATE(C96,".",F96) -> DSP1.NUT5 | I96: =E96 -> 0
A97: SCHEMATIC1 | B97: P000Z_SD0_SD1_DB_ACR | C97: DSP1 | D97: NUT6 | F97: NUT6 | G97: NUT6 | H97: =CONCATENATE(C97,".",F97) -> DSP1.NUT6 | I97: =E97 -> 0
A98: SCHEMATIC1 | B98: P0001_S0_DUT | C98: JK54 | D98: 1 | E98: SC0145_RLY_K054 | F98: 1 | G98: 1 | H98: =CONCATENATE(C98,".",F98) -> JK54.1 | I98: =E98 -> SC0145_RLY_K054
A99: SCHEMATIC1 | B99: P0001_S0_DUT | C99: JK54 | D99: 2 | E99: DGND | F99: 2 | G99: 2 | H99: =CONCATENATE(C99,".",F99) -> JK54.2 | I99: =E99 -> DGND
A100: SCHEMATIC1 | B100: P0001_S0_DUT | C100: K54 | D100: 2 | F100: 2 | G100: 2 | H100: =CONCATENATE(C100,".",F100) -> K54.2 | I100: =E100 -> 0
A101: SCHEMATIC1 | B101: P0001_S0_DUT | C101: K54 | D101: 3 | F101: 3 | G101: 3 | H101: =CONCATENATE(C101,".",F101) -> K54.3 | I101: =E101 -> 0
...

Sheet EtchLengthFromLayout
A1: Design Name D:/asen/980RT-9010JS-KCD-A10/0828/038RT-9010JSKCD-A100-0828.brd
A2: Date Fri Aug 28 16:12:56 2026
A3: Net Name | B3: Etch Length (mils) | C3: Manhattan Length (mils) | D3: Percent Manhattan (mils)
A4: AGND | B4: 9988.46 | C4: 29804.87 | D4: 33.51
A5: ATX_P3_3V | B5: 0 | C5: 4237.66 | D5: 0
A6: ATX_P5V | B6: 0 | C6: 2193.61 | D6: 0
A7: ATX_P12V | B7: 0 | C7: 653.81 | D7: 0
A8: CTO_DGS00 | B8: 98.71 | C8: 109.01 | D8: 90.55
A9: CTO_DGS01 | B9: 98.71 | C9: 109.01 | D9: 90.55
A10: CTO_DGS02 | B10: 98.71 | C10: 109.01 | D10: 90.55
A11: CTO_DGS03 | B11: 98.71 | C11: 109.01 | D11: 90.55
A12: CTO_DGS04 | B12: 98.71 | C12: 109.01 | D12: 90.55
A13: CTO_DGS05 | B13: 98.71 | C13: 109.01 | D13: 90.55
A14: CTO_DGS06 | B14: 98.71 | C14: 109.01 | D14: 90.55
A15: CTO_DGS07 | B15: 98.71 | C15: 109.01 | D15: 90.55
... A1625: VR24 | B1625: 78.74 | C1625: 78.74 | D1625: 100

Sheet Assigned_Channel
A1: S0_DCH004- | B1: 0.DIG_CH061 | C1: =VLOOKUP(B1,I:J,2,0) -> SLOT0.CH61 | I1: 0.DIG_CH000 | J1: SLOT0.CH0
A2: S0_DCH004+ | B2: 0.DIG_CH060 | C2: =VLOOKUP(B2,I:J,2,0) -> SLOT0.CH60 | I2: 0.DIG_CH001 | J2: SLOT0.CH1
A3: S0_DCH006- | B3: 2.DIG_CH061 | C3: =VLOOKUP(B3,I:J,2,0) -> SLOT2.CH61 | I3: 0.DIG_CH004 | J3: SLOT0.CH4
A4: S0_DCH006+ | B4: 2.DIG_CH060 | C4: =VLOOKUP(B4,I:J,2,0) -> SLOT2.CH60 | I4: 0.DIG_CH010 | J4: SLOT0.CH10
A5: S0_DCH008- | B5: 2.DIG_CH059 | C5: =VLOOKUP(B5,I:J,2,0) -> SLOT2.CH59 | I5: 0.DIG_CH011 | J5: SLOT0.CH11
A6: S0_DCH008+ | B6: 2.DIG_CH058 | C6: =VLOOKUP(B6,I:J,2,0) -> SLOT2.CH58 | I6: 0.DIG_CH016 | J6: SLOT0.CH16
A7: S0_DCH011 | B7: 2.DIG_CH096 | C7: =VLOOKUP(B7,I:J,2,0) -> SLOT2.CH96 | I7: 0.DIG_CH019 | J7: SLOT0.CH19
A8: S0_DCH012- | B8: 0.DIG_CH045 | C8: =VLOOKUP(B8,I:J,2,0) -> SLOT0.CH45 | I8: 0.DIG_CH020 | J8: SLOT0.CH20
A9: S0_DCH012+ | B9: 0.DIG_CH044 | C9: =VLOOKUP(B9,I:J,2,0) -> SLOT0.CH44 | I9: 0.DIG_CH021 | J9: SLOT0.CH21
A10: S0_DCH014- | B10: 2.DIG_CH063 | C10: =VLOOKUP(B10,I:J,2,0) -> SLOT2.CH63 | I10: 0.DIG_CH022 | J10: SLOT0.CH22
A11: S0_DCH014+ | B11: 2.DIG_CH062 | C11: =VLOOKUP(B11,I:J,2,0) -> SLOT2.CH62 | I11: 0.DIG_CH023 | J11: SLOT0.CH23
A12: S0_DCH016- | B12: 2.DIG_CH119 | C12: =VLOOKUP(B12,I:J,2,0) -> SLOT2.CH119 | I12: 0.DIG_CH024 | J12: SLOT0.CH24
... A337: S6_DCH014- | B337: 1.DIG_CH077 | C337: =VLOOKUP(B337,I:J,2,0) -> SLOT1.CH77 | I337: 3.DIG_CH127 | J337: SLOT3.CH127
A338: S6_DCH014+ | B338: 1.DIG_CH076 | C338: =VLOOKUP(B338,I:J,2,0) -> SLOT1.CH76
A339: S6_DCH016- | B339: 3.DIG_CH007 | C339: =VLOOKUP(B339,I:J,2,0) -> SLOT3.CH7
A340: S6_DCH016+ | B340: 3.DIG_CH006 | C340: =VLOOKUP(B340,I:J,2,0) -> SLOT3.CH6
A341: S6_DCH018 | B341: 1.DIG_CH002 | C341: =VLOOKUP(B341,I:J,2,0) -> SLOT1.CH2
A342: S6_DCH021 | B342: 1.DIG_CH082 | C342: =VLOOKUP(B342,I:J,2,0) -> SLOT1.CH82
A343: S6_DCH025 | B343: 1.DIG_CH095 | C343: =VLOOKUP(B343,I:J,2,0) -> SLOT1.CH95
A344: S6_DCH026 | B344: 1.DIG_CH094 | C344: =VLOOKUP(B344,I:J,2,0) -> SLOT1.CH94
A345: S6_DCH027 | B345: 3.DIG_CH072 | C345: =VLOOKUP(B345,I:J,2,0) -> SLOT3.CH72
A346: S6_DCH028 | B346: 3.DIG_CH069 | C346: =VLOOKUP(B346,I:J,2,0) -> SLOT3.CH69
A347: S6_DCH029 | B347: 3.DIG_CH070 | C347: =VLOOKUP(B347,I:J,2,0) -> SLOT3.CH70
A348: S6_DCH030 | B348: 3.DIG_CH005 | C348: =VLOOKUP(B348,I:J,2,0) -> SLOT3.CH5
A349: S6_DCH031 | B349: 3.DIG_CH002 | C349: =VLOOKUP(B349,I:J,2,0) -> SLOT3.CH2
... A509: S7_BDCH024 | B509: 3.DIG_CH083 | C509: =VLOOKUP(B509,I:J,2,0) -> SLOT3.CH83

Sheet BRPHY
A1: DUT to Golden Loopback:
A2: Site | B2: Pin No | C2: Pin Name | D2: Net | E2: Length | F2: Net | G2: Length | H2: Net | I2: Length | J2: DUT-> Choke ( E + G + I ) as short as possible | K2: Net | L2: Length | M2: Net | N2: Length | O2: Net | P2: Length | Q2: Net | R2: Length | S2: Net | T2: Length | U2: Net | V2: Length | W2: Net | X2: Length | Z2: Golden -> Choke 此處為最短距離 Net | AA2: Length | AB2: Total Length (mils) | AC2: P/N Difference (mils) | AD2: Golden | AE2: Pin No | AF2: Pin Name | AG2: Note
A3: SITE0 | B3: 16 | C3: MDIN | D3: S0_MDI- | E3: =VLOOKUP(D3,EtchLengthFromLayout!$A:$B,2,0) -> 1114.46 | H3: S0_1_MDI- | I3: =VLOOKUP(H3,EtchLengthFromLayout!$A:$B,2,0) -> 309.47 | J3: =E3+G3+I3 -> 1423.93 | K3: S0_2_MDI- | L3: =VLOOKUP(K3,EtchLengthFromLayout!$A:$B,2,0) -> 103.82 | M3: S0_3_MDI- | N3: =VLOOKUP(M3,EtchLengthFromLayout!$A:$B,2,0) -> 14048.5 | O3: S0_4_MDI- | P3: =VLOOKUP(O3,EtchLengthFromLayout!$A:$B,2,0) -> 635.93 | S3: S0_SG_LB_MDI- | T3: =VLOOKUP(S3,EtchLengthFromLayout!$A:$B,2,0) -> 1228 | U3: SG0_2_MDI- | V3: =VLOOKUP(U3,EtchLengthFromLayout!$A:$B,2,0) -> 783.26 | W3: SG0_1_MDI- | X3: =VLOOKUP(W3,EtchLengthFromLayout!$A:$B,2,0) -> 114.88 | Z3: SG0_MDI- | AA3: =VLOOKUP(Z3,EtchLengthFromLayout!$A:$B,2,0) -> 911.27 | AB3: =E3+G3+I3+L3+N3+P3+R3+T3+V3+X3+AA3 -> 19249.59 | AC3: =ABS(AB3-AB4) -> 0 | AD3: GOLD0 | AE3: 17 | AF3: MDIN | AG3: DUT to Golden Loopback
A4: SITE0 | B4: 15 | C4: MDIP | D4: S0_MDI+ | E4: =VLOOKUP(D4,EtchLengthFromLayout!$A:$B,2,0) -> 1114.46 | H4: S0_1_MDI+ | I4: =VLOOKUP(H4,EtchLengthFromLayout!$A:$B,2,0) -> 309.46 | J4: =E4+G4+I4 -> 1423.92 | K4: S0_2_MDI+ | L4: =VLOOKUP(K4,EtchLengthFromLayout!$A:$B,2,0) -> 103.82 | M4: S0_3_MDI+ | N4: =VLOOKUP(M4,EtchLengthFromLayout!$A:$B,2,0) -> 14048.5 | O4: S0_4_MDI+ | P4: =VLOOKUP(O4,EtchLengthFromLayout!$A:$B,2,0) -> 635.93 | S4: S0_SG_LB_MDI+ | T4: =VLOOKUP(S4,EtchLengthFromLayout!$A:$B,2,0) -> 1228 | U4: SG0_2_MDI+ | V4: =VLOOKUP(U4,EtchLengthFromLayout!$A:$B,2,0) -> 783.27 | W4: SG0_1_MDI+ | X4: =VLOOKUP(W4,EtchLengthFromLayout!$A:$B,2,0) -> 114.88 | Z4: SG0_MDI+ | AA4: =VLOOKUP(Z4,EtchLengthFromLayout!$A:$B,2,0) -> 911.27 | AB4: =E4+G4+I4+L4+N4+P4+R4+T4+V4+X4+AA4 -> 19249.59 | AC4: =IF(AC3<=1,"OK, Tolerance<= 1 mil", "Not OK, Tolerance > 1 mil") -> OK, Tolerance<= 1 mil | AD4: GOLD0 | AE4: 16 | AF4: MDIP
A5: SITE1 | B5: 16 | C5: MDIN | D5: =REPLACE(D3,2,1,"1") -> S1_MDI- | E5: =VLOOKUP(D5,EtchLengthFromLayout!$A:$B,2,0) -> 1114.46 | H5: =REPLACE(H3,2,1,"1") -> S1_1_MDI- | I5: =VLOOKUP(H5,EtchLengthFromLayout!$A:$B,2,0) -> 309.47 | J5: =E5+G5+I5 -> 1423.93 | K5: =REPLACE(K3,2,1,"1") -> S1_2_MDI- | L5: =VLOOKUP(K5,EtchLengthFromLayout!$A:$B,2,0) -> 103.82 | M5: =REPLACE(M3,2,1,"1") -> S1_3_MDI- | N5: =VLOOKUP(M5,EtchLengthFromLayout!$A:$B,2,0) -> 14048.36 | O5: =REPLACE(O3,2,1,"1") -> S1_4_MDI- | P5: =VLOOKUP(O5,EtchLengthFromLayout!$A:$B,2,0) -> 635.93 | S5: =REPLACE(S3,2,1,"1") -> S1_SG_LB_MDI- | T5: =VLOOKUP(S5,EtchLengthFromLayout!$A:$B,2,0) -> 1228 | U5: =REPLACE(U3,3,1,"1") -> SG1_2_MDI- | V5: =VLOOKUP(U5,EtchLengthFromLayout!$A:$B,2,0) -> 783.26 | W5: =REPLACE(W3,3,1,"1") -> SG1_1_MDI- | X5: =VLOOKUP(W5,EtchLengthFromLayout!$A:$B,2,0) -> 114.88 | Z5: =REPLACE(Z3,3,1,"1") -> SG1_MDI- | AA5: =VLOOKUP(Z5,EtchLengthFromLayout!$A:$B,2,0) -> 911.27 | AB5: =E5+G5+I5+L5+N5+P5+R5+T5+V5+X5+AA5 -> 19249.45 | AC5: =ABS(AB5-AB6) -> 0 | AD5: GOLD1 | AE5: 17 | AF5: MDIN
A6: SITE1 | B6: 15 | C6: MDIP | D6: =REPLACE(D4,2,1,"1") -> S1_MDI+ | E6: =VLOOKUP(D6,EtchLengthFromLayout!$A:$B,2,0) -> 1114.46 | H6: =REPLACE(H4,2,1,"1") -> S1_1_MDI+ | I6: =VLOOKUP(H6,EtchLengthFromLayout!$A:$B,2,0) -> 309.46 | J6: =E6+G6+I6 -> 1423.92 | K6: =REPLACE(K4,2,1,"1") -> S1_2_MDI+ | L6: =VLOOKUP(K6,EtchLengthFromLayout!$A:$B,2,0) -> 103.82 | M6: =REPLACE(M4,2,1,"1") -> S1_3_MDI+ | N6: =VLOOKUP(M6,EtchLengthFromLayout!$A:$B,2,0) -> 14048.36 | O6: =REPLACE(O4,2,1,"1") -> S1_4_MDI+ | P6: =VLOOKUP(O6,EtchLengthFromLayout!$A:$B,2,0) -> 635.93 | S6: =REPLACE(S4,2,1,"1") -> S1_SG_LB_MDI+ | T6: =VLOOKUP(S6,EtchLengthFromLayout!$A:$B,2,0) -> 1228 | U6: =REPLACE(U4,3,1,"1") -> SG1_2_MDI+ | V6: =VLOOKUP(U6,EtchLengthFromLayout!$A:$B,2,0) -> 783.27 | W6: =REPLACE(W4,3,1,"1") -> SG1_1_MDI+ | X6: =VLOOKUP(W6,EtchLengthFromLayout!$A:$B,2,0) -> 114.88 | Z6: =REPLACE(Z4,3,1,"1") -> SG1_MDI+ | AA6: =VLOOKUP(Z6,EtchLengthFromLayout!$A:$B,2,0) -> 911.27 | AB6: =E6+G6+I6+L6+N6+P6+R6+T6+V6+X6+AA6 -> 19249.45 | AC6: =IF(AC5<=1,"OK, Tolerance<= 1 mil", "Not OK, Tolerance > 1 mil") -> OK, Tolerance<= 1 mil | AD6: GOLD1 | AE6: 16 | AF6: MDIP
A7: SITE2 | B7: 16 | C7: MDIN | D7: =REPLACE(D5,2,1,"2") -> S2_MDI- | E7: =VLOOKUP(D7,EtchLengthFromLayout!$A:$B,2,0) -> 1114.46 | H7: =REPLACE(H5,2,1,"2") -> S2_1_MDI- | I7: =VLOOKUP(H7,EtchLengthFromLayout!$A:$B,2,0) -> 309.47 | J7: =E7+G7+I7 -> 1423.93 | K7: =REPLACE(K5,2,1,"2") -> S2_2_MDI- | L7: =VLOOKUP(K7,EtchLengthFromLayout!$A:$B,2,0) -> 103.82 | M7: =REPLACE(M5,2,1,"2") -> S2_3_MDI- | N7: =VLOOKUP(M7,EtchLengthFromLayout!$A:$B,2,0) -> 14048.19 | O7: =REPLACE(O5,2,1,"2") -> S2_4_MDI- | P7: =VLOOKUP(O7,EtchLengthFromLayout!$A:$B,2,0) -> 635.93 | S7: =REPLACE(S5,2,1,"2") -> S2_SG_LB_MDI- | T7: =VLOOKUP(S7,EtchLengthFromLayout!$A:$B,2,0) -> 1228 | U7: =REPLACE(U5,3,1,"2") -> SG2_2_MDI- | V7: =VLOOKUP(U7,EtchLengthFromLayout!$A:$B,2,0) -> 783.26 | W7: =REPLACE(W5,3,1,"2") -> SG2_1_MDI- | X7: =VLOOKUP(W7,EtchLengthFromLayout!$A:$B,2,0) -> 114.88 | Z7: =REPLACE(Z5,3,1,"2") -> SG2_MDI- | AA7: =VLOOKUP(Z7,EtchLengthFromLayout!$A:$B,2,0) -> 911.27 | AB7: =E7+G7+I7+L7+N7+P7+R7+T7+V7+X7+AA7 -> 19249.28 | AC7: =ABS(AB7-AB8) -> 0.04 | AD7: GOLD2 | AE7: 17 | AF7: MDIN
A8: SITE2 | B8: 15 | C8: MDIP | D8: =REPLACE(D6,2,1,"2") -> S2_MDI+ | E8: =VLOOKUP(D8,EtchLengthFromLayout!$A:$B,2,0) -> 1114.46 | H8: =REPLACE(H6,2,1,"2") -> S2_1_MDI+ | I8: =VLOOKUP(H8,EtchLengthFromLayout!$A:$B,2,0) -> 309.46 | J8: =E8+G8+I8 -> 1423.92 | K8: =REPLACE(K6,2,1,"2") -> S2_2_MDI+ | L8: =VLOOKUP(K8,EtchLengthFromLayout!$A:$B,2,0) -> 103.82 | M8: =REPLACE(M6,2,1,"2") -> S2_3_MDI+ | N8: =VLOOKUP(M8,EtchLengthFromLayout!$A:$B,2,0) -> 14048.15 | O8: =REPLACE(O6,2,1,"2") -> S2_4_MDI+ | P8: =VLOOKUP(O8,EtchLengthFromLayout!$A:$B,2,0) -> 635.93 | S8: =REPLACE(S6,2,1,"2") -> S2_SG_LB_MDI+ | T8: =VLOOKUP(S8,EtchLengthFromLayout!$A:$B,2,0) -> 1228 | U8: =REPLACE(U6,3,1,"2") -> SG2_2_MDI+ | V8: =VLOOKUP(U8,EtchLengthFromLayout!$A:$B,2,0) -> 783.27 | W8: =REPLACE(W6,3,1,"2") -> SG2_1_MDI+ | X8: =VLOOKUP(W8,EtchLengthFromLayout!$A:$B,2,0) -> 114.88 | Z8: =REPLACE(Z6,3,1,"2") -> SG2_MDI+ | AA8: =VLOOKUP(Z8,EtchLengthFromLayout!$A:$B,2,0) -> 911.27 | AB8: =E8+G8+I8+L8+N8+P8+R8+T8+V8+X8+AA8 -> 19249.24 | AC8: =IF(AC7<=1,"OK, Tolerance<= 1 mil", "Not OK, Tolerance > 1 mil") -> OK, Tolerance<= 1 mil | AD8: GOLD2 | AE8: 16 | AF8: MDIP
A9: SITE3 | B9: 16 | C9: MDIN | D9: =REPLACE(D7,2,1,"3") -> S3_MDI- | E9: =VLOOKUP(D9,EtchLengthFromLayout!$A:$B,2,0) -> 1114.46 | H9: =REPLACE(H7,2,1,"3") -> S3_1_MDI- | I9: =VLOOKUP(H9,EtchLengthFromLayout!$A:$B,2,0) -> 309.47 | J9: =E9+G9+I9 -> 1423.93 | K9: =REPLACE(K7,2,1,"3") -> S3_2_MDI- | L9: =VLOOKUP(K9,EtchLengthFromLayout!$A:$B,2,0) -> 103.82 | M9: =REPLACE(M7,2,1,"3") -> S3_3_MDI- | N9: =VLOOKUP(M9,EtchLengthFromLayout!$A:$B,2,0) -> 14048.76 | O9: =REPLACE(O7,2,1,"3") -> S3_4_MDI- | P9: =VLOOKUP(O9,EtchLengthFromLayout!$A:$B,2,0) -> 635.93 | S9: =REPLACE(S7,2,1,"3") -> S3_SG_LB_MDI- | T9: =VLOOKUP(S9,EtchLengthFromLayout!$A:$B,2,0) -> 1228 | U9: =REPLACE(U7,3,1,"3") -> SG3_2_MDI- | V9: =VLOOKUP(U9,EtchLengthFromLayout!$A:$B,2,0) -> 783.26 | W9: =REPLACE(W7,3,1,"3") -> SG3_1_MDI- | X9: =VLOOKUP(W9,EtchLengthFromLayout!$A:$B,2,0) -> 114.88 | Z9: =REPLACE(Z7,3,1,"3") -> SG3_MDI- | AA9: =VLOOKUP(Z9,EtchLengthFromLayout!$A:$B,2,0) -> 911.27 | AB9: =E9+G9+I9+L9+N9+P9+R9+T9+V9+X9+AA9 -> 19249.85 | AC9: =ABS(AB9-AB10) -> 0.05 | AD9: GOLD3 | AE9: 17 | AF9: MDIN
A10: SITE3 | B10: 15 | C10: MDIP | D10: =REPLACE(D8,2,1,"3") -> S3_MDI+ | E10: =VLOOKUP(D10,EtchLengthFromLayout!$A:$B,2,0) -> 1114.46 | H10: =REPLACE(H8,2,1,"3") -> S3_1_MDI+ | I10: =VLOOKUP(H10,EtchLengthFromLayout!$A:$B,2,0) -> 309.46 | J10: =E10+G10+I10 -> 1423.92 | K10: =REPLACE(K8,2,1,"3") -> S3_2_MDI+ | L10: =VLOOKUP(K10,EtchLengthFromLayout!$A:$B,2,0) -> 103.82 | M10: =REPLACE(M8,2,1,"3") -> S3_3_MDI+ | N10: =VLOOKUP(M10,EtchLengthFromLayout!$A:$B,2,0) -> 14048.71 | O10: =REPLACE(O8,2,1,"3") -> S3_4_MDI+ | P10: =VLOOKUP(O10,EtchLengthFromLayout!$A:$B,2,0) -> 635.93 | S10: =REPLACE(S8,2,1,"3") -> S3_SG_LB_MDI+ | T10: =VLOOKUP(S10,EtchLengthFromLayout!$A:$B,2,0) -> 1228 | U10: =REPLACE(U8,3,1,"3") -> SG3_2_MDI+ | V10: =VLOOKUP(U10,EtchLengthFromLayout!$A:$B,2,0) -> 783.27 | W10: =REPLACE(W8,3,1,"3") -> SG3_1_MDI+ | X10: =VLOOKUP(W10,EtchLengthFromLayout!$A:$B,2,0) -> 114.88 | Z10: =REPLACE(Z8,3,1,"3") -> SG3_MDI+ | AA10: =VLOOKUP(Z10,EtchLengthFromLayout!$A:$B,2,0) -> 911.27 | AB10: =E10+G10+I10+L10+N10+P10+R10+T10+V10+X10+AA10 -> 19249.8 | AC10: =IF(AC9<=1,"OK, Tolerance<= 1 mil", "Not OK, Tolerance > 1 mil") -> OK, Tolerance<= 1 mil | AD10: GOLD3 | AE10: 16 | AF10: MDIP
A11: SITE4 | B11: 16 | C11: MDIN | D11: =REPLACE(D9,2,1,"4") -> S4_MDI- | E11: =VLOOKUP(D11,EtchLengthFromLayout!$A:$B,2,0) -> 1114.46 | H11: =REPLACE(H9,2,1,"4") -> S4_1_MDI- | I11: =VLOOKUP(H11,EtchLengthFromLayout!$A:$B,2,0) -> 309.47 | J11: =E11+G11+I11 -> 1423.93 | K11: =REPLACE(K9,2,1,"4") -> S4_2_MDI- | L11: =VLOOKUP(K11,EtchLengthFromLayout!$A:$B,2,0) -> 103.82 | M11: =REPLACE(M9,2,1,"4") -> S4_3_MDI- | N11: =VLOOKUP(M11,EtchLengthFromLayout!$A:$B,2,0) -> 14048.25 | O11: =REPLACE(O9,2,1,"4") -> S4_4_MDI- | P11: =VLOOKUP(O11,EtchLengthFromLayout!$A:$B,2,0) -> 635.93 | S11: =REPLACE(S9,2,1,"4") -> S4_SG_LB_MDI- | T11: =VLOOKUP(S11,EtchLengthFromLayout!$A:$B,2,0) -> 1228 | U11: =REPLACE(U9,3,1,"4") -> SG4_2_MDI- | V11: =VLOOKUP(U11,EtchLengthFromLayout!$A:$B,2,0) -> 783.26 | W11: =REPLACE(W9,3,1,"4") -> SG4_1_MDI- | X11: =VLOOKUP(W11,EtchLengthFromLayout!$A:$B,2,0) -> 114.88 | Z11: =REPLACE(Z9,3,1,"4") -> SG4_MDI- | AA11: =VLOOKUP(Z11,EtchLengthFromLayout!$A:$B,2,0) -> 911.27 | AB11: =E11+G11+I11+L11+N11+P11+R11+T11+V11+X11+AA11 -> 19249.34 | AC11: =ABS(AB11-AB12) -> 0 | AD11: GOLD4 | AE11: 17 | AF11: MDIN
A12: SITE4 | B12: 15 | C12: MDIP | D12: =REPLACE(D10,2,1,"4") -> S4_MDI+ | E12: =VLOOKUP(D12,EtchLengthFromLayout!$A:$B,2,0) -> 1114.46 | H12: =REPLACE(H10,2,1,"4") -> S4_1_MDI+ | I12: =VLOOKUP(H12,EtchLengthFromLayout!$A:$B,2,0) -> 309.46 | J12: =E12+G12+I12 -> 1423.92 | K12: =REPLACE(K10,2,1,"4") -> S4_2_MDI+ | L12: =VLOOKUP(K12,EtchLengthFromLayout!$A:$B,2,0) -> 103.82 | M12: =REPLACE(M10,2,1,"4") -> S4_3_MDI+ | N12: =VLOOKUP(M12,EtchLengthFromLayout!$A:$B,2,0) -> 14048.25 | O12: =REPLACE(O10,2,1,"4") -> S4_4_MDI+ | P12: =VLOOKUP(O12,EtchLengthFromLayout!$A:$B,2,0) -> 635.93 | S12: =REPLACE(S10,2,1,"4") -> S4_SG_LB_MDI+ | T12: =VLOOKUP(S12,EtchLengthFromLayout!$A:$B,2,0) -> 1228 | U12: =REPLACE(U10,3,1,"4") -> SG4_2_MDI+ | V12: =VLOOKUP(U12,EtchLengthFromLayout!$A:$B,2,0) -> 783.27 | W12: =REPLACE(W10,3,1,"4") -> SG4_1_MDI+ | X12: =VLOOKUP(W12,EtchLengthFromLayout!$A:$B,2,0) -> 114.88 | Z12: =REPLACE(Z10,3,1,"4") -> SG4_MDI+ | AA12: =VLOOKUP(Z12,EtchLengthFromLayout!$A:$B,2,0) -> 911.27 | AB12: =E12+G12+I12+L12+N12+P12+R12+T12+V12+X12+AA12 -> 19249.34 | AC12: =IF(AC11<=1,"OK, Tolerance<= 1 mil", "Not OK, Tolerance > 1 mil") -> OK, Tolerance<= 1 mil | AD12: GOLD4 | AE12: 16 | AF12: MDIP
A13: SITE5 | B13: 16 | C13: MDIN | D13: =REPLACE(D11,2,1,"5") -> S5_MDI- | E13: =VLOOKUP(D13,EtchLengthFromLayout!$A:$B,2,0) -> 1114.46 | H13: =REPLACE(H11,2,1,"5") -> S5_1_MDI- | I13: =VLOOKUP(H13,EtchLengthFromLayout!$A:$B,2,0) -> 309.47 | J13: =E13+G13+I13 -> 1423.93 | K13: =REPLACE(K11,2,1,"5") -> S5_2_MDI- | L13: =VLOOKUP(K13,EtchLengthFromLayout!$A:$B,2,0) -> 103.82 | M13: =REPLACE(M11,2,1,"5") -> S5_3_MDI- | N13: =VLOOKUP(M13,EtchLengthFromLayout!$A:$B,2,0) -> 14048.6 | O13: =REPLACE(O11,2,1,"5") -> S5_4_MDI- | P13: =VLOOKUP(O13,EtchLengthFromLayout!$A:$B,2,0) -> 635.93 | S13: =REPLACE(S11,2,1,"5") -> S5_SG_LB_MDI- | T13: =VLOOKUP(S13,EtchLengthFromLayout!$A:$B,2,0) -> 1228 | U13: =REPLACE(U11,3,1,"5") -> SG5_2_MDI- | V13: =VLOOKUP(U13,EtchLengthFromLayout!$A:$B,2,0) -> 783.26 | W13: =REPLACE(W11,3,1,"5") -> SG5_1_MDI- | X13: =VLOOKUP(W13,EtchLengthFromLayout!$A:$B,2,0) -> 114.88 | Z13: =REPLACE(Z11,3,1,"5") -> SG5_MDI- | AA13: =VLOOKUP(Z13,EtchLengthFromLayout!$A:$B,2,0) -> 911.27 | AB13: =E13+G13+I13+L13+N13+P13+R13+T13+V13+X13+AA13 -> 19249.69 | AC13: =ABS(AB13-AB14) -> 3.6379788e-12 | AD13: GOLD5 | AE13: 17 | AF13: MDIN
A14: SITE5 | B14: 15 | C14: MDIP | D14: =REPLACE(D12,2,1,"5") -> S5_MDI+ | E14: =VLOOKUP(D14,EtchLengthFromLayout!$A:$B,2,0) -> 1114.46 | H14: =REPLACE(H12,2,1,"5") -> S5_1_MDI+ | I14: =VLOOKUP(H14,EtchLengthFromLayout!$A:$B,2,0) -> 309.46 | J14: =E14+G14+I14 -> 1423.92 | K14: =REPLACE(K12,2,1,"5") -> S5_2_MDI+ | L14: =VLOOKUP(K14,EtchLengthFromLayout!$A:$B,2,0) -> 103.82 | M14: =REPLACE(M12,2,1,"5") -> S5_3_MDI+ | N14: =VLOOKUP(M14,EtchLengthFromLayout!$A:$B,2,0) -> 14048.6 | O14: =REPLACE(O12,2,1,"5") -> S5_4_MDI+ | P14: =VLOOKUP(O14,EtchLengthFromLayout!$A:$B,2,0) -> 635.93 | S14: =REPLACE(S12,2,1,"5") -> S5_SG_LB_MDI+ | T14: =VLOOKUP(S14,EtchLengthFromLayout!$A:$B,2,0) -> 1228 | U14: =REPLACE(U12,3,1,"5") -> SG5_2_MDI+ | V14: =VLOOKUP(U14,EtchLengthFromLayout!$A:$B,2,0) -> 783.27 | W14: =REPLACE(W12,3,1,"5") -> SG5_1_MDI+ | X14: =VLOOKUP(W14,EtchLengthFromLayout!$A:$B,2,0) -> 114.88 | Z14: =REPLACE(Z12,3,1,"5") -> SG5_MDI+ | AA14: =VLOOKUP(Z14,EtchLengthFromLayout!$A:$B,2,0) -> 911.27 | AB14: =E14+G14+I14+L14+N14+P14+R14+T14+V14+X14+AA14 -> 19249.69 | AC14: =IF(AC13<=1,"OK, Tolerance<= 1 mil", "Not OK, Tolerance > 1 mil") -> OK, Tolerance<= 1 mil | AD14: GOLD5 | AE14: 16 | AF14: MDIP
A15: SITE6 | B15: 16 | C15: MDIN | D15: =REPLACE(D13,2,1,"6") -> S6_MDI- | E15: =VLOOKUP(D15,EtchLengthFromLayout!$A:$B,2,0) -> 1114.46 | H15: =REPLACE(H13,2,1,"6") -> S6_1_MDI- | I15: =VLOOKUP(H15,EtchLengthFromLayout!$A:$B,2,0) -> 309.47 | J15: =E15+G15+I15 -> 1423.93 | K15: =REPLACE(K13,2,1,"6") -> S6_2_MDI- | L15: =VLOOKUP(K15,EtchLengthFromLayout!$A:$B,2,0) -> 103.82 | M15: =REPLACE(M13,2,1,"6") -> S6_3_MDI- | N15: =VLOOKUP(M15,EtchLengthFromLayout!$A:$B,2,0) -> 14048.73 | O15: =REPLACE(O13,2,1,"6") -> S6_4_MDI- | P15: =VLOOKUP(O15,EtchLengthFromLayout!$A:$B,2,0) -> 635.93 | S15: =REPLACE(S13,2,1,"6") -> S6_SG_LB_MDI- | T15: =VLOOKUP(S15,EtchLengthFromLayout!$A:$B,2,0) -> 1228 | U15: =REPLACE(U13,3,1,"6") -> SG6_2_MDI- | V15: =VLOOKUP(U15,EtchLengthFromLayout!$A:$B,2,0) -> 783.26 | W15: =REPLACE(W13,3,1,"6") -> SG6_1_MDI- | X15: =VLOOKUP(W15,EtchLengthFromLayout!$A:$B,2,0) -> 114.88 | Z15: =REPLACE(Z13,3,1,"6") -> SG6_MDI- | AA15: =VLOOKUP(Z15,EtchLengthFromLayout!$A:$B,2,0) -> 911.27 | AB15: =E15+G15+I15+L15+N15+P15+R15+T15+V15+X15+AA15 -> 19249.82 | AC15: =ABS(AB15-AB16) -> 0.01 | AD15: GOLD6 | AE15: 17 | AF15: MDIN
A16: SITE6 | B16: 15 | C16: MDIP | D16: =REPLACE(D14,2,1,"6") -> S6_MDI+ | E16: =VLOOKUP(D16,EtchLengthFromLayout!$A:$B,2,0) -> 1114.46 | H16: =REPLACE(H14,2,1,"6") -> S6_1_MDI+ | I16: =VLOOKUP(H16,EtchLengthFromLayout!$A:$B,2,0) -> 309.46 | J16: =E16+G16+I16 -> 1423.92 | K16: =REPLACE(K14,2,1,"6") -> S6_2_MDI+ | L16: =VLOOKUP(K16,EtchLengthFromLayout!$A:$B,2,0) -> 103.82 | M16: =REPLACE(M14,2,1,"6") -> S6_3_MDI+ | N16: =VLOOKUP(M16,EtchLengthFromLayout!$A:$B,2,0) -> 14048.74 | O16: =REPLACE(O14,2,1,"6") -> S6_4_MDI+ | P16: =VLOOKUP(O16,EtchLengthFromLayout!$A:$B,2,0) -> 635.93 | S16: =REPLACE(S14,2,1,"6") -> S6_SG_LB_MDI+ | T16: =VLOOKUP(S16,EtchLengthFromLayout!$A:$B,2,0) -> 1228 | U16: =REPLACE(U14,3,1,"6") -> SG6_2_MDI+ | V16: =VLOOKUP(U16,EtchLengthFromLayout!$A:$B,2,0) -> 783.27 | W16: =REPLACE(W14,3,1,"6") -> SG6_1_MDI+ | X16: =VLOOKUP(W16,EtchLengthFromLayout!$A:$B,2,0) -> 114.88 | Z16: =REPLACE(Z14,3,1,"6") -> SG6_MDI+ | AA16: =VLOOKUP(Z16,EtchLengthFromLayout!$A:$B,2,0) -> 911.27 | AB16: =E16+G16+I16+L16+N16+P16+R16+T16+V16+X16+AA16 -> 19249.83 | AC16: =IF(AC15<=1,"OK, Tolerance<= 1 mil", "Not OK, Tolerance > 1 mil") -> OK, Tolerance<= 1 mil | AD16: GOLD6 | AE16: 16 | AF16: MDIP
A17: SITE7 | B17: 16 | C17: MDIN | D17: =REPLACE(D15,2,1,"7") -> S7_MDI- | E17: =VLOOKUP(D17,EtchLengthFromLayout!$A:$B,2,0) -> 1114.46 | H17: =REPLACE(H15,2,1,"7") -> S7_1_MDI- | I17: =VLOOKUP(H17,EtchLengthFromLayout!$A:$B,2,0) -> 309.47 | J17: =E17+G17+I17 -> 1423.93 | K17: =REPLACE(K15,2,1,"7") -> S7_2_MDI- | L17: =VLOOKUP(K17,EtchLengthFromLayout!$A:$B,2,0) -> 103.82 | M17: =REPLACE(M15,2,1,"7") -> S7_3_MDI- | N17: =VLOOKUP(M17,EtchLengthFromLayout!$A:$B,2,0) -> 14048.83 | O17: =REPLACE(O15,2,1,"7") -> S7_4_MDI- | P17: =VLOOKUP(O17,EtchLengthFromLayout!$A:$B,2,0) -> 635.93 | S17: =REPLACE(S15,2,1,"7") -> S7_SG_LB_MDI- | T17: =VLOOKUP(S17,EtchLengthFromLayout!$A:$B,2,0) -> 1228 | U17: =REPLACE(U15,3,1,"7") -> SG7_2_MDI- | V17: =VLOOKUP(U17,EtchLengthFromLayout!$A:$B,2,0) -> 783.26 | W17: =REPLACE(W15,3,1,"7") -> SG7_1_MDI- | X17: =VLOOKUP(W17,EtchLengthFromLayout!$A:$B,2,0) -> 114.88 | Z17: =REPLACE(Z15,3,1,"7") -> SG7_MDI- | AA17: =VLOOKUP(Z17,EtchLengthFromLayout!$A:$B,2,0) -> 911.27 | AB17: =E17+G17+I17+L17+N17+P17+R17+T17+V17+X17+AA17 -> 19249.92 | AC17: =ABS(AB17-AB18) -> 0.03 | AD17: GOLD7 | AE17: 17 | AF17: MDIN
A18: SITE7 | B18: 15 | C18: MDIP | D18: =REPLACE(D16,2,1,"7") -> S7_MDI+ | E18: =VLOOKUP(D18,EtchLengthFromLayout!$A:$B,2,0) -> 1114.46 | H18: =REPLACE(H16,2,1,"7") -> S7_1_MDI+ | I18: =VLOOKUP(H18,EtchLengthFromLayout!$A:$B,2,0) -> 309.46 | J18: =E18+G18+I18 -> 1423.92 | K18: =REPLACE(K16,2,1,"7") -> S7_2_MDI+ | L18: =VLOOKUP(K18,EtchLengthFromLayout!$A:$B,2,0) -> 103.82 | M18: =REPLACE(M16,2,1,"7") -> S7_3_MDI+ | N18: =VLOOKUP(M18,EtchLengthFromLayout!$A:$B,2,0) -> 14048.86 | O18: =REPLACE(O16,2,1,"7") -> S7_4_MDI+ | P18: =VLOOKUP(O18,EtchLengthFromLayout!$A:$B,2,0) -> 635.93 | S18: =REPLACE(S16,2,1,"7") -> S7_SG_LB_MDI+ | T18: =VLOOKUP(S18,EtchLengthFromLayout!$A:$B,2,0) -> 1228 | U18: =REPLACE(U16,3,1,"7") -> SG7_2_MDI+ | V18: =VLOOKUP(U18,EtchLengthFromLayout!$A:$B,2,0) -> 783.27 | W18: =REPLACE(W16,3,1,"7") -> SG7_1_MDI+ | X18: =VLOOKUP(W18,EtchLengthFromLayout!$A:$B,2,0) -> 114.88 | Z18: =REPLACE(Z16,3,1,"7") -> SG7_MDI+ | AA18: =VLOOKUP(Z18,EtchLengthFromLayout!$A:$B,2,0) -> 911.27 | AB18: =E18+G18+I18+L18+N18+P18+R18+T18+V18+X18+AA18 -> 19249.95 | AC18: =IF(AC17<=1,"OK, Tolerance<= 1 mil", "Not OK, Tolerance > 1 mil") -> OK, Tolerance<= 1 mil | AD18: GOLD7 | AE18: 16 | AF18: MDIP
H19: Max | J19: =MAX(J3:J18) -> 1423.93 | Z19: Max | AA19: =MAX(AA3:AA18) -> 911.27 | AB19: =MAX(AB3:AB18) -> 19249.95
H20: Min | J20: =MIN(J3:J18) -> 1423.92 | Z20: Min | AA20: =MIN(AA3:AA18) -> 911.27 | AB20: =MIN(AB3:AB18) -> 19249.24
H21: Max-Min | J21: =ABS(J19-J20) -> 0.01 | Z21: Max-Min | AA21: =ABS(AA19-AA20) -> 0 | AB21: =ABS(AB19-AB20) -> 0.71
Z22: Tolerence Check | AB22: =IF(AB21<=1000,"OK, Tolerance<= 1000 mils", "Not OK, Tolerance > 1000 mils") -> OK, Tolerance<= 1000 mils
A27: DUT to Connector:
A28: Site | B28: Pin No | C28: Pin Name | D28: Net | E28: Length | F28: Net | G28: Length | H28: Net | I28: Length | J28: DUT-> Choke ( E + G + I ) as short as possible | K28: Net | L28: Length | M28: Net | N28: Length | O28: Net | P28: Length | Q28: Net | R28: Length | S28: Net | T28: Length | U28: Net | V28: Length | W28: Net | X28: Length | Z28: Net | AA28: Length | AB28: Total Length (mils) | AC28: P/N Difference (mils) | AG28: Note
A29: SITE0 | B29: 16 | C29: MDIN | D29: S0_MDI- | E29: =VLOOKUP(D29,EtchLengthFromLayout!$A:$B,2,0) -> 1114.46 | H29: S0_1_MDI- | I29: =VLOOKUP(H29,EtchLengthFromLayout!$A:$B,2,0) -> 309.47 | J29: =E29+G29+I29 -> 1423.93 | K29: S0_2_MDI- | L29: =VLOOKUP(K29,EtchLengthFromLayout!$A:$B,2,0) -> 103.82 | M29: S0_3_MDI- | N29: =VLOOKUP(M29,EtchLengthFromLayout!$A:$B,2,0) -> 14048.5 | O29: S0_4_MDI- | P29: =VLOOKUP(O29,EtchLengthFromLayout!$A:$B,2,0) -> 635.93 | Q29: S0_AC_MDI- | R29: =VLOOKUP(Q29,EtchLengthFromLayout!$A:$B,2,0) -> 505.56 | AB29: =E29+G29+I29+L29+N29+P29+R29+T29+V29+X29+AA29 -> 16717.74 | AC29: =ABS(AB29-AB30) -> 0.01 | AG29: DUT to Connector MQS1
A30: SITE0 | B30: 15 | C30: MDIP | D30: S0_MDI+ | E30: =VLOOKUP(D30,EtchLengthFromLayout!$A:$B,2,0) -> 1114.46 | H30: S0_1_MDI+ | I30: =VLOOKUP(H30,EtchLengthFromLayout!$A:$B,2,0) -> 309.46 | J30: =E30+G30+I30 -> 1423.92 | K30: S0_2_MDI+ | L30: =VLOOKUP(K30,EtchLengthFromLayout!$A:$B,2,0) -> 103.82 | M30: S0_3_MDI+ | N30: =VLOOKUP(M30,EtchLengthFromLayout!$A:$B,2,0) -> 14048.5 | O30: S0_4_MDI+ | P30: =VLOOKUP(O30,EtchLengthFromLayout!$A:$B,2,0) -> 635.93 | Q30: S0_AC_MDI+ | R30: =VLOOKUP(Q30,EtchLengthFromLayout!$A:$B,2,0) -> 505.56 | AB30: =E30+G30+I30+L30+N30+P30+R30+T30+V30+X30+AA30 -> 16717.73 | AC30: =IF(AC29<=1,"OK, Tolerance<= 1 mil", "Not OK, Tolerance > 1 mil") -> OK, Tolerance<= 1 mil
A31: SITE1 | B31: 16 | C31: MDIN | D31: =REPLACE(D29,2,1,"1") -> S1_MDI- | E31: =VLOOKUP(D31,EtchLengthFromLayout!$A:$B,2,0) -> 1114.46 | H31: =REPLACE(H29,2,1,"1") -> S1_1_MDI- | I31: =VLOOKUP(H31,EtchLengthFromLayout!$A:$B,2,0) -> 309.47 | J31: =E31+G31+I31 -> 1423.93 | K31: =REPLACE(K29,2,1,"1") -> S1_2_MDI- | L31: =VLOOKUP(K31,EtchLengthFromLayout!$A:$B,2,0) -> 103.82 | M31: =REPLACE(M29,2,1,"1") -> S1_3_MDI- | N31: =VLOOKUP(M31,EtchLengthFromLayout!$A:$B,2,0) -> 14048.36 | O31: =REPLACE(O29,2,1,"1") -> S1_4_MDI- | P31: =VLOOKUP(O31,EtchLengthFromLayout!$A:$B,2,0) -> 635.93 | Q31: =REPLACE(Q29,2,1,"1") -> S1_AC_MDI- | R31: =VLOOKUP(Q31,EtchLengthFromLayout!$A:$B,2,0) -> 505.56 | AB31: =E31+G31+I31+L31+N31+P31+R31+T31+V31+X31+AA31 -> 16717.6 | AC31: =ABS(AB31-AB32) -> 0.01
A32: SITE1 | B32: 15 | C32: MDIP | D32: =REPLACE(D30,2,1,"1") -> S1_MDI+ | E32: =VLOOKUP(D32,EtchLengthFromLayout!$A:$B,2,0) -> 1114.46 | H32: =REPLACE(H30,2,1,"1") -> S1_1_MDI+ | I32: =VLOOKUP(H32,EtchLengthFromLayout!$A:$B,2,0) -> 309.46 | J32: =E32+G32+I32 -> 1423.92 | K32: =REPLACE(K30,2,1,"1") -> S1_2_MDI+ | L32: =VLOOKUP(K32,EtchLengthFromLayout!$A:$B,2,0) -> 103.82 | M32: =REPLACE(M30,2,1,"1") -> S1_3_MDI+ | N32: =VLOOKUP(M32,EtchLengthFromLayout!$A:$B,2,0) -> 14048.36 | O32: =REPLACE(O30,2,1,"1") -> S1_4_MDI+ | P32: =VLOOKUP(O32,EtchLengthFromLayout!$A:$B,2,0) -> 635.93 | Q32: =REPLACE(Q30,2,1,"1") -> S1_AC_MDI+ | R32: =VLOOKUP(Q32,EtchLengthFromLayout!$A:$B,2,0) -> 505.56 | AB32: =E32+G32+I32+L32+N32+P32+R32+T32+V32+X32+AA32 -> 16717.59 | AC32: =IF(AC31<=1,"OK, Tolerance<= 1 mil", "Not OK, Tolerance > 1 mil") -> OK, Tolerance<= 1 mil
A33: SITE2 | B33: 16 | C33: MDIN | D33: =REPLACE(D31,2,1,"2") -> S2_MDI- | E33: =VLOOKUP(D33,EtchLengthFromLayout!$A:$B,2,0) -> 1114.46 | H33: =REPLACE(H31,2,1,"2") -> S2_1_MDI- | I33: =VLOOKUP(H33,EtchLengthFromLayout!$A:$B,2,0) -> 309.47 | J33: =E33+G33+I33 -> 1423.93 | K33: =REPLACE(K31,2,1,"2") -> S2_2_MDI- | L33: =VLOOKUP(K33,EtchLengthFromLayout!$A:$B,2,0) -> 103.82 | M33: =REPLACE(M31,2,1,"2") -> S2_3_MDI- | N33: =VLOOKUP(M33,EtchLengthFromLayout!$A:$B,2,0) -> 14048.19 | O33: =REPLACE(O31,2,1,"2") -> S2_4_MDI- | P33: =VLOOKUP(O33,EtchLengthFromLayout!$A:$B,2,0) -> 635.93 | Q33: =REPLACE(Q31,2,1,"2") -> S2_AC_MDI- | R33: =VLOOKUP(Q33,EtchLengthFromLayout!$A:$B,2,0) -> 505.56 | AB33: =E33+G33+I33+L33+N33+P33+R33+T33+V33+X33+AA33 -> 16717.43 | AC33: =ABS(AB33-AB34) -> 0.05
A34: SITE2 | B34: 15 | C34: MDIP | D34: =REPLACE(D32,2,1,"2") -> S2_MDI+ | E34: =VLOOKUP(D34,EtchLengthFromLayout!$A:$B,2,0) -> 1114.46 | H34: =REPLACE(H32,2,1,"2") -> S2_1_MDI+ | I34: =VLOOKUP(H34,EtchLengthFromLayout!$A:$B,2,0) -> 309.46 | J34: =E34+G34+I34 -> 1423.92 | K34: =REPLACE(K32,2,1,"2") -> S2_2_MDI+ | L34: =VLOOKUP(K34,EtchLengthFromLayout!$A:$B,2,0) -> 103.82 | M34: =REPLACE(M32,2,1,"2") -> S2_3_MDI+ | N34: =VLOOKUP(M34,EtchLengthFromLayout!$A:$B,2,0) -> 14048.15 | O34: =REPLACE(O32,2,1,"2") -> S2_4_MDI+ | P34: =VLOOKUP(O34,EtchLengthFromLayout!$A:$B,2,0) -> 635.93 | Q34: =REPLACE(Q32,2,1,"2") -> S2_AC_MDI+ | R34: =VLOOKUP(Q34,EtchLengthFromLayout!$A:$B,2,0) -> 505.56 | AB34: =E34+G34+I34+L34+N34+P34+R34+T34+V34+X34+AA34 -> 16717.38 | AC34: =IF(AC33<=1,"OK, Tolerance<= 1 mil", "Not OK, Tolerance > 1 mil") -> OK, Tolerance<= 1 mil
A35: SITE3 | B35: 16 | C35: MDIN | D35: =REPLACE(D33,2,1,"3") -> S3_MDI- | E35: =VLOOKUP(D35,EtchLengthFromLayout!$A:$B,2,0) -> 1114.46 | H35: =REPLACE(H33,2,1,"3") -> S3_1_MDI- | I35: =VLOOKUP(H35,EtchLengthFromLayout!$A:$B,2,0) -> 309.47 | J35: =E35+G35+I35 -> 1423.93 | K35: =REPLACE(K33,2,1,"3") -> S3_2_MDI- | L35: =VLOOKUP(K35,EtchLengthFromLayout!$A:$B,2,0) -> 103.82 | M35: =REPLACE(M33,2,1,"3") -> S3_3_MDI- | N35: =VLOOKUP(M35,EtchLengthFromLayout!$A:$B,2,0) -> 14048.76 | O35: =REPLACE(O33,2,1,"3") -> S3_4_MDI- | P35: =VLOOKUP(O35,EtchLengthFromLayout!$A:$B,2,0) -> 635.93 | Q35: =REPLACE(Q33,2,1,"3") -> S3_AC_MDI- | R35: =VLOOKUP(Q35,EtchLengthFromLayout!$A:$B,2,0) -> 505.56 | AB35: =E35+G35+I35+L35+N35+P35+R35+T35+V35+X35+AA35 -> 16718 | AC35: =ABS(AB35-AB36) -> 0.06
A36: SITE3 | B36: 15 | C36: MDIP | D36: =REPLACE(D34,2,1,"3") -> S3_MDI+ | E36: =VLOOKUP(D36,EtchLengthFromLayout!$A:$B,2,0) -> 1114.46 | H36: =REPLACE(H34,2,1,"3") -> S3_1_MDI+ | I36: =VLOOKUP(H36,EtchLengthFromLayout!$A:$B,2,0) -> 309.46 | J36: =E36+G36+I36 -> 1423.92 | K36: =REPLACE(K34,2,1,"3") -> S3_2_MDI+ | L36: =VLOOKUP(K36,EtchLengthFromLayout!$A:$B,2,0) -> 103.82 | M36: =REPLACE(M34,2,1,"3") -> S3_3_MDI+ | N36: =VLOOKUP(M36,EtchLengthFromLayout!$A:$B,2,0) -> 14048.71 | O36: =REPLACE(O34,2,1,"3") -> S3_4_MDI+ | P36: =VLOOKUP(O36,EtchLengthFromLayout!$A:$B,2,0) -> 635.93 | Q36: =REPLACE(Q34,2,1,"3") -> S3_AC_MDI+ | R36: =VLOOKUP(Q36,EtchLengthFromLayout!$A:$B,2,0) -> 505.56 | AB36: =E36+G36+I36+L36+N36+P36+R36+T36+V36+X36+AA36 -> 16717.94 | AC36: =IF(AC35<=1,"OK, Tolerance<= 1 mil", "Not OK, Tolerance > 1 mil") -> OK, Tolerance<= 1 mil
A37: SITE4 | B37: 16 | C37: MDIN | D37: =REPLACE(D35,2,1,"4") -> S4_MDI- | E37: =VLOOKUP(D37,EtchLengthFromLayout!$A:$B,2,0) -> 1114.46 | H37: =REPLACE(H35,2,1,"4") -> S4_1_MDI- | I37: =VLOOKUP(H37,EtchLengthFromLayout!$A:$B,2,0) -> 309.47 | J37: =E37+G37+I37 -> 1423.93 | K37: =REPLACE(K35,2,1,"4") -> S4_2_MDI- | L37: =VLOOKUP(K37,EtchLengthFromLayout!$A:$B,2,0) -> 103.82 | M37: =REPLACE(M35,2,1,"4") -> S4_3_MDI- | N37: =VLOOKUP(M37,EtchLengthFromLayout!$A:$B,2,0) -> 14048.25 | O37: =REPLACE(O35,2,1,"4") -> S4_4_MDI- | P37: =VLOOKUP(O37,EtchLengthFromLayout!$A:$B,2,0) -> 635.93 | Q37: =REPLACE(Q35,2,1,"4") -> S4_AC_MDI- | R37: =VLOOKUP(Q37,EtchLengthFromLayout!$A:$B,2,0) -> 505.56 | AB37: =E37+G37+I37+L37+N37+P37+R37+T37+V37+X37+AA37 -> 16717.49 | AC37: =ABS(AB37-AB38) -> 0.01
A38: SITE4 | B38: 15 | C38: MDIP | D38: =REPLACE(D36,2,1,"4") -> S4_MDI+ | E38: =VLOOKUP(D38,EtchLengthFromLayout!$A:$B,2,0) -> 1114.46 | H38: =REPLACE(H36,2,1,"4") -> S4_1_MDI+ | I38: =VLOOKUP(H38,EtchLengthFromLayout!$A:$B,2,0) -> 309.46 | J38: =E38+G38+I38 -> 1423.92 | K38: =REPLACE(K36,2,1,"4") -> S4_2_MDI+ | L38: =VLOOKUP(K38,EtchLengthFromLayout!$A:$B,2,0) -> 103.82 | M38: =REPLACE(M36,2,1,"4") -> S4_3_MDI+ | N38: =VLOOKUP(M38,EtchLengthFromLayout!$A:$B,2,0) -> 14048.25 | O38: =REPLACE(O36,2,1,"4") -> S4_4_MDI+ | P38: =VLOOKUP(O38,EtchLengthFromLayout!$A:$B,2,0) -> 635.93 | Q38: =REPLACE(Q36,2,1,"4") -> S4_AC_MDI+ | R38: =VLOOKUP(Q38,EtchLengthFromLayout!$A:$B,2,0) -> 505.56 | AB38: =E38+G38+I38+L38+N38+P38+R38+T38+V38+X38+AA38 -> 16717.48 | AC38: =IF(AC37<=1,"OK, Tolerance<= 1 mil", "Not OK, Tolerance > 1 mil") -> OK, Tolerance<= 1 mil
A39: SITE5 | B39: 16 | C39: MDIN | D39: =REPLACE(D37,2,1,"5") -> S5_MDI- | E39: =VLOOKUP(D39,EtchLengthFromLayout!$A:$B,2,0) -> 1114.46 | H39: =REPLACE(H37,2,1,"5") -> S5_1_MDI- | I39: =VLOOKUP(H39,EtchLengthFromLayout!$A:$B,2,0) -> 309.47 | J39: =E39+G39+I39 -> 1423.93 | K39: =REPLACE(K37,2,1,"5") -> S5_2_MDI- | L39: =VLOOKUP(K39,EtchLengthFromLayout!$A:$B,2,0) -> 103.82 | M39: =REPLACE(M37,2,1,"5") -> S5_3_MDI- | N39: =VLOOKUP(M39,EtchLengthFromLayout!$A:$B,2,0) -> 14048.6 | O39: =REPLACE(O37,2,1,"5") -> S5_4_MDI- | P39: =VLOOKUP(O39,EtchLengthFromLayout!$A:$B,2,0) -> 635.93 | Q39: =REPLACE(Q37,2,1,"5") -> S5_AC_MDI- | R39: =VLOOKUP(Q39,EtchLengthFromLayout!$A:$B,2,0) -> 505.56 | AB39: =E39+G39+I39+L39+N39+P39+R39+T39+V39+X39+AA39 -> 16717.84 | AC39: =ABS(AB39-AB40) -> 0.01
A40: SITE5 | B40: 15 | C40: MDIP | D40: =REPLACE(D38,2,1,"5") -> S5_MDI+ | E40: =VLOOKUP(D40,EtchLengthFromLayout!$A:$B,2,0) -> 1114.46 | H40: =REPLACE(H38,2,1,"5") -> S5_1_MDI+ | I40: =VLOOKUP(H40,EtchLengthFromLayout!$A:$B,2,0) -> 309.46 | J40: =E40+G40+I40 -> 1423.92 | K40: =REPLACE(K38,2,1,"5") -> S5_2_MDI+ | L40: =VLOOKUP(K40,EtchLengthFromLayout!$A:$B,2,0) -> 103.82 | M40: =REPLACE(M38,2,1,"5") -> S5_3_MDI+ | N40: =VLOOKUP(M40,EtchLengthFromLayout!$A:$B,2,0) -> 14048.6 | O40: =REPLACE(O38,2,1,"5") -> S5_4_MDI+ | P40: =VLOOKUP(O40,EtchLengthFromLayout!$A:$B,2,0) -> 635.93 | Q40: =REPLACE(Q38,2,1,"5") -> S5_AC_MDI+ | R40: =VLOOKUP(Q40,EtchLengthFromLayout!$A:$B,2,0) -> 505.56 | AB40: =E40+G40+I40+L40+N40+P40+R40+T40+V40+X40+AA40 -> 16717.83 | AC40: =IF(AC39<=1,"OK, Tolerance<= 1 mil", "Not OK, Tolerance > 1 mil") -> OK, Tolerance<= 1 mil
A41: SITE6 | B41: 16 | C41: MDIN | D41: =REPLACE(D39,2,1,"6") -> S6_MDI- | E41: =VLOOKUP(D41,EtchLengthFromLayout!$A:$B,2,0) -> 1114.46 | H41: =REPLACE(H39,2,1,"6") -> S6_1_MDI- | I41: =VLOOKUP(H41,EtchLengthFromLayout!$A:$B,2,0) -> 309.47 | J41: =E41+G41+I41 -> 1423.93 | K41: =REPLACE(K39,2,1,"6") -> S6_2_MDI- | L41: =VLOOKUP(K41,EtchLengthFromLayout!$A:$B,2,0) -> 103.82 | M41: =REPLACE(M39,2,1,"6") -> S6_3_MDI- | N41: =VLOOKUP(M41,EtchLengthFromLayout!$A:$B,2,0) -> 14048.73 | O41: =REPLACE(O39,2,1,"6") -> S6_4_MDI- | P41: =VLOOKUP(O41,EtchLengthFromLayout!$A:$B,2,0) -> 635.93 | Q41: =REPLACE(Q39,2,1,"6") -> S6_AC_MDI- | R41: =VLOOKUP(Q41,EtchLengthFromLayout!$A:$B,2,0) -> 505.56 | AB41: =E41+G41+I41+L41+N41+P41+R41+T41+V41+X41+AA41 -> 16717.97 | AC41: =ABS(AB41-AB42) -> 0
A42: SITE6 | B42: 15 | C42: MDIP | D42: =REPLACE(D40,2,1,"6") -> S6_MDI+ | E42: =VLOOKUP(D42,EtchLengthFromLayout!$A:$B,2,0) -> 1114.46 | H42: =REPLACE(H40,2,1,"6") -> S6_1_MDI+ | I42: =VLOOKUP(H42,EtchLengthFromLayout!$A:$B,2,0) -> 309.46 | J42: =E42+G42+I42 -> 1423.92 | K42: =REPLACE(K40,2,1,"6") -> S6_2_MDI+ | L42: =VLOOKUP(K42,EtchLengthFromLayout!$A:$B,2,0) -> 103.82 | M42: =REPLACE(M40,2,1,"6") -> S6_3_MDI+ | N42: =VLOOKUP(M42,EtchLengthFromLayout!$A:$B,2,0) -> 14048.74 | O42: =REPLACE(O40,2,1,"6") -> S6_4_MDI+ | P42: =VLOOKUP(O42,EtchLengthFromLayout!$A:$B,2,0) -> 635.93 | Q42: =REPLACE(Q40,2,1,"6") -> S6_AC_MDI+ | R42: =VLOOKUP(Q42,EtchLengthFromLayout!$A:$B,2,0) -> 505.56 | AB42: =E42+G42+I42+L42+N42+P42+R42+T42+V42+X42+AA42 -> 16717.97 | AC42: =IF(AC41<=1,"OK, Tolerance<= 1 mil", "Not OK, Tolerance > 1 mil") -> OK, Tolerance<= 1 mil
A43: SITE7 | B43: 16 | C43: MDIN | D43: =REPLACE(D41,2,1,"7") -> S7_MDI- | E43: =VLOOKUP(D43,EtchLengthFromLayout!$A:$B,2,0) -> 1114.46 | H43: =REPLACE(H41,2,1,"7") -> S7_1_MDI- | I43: =VLOOKUP(H43,EtchLengthFromLayout!$A:$B,2,0) -> 309.47 | J43: =E43+G43+I43 -> 1423.93 | K43: =REPLACE(K41,2,1,"7") -> S7_2_MDI- | L43: =VLOOKUP(K43,EtchLengthFromLayout!$A:$B,2,0) -> 103.82 | M43: =REPLACE(M41,2,1,"7") -> S7_3_MDI- | N43: =VLOOKUP(M43,EtchLengthFromLayout!$A:$B,2,0) -> 14048.83 | O43: =REPLACE(O41,2,1,"7") -> S7_4_MDI- | P43: =VLOOKUP(O43,EtchLengthFromLayout!$A:$B,2,0) -> 635.93 | Q43: =REPLACE(Q41,2,1,"7") -> S7_AC_MDI- | R43: =VLOOKUP(Q43,EtchLengthFromLayout!$A:$B,2,0) -> 505.56 | AB43: =E43+G43+I43+L43+N43+P43+R43+T43+V43+X43+AA43 -> 16718.07 | AC43: =ABS(AB43-AB44) -> 0.02
A44: SITE7 | B44: 15 | C44: MDIP | D44: =REPLACE(D42,2,1,"7") -> S7_MDI+ | E44: =VLOOKUP(D44,EtchLengthFromLayout!$A:$B,2,0) -> 1114.46 | H44: =REPLACE(H42,2,1,"7") -> S7_1_MDI+ | I44: =VLOOKUP(H44,EtchLengthFromLayout!$A:$B,2,0) -> 309.46 | J44: =E44+G44+I44 -> 1423.92 | K44: =REPLACE(K42,2,1,"7") -> S7_2_MDI+ | L44: =VLOOKUP(K44,EtchLengthFromLayout!$A:$B,2,0) -> 103.82 | M44: =REPLACE(M42,2,1,"7") -> S7_3_MDI+ | N44: =VLOOKUP(M44,EtchLengthFromLayout!$A:$B,2,0) -> 14048.86 | O44: =REPLACE(O42,2,1,"7") -> S7_4_MDI+ | P44: =VLOOKUP(O44,EtchLengthFromLayout!$A:$B,2,0) -> 635.93 | Q44: =REPLACE(Q42,2,1,"7") -> S7_AC_MDI+ | R44: =VLOOKUP(Q44,EtchLengthFromLayout!$A:$B,2,0) -> 505.56 | AB44: =E44+G44+I44+L44+N44+P44+R44+T44+V44+X44+AA44 -> 16718.09 | AC44: =IF(AC43<=1,"OK, Tolerance<= 1 mil", "Not OK, Tolerance > 1 mil") -> OK, Tolerance<= 1 mil
...

Sheet Scan
A1: DUT to Scan In Channel
A2: Site | B2: Pin No | C2: Pin Name | D2: Net | E2: Length | F2: Net | G2: Length | J2: Serial Number | K2: Assign_CH | L2: Length | M2: Total Length (mils) | N2: Golden | O2: Pin No | P2: Pin Name | Q2: Note
A3: SITE0 | B3: 32 | C3: MDIO | D3: S0_MDIO | E3: =VLOOKUP(D3,EtchLengthFromLayout!$A:$B,2,0) -> 2728.55 | F3: S0_1_MDIO | G3: =VLOOKUP(F3,EtchLengthFromLayout!$A:$B,2,0) -> 159.24 | J3: S0_ADCH001 | K3: SLOT2.CH114 | L3: =VLOOKUP(K3,EtchLengthFromLayout!$A:$B,2,0) -> 3640.08 | M3: =E3+G3-I3+L3 -> 6527.87 | Q3: DUT0 To Scan In Channel
A4: SITE0 | B4: 1 | C4: MDC | D4: S0_MDC | E4: =VLOOKUP(D4,EtchLengthFromLayout!$A:$B,2,0) -> 2360.08 | F4: S0_1_MDC | G4: =VLOOKUP(F4,EtchLengthFromLayout!$A:$B,2,0) -> 132.03 | J4: S0_ADCH002 | K4: SLOT2.CH116 | L4: =VLOOKUP(K4,EtchLengthFromLayout!$A:$B,2,0) -> 4015.2 | M4: =E4+G4-I4+L4 -> 6507.31
A5: SITE0 | B5: 3 | C5: INTB | D5: S0_INTB | E5: =VLOOKUP(D5,EtchLengthFromLayout!$A:$B,2,0) -> 129.9 | J5: S0_ADCH019 | K5: SLOT2.CH113 | L5: =VLOOKUP(K5,EtchLengthFromLayout!$A:$B,2,0) -> 6383.64 | M5: =E5+G5-I5+L5 -> 6513.54
K6: Max | M6: =MAX(M3:M5) -> 6527.87
K7: Min | M7: =MIN(M3:M5) -> 6507.31
K8: Max-Min | M8: =ABS(M6-M7) -> 20.56
K9: Tolerence Check | M9: =IF(M8<=1000,"OK, Tolerance<= 1000 mils", "Not OK, Tolerance > 1000 mils") -> OK, Tolerance<= 1000 mils
A11: Site | B11: Pin No | C11: Pin Name | D11: Net | E11: Length | J11: Serial Number | L11: Length | M11: Total Length (mils) | N11: Golden | O11: Pin No | P11: Pin Name | Q11: Note
A12: SITE1 | B12: 32 | C12: MDIO | D12: =REPLACE(D3,2,1,"1") -> S1_MDIO | E12: =VLOOKUP(D12,EtchLengthFromLayout!$A:$B,2,0) -> 4099.45 | F12: S1_1_MDIO | G12: =VLOOKUP(F12,EtchLengthFromLayout!$A:$B,2,0) -> 159.24 | J12: =REPLACE(J3,2,1,"1") -> S1_ADCH001 | K12: SLOT0.CH114 | L12: =VLOOKUP(K12,EtchLengthFromLayout!$A:$B,2,0) -> 4514.66 | M12: =E12+G12-I12+L12 -> 8773.35 | Q12: DUT1 To Scan In Channel
A13: SITE1 | B13: 1 | C13: MDC | D13: =REPLACE(D4,2,1,"1") -> S1_MDC | E13: =VLOOKUP(D13,EtchLengthFromLayout!$A:$B,2,0) -> 3662.74 | F13: S1_1_MDC | G13: =VLOOKUP(F13,EtchLengthFromLayout!$A:$B,2,0) -> 132.03 | J13: =REPLACE(J4,2,1,"1") -> S1_ADCH002 | K13: SLOT0.CH116 | L13: =VLOOKUP(K13,EtchLengthFromLayout!$A:$B,2,0) -> 5008.98 | M13: =E13+G13-I13+L13 -> 8803.75
A14: SITE1 | B14: 3 | C14: INTB | D14: =REPLACE(D5,2,1,"1") -> S1_INTB | E14: =VLOOKUP(D14,EtchLengthFromLayout!$A:$B,2,0) -> 129.9 | J14: =REPLACE(J5,2,1,"1") -> S1_ADCH019 | K14: SLOT0.CH113 | L14: =VLOOKUP(K14,EtchLengthFromLayout!$A:$B,2,0) -> 8634.61 | M14: =E14+G14-I14+L14 -> 8764.51
K15: Max | M15: =MAX(M12:M14) -> 8803.75
K16: Min | M16: =MIN(M12:M14) -> 8764.51
K17: Max-Min | M17: =ABS(M15-M16) -> 39.24
K18: Tolerence Check | M18: =IF(M17<=1000,"OK, Tolerance<= 1000 mils", "Not OK, Tolerance > 1000 mils") -> OK, Tolerance<= 1000 mils
A20: Site | B20: Pin No | C20: Pin Name | D20: Net | E20: Length | J20: Serial Number | L20: Length | M20: Total Length (mils) | N20: Golden | O20: Pin No | P20: Pin Name | Q20: Note
A21: SITE2 | B21: 32 | C21: MDIO | D21: =REPLACE(D12,2,1,"2") -> S2_MDIO | E21: =VLOOKUP(D21,EtchLengthFromLayout!$A:$B,2,0) -> 4800.85 | F21: S2_1_MDIO | G21: =VLOOKUP(F21,EtchLengthFromLayout!$A:$B,2,0) -> 159.24 | J21: =REPLACE(J12,2,1,"2") -> S2_ADCH001 | K21: SLOT1.CH114 | L21: =VLOOKUP(K21,EtchLengthFromLayout!$A:$B,2,0) -> 5387.05 | M21: =E21+G21-I21+L21 -> 10347.14 | Q21: DUT2 To Scan In Channel
A22: SITE2 | B22: 1 | C22: MDC | D22: =REPLACE(D13,2,1,"2") -> S2_MDC | E22: =VLOOKUP(D22,EtchLengthFromLayout!$A:$B,2,0) -> 4839.36 | F22: S2_1_MDC | G22: =VLOOKUP(F22,EtchLengthFromLayout!$A:$B,2,0) -> 132.03 | J22: =REPLACE(J13,2,1,"2") -> S2_ADCH002 | K22: SLOT1.CH116 | L22: =VLOOKUP(K22,EtchLengthFromLayout!$A:$B,2,0) -> 5442.47 | M22: =E22+G22-I22+L22 -> 10413.86
A23: SITE2 | B23: 3 | C23: INTB | D23: =REPLACE(D14,2,1,"2") -> S2_INTB | E23: =VLOOKUP(D23,EtchLengthFromLayout!$A:$B,2,0) -> 129.9 | J23: =REPLACE(J14,2,1,"2") -> S2_ADCH019 | K23: SLOT1.CH113 | L23: =VLOOKUP(K23,EtchLengthFromLayout!$A:$B,2,0) -> 10236.21 | M23: =E23+G23-I23+L23 -> 10366.11
K24: Max | M24: =MAX(M21:M23) -> 10413.86
K25: Min | M25: =MIN(M21:M23) -> 10347.14
K26: Max-Min | M26: =ABS(M24-M25) -> 66.72
K27: Tolerence Check | M27: =IF(M26<=1000,"OK, Tolerance<= 1000 mils", "Not OK, Tolerance > 1000 mils") -> OK, Tolerance<= 1000 mils
A29: Site | B29: Pin No | C29: Pin Name | D29: Net | E29: Length | J29: Serial Number | L29: Length | M29: Total Length (mils) | N29: Golden | O29: Pin No | P29: Pin Name | Q29: Note
A30: SITE3 | B30: 32 | C30: MDIO | D30: =REPLACE(D21,2,1,"3") -> S3_MDIO | E30: =VLOOKUP(D30,EtchLengthFromLayout!$A:$B,2,0) -> 3008.72 | F30: S3_1_MDIO | G30: =VLOOKUP(F30,EtchLengthFromLayout!$A:$B,2,0) -> 159.24 | J30: =REPLACE(J21,2,1,"3") -> S3_ADCH001 | K30: SLOT3.CH116 | L30: =VLOOKUP(K30,EtchLengthFromLayout!$A:$B,2,0) -> 3789.97 | M30: =E30+G30-I30+L30 -> 6957.93 | Q30: DUT3 To Scan In Channel
A31: SITE3 | B31: 1 | C31: MDC | D31: =REPLACE(D22,2,1,"3") -> S3_MDC | E31: =VLOOKUP(D31,EtchLengthFromLayout!$A:$B,2,0) -> 2768.14 | F31: S3_1_MDC | G31: =VLOOKUP(F31,EtchLengthFromLayout!$A:$B,2,0) -> 132.03 | J31: =REPLACE(J22,2,1,"3") -> S3_ADCH002 | K31: SLOT3.CH114 | L31: =VLOOKUP(K31,EtchLengthFromLayout!$A:$B,2,0) -> 4066.74 | M31: =E31+G31-I31+L31 -> 6966.91
A32: SITE3 | B32: 3 | C32: INTB | D32: =REPLACE(D23,2,1,"3") -> S3_INTB | E32: =VLOOKUP(D32,EtchLengthFromLayout!$A:$B,2,0) -> 129.9 | J32: =REPLACE(J23,2,1,"3") -> S3_ADCH019 | K32: SLOT3.CH113 | L32: =VLOOKUP(K32,EtchLengthFromLayout!$A:$B,2,0) -> 6765.29 | M32: =E32+G32-I32+L32 -> 6895.19
K33: Max | M33: =MAX(M30:M32) -> 6966.91
K34: Min | M34: =MIN(M30:M32) -> 6895.19
K35: Max-Min | M35: =ABS(M33-M34) -> 71.72
M36: =IF(M35<=1000,"OK, Tolerance<= 1000 mils", "Not OK, Tolerance > 1000 mils") -> OK, Tolerance<= 1000 mils
A38: Site | B38: Pin No | C38: Pin Name | D38: Net | E38: Length | J38: Serial Number | L38: Length | M38: Total Length (mils) | N38: Golden | O38: Pin No | P38: Pin Name | Q38: Note
A39: SITE4 | B39: 32 | C39: MDIO | D39: =REPLACE(D30,2,1,"4") -> S4_MDIO | E39: =VLOOKUP(D39,EtchLengthFromLayout!$A:$B,2,0) -> 2423.37 | F39: S4_1_MDIO | G39: =VLOOKUP(F39,EtchLengthFromLayout!$A:$B,2,0) -> 159.24 | J39: =REPLACE(J30,2,1,"4") -> S4_ADCH001 | K39: SLOT2.CH78 | L39: =VLOOKUP(K39,EtchLengthFromLayout!$A:$B,2,0) -> 6353.1 | M39: =E39+G39-I39+L39 -> 8935.71 | Q39: DUT4 To Scan In Channel
A40: SITE4 | B40: 1 | C40: MDC | D40: =REPLACE(D31,2,1,"4") -> S4_MDC | E40: =VLOOKUP(D40,EtchLengthFromLayout!$A:$B,2,0) -> 2043.54 | F40: S4_1_MDC | G40: =VLOOKUP(F40,EtchLengthFromLayout!$A:$B,2,0) -> 132.03 | J40: =REPLACE(J31,2,1,"4") -> S4_ADCH002 | K40: SLOT2.CH79 | L40: =VLOOKUP(K40,EtchLengthFromLayout!$A:$B,2,0) -> 6067.98 | M40: =E40+G40-I40+L40 -> 8243.55
A41: SITE4 | B41: 3 | C41: INTB | D41: =REPLACE(D32,2,1,"4") -> S4_INTB | E41: =VLOOKUP(D41,EtchLengthFromLayout!$A:$B,2,0) -> 129.9 | J41: =REPLACE(J32,2,1,"4") -> S4_ADCH019 | K41: SLOT2.CH64 | L41: =VLOOKUP(K41,EtchLengthFromLayout!$A:$B,2,0) -> 8722.13 | M41: =E41+G41-I41+L41 -> 8852.03
K42: Max | M42: =MAX(M39:M41) -> 8935.71
K43: Min | M43: =MIN(M39:M41) -> 8243.55
K44: Max-Min | M44: =ABS(M42-M43) -> 692.16
...

Sheet SGMII
A1: DUT to Golden Loopback: | M1: arc shape
A2: Site | B2: Pin No | C2: Pin Name | D2: Net | E2: Length | F2: Net | G2: Length | K2: Net | L2: Length | M2: Total Length (mils) | N2: P/N Difference (mils) | O2: Golden | P2: Pin No | Q2: Pin Name | R2: Note
A3: SITE0 | B3: 25 | C3: HSON | D3: S0_HSO- | E3: =VLOOKUP(D3,EtchLengthFromLayout!$A:$B,2,0) -> 839.88 | F3: SG0_C_HSI- | G3: =VLOOKUP(F3,EtchLengthFromLayout!$A:$B,2,0) -> 179.12 | K3: SG0_HSI- | L3: =VLOOKUP(K3,EtchLengthFromLayout!$A:$B,2,0) -> 12303.33 | M3: =E3+G3+I3+L3 -> 13322.33 | N3: =ABS(M3-M4) -> 0 | O3: GOLD0 | P3: 25 | Q3: HSON | R3: DUT to Golden Loopback
A4: SITE0 | B4: 26 | C4: HSOP | D4: S0_HSO+ | E4: =VLOOKUP(D4,EtchLengthFromLayout!$A:$B,2,0) -> 839.88 | F4: SG0_C_HSI+ | G4: =VLOOKUP(F4,EtchLengthFromLayout!$A:$B,2,0) -> 179.12 | K4: SG0_HSI+ | L4: =VLOOKUP(K4,EtchLengthFromLayout!$A:$B,2,0) -> 12303.33 | M4: =E4+G4+I4+L4 -> 13322.33 | N4: =IF(N3<=1,"OK, Tolerance<= 1 mil", "Not OK, Tolerance > 1 mil") -> OK, Tolerance<= 1 mil | O4: GOLD0 | P4: 26 | Q4: HSOP
A5: SITE0 | B5: 28 | C5: HSIN | D5: S0_HSI- | E5: =VLOOKUP(D5,EtchLengthFromLayout!$A:$B,2,0) -> 839.88 | F5: SG0_C_HSO- | G5: =VLOOKUP(F5,EtchLengthFromLayout!$A:$B,2,0) -> 179.12 | K5: SG0_HSO- | L5: =VLOOKUP(K5,EtchLengthFromLayout!$A:$B,2,0) -> 11708.67 | M5: =E5+G5+I5+L5 -> 12727.67 | N5: =ABS(M5-M6) -> 0.01 | O5: GOLD0 | P5: 28 | Q5: HSIN
A6: SITE0 | B6: 29 | C6: HSIP | D6: S0_HSI+ | E6: =VLOOKUP(D6,EtchLengthFromLayout!$A:$B,2,0) -> 839.88 | F6: SG0_C_HSO+ | G6: =VLOOKUP(F6,EtchLengthFromLayout!$A:$B,2,0) -> 179.12 | K6: SG0_HSO+ | L6: =VLOOKUP(K6,EtchLengthFromLayout!$A:$B,2,0) -> 11708.66 | M6: =E6+G6+I6+L6 -> 12727.66 | N6: =IF(N5<=1,"OK, Tolerance<= 1 mil", "Not OK, Tolerance > 1 mil") -> OK, Tolerance<= 1 mil | O6: GOLD0 | P6: 29 | Q6: HSIP
K7: Max | M7: =MAX(M3:M6) -> 13322.33
K8: Min | M8: =MIN(M3:M6) -> 12727.66
K9: Max-Min | M9: =ABS(M7-M8) -> 594.67
K10: Tolerence Check | M10: =IF(M9<=1000,"OK, Tolerance<= 1000 mils", "Not OK, Tolerance > 1000 mils") -> OK, Tolerance<= 1000 mils
A12: Site | B12: Pin No | C12: Pin Name | D12: Net | E12: Length | F12: Net | G12: Length | K12: Net | L12: Length | M12: Total Length (mils) | N12: P/N Difference (mils) | O12: Golden | P12: Pin No | Q12: Pin Name
A13: SITE1 | B13: 25 | C13: HSON | D13: =REPLACE(D3,2,1,"1") -> S1_HSO- | E13: =VLOOKUP(D13,EtchLengthFromLayout!$A:$B,2,0) -> 839.88 | F13: =REPLACE(F3,3,1,"1") -> SG1_C_HSI- | G13: =VLOOKUP(F13,EtchLengthFromLayout!$A:$B,2,0) -> 179.12 | K13: =REPLACE(K3,3,1,"1") -> SG1_HSI- | L13: =VLOOKUP(K13,EtchLengthFromLayout!$A:$B,2,0) -> 12978.79 | M13: =E13+G13+I13+L13 -> 13997.79 | N13: =ABS(M13-M14) -> 0.03 | O13: GOLD1 | P13: 25 | Q13: HSON
A14: SITE1 | B14: 26 | C14: HSOP | D14: =REPLACE(D4,2,1,"1") -> S1_HSO+ | E14: =VLOOKUP(D14,EtchLengthFromLayout!$A:$B,2,0) -> 839.88 | F14: =REPLACE(F4,3,1,"1") -> SG1_C_HSI+ | G14: =VLOOKUP(F14,EtchLengthFromLayout!$A:$B,2,0) -> 179.12 | K14: =REPLACE(K4,3,1,"1") -> SG1_HSI+ | L14: =VLOOKUP(K14,EtchLengthFromLayout!$A:$B,2,0) -> 12978.82 | M14: =E14+G14+I14+L14 -> 13997.82 | N14: =IF(N13<=1,"OK, Tolerance<= 1 mil", "Not OK, Tolerance > 1 mil") -> OK, Tolerance<= 1 mil | O14: GOLD1 | P14: 26 | Q14: HSOP
A15: SITE1 | B15: 28 | C15: HSIN | D15: =REPLACE(D5,2,1,"1") -> S1_HSI- | E15: =VLOOKUP(D15,EtchLengthFromLayout!$A:$B,2,0) -> 839.88 | F15: =REPLACE(F5,3,1,"1") -> SG1_C_HSO- | G15: =VLOOKUP(F15,EtchLengthFromLayout!$A:$B,2,0) -> 179.12 | K15: =REPLACE(K5,3,1,"1") -> SG1_HSO- | L15: =VLOOKUP(K15,EtchLengthFromLayout!$A:$B,2,0) -> 12515.18 | M15: =E15+G15+I15+L15 -> 13534.18 | N15: =ABS(M15-M16) -> 0 | O15: GOLD1 | P15: 28 | Q15: HSIN
A16: SITE1 | B16: 29 | C16: HSIP | D16: =REPLACE(D6,2,1,"1") -> S1_HSI+ | E16: =VLOOKUP(D16,EtchLengthFromLayout!$A:$B,2,0) -> 839.88 | F16: =REPLACE(F6,3,1,"1") -> SG1_C_HSO+ | G16: =VLOOKUP(F16,EtchLengthFromLayout!$A:$B,2,0) -> 179.12 | K16: =REPLACE(K6,3,1,"1") -> SG1_HSO+ | L16: =VLOOKUP(K16,EtchLengthFromLayout!$A:$B,2,0) -> 12515.18 | M16: =E16+G16+I16+L16 -> 13534.18 | N16: =IF(N15<=1,"OK, Tolerance<= 1 mil", "Not OK, Tolerance > 1 mil") -> OK, Tolerance<= 1 mil | O16: GOLD1 | P16: 29 | Q16: HSIP
K17: Max | M17: =MAX(M13:M16) -> 13997.82
K18: Min | M18: =MIN(M13:M16) -> 13534.18
K19: Max-Min | M19: =ABS(M17-M18) -> 463.64
K20: Tolerence Check | M20: =IF(M19<=1000,"OK, Tolerance<= 1000 mils", "Not OK, Tolerance > 1000 mils") -> OK, Tolerance<= 1000 mils
A22: Site | B22: Pin No | C22: Pin Name | D22: Net | E22: Length | F22: Net | G22: Length | K22: Net | L22: Length | M22: Total Length (mils) | N22: P/N Difference (mils) | O22: Golden | P22: Pin No | Q22: Pin Name
A23: SITE2 | B23: 25 | C23: HSON | D23: =REPLACE(D13,2,1,"2") -> S2_HSO- | E23: =VLOOKUP(D23,EtchLengthFromLayout!$A:$B,2,0) -> 839.88 | F23: =REPLACE(F13,3,1,"2") -> SG2_C_HSI- | G23: =VLOOKUP(F23,EtchLengthFromLayout!$A:$B,2,0) -> 179.12 | K23: =REPLACE(K13,3,1,"2") -> SG2_HSI- | L23: =VLOOKUP(K23,EtchLengthFromLayout!$A:$B,2,0) -> 12253.03 | M23: =E23+G23+I23+L23 -> 13272.03 | N23: =ABS(M23-M24) -> 0.17 | O23: GOLD2 | P23: 25 | Q23: HSON
A24: SITE2 | B24: 26 | C24: HSOP | D24: =REPLACE(D14,2,1,"2") -> S2_HSO+ | E24: =VLOOKUP(D24,EtchLengthFromLayout!$A:$B,2,0) -> 839.88 | F24: =REPLACE(F14,3,1,"2") -> SG2_C_HSI+ | G24: =VLOOKUP(F24,EtchLengthFromLayout!$A:$B,2,0) -> 179.12 | K24: =REPLACE(K14,3,1,"2") -> SG2_HSI+ | L24: =VLOOKUP(K24,EtchLengthFromLayout!$A:$B,2,0) -> 12253.2 | M24: =E24+G24+I24+L24 -> 13272.2 | N24: =IF(N23<=1,"OK, Tolerance<= 1 mil", "Not OK, Tolerance > 1 mil") -> OK, Tolerance<= 1 mil | O24: GOLD2 | P24: 26 | Q24: HSOP
A25: SITE2 | B25: 28 | C25: HSIN | D25: =REPLACE(D15,2,1,"2") -> S2_HSI- | E25: =VLOOKUP(D25,EtchLengthFromLayout!$A:$B,2,0) -> 839.88 | F25: =REPLACE(F15,3,1,"2") -> SG2_C_HSO- | G25: =VLOOKUP(F25,EtchLengthFromLayout!$A:$B,2,0) -> 179.12 | K25: =REPLACE(K15,3,1,"2") -> SG2_HSO- | L25: =VLOOKUP(K25,EtchLengthFromLayout!$A:$B,2,0) -> 12651.9 | M25: =E25+G25+I25+L25 -> 13670.9 | N25: =ABS(M25-M26) -> 0.52 | O25: GOLD2 | P25: 28 | Q25: HSIN
A26: SITE2 | B26: 29 | C26: HSIP | D26: =REPLACE(D16,2,1,"2") -> S2_HSI+ | E26: =VLOOKUP(D26,EtchLengthFromLayout!$A:$B,2,0) -> 839.88 | F26: =REPLACE(F16,3,1,"2") -> SG2_C_HSO+ | G26: =VLOOKUP(F26,EtchLengthFromLayout!$A:$B,2,0) -> 179.12 | K26: =REPLACE(K16,3,1,"2") -> SG2_HSO+ | L26: =VLOOKUP(K26,EtchLengthFromLayout!$A:$B,2,0) -> 12651.38 | M26: =E26+G26+I26+L26 -> 13670.38 | N26: =IF(N25<=1,"OK, Tolerance<= 1 mil", "Not OK, Tolerance > 1 mil") -> OK, Tolerance<= 1 mil | O26: GOLD2 | P26: 29 | Q26: HSIP
K27: Max | M27: =MAX(M23:M26) -> 13670.9
K28: Min | M28: =MIN(M23:M26) -> 13272.03
K29: Max-Min | M29: =ABS(M27-M28) -> 398.87
K30: Tolerence Check | M30: =IF(M29<=1000,"OK, Tolerance<= 1000 mils", "Not OK, Tolerance > 1000 mils") -> OK, Tolerance<= 1000 mils
A32: Site | B32: Pin No | C32: Pin Name | D32: Net | E32: Length | F32: Net | G32: Length | K32: Net | L32: Length | M32: Total Length (mils) | N32: P/N Difference (mils) | O32: Golden | P32: Pin No | Q32: Pin Name
A33: SITE3 | B33: 25 | C33: HSON | D33: =REPLACE(D23,2,1,"3") -> S3_HSO- | E33: =VLOOKUP(D33,EtchLengthFromLayout!$A:$B,2,0) -> 839.88 | F33: =REPLACE(F23,3,1,"3") -> SG3_C_HSI- | G33: =VLOOKUP(F33,EtchLengthFromLayout!$A:$B,2,0) -> 179.12 | K33: =REPLACE(K23,3,1,"3") -> SG3_HSI- | L33: =VLOOKUP(K33,EtchLengthFromLayout!$A:$B,2,0) -> 12152.45 | M33: =E33+G33+I33+L33 -> 13171.45 | N33: =ABS(M33-M34) -> 0.05 | O33: GOLD3 | P33: 25 | Q33: HSON
A34: SITE3 | B34: 26 | C34: HSOP | D34: =REPLACE(D24,2,1,"3") -> S3_HSO+ | E34: =VLOOKUP(D34,EtchLengthFromLayout!$A:$B,2,0) -> 839.88 | F34: =REPLACE(F24,3,1,"3") -> SG3_C_HSI+ | G34: =VLOOKUP(F34,EtchLengthFromLayout!$A:$B,2,0) -> 179.12 | K34: =REPLACE(K24,3,1,"3") -> SG3_HSI+ | L34: =VLOOKUP(K34,EtchLengthFromLayout!$A:$B,2,0) -> 12152.5 | M34: =E34+G34+I34+L34 -> 13171.5 | N34: =IF(N33<=1,"OK, Tolerance<= 1 mil", "Not OK, Tolerance > 1 mil") -> OK, Tolerance<= 1 mil | O34: GOLD3 | P34: 26 | Q34: HSOP
A35: SITE3 | B35: 28 | C35: HSIN | D35: =REPLACE(D25,2,1,"3") -> S3_HSI- | E35: =VLOOKUP(D35,EtchLengthFromLayout!$A:$B,2,0) -> 839.88 | F35: =REPLACE(F25,3,1,"3") -> SG3_C_HSO- | G35: =VLOOKUP(F35,EtchLengthFromLayout!$A:$B,2,0) -> 179.12 | K35: =REPLACE(K25,3,1,"3") -> SG3_HSO- | L35: =VLOOKUP(K35,EtchLengthFromLayout!$A:$B,2,0) -> 12131.15 | M35: =E35+G35+I35+L35 -> 13150.15 | N35: =ABS(M35-M36) -> 0.18 | O35: GOLD3 | P35: 28 | Q35: HSIN
A36: SITE3 | B36: 29 | C36: HSIP | D36: =REPLACE(D26,2,1,"3") -> S3_HSI+ | E36: =VLOOKUP(D36,EtchLengthFromLayout!$A:$B,2,0) -> 839.88 | F36: =REPLACE(F26,3,1,"3") -> SG3_C_HSO+ | G36: =VLOOKUP(F36,EtchLengthFromLayout!$A:$B,2,0) -> 179.12 | K36: =REPLACE(K26,3,1,"3") -> SG3_HSO+ | L36: =VLOOKUP(K36,EtchLengthFromLayout!$A:$B,2,0) -> 12130.97 | M36: =E36+G36+I36+L36 -> 13149.97 | N36: =IF(N35<=1,"OK, Tolerance<= 1 mil", "Not OK, Tolerance > 1 mil") -> OK, Tolerance<= 1 mil | O36: GOLD3 | P36: 29 | Q36: HSIP
K37: Max | M37: =MAX(M33:M36) -> 13171.5
K38: Min | M38: =MIN(M33:M36) -> 13149.97
K39: Max-Min | M39: =ABS(M37-M38) -> 21.53
K40: Tolerence Check | M40: =IF(M39<=1000,"OK, Tolerance<= 1000 mils", "Not OK, Tolerance > 1000 mils") -> OK, Tolerance<= 1000 mils
A42: Site | B42: Pin No | C42: Pin Name | D42: Net | E42: Length | F42: Net | G42: Length | K42: Net | L42: Length | M42: Total Length (mils) | N42: P/N Difference (mils) | O42: Golden | P42: Pin No | Q42: Pin Name
