Workbook

Sheet eDP_RX
B1: PS9G channel，對與對誤差1 mil，+/-誤差1mil；4 Site等長
B2: SITE | C2: Pin number | D2: Pin name | E2: Net name | F2: Channel | G2: Length (mils) | H2: Total length (mils) | I2: +/- CHECK
B3: SITE1 | C3: 26 | D3: RXD0P | E3: S1_RX_85DCH001+ | F3: =VLOOKUP(E3,'CH assign'!A:B,2,0) -> D32102 | G3: =VLOOKUP(F3,Etch_Length_From_Layout!A:B,2,0) -> 7574 | H3: =G3 -> 7574 | I3: =IF(ABS(H3-H4)<1,"PASS","FAIL") -> PASS
C4: 27 | D4: RXD0N | E4: S1_RX_85DCH001- | F4: =VLOOKUP(E4,'CH assign'!A:B,2,0) -> D32104 | G4: =VLOOKUP(F4,Etch_Length_From_Layout!A:B,2,0) -> 7573.01 | H4: =G4 -> 7573.01
C5: 29 | D5: RXD1P | E5: S1_RX_85DCH002+ | F5: =VLOOKUP(E5,'CH assign'!A:B,2,0) -> D32106 | G5: =VLOOKUP(F5,Etch_Length_From_Layout!A:B,2,0) -> 7573.48 | H5: =G5 -> 7573.48 | I5: =IF(ABS(H5-H6)<1,"PASS","FAIL") -> PASS
C6: 30 | D6: RXD1N | E6: S1_RX_85DCH002- | F6: =VLOOKUP(E6,'CH assign'!A:B,2,0) -> D32108 | G6: =VLOOKUP(F6,Etch_Length_From_Layout!A:B,2,0) -> 7573.02 | H6: =G6 -> 7573.02
C7: 32 | D7: RXD2P | E7: S1_RX_85DCH003+ | F7: =VLOOKUP(E7,'CH assign'!A:B,2,0) -> D32110 | G7: =VLOOKUP(F7,Etch_Length_From_Layout!A:B,2,0) -> 7573.06 | H7: =G7 -> 7573.06 | I7: =IF(ABS(H7-H8)<1,"PASS","FAIL") -> PASS
C8: 33 | D8: RXD2N | E8: S1_RX_85DCH003- | F8: =VLOOKUP(E8,'CH assign'!A:B,2,0) -> D32112 | G8: =VLOOKUP(F8,Etch_Length_From_Layout!A:B,2,0) -> 7573.62 | H8: =G8 -> 7573.62
C9: 35 | D9: RXD3P | E9: S1_RX_85DCH004+ | F9: =VLOOKUP(E9,'CH assign'!A:B,2,0) -> D32114 | G9: =VLOOKUP(F9,Etch_Length_From_Layout!A:B,2,0) -> 7573.1 | H9: =G9 -> 7573.1 | I9: =IF(ABS(H9-H10)<1,"PASS","FAIL") -> PASS
C10: 36 | D10: RXD3N | E10: S1_RX_85DCH004- | F10: =VLOOKUP(E10,'CH assign'!A:B,2,0) -> D32116 | G10: =VLOOKUP(F10,Etch_Length_From_Layout!A:B,2,0) -> 7573.15 | H10: =G10 -> 7573.15
B11: SITE2 | C11: 26 | D11: RXD0P | E11: S2_RX_85DCH001+ | F11: =VLOOKUP(E11,'CH assign'!A:B,2,0) -> D30502 | G11: =VLOOKUP(F11,Etch_Length_From_Layout!A:B,2,0) -> 7573.06 | H11: =G11 -> 7573.06 | I11: =IF(ABS(H11-H12)<1,"PASS","FAIL") -> PASS
C12: 27 | D12: RXD0N | E12: S2_RX_85DCH001- | F12: =VLOOKUP(E12,'CH assign'!A:B,2,0) -> D30504 | G12: =VLOOKUP(F12,Etch_Length_From_Layout!A:B,2,0) -> 7573.95 | H12: =G12 -> 7573.95
C13: 29 | D13: RXD1P | E13: S2_RX_85DCH002+ | F13: =VLOOKUP(E13,'CH assign'!A:B,2,0) -> D30506 | G13: =VLOOKUP(F13,Etch_Length_From_Layout!A:B,2,0) -> 7573.03 | H13: =G13 -> 7573.03 | I13: =IF(ABS(H13-H14)<1,"PASS","FAIL") -> PASS
C14: 30 | D14: RXD1N | E14: S2_RX_85DCH002- | F14: =VLOOKUP(E14,'CH assign'!A:B,2,0) -> D30508 | G14: =VLOOKUP(F14,Etch_Length_From_Layout!A:B,2,0) -> 7573.94 | H14: =G14 -> 7573.94
C15: 32 | D15: RXD2P | E15: S2_RX_85DCH003+ | F15: =VLOOKUP(E15,'CH assign'!A:B,2,0) -> D30510 | G15: =VLOOKUP(F15,Etch_Length_From_Layout!A:B,2,0) -> 7573.31 | H15: =G15 -> 7573.31 | I15: =IF(ABS(H15-H16)<1,"PASS","FAIL") -> PASS
C16: 33 | D16: RXD2N | E16: S2_RX_85DCH003- | F16: =VLOOKUP(E16,'CH assign'!A:B,2,0) -> D30512 | G16: =VLOOKUP(F16,Etch_Length_From_Layout!A:B,2,0) -> 7573.82 | H16: =G16 -> 7573.82
C17: 35 | D17: RXD3P | E17: S2_RX_85DCH004+ | F17: =VLOOKUP(E17,'CH assign'!A:B,2,0) -> D30514 | G17: =VLOOKUP(F17,Etch_Length_From_Layout!A:B,2,0) -> 7573.7 | H17: =G17 -> 7573.7 | I17: =IF(ABS(H17-H18)<1,"PASS","FAIL") -> PASS
C18: 36 | D18: RXD3N | E18: S2_RX_85DCH004- | F18: =VLOOKUP(E18,'CH assign'!A:B,2,0) -> D30516 | G18: =VLOOKUP(F18,Etch_Length_From_Layout!A:B,2,0) -> 7573.11 | H18: =G18 -> 7573.11
B19: SITE3 | C19: 26 | D19: RXD0P | E19: S3_RX_85DCH001+ | F19: =VLOOKUP(E19,'CH assign'!A:B,2,0) -> D31702 | G19: =VLOOKUP(F19,Etch_Length_From_Layout!A:B,2,0) -> 7573.5 | H19: =G19 -> 7573.5 | I19: =IF(ABS(H19-H20)<1,"PASS","FAIL") -> PASS
C20: 27 | D20: RXD0N | E20: S3_RX_85DCH001- | F20: =VLOOKUP(E20,'CH assign'!A:B,2,0) -> D31704 | G20: =VLOOKUP(F20,Etch_Length_From_Layout!A:B,2,0) -> 7573.18 | H20: =G20 -> 7573.18
C21: 29 | D21: RXD1P | E21: S3_RX_85DCH002+ | F21: =VLOOKUP(E21,'CH assign'!A:B,2,0) -> D31706 | G21: =VLOOKUP(F21,Etch_Length_From_Layout!A:B,2,0) -> 7573.36 | H21: =G21 -> 7573.36 | I21: =IF(ABS(H21-H22)<1,"PASS","FAIL") -> PASS
C22: 30 | D22: RXD1N | E22: S3_RX_85DCH002- | F22: =VLOOKUP(E22,'CH assign'!A:B,2,0) -> D31708 | G22: =VLOOKUP(F22,Etch_Length_From_Layout!A:B,2,0) -> 7573.17 | H22: =G22 -> 7573.17
C23: 32 | D23: RXD2P | E23: S3_RX_85DCH003+ | F23: =VLOOKUP(E23,'CH assign'!A:B,2,0) -> D31710 | G23: =VLOOKUP(F23,Etch_Length_From_Layout!A:B,2,0) -> 7573.08 | H23: =G23 -> 7573.08 | I23: =IF(ABS(H23-H24)<1,"PASS","FAIL") -> PASS
C24: 33 | D24: RXD2N | E24: S3_RX_85DCH003- | F24: =VLOOKUP(E24,'CH assign'!A:B,2,0) -> D31712 | G24: =VLOOKUP(F24,Etch_Length_From_Layout!A:B,2,0) -> 7573.83 | H24: =G24 -> 7573.83
C25: 35 | D25: RXD3P | E25: S3_RX_85DCH004+ | F25: =VLOOKUP(E25,'CH assign'!A:B,2,0) -> D31714 | G25: =VLOOKUP(F25,Etch_Length_From_Layout!A:B,2,0) -> 7573.05 | H25: =G25 -> 7573.05 | I25: =IF(ABS(H25-H26)<1,"PASS","FAIL") -> PASS
C26: 36 | D26: RXD3N | E26: S3_RX_85DCH004- | F26: =VLOOKUP(E26,'CH assign'!A:B,2,0) -> D31716 | G26: =VLOOKUP(F26,Etch_Length_From_Layout!A:B,2,0) -> 7573.86 | H26: =G26 -> 7573.86
B27: SITE4 | C27: 26 | D27: RXD0P | E27: S4_RX_85DCH001+ | F27: =VLOOKUP(E27,'CH assign'!A:B,2,0) -> D30102 | G27: =VLOOKUP(F27,Etch_Length_From_Layout!A:B,2,0) -> 7573.89 | H27: =G27 -> 7573.89 | I27: =IF(ABS(H27-H28)<1,"PASS","FAIL") -> PASS
C28: 27 | D28: RXD0N | E28: S4_RX_85DCH001- | F28: =VLOOKUP(E28,'CH assign'!A:B,2,0) -> D30104 | G28: =VLOOKUP(F28,Etch_Length_From_Layout!A:B,2,0) -> 7573.69 | H28: =G28 -> 7573.69
C29: 29 | D29: RXD1P | E29: S4_RX_85DCH002+ | F29: =VLOOKUP(E29,'CH assign'!A:B,2,0) -> D30106 | G29: =VLOOKUP(F29,Etch_Length_From_Layout!A:B,2,0) -> 7573.64 | H29: =G29 -> 7573.64 | I29: =IF(ABS(H29-H30)<1,"PASS","FAIL") -> PASS
C30: 30 | D30: RXD1N | E30: S4_RX_85DCH002- | F30: =VLOOKUP(E30,'CH assign'!A:B,2,0) -> D30108 | G30: =VLOOKUP(F30,Etch_Length_From_Layout!A:B,2,0) -> 7573.03 | H30: =G30 -> 7573.03
C31: 32 | D31: RXD2P | E31: S4_RX_85DCH003+ | F31: =VLOOKUP(E31,'CH assign'!A:B,2,0) -> D30110 | G31: =VLOOKUP(F31,Etch_Length_From_Layout!A:B,2,0) -> 7573.02 | H31: =G31 -> 7573.02 | I31: =IF(ABS(H31-H32)<1,"PASS","FAIL") -> PASS
C32: 33 | D32: RXD2N | E32: S4_RX_85DCH003- | F32: =VLOOKUP(E32,'CH assign'!A:B,2,0) -> D30112 | G32: =VLOOKUP(F32,Etch_Length_From_Layout!A:B,2,0) -> 7573.86 | H32: =G32 -> 7573.86
C33: 35 | D33: RXD3P | E33: S4_RX_85DCH004+ | F33: =VLOOKUP(E33,'CH assign'!A:B,2,0) -> D30114 | G33: =VLOOKUP(F33,Etch_Length_From_Layout!A:B,2,0) -> 7573.42 | H33: =G33 -> 7573.42 | I33: =IF(ABS(H33-H34)<1,"PASS","FAIL") -> PASS
C34: 36 | D34: RXD3N | E34: S4_RX_85DCH004- | F34: =VLOOKUP(E34,'CH assign'!A:B,2,0) -> D30116 | G34: =VLOOKUP(F34,Etch_Length_From_Layout!A:B,2,0) -> 7573.3 | H34: =G34 -> 7573.3
G35: MAX | H35: =MAX(H3:H34) -> 7574
G36: min | H36: =MIN(H3:H34) -> 7573.01
G37: MAX-min | H37: =H35-H36 -> 0.99
G38: Result | H38: =IF(H37<=1,"PASS", "FAIL") -> PASS

Sheet iSP_TX
B1: PS1600 channel，對與對誤差1 mil，+/-誤差1mil；4 Site等長；ISP00 / ISP14 share CH
B2: SITE | C2: Pin number | D2: Pin name | E2: Net name | F2: Channel | G2: Length (mils) | I2: Channel | J2: Length (mils) | K2: Total length (mils) | L2: +/- CHECK
B3: SITE1 | C3: 73 | D3: AML0P | E3: S1_ISP00+ | G3: =VLOOKUP(E3,Etch_Length_From_Layout!A:B,2,0) -> 2867.74 | H3: S1_1TX_100DCH001+ | I3: =VLOOKUP(H3,'CH assign'!$A:$B,2,0) -> D13105 | J3: =VLOOKUP(I3,Etch_Length_From_Layout!$A:$B,2,0) -> 29954.55 | K3: =G3+J3 -> 32822.29 | L3: =IF(ABS(K3-K4)<1,"PASS","FAIL") -> PASS
C4: 74 | D4: AML0N | E4: S1_ISP00- | G4: =VLOOKUP(E4,Etch_Length_From_Layout!A:B,2,0) -> 2867.9 | H4: S1_1TX_100DCH001- | I4: =VLOOKUP(H4,'CH assign'!$A:$B,2,0) -> D13107 | J4: =VLOOKUP(I4,Etch_Length_From_Layout!$A:$B,2,0) -> 29954.69 | K4: =G4+J4 -> 32822.59
C5: 75 | D5: AML1P | E5: S1_1TX_100DCH002+ | F5: =VLOOKUP(E5,'CH assign'!$A:$B,2,0) -> D13109 | G5: =VLOOKUP(F5,Etch_Length_From_Layout!A:B,2,0) -> 32822.32 | K5: =G5+J5 -> 32822.32 | L5: =IF(ABS(K5-K6)<1,"PASS","FAIL") -> PASS
C6: 76 | D6: AML1N | E6: S1_1TX_100DCH002- | F6: =VLOOKUP(E6,'CH assign'!A:B,2,0) -> D13111 | G6: =VLOOKUP(F6,Etch_Length_From_Layout!A:B,2,0) -> 32822.01 | K6: =G6+J6 -> 32822.01
C7: 79 | D7: AML2P | E7: S1_1TX_100DCH003+ | F7: =VLOOKUP(E7,'CH assign'!A:B,2,0) -> D13113 | G7: =VLOOKUP(F7,Etch_Length_From_Layout!A:B,2,0) -> 32822.49 | K7: =G7+J7 -> 32822.49 | L7: =IF(ABS(K7-K8)<1,"PASS","FAIL") -> PASS
C8: 80 | D8: AML2N | E8: S1_1TX_100DCH003- | F8: =VLOOKUP(E8,'CH assign'!A:B,2,0) -> D13115 | G8: =VLOOKUP(F8,Etch_Length_From_Layout!A:B,2,0) -> 32822 | K8: =G8+J8 -> 32822
C9: 81 | D9: AMLCKP | E9: S1_1TX_100DCH004+ | F9: =VLOOKUP(E9,'CH assign'!A:B,2,0) -> D13214 | G9: =VLOOKUP(F9,Etch_Length_From_Layout!A:B,2,0) -> 32822.34 | K9: =G9+J9 -> 32822.34 | L9: =IF(ABS(K9-K10)<1,"PASS","FAIL") -> PASS
C10: 82 | D10: AMLCKN | E10: S1_1TX_100DCH004- | F10: =VLOOKUP(E10,'CH assign'!A:B,2,0) -> D13216 | G10: =VLOOKUP(F10,Etch_Length_From_Layout!A:B,2,0) -> 32822.23 | K10: =G10+J10 -> 32822.23
C11: 83 | D11: AML3P | E11: S1_1TX_100DCH005+ | F11: =VLOOKUP(E11,'CH assign'!A:B,2,0) -> D12709 | G11: =VLOOKUP(F11,Etch_Length_From_Layout!A:B,2,0) -> 32822.42 | K11: =G11+J11 -> 32822.42 | L11: =IF(ABS(K11-K12)<1,"PASS","FAIL") -> PASS
C12: 84 | D12: AML3N | E12: S1_1TX_100DCH005- | F12: =VLOOKUP(E12,'CH assign'!A:B,2,0) -> D12711 | G12: =VLOOKUP(F12,Etch_Length_From_Layout!A:B,2,0) -> 32822.07 | K12: =G12+J12 -> 32822.07
C13: 85 | D13: AML4P | E13: S1_1TX_100DCH006+ | F13: =VLOOKUP(E13,'CH assign'!A:B,2,0) -> D12706 | G13: =VLOOKUP(F13,Etch_Length_From_Layout!A:B,2,0) -> 32822.48 | K13: =G13+J13 -> 32822.48 | L13: =IF(ABS(K13-K14)<1,"PASS","FAIL") -> PASS
C14: 86 | D14: AML4N | E14: S1_1TX_100DCH006- | F14: =VLOOKUP(E14,'CH assign'!A:B,2,0) -> D12708 | G14: =VLOOKUP(F14,Etch_Length_From_Layout!A:B,2,0) -> 32822.13 | K14: =G14+J14 -> 32822.13
C15: 87 | D15: AML5P | E15: S1_1TX_100DCH007+ | F15: =VLOOKUP(E15,'CH assign'!A:B,2,0) -> D12713 | G15: =VLOOKUP(F15,Etch_Length_From_Layout!A:B,2,0) -> 32822.28 | K15: =G15+J15 -> 32822.28 | L15: =IF(ABS(K15-K16)<1,"PASS","FAIL") -> PASS
C16: 88 | D16: AML5N | E16: S1_1TX_100DCH007- | F16: =VLOOKUP(E16,'CH assign'!A:B,2,0) -> D12715 | G16: =VLOOKUP(F16,Etch_Length_From_Layout!A:B,2,0) -> 32822.42 | K16: =G16+J16 -> 32822.42
C17: 89 | D17: BML0P | E17: S1_2TX_100DCH001+ | F17: =VLOOKUP(E17,'CH assign'!A:B,2,0) -> D12702 | G17: =VLOOKUP(F17,Etch_Length_From_Layout!A:B,2,0) -> 32822.28 | K17: =G17+J17 -> 32822.28 | L17: =IF(ABS(K17-K18)<1,"PASS","FAIL") -> PASS
C18: 90 | D18: BML0N | E18: S1_2TX_100DCH001- | F18: =VLOOKUP(E18,'CH assign'!A:B,2,0) -> D12704 | G18: =VLOOKUP(F18,Etch_Length_From_Layout!A:B,2,0) -> 32822.1 | K18: =G18+J18 -> 32822.1
C19: 91 | D19: BML1P | E19: S1_2TX_100DCH002+ | F19: =VLOOKUP(E19,'CH assign'!A:B,2,0) -> D12809 | G19: =VLOOKUP(F19,Etch_Length_From_Layout!A:B,2,0) -> 32822.14 | K19: =G19+J19 -> 32822.14 | L19: =IF(ABS(K19-K20)<1,"PASS","FAIL") -> PASS
C20: 92 | D20: BML1N | E20: S1_2TX_100DCH002- | F20: =VLOOKUP(E20,'CH assign'!A:B,2,0) -> D12811 | G20: =VLOOKUP(F20,Etch_Length_From_Layout!A:B,2,0) -> 32822.07 | K20: =G20+J20 -> 32822.07
C21: 93 | D21: BML2P | E21: S1_2TX_100DCH003+ | F21: =VLOOKUP(E21,'CH assign'!A:B,2,0) -> D12813 | G21: =VLOOKUP(F21,Etch_Length_From_Layout!A:B,2,0) -> 32822.35 | K21: =G21+J21 -> 32822.35 | L21: =IF(ABS(K21-K22)<1,"PASS","FAIL") -> PASS
C22: 94 | D22: BML2N | E22: S1_2TX_100DCH003- | F22: =VLOOKUP(E22,'CH assign'!A:B,2,0) -> D12815 | G22: =VLOOKUP(F22,Etch_Length_From_Layout!A:B,2,0) -> 32822.49 | K22: =G22+J22 -> 32822.49
C23: 95 | D23: BMLCKP | E23: S1_2TX_100DCH004+ | F23: =VLOOKUP(E23,'CH assign'!A:B,2,0) -> D12805 | G23: =VLOOKUP(F23,Etch_Length_From_Layout!A:B,2,0) -> 32822.02 | K23: =G23+J23 -> 32822.02 | L23: =IF(ABS(K23-K24)<1,"PASS","FAIL") -> PASS
C24: 96 | D24: BMLCKN | E24: S1_2TX_100DCH004- | F24: =VLOOKUP(E24,'CH assign'!A:B,2,0) -> D12807 | G24: =VLOOKUP(F24,Etch_Length_From_Layout!A:B,2,0) -> 32822.3 | K24: =G24+J24 -> 32822.3
C25: 98 | D25: BML3P | E25: S1_2TX_100DCH005+ | F25: =VLOOKUP(E25,'CH assign'!A:B,2,0) -> D12705 | G25: =VLOOKUP(F25,Etch_Length_From_Layout!A:B,2,0) -> 32822.3 | K25: =G25+J25 -> 32822.3 | L25: =IF(ABS(K25-K26)<1,"PASS","FAIL") -> PASS
C26: 99 | D26: BML3N | E26: S1_2TX_100DCH005- | F26: =VLOOKUP(E26,'CH assign'!A:B,2,0) -> D12707 | G26: =VLOOKUP(F26,Etch_Length_From_Layout!A:B,2,0) -> 32822.34 | K26: =G26+J26 -> 32822.34
C27: 100 | D27: BML4P | E27: S1_2TX_100DCH006+ | F27: =VLOOKUP(E27,'CH assign'!A:B,2,0) -> D12801 | G27: =VLOOKUP(F27,Etch_Length_From_Layout!A:B,2,0) -> 32822.19 | K27: =G27+J27 -> 32822.19 | L27: =IF(ABS(K27-K28)<1,"PASS","FAIL") -> PASS
C28: 101 | D28: BML4N | E28: S1_2TX_100DCH006- | F28: =VLOOKUP(E28,'CH assign'!A:B,2,0) -> D12803 | G28: =VLOOKUP(F28,Etch_Length_From_Layout!A:B,2,0) -> 32822.43 | K28: =G28+J28 -> 32822.43
C29: 102 | D29: BML5P | E29: S1_2TX_100DCH007+ | F29: =VLOOKUP(E29,'CH assign'!A:B,2,0) -> D12701 | G29: =VLOOKUP(F29,Etch_Length_From_Layout!A:B,2,0) -> 32822.29 | K29: =G29+J29 -> 32822.29 | L29: =IF(ABS(K29-K30)<1,"PASS","FAIL") -> PASS
C30: 103 | D30: BML5N | E30: S1_2TX_100DCH007- | F30: =VLOOKUP(E30,'CH assign'!A:B,2,0) -> D12703 | G30: =VLOOKUP(F30,Etch_Length_From_Layout!A:B,2,0) -> 32822.34 | K30: =G30+J30 -> 32822.34
C31: 112 | D31: CML0P | E31: S1_ISP14+ | G31: =VLOOKUP(E31,Etch_Length_From_Layout!A:B,2,0) -> 2867.66 | H31: S1_1TX_100DCH001+ | I31: =VLOOKUP(H31,'CH assign'!$A:$B,2,0) -> D13105 | J31: =VLOOKUP(I31,Etch_Length_From_Layout!$A:$B,2,0) -> 29954.55 | K31: =G31+J31 -> 32822.21 | L31: =IF(ABS(K31-K32)<1,"PASS","FAIL") -> PASS
C32: 113 | D32: CML0N | E32: S1_ISP14- | G32: =VLOOKUP(E32,Etch_Length_From_Layout!A:B,2,0) -> 2867.99 | H32: S1_1TX_100DCH001- | I32: =VLOOKUP(H32,'CH assign'!$A:$B,2,0) -> D13107 | J32: =VLOOKUP(I32,Etch_Length_From_Layout!$A:$B,2,0) -> 29954.69 | K32: =G32+J32 -> 32822.68
C33: 114 | D33: CML1P | E33: S1_3TX_100DCH002+ | F33: =VLOOKUP(E33,'CH assign'!A:B,2,0) -> D13209 | G33: =VLOOKUP(F33,Etch_Length_From_Layout!A:B,2,0) -> 32822.1 | K33: =G33+J33 -> 32822.1 | L33: =IF(ABS(K33-K34)<1,"PASS","FAIL") -> PASS
C34: 115 | D34: CML1N | E34: S1_3TX_100DCH002- | F34: =VLOOKUP(E34,'CH assign'!A:B,2,0) -> D13211 | G34: =VLOOKUP(F34,Etch_Length_From_Layout!A:B,2,0) -> 32822.46 | K34: =G34+J34 -> 32822.46
C35: 116 | D35: CML2P | E35: S1_3TX_100DCH003+ | F35: =VLOOKUP(E35,'CH assign'!A:B,2,0) -> D13210 | G35: =VLOOKUP(F35,Etch_Length_From_Layout!A:B,2,0) -> 32822.11 | K35: =G35+J35 -> 32822.11 | L35: =IF(ABS(K35-K36)<1,"PASS","FAIL") -> PASS
C36: 117 | D36: CML2N | E36: S1_3TX_100DCH003- | F36: =VLOOKUP(E36,'CH assign'!A:B,2,0) -> D13212 | G36: =VLOOKUP(F36,Etch_Length_From_Layout!A:B,2,0) -> 32822.49 | K36: =G36+J36 -> 32822.49
C37: 120 | D37: CMLCKP | E37: S1_3TX_100DCH004+ | F37: =VLOOKUP(E37,'CH assign'!A:B,2,0) -> D12710 | G37: =VLOOKUP(F37,Etch_Length_From_Layout!A:B,2,0) -> 32822.44 | K37: =G37+J37 -> 32822.44 | L37: =IF(ABS(K37-K38)<1,"PASS","FAIL") -> PASS
C38: 121 | D38: CMLCKN | E38: S1_3TX_100DCH004- | F38: =VLOOKUP(E38,'CH assign'!A:B,2,0) -> D12712 | G38: =VLOOKUP(F38,Etch_Length_From_Layout!A:B,2,0) -> 32822.01 | K38: =G38+J38 -> 32822.01
C39: 122 | D39: CML3P | E39: S1_3TX_100DCH005+ | F39: =VLOOKUP(E39,'CH assign'!A:B,2,0) -> D12814 | G39: =VLOOKUP(F39,Etch_Length_From_Layout!A:B,2,0) -> 32822.48 | K39: =G39+J39 -> 32822.48 | L39: =IF(ABS(K39-K40)<1,"PASS","FAIL") -> PASS
C40: 123 | D40: CML3N | E40: S1_3TX_100DCH005- | F40: =VLOOKUP(E40,'CH assign'!A:B,2,0) -> D12816 | G40: =VLOOKUP(F40,Etch_Length_From_Layout!A:B,2,0) -> 32822.42 | K40: =G40+J40 -> 32822.42
...

Sheet ELV_RX
B1: PS1600 channel，對與對誤差1 mil，+/-誤差1mil；4 Site等長
B2: SITE | C2: Pin number | D2: Pin name | E2: Net name | F2: Channel | G2: Length (mils) | H2: Total length (mils) | I2: +/- CHECK
B3: SITE1 | C3: 5 | D3: ELV0N | E3: S1_ELVRX_100DCH001- | F3: =VLOOKUP(E3,'CH assign'!A:B,2,0) -> D12504 | G3: =VLOOKUP(F3,Etch_Length_From_Layout!A:B,2,0) -> 17991.12 | H3: =G3 -> 17991.12 | I3: =IF(ABS(H3-H4)<1,"PASS","FAIL") -> PASS
C4: 6 | D4: ELV0P | E4: S1_ELVRX_100DCH001+ | F4: =VLOOKUP(E4,'CH assign'!A:B,2,0) -> D12502 | G4: =VLOOKUP(F4,Etch_Length_From_Layout!A:B,2,0) -> 17991.96 | H4: =G4 -> 17991.96
C5: 7 | D5: ELV1N | E5: S1_ELVRX_100DCH002- | F5: =VLOOKUP(E5,'CH assign'!A:B,2,0) -> D12508 | G5: =VLOOKUP(F5,Etch_Length_From_Layout!A:B,2,0) -> 17991.61 | H5: =G5 -> 17991.61 | I5: =IF(ABS(H5-H6)<1,"PASS","FAIL") -> PASS
C6: 8 | D6: ELV1P | E6: S1_ELVRX_100DCH002+ | F6: =VLOOKUP(E6,'CH assign'!A:B,2,0) -> D12506 | G6: =VLOOKUP(F6,Etch_Length_From_Layout!A:B,2,0) -> 17991.37 | H6: =G6 -> 17991.37
C7: 9 | D7: ELV2N | E7: S1_ELVRX_100DCH003- | F7: =VLOOKUP(E7,'CH assign'!A:B,2,0) -> D12615 | G7: =VLOOKUP(F7,Etch_Length_From_Layout!A:B,2,0) -> 17991.79 | H7: =G7 -> 17991.79 | I7: =IF(ABS(H7-H8)<1,"PASS","FAIL") -> PASS
C8: 10 | D8: ELV2P | E8: S1_ELVRX_100DCH003+ | F8: =VLOOKUP(E8,'CH assign'!A:B,2,0) -> D12613 | G8: =VLOOKUP(F8,Etch_Length_From_Layout!A:B,2,0) -> 17991.53 | H8: =G8 -> 17991.53
C9: 11 | D9: ELVCKN | E9: S1_ELVRX_100DCH004- | F9: =VLOOKUP(E9,'CH assign'!A:B,2,0) -> D12616 | G9: =VLOOKUP(F9,Etch_Length_From_Layout!A:B,2,0) -> 17991.56 | H9: =G9 -> 17991.56 | I9: =IF(ABS(H9-H10)<1,"PASS","FAIL") -> PASS
C10: 12 | D10: ELVCKP | E10: S1_ELVRX_100DCH004+ | F10: =VLOOKUP(E10,'CH assign'!A:B,2,0) -> D12614 | G10: =VLOOKUP(F10,Etch_Length_From_Layout!A:B,2,0) -> 17991.41 | H10: =G10 -> 17991.41
C11: 13 | D11: ELV3N | E11: S1_ELVRX_100DCH005- | F11: =VLOOKUP(E11,'CH assign'!A:B,2,0) -> D12612 | G11: =VLOOKUP(F11,Etch_Length_From_Layout!A:B,2,0) -> 17991.88 | H11: =G11 -> 17991.88 | I11: =IF(ABS(H11-H12)<1,"PASS","FAIL") -> PASS
C12: 14 | D12: ELV3P | E12: S1_ELVRX_100DCH005+ | F12: =VLOOKUP(E12,'CH assign'!A:B,2,0) -> D12610 | G12: =VLOOKUP(F12,Etch_Length_From_Layout!A:B,2,0) -> 17991.22 | H12: =G12 -> 17991.22
C13: 15 | D13: ELV4N | E13: S1_ELVRX_100DCH006- | F13: =VLOOKUP(E13,'CH assign'!A:B,2,0) -> D12611 | G13: =VLOOKUP(F13,Etch_Length_From_Layout!A:B,2,0) -> 17991.01 | H13: =G13 -> 17991.01 | I13: =IF(ABS(H13-H14)<1,"PASS","FAIL") -> PASS
C14: 16 | D14: ELV4P | E14: S1_ELVRX_100DCH006+ | F14: =VLOOKUP(E14,'CH assign'!A:B,2,0) -> D12609 | G14: =VLOOKUP(F14,Etch_Length_From_Layout!A:B,2,0) -> 17991.98 | H14: =G14 -> 17991.98
B15: SITE2 | C15: 5 | D15: ELV0N | E15: S2_ELVRX_100DCH001- | F15: =VLOOKUP(E15,'CH assign'!A:B,2,0) -> D11308 | G15: =VLOOKUP(F15,Etch_Length_From_Layout!A:B,2,0) -> 17991.13 | H15: =G15 -> 17991.13 | I15: =IF(ABS(H15-H16)<1,"PASS","FAIL") -> PASS
C16: 6 | D16: ELV0P | E16: S2_ELVRX_100DCH001+ | F16: =VLOOKUP(E16,'CH assign'!A:B,2,0) -> D11306 | G16: =VLOOKUP(F16,Etch_Length_From_Layout!A:B,2,0) -> 17991.84 | H16: =G16 -> 17991.84
C17: 7 | D17: ELV1N | E17: S2_ELVRX_100DCH002- | F17: =VLOOKUP(E17,'CH assign'!A:B,2,0) -> D11304 | G17: =VLOOKUP(F17,Etch_Length_From_Layout!A:B,2,0) -> 17991.02 | H17: =G17 -> 17991.02 | I17: =IF(ABS(H17-H18)<1,"PASS","FAIL") -> PASS
C18: 8 | D18: ELV1P | E18: S2_ELVRX_100DCH002+ | F18: =VLOOKUP(E18,'CH assign'!A:B,2,0) -> D11302 | G18: =VLOOKUP(F18,Etch_Length_From_Layout!A:B,2,0) -> 17991.97 | H18: =G18 -> 17991.97
C19: 9 | D19: ELV2N | E19: S2_ELVRX_100DCH003- | F19: =VLOOKUP(E19,'CH assign'!A:B,2,0) -> D10915 | G19: =VLOOKUP(F19,Etch_Length_From_Layout!A:B,2,0) -> 17991.57 | H19: =G19 -> 17991.57 | I19: =IF(ABS(H19-H20)<1,"PASS","FAIL") -> PASS
C20: 10 | D20: ELV2P | E20: S2_ELVRX_100DCH003+ | F20: =VLOOKUP(E20,'CH assign'!A:B,2,0) -> D10913 | G20: =VLOOKUP(F20,Etch_Length_From_Layout!A:B,2,0) -> 17991.78 | H20: =G20 -> 17991.78
C21: 11 | D21: ELVCKN | E21: S2_ELVRX_100DCH004- | F21: =VLOOKUP(E21,'CH assign'!A:B,2,0) -> D10916 | G21: =VLOOKUP(F21,Etch_Length_From_Layout!A:B,2,0) -> 17991.27 | H21: =G21 -> 17991.27 | I21: =IF(ABS(H21-H22)<1,"PASS","FAIL") -> PASS
C22: 12 | D22: ELVCKP | E22: S2_ELVRX_100DCH004+ | F22: =VLOOKUP(E22,'CH assign'!A:B,2,0) -> D10914 | G22: =VLOOKUP(F22,Etch_Length_From_Layout!A:B,2,0) -> 17991.8 | H22: =G22 -> 17991.8
C23: 13 | D23: ELV3N | E23: S2_ELVRX_100DCH005- | F23: =VLOOKUP(E23,'CH assign'!A:B,2,0) -> D10911 | G23: =VLOOKUP(F23,Etch_Length_From_Layout!A:B,2,0) -> 17991.25 | H23: =G23 -> 17991.25 | I23: =IF(ABS(H23-H24)<1,"PASS","FAIL") -> PASS
C24: 14 | D24: ELV3P | E24: S2_ELVRX_100DCH005+ | F24: =VLOOKUP(E24,'CH assign'!A:B,2,0) -> D10909 | G24: =VLOOKUP(F24,Etch_Length_From_Layout!A:B,2,0) -> 17991.54 | H24: =G24 -> 17991.54
C25: 15 | D25: ELV4N | E25: S2_ELVRX_100DCH006- | F25: =VLOOKUP(E25,'CH assign'!A:B,2,0) -> D11307 | G25: =VLOOKUP(F25,Etch_Length_From_Layout!A:B,2,0) -> 17991.15 | H25: =G25 -> 17991.15 | I25: =IF(ABS(H25-H26)<1,"PASS","FAIL") -> PASS
C26: 16 | D26: ELV4P | E26: S2_ELVRX_100DCH006+ | F26: =VLOOKUP(E26,'CH assign'!A:B,2,0) -> D11305 | G26: =VLOOKUP(F26,Etch_Length_From_Layout!A:B,2,0) -> 17991.09 | H26: =G26 -> 17991.09
B27: SITE3 | C27: 5 | D27: ELV0N | E27: S3_ELVRX_100DCH001- | F27: =VLOOKUP(E27,'CH assign'!A:B,2,0) -> D13016 | G27: =VLOOKUP(F27,Etch_Length_From_Layout!A:B,2,0) -> 17991.66 | H27: =G27 -> 17991.66 | I27: =IF(ABS(H27-H28)<1,"PASS","FAIL") -> PASS
C28: 6 | D28: ELV0P | E28: S3_ELVRX_100DCH001+ | F28: =VLOOKUP(E28,'CH assign'!A:B,2,0) -> D13014 | G28: =VLOOKUP(F28,Etch_Length_From_Layout!A:B,2,0) -> 17991.69 | H28: =G28 -> 17991.69
C29: 7 | D29: ELV1N | E29: S3_ELVRX_100DCH002- | F29: =VLOOKUP(E29,'CH assign'!A:B,2,0) -> D12915 | G29: =VLOOKUP(F29,Etch_Length_From_Layout!A:B,2,0) -> 17991.42 | H29: =G29 -> 17991.42 | I29: =IF(ABS(H29-H30)<1,"PASS","FAIL") -> PASS
C30: 8 | D30: ELV1P | E30: S3_ELVRX_100DCH002+ | F30: =VLOOKUP(E30,'CH assign'!A:B,2,0) -> D12913 | G30: =VLOOKUP(F30,Etch_Length_From_Layout!A:B,2,0) -> 17991.78 | H30: =G30 -> 17991.78
C31: 9 | D31: ELV2N | E31: S3_ELVRX_100DCH003- | F31: =VLOOKUP(E31,'CH assign'!A:B,2,0) -> D13012 | G31: =VLOOKUP(F31,Etch_Length_From_Layout!A:B,2,0) -> 17991.54 | H31: =G31 -> 17991.54 | I31: =IF(ABS(H31-H32)<1,"PASS","FAIL") -> PASS
C32: 10 | D32: ELV2P | E32: S3_ELVRX_100DCH003+ | F32: =VLOOKUP(E32,'CH assign'!A:B,2,0) -> D13010 | G32: =VLOOKUP(F32,Etch_Length_From_Layout!A:B,2,0) -> 17991.05 | H32: =G32 -> 17991.05
C33: 11 | D33: ELVCKN | E33: S3_ELVRX_100DCH004- | F33: =VLOOKUP(E33,'CH assign'!A:B,2,0) -> D12911 | G33: =VLOOKUP(F33,Etch_Length_From_Layout!A:B,2,0) -> 17991.74 | H33: =G33 -> 17991.74 | I33: =IF(ABS(H33-H34)<1,"PASS","FAIL") -> PASS
C34: 12 | D34: ELVCKP | E34: S3_ELVRX_100DCH004+ | F34: =VLOOKUP(E34,'CH assign'!A:B,2,0) -> D12909 | G34: =VLOOKUP(F34,Etch_Length_From_Layout!A:B,2,0) -> 17991.27 | H34: =G34 -> 17991.27
C35: 13 | D35: ELV3N | E35: S3_ELVRX_100DCH005- | F35: =VLOOKUP(E35,'CH assign'!A:B,2,0) -> D13015 | G35: =VLOOKUP(F35,Etch_Length_From_Layout!A:B,2,0) -> 17991.5 | H35: =G35 -> 17991.5 | I35: =IF(ABS(H35-H36)<1,"PASS","FAIL") -> PASS
C36: 14 | D36: ELV3P | E36: S3_ELVRX_100DCH005+ | F36: =VLOOKUP(E36,'CH assign'!A:B,2,0) -> D13013 | G36: =VLOOKUP(F36,Etch_Length_From_Layout!A:B,2,0) -> 17991.4 | H36: =G36 -> 17991.4
C37: 15 | D37: ELV4N | E37: S3_ELVRX_100DCH006- | F37: =VLOOKUP(E37,'CH assign'!A:B,2,0) -> D13011 | G37: =VLOOKUP(F37,Etch_Length_From_Layout!A:B,2,0) -> 17991.84 | H37: =G37 -> 17991.84 | I37: =IF(ABS(H37-H38)<1,"PASS","FAIL") -> PASS
C38: 16 | D38: ELV4P | E38: S3_ELVRX_100DCH006+ | F38: =VLOOKUP(E38,'CH assign'!A:B,2,0) -> D13009 | G38: =VLOOKUP(F38,Etch_Length_From_Layout!A:B,2,0) -> 17991.04 | H38: =G38 -> 17991.04
B39: SITE4 | C39: 5 | D39: ELV0N | E39: S4_ELVRX_100DCH001- | F39: =VLOOKUP(E39,'CH assign'!A:B,2,0) -> D10801 | G39: =VLOOKUP(F39,Etch_Length_From_Layout!A:B,2,0) -> 17991.93 | H39: =G39 -> 17991.93 | I39: =IF(ABS(H39-H40)<1,"PASS","FAIL") -> PASS
C40: 6 | D40: ELV0P | E40: S4_ELVRX_100DCH001+ | F40: =VLOOKUP(E40,'CH assign'!A:B,2,0) -> D10803 | G40: =VLOOKUP(F40,Etch_Length_From_Layout!A:B,2,0) -> 17991.02 | H40: =G40 -> 17991.02
...

Sheet OLV_RX
B1: PS1600 channel，對與對誤差1 mil，+/-誤差1mil；4 Site等長
B2: SITE | C2: Pin number | D2: Pin name | E2: Net name | F2: Channel | G2: Length (mils) | H2: Total length (mils) | I2: +/- CHECK
B3: SITE1 | C3: 167 | D3: OLV0N | E3: S1_OLVRX_100DCH001- | F3: =VLOOKUP(E3,'CH assign'!A:B,2,0) -> D12507 | G3: =VLOOKUP(F3,Etch_Length_From_Layout!A:B,2,0) -> 16278.21 | H3: =G3 -> 16278.21 | I3: =IF(ABS(H3-H4)<1,"PASS","FAIL") -> PASS
C4: 168 | D4: OLV0P | E4: S1_OLVRX_100DCH001+ | F4: =VLOOKUP(E4,'CH assign'!A:B,2,0) -> D12505 | G4: =VLOOKUP(F4,Etch_Length_From_Layout!A:B,2,0) -> 16278.26 | H4: =G4 -> 16278.26
C5: 169 | D5: OLV1N | E5: S1_OLVRX_100DCH002- | F5: =VLOOKUP(E5,'CH assign'!A:B,2,0) -> D12503 | G5: =VLOOKUP(F5,Etch_Length_From_Layout!A:B,2,0) -> 16278.09 | H5: =G5 -> 16278.09 | I5: =IF(ABS(H5-H6)<1,"PASS","FAIL") -> PASS
C6: 170 | D6: OLV1P | E6: S1_OLVRX_100DCH002+ | F6: =VLOOKUP(E6,'CH assign'!A:B,2,0) -> D12501 | G6: =VLOOKUP(F6,Etch_Length_From_Layout!A:B,2,0) -> 16278.69 | H6: =G6 -> 16278.69
C7: 171 | D7: OLV2N | E7: S1_OLVRX_100DCH003- | F7: =VLOOKUP(E7,'CH assign'!A:B,2,0) -> D12515 | G7: =VLOOKUP(F7,Etch_Length_From_Layout!A:B,2,0) -> 16278.1 | H7: =G7 -> 16278.1 | I7: =IF(ABS(H7-H8)<1,"PASS","FAIL") -> PASS
C8: 172 | D8: OLV2P | E8: S1_OLVRX_100DCH003+ | F8: =VLOOKUP(E8,'CH assign'!A:B,2,0) -> D12513 | G8: =VLOOKUP(F8,Etch_Length_From_Layout!A:B,2,0) -> 16278.48 | H8: =G8 -> 16278.48
C9: 173 | D9: OLVCKN | E9: S1_OLVRX_100DCH004- | F9: =VLOOKUP(E9,'CH assign'!A:B,2,0) -> D12512 | G9: =VLOOKUP(F9,Etch_Length_From_Layout!A:B,2,0) -> 16278.14 | H9: =G9 -> 16278.14 | I9: =IF(ABS(H9-H10)<1,"PASS","FAIL") -> PASS
C10: 174 | D10: OLVCKP | E10: S1_OLVRX_100DCH004+ | F10: =VLOOKUP(E10,'CH assign'!A:B,2,0) -> D12510 | G10: =VLOOKUP(F10,Etch_Length_From_Layout!A:B,2,0) -> 16278.85 | H10: =G10 -> 16278.85
C11: 175 | D11: OLV3N | E11: S1_OLVRX_100DCH005- | F11: =VLOOKUP(E11,'CH assign'!A:B,2,0) -> D12516 | G11: =VLOOKUP(F11,Etch_Length_From_Layout!A:B,2,0) -> 16278.95 | H11: =G11 -> 16278.95 | I11: =IF(ABS(H11-H12)<1,"PASS","FAIL") -> PASS
C12: 176 | D12: OLV3P | E12: S1_OLVRX_100DCH005+ | F12: =VLOOKUP(E12,'CH assign'!A:B,2,0) -> D12514 | G12: =VLOOKUP(F12,Etch_Length_From_Layout!A:B,2,0) -> 16278.04 | H12: =G12 -> 16278.04
C13: 1 | D13: OLV4N | E13: S1_OLVRX_100DCH006- | F13: =VLOOKUP(E13,'CH assign'!A:B,2,0) -> D12511 | G13: =VLOOKUP(F13,Etch_Length_From_Layout!A:B,2,0) -> 16278.47 | H13: =G13 -> 16278.47 | I13: =IF(ABS(H13-H14)<1,"PASS","FAIL") -> PASS
C14: 2 | D14: OLV4P | E14: S1_OLVRX_100DCH006+ | F14: =VLOOKUP(E14,'CH assign'!A:B,2,0) -> D12509 | G14: =VLOOKUP(F14,Etch_Length_From_Layout!A:B,2,0) -> 16278.96 | H14: =G14 -> 16278.96
B15: SITE2 | C15: 167 | D15: OLV0N | E15: S2_OLVRX_100DCH001- | F15: =VLOOKUP(E15,'CH assign'!A:B,2,0) -> D10904 | G15: =VLOOKUP(F15,Etch_Length_From_Layout!A:B,2,0) -> 16278.98 | H15: =G15 -> 16278.98 | I15: =IF(ABS(H15-H16)<1,"PASS","FAIL") -> PASS
C16: 168 | D16: OLV0P | E16: S2_OLVRX_100DCH001+ | F16: =VLOOKUP(E16,'CH assign'!A:B,2,0) -> D10902 | G16: =VLOOKUP(F16,Etch_Length_From_Layout!A:B,2,0) -> 16278.27 | H16: =G16 -> 16278.27
C17: 169 | D17: OLV1N | E17: S2_OLVRX_100DCH002- | F17: =VLOOKUP(E17,'CH assign'!A:B,2,0) -> D10908 | G17: =VLOOKUP(F17,Etch_Length_From_Layout!A:B,2,0) -> 16278.53 | H17: =G17 -> 16278.53 | I17: =IF(ABS(H17-H18)<1,"PASS","FAIL") -> PASS
C18: 170 | D18: OLV1P | E18: S2_OLVRX_100DCH002+ | F18: =VLOOKUP(E18,'CH assign'!A:B,2,0) -> D10906 | G18: =VLOOKUP(F18,Etch_Length_From_Layout!A:B,2,0) -> 16278.33 | H18: =G18 -> 16278.33
C19: 171 | D19: OLV2N | E19: S2_OLVRX_100DCH003- | F19: =VLOOKUP(E19,'CH assign'!A:B,2,0) -> D11303 | G19: =VLOOKUP(F19,Etch_Length_From_Layout!A:B,2,0) -> 16278.08 | H19: =G19 -> 16278.08 | I19: =IF(ABS(H19-H20)<1,"PASS","FAIL") -> PASS
C20: 172 | D20: OLV2P | E20: S2_OLVRX_100DCH003+ | F20: =VLOOKUP(E20,'CH assign'!A:B,2,0) -> D11301 | G20: =VLOOKUP(F20,Etch_Length_From_Layout!A:B,2,0) -> 16278.94 | H20: =G20 -> 16278.94
C21: 173 | D21: OLVCKN | E21: S2_OLVRX_100DCH004- | F21: =VLOOKUP(E21,'CH assign'!A:B,2,0) -> D10907 | G21: =VLOOKUP(F21,Etch_Length_From_Layout!A:B,2,0) -> 16278.03 | H21: =G21 -> 16278.03 | I21: =IF(ABS(H21-H22)<1,"PASS","FAIL") -> PASS
C22: 174 | D22: OLVCKP | E22: S2_OLVRX_100DCH004+ | F22: =VLOOKUP(E22,'CH assign'!A:B,2,0) -> D10905 | G22: =VLOOKUP(F22,Etch_Length_From_Layout!A:B,2,0) -> 16278.25 | H22: =G22 -> 16278.25
C23: 175 | D23: OLV3N | E23: S2_OLVRX_100DCH005- | F23: =VLOOKUP(E23,'CH assign'!A:B,2,0) -> D10903 | G23: =VLOOKUP(F23,Etch_Length_From_Layout!A:B,2,0) -> 16278.89 | H23: =G23 -> 16278.89 | I23: =IF(ABS(H23-H24)<1,"PASS","FAIL") -> PASS
C24: 176 | D24: OLV3P | E24: S2_OLVRX_100DCH005+ | F24: =VLOOKUP(E24,'CH assign'!A:B,2,0) -> D10901 | G24: =VLOOKUP(F24,Etch_Length_From_Layout!A:B,2,0) -> 16278.95 | H24: =G24 -> 16278.95
C25: 1 | D25: OLV4N | E25: S2_OLVRX_100DCH006- | F25: =VLOOKUP(E25,'CH assign'!A:B,2,0) -> D10912 | G25: =VLOOKUP(F25,Etch_Length_From_Layout!A:B,2,0) -> 16278.35 | H25: =G25 -> 16278.35 | I25: =IF(ABS(H25-H26)<1,"PASS","FAIL") -> PASS
C26: 2 | D26: OLV4P | E26: S2_OLVRX_100DCH006+ | F26: =VLOOKUP(E26,'CH assign'!A:B,2,0) -> D10910 | G26: =VLOOKUP(F26,Etch_Length_From_Layout!A:B,2,0) -> 16278.6 | H26: =G26 -> 16278.6
B27: SITE3 | C27: 167 | D27: OLV0N | E27: S3_OLVRX_100DCH001- | F27: =VLOOKUP(E27,'CH assign'!A:B,2,0) -> D12916 | G27: =VLOOKUP(F27,Etch_Length_From_Layout!A:B,2,0) -> 16278.22 | H27: =G27 -> 16278.22 | I27: =IF(ABS(H27-H28)<1,"PASS","FAIL") -> PASS
C28: 168 | D28: OLV0P | E28: S3_OLVRX_100DCH001+ | F28: =VLOOKUP(E28,'CH assign'!A:B,2,0) -> D12914 | G28: =VLOOKUP(F28,Etch_Length_From_Layout!A:B,2,0) -> 16278.88 | H28: =G28 -> 16278.88
C29: 169 | D29: OLV1N | E29: S3_OLVRX_100DCH002- | F29: =VLOOKUP(E29,'CH assign'!A:B,2,0) -> D12904 | G29: =VLOOKUP(F29,Etch_Length_From_Layout!A:B,2,0) -> 16278.41 | H29: =G29 -> 16278.41 | I29: =IF(ABS(H29-H30)<1,"PASS","FAIL") -> PASS
C30: 170 | D30: OLV1P | E30: S3_OLVRX_100DCH002+ | F30: =VLOOKUP(E30,'CH assign'!A:B,2,0) -> D12902 | G30: =VLOOKUP(F30,Etch_Length_From_Layout!A:B,2,0) -> 16278.16 | H30: =G30 -> 16278.16
C31: 171 | D31: OLV2N | E31: S3_OLVRX_100DCH003- | F31: =VLOOKUP(E31,'CH assign'!A:B,2,0) -> D12907 | G31: =VLOOKUP(F31,Etch_Length_From_Layout!A:B,2,0) -> 16278.92 | H31: =G31 -> 16278.92 | I31: =IF(ABS(H31-H32)<1,"PASS","FAIL") -> PASS
C32: 172 | D32: OLV2P | E32: S3_OLVRX_100DCH003+ | F32: =VLOOKUP(E32,'CH assign'!A:B,2,0) -> D12905 | G32: =VLOOKUP(F32,Etch_Length_From_Layout!A:B,2,0) -> 16278.35 | H32: =G32 -> 16278.35
C33: 173 | D33: OLVCKN | E33: S3_OLVRX_100DCH004- | F33: =VLOOKUP(E33,'CH assign'!A:B,2,0) -> D12908 | G33: =VLOOKUP(F33,Etch_Length_From_Layout!A:B,2,0) -> 16278.07 | H33: =G33 -> 16278.07 | I33: =IF(ABS(H33-H34)<1,"PASS","FAIL") -> PASS
C34: 174 | D34: OLVCKP | E34: S3_OLVRX_100DCH004+ | F34: =VLOOKUP(E34,'CH assign'!A:B,2,0) -> D12906 | G34: =VLOOKUP(F34,Etch_Length_From_Layout!A:B,2,0) -> 16278.44 | H34: =G34 -> 16278.44
C35: 175 | D35: OLV3N | E35: S3_OLVRX_100DCH005- | F35: =VLOOKUP(E35,'CH assign'!A:B,2,0) -> D12901 | G35: =VLOOKUP(F35,Etch_Length_From_Layout!A:B,2,0) -> 16278.02 | H35: =G35 -> 16278.02 | I35: =IF(ABS(H35-H36)<1,"PASS","FAIL") -> PASS
C36: 176 | D36: OLV3P | E36: S3_OLVRX_100DCH005+ | F36: =VLOOKUP(E36,'CH assign'!A:B,2,0) -> D12903 | G36: =VLOOKUP(F36,Etch_Length_From_Layout!A:B,2,0) -> 16278.73 | H36: =G36 -> 16278.73
C37: 1 | D37: OLV4N | E37: S3_OLVRX_100DCH006- | F37: =VLOOKUP(E37,'CH assign'!A:B,2,0) -> D12912 | G37: =VLOOKUP(F37,Etch_Length_From_Layout!A:B,2,0) -> 16278.35 | H37: =G37 -> 16278.35 | I37: =IF(ABS(H37-H38)<1,"PASS","FAIL") -> PASS
C38: 2 | D38: OLV4P | E38: S3_OLVRX_100DCH006+ | F38: =VLOOKUP(E38,'CH assign'!A:B,2,0) -> D12910 | G38: =VLOOKUP(F38,Etch_Length_From_Layout!A:B,2,0) -> 16278.87 | H38: =G38 -> 16278.87
B39: SITE4 | C39: 167 | D39: OLV0N | E39: S4_OLVRX_100DCH001- | F39: =VLOOKUP(E39,'CH assign'!A:B,2,0) -> D10812 | G39: =VLOOKUP(F39,Etch_Length_From_Layout!A:B,2,0) -> 16278.02 | H39: =G39 -> 16278.02 | I39: =IF(ABS(H39-H40)<1,"PASS","FAIL") -> PASS
C40: 168 | D40: OLV0P | E40: S4_OLVRX_100DCH001+ | F40: =VLOOKUP(E40,'CH assign'!A:B,2,0) -> D10810 | G40: =VLOOKUP(F40,Etch_Length_From_Layout!A:B,2,0) -> 16278.66 | H40: =G40 -> 16278.66
...

Sheet AUX
B1: 對與對誤差1 mil，+/-誤差1mil；4 Site等長
B2: SITE | C2: Pin number | D2: Pin name | E2: DUT->RLY | F2: Length1 (mils) | G2: RLY->Channel | H2: Channel | I2: Length2 (mils) | J2: Total length (mils) | K2: +/- CHECK
B3: SITE1 | C3: 21 | D3: AUXCHP | E3: S1_AUXCH+ | F3: =VLOOKUP(E3,Etch_Length_From_Layout!A:B,2,0) -> 944.9 | G3: S1_AUX_100DCH001+ | H3: =VLOOKUP(G3,'CH assign'!A:B,2,0) -> #N/A | I3: =VLOOKUP(H3,Etch_Length_From_Layout!A:B,2,0) -> #N/A | J3: =F3+I3 -> #N/A | K3: =IF(ABS(J3-J4)<1,"PASS","FAIL") -> #N/A
C4: 20 | D4: AUXCHN | E4: S1_AUXCH- | F4: =VLOOKUP(E4,Etch_Length_From_Layout!A:B,2,0) -> 944.89 | G4: S1_AUX_100DCH001- | H4: =VLOOKUP(G4,'CH assign'!A:B,2,0) -> #N/A | I4: =VLOOKUP(H4,Etch_Length_From_Layout!A:B,2,0) -> #N/A | J4: =F4+I4 -> #N/A
B5: SITE2 | C5: 21 | D5: AUXCHP | E5: S2_AUXCH+ | F5: =VLOOKUP(E5,Etch_Length_From_Layout!A:B,2,0) -> 1270.93 | G5: S2_AUX_100DCH001+ | H5: =VLOOKUP(G5,'CH assign'!A:B,2,0) -> #N/A | I5: =VLOOKUP(H5,Etch_Length_From_Layout!A:B,2,0) -> #N/A | J5: =F5+I5 -> #N/A | K5: =IF(ABS(J5-J6)<1,"PASS","FAIL") -> #N/A
C6: 20 | D6: AUXCHN | E6: S2_AUXCH- | F6: =VLOOKUP(E6,Etch_Length_From_Layout!A:B,2,0) -> 1261.97 | G6: S2_AUX_100DCH001- | H6: =VLOOKUP(G6,'CH assign'!A:B,2,0) -> #N/A | I6: =VLOOKUP(H6,Etch_Length_From_Layout!A:B,2,0) -> #N/A | J6: =F6+I6 -> #N/A
B7: SITE3 | C7: 21 | D7: AUXCHP | E7: S3_AUXCH+ | F7: =VLOOKUP(E7,Etch_Length_From_Layout!A:B,2,0) -> 1270.93 | G7: S3_AUX_100DCH001+ | H7: =VLOOKUP(G7,'CH assign'!A:B,2,0) -> #N/A | I7: =VLOOKUP(H7,Etch_Length_From_Layout!A:B,2,0) -> #N/A | J7: =F7+I7 -> #N/A | K7: =IF(ABS(J7-J8)<1,"PASS","FAIL") -> #N/A
C8: 20 | D8: AUXCHN | E8: S3_AUXCH- | F8: =VLOOKUP(E8,Etch_Length_From_Layout!A:B,2,0) -> 1261.97 | G8: S3_AUX_100DCH001- | H8: =VLOOKUP(G8,'CH assign'!A:B,2,0) -> #N/A | I8: =VLOOKUP(H8,Etch_Length_From_Layout!A:B,2,0) -> #N/A | J8: =F8+I8 -> #N/A
B9: SITE4 | C9: 21 | D9: AUXCHP | E9: S4_AUXCH+ | F9: =VLOOKUP(E9,Etch_Length_From_Layout!A:B,2,0) -> 1270.93 | G9: S4_AUX_100DCH001+ | H9: =VLOOKUP(G9,'CH assign'!A:B,2,0) -> #N/A | I9: =VLOOKUP(H9,Etch_Length_From_Layout!A:B,2,0) -> #N/A | J9: =F9+I9 -> #N/A | K9: =IF(ABS(J9-J10)<1,"PASS","FAIL") -> #N/A
C10: 20 | D10: AUXCHN | E10: S4_AUXCH- | F10: =VLOOKUP(E10,Etch_Length_From_Layout!A:B,2,0) -> 1261.97 | G10: S4_AUX_100DCH001- | H10: =VLOOKUP(G10,'CH assign'!A:B,2,0) -> #N/A | I10: =VLOOKUP(H10,Etch_Length_From_Layout!A:B,2,0) -> #N/A | J10: =F10+I10 -> #N/A
I11: MAX | J11: =MAX(J3:J10) -> #N/A
I12: min | J12: =MIN(J3:J10) -> #N/A
I13: MAX-min | J13: =J11-J12 -> #N/A
I14: Result | J14: =IF(J13<=1,"PASS", "FAIL") -> #N/A
B16: 對與對誤差1 mil，+/-誤差1mil；4 Site等長
B17: SITE | C17: Pin number | D17: Pin name | E17: DUT->RLY | F17: Length1 (mils) | G17: DUT->0 R | H17: Length2 (mils) | I17: 0R->0.1uF | J17: Length3 (mils) | K17: 0.1uF->Channel | L17: Channel | M17: Length4 (mils) | N17: Total length (mils) | O17: +/- CHECK
B18: SITE1 | C18: 21 | D18: AUXCHP | E18: S1_AUXCH+ | F18: =VLOOKUP(E18,Etch_Length_From_Layout!A:B,2,0) -> 944.9 | G18: S1_1AUX+ | H18: =VLOOKUP(G18,Etch_Length_From_Layout!A:B,2,0) -> 0 | I18: S1_2AUX+ | J18: =VLOOKUP(I18,Etch_Length_From_Layout!A:B,2,0) -> 0 | K18: S1_AUX_100DCH002+ | L18: =VLOOKUP(K18,'CH assign'!A:B,2,0) -> #N/A | M18: =VLOOKUP(L18,Etch_Length_From_Layout!A:B,2,0) -> #N/A | N18: =F18+H18+J18+M18 -> #N/A | O18: =IF(ABS(N18-N19)<1,"PASS","FAIL") -> #N/A
C19: 20 | D19: AUXCHN | E19: S1_AUXCH- | F19: =VLOOKUP(E19,Etch_Length_From_Layout!A:B,2,0) -> 944.89 | G19: S1_1AUX- | H19: =VLOOKUP(G19,Etch_Length_From_Layout!A:B,2,0) -> 0 | I19: S1_2AUX- | J19: =VLOOKUP(I19,Etch_Length_From_Layout!A:B,2,0) -> 0 | K19: S1_AUX_100DCH002- | L19: =VLOOKUP(K19,'CH assign'!A:B,2,0) -> #N/A | M19: =VLOOKUP(L19,Etch_Length_From_Layout!A:B,2,0) -> #N/A | N19: =F19+H19+J19+M19 -> #N/A
B20: SITE2 | C20: 21 | D20: AUXCHP | E20: S2_AUXCH+ | F20: =VLOOKUP(E20,Etch_Length_From_Layout!A:B,2,0) -> 1270.93 | G20: S2_1AUX+ | H20: =VLOOKUP(G20,Etch_Length_From_Layout!A:B,2,0) -> 0 | I20: S2_2AUX+ | J20: =VLOOKUP(I20,Etch_Length_From_Layout!A:B,2,0) -> 0 | K20: S2_AUX_100DCH002+ | L20: =VLOOKUP(K20,'CH assign'!A:B,2,0) -> #N/A | M20: =VLOOKUP(L20,Etch_Length_From_Layout!A:B,2,0) -> #N/A | N20: =F20+H20+J20+M20 -> #N/A | O20: =IF(ABS(N20-N21)<1,"PASS","FAIL") -> #N/A
C21: 20 | D21: AUXCHN | E21: S2_AUXCH- | F21: =VLOOKUP(E21,Etch_Length_From_Layout!A:B,2,0) -> 1261.97 | G21: S2_1AUX- | H21: =VLOOKUP(G21,Etch_Length_From_Layout!A:B,2,0) -> 0 | I21: S2_2AUX- | J21: =VLOOKUP(I21,Etch_Length_From_Layout!A:B,2,0) -> 0 | K21: S2_AUX_100DCH002- | L21: =VLOOKUP(K21,'CH assign'!A:B,2,0) -> #N/A | M21: =VLOOKUP(L21,Etch_Length_From_Layout!A:B,2,0) -> #N/A | N21: =F21+H21+J21+M21 -> #N/A
B22: SITE3 | C22: 21 | D22: AUXCHP | E22: S3_AUXCH+ | F22: =VLOOKUP(E22,Etch_Length_From_Layout!A:B,2,0) -> 1270.93 | G22: S3_1AUX+ | H22: =VLOOKUP(G22,Etch_Length_From_Layout!A:B,2,0) -> 0 | I22: S3_2AUX+ | J22: =VLOOKUP(I22,Etch_Length_From_Layout!A:B,2,0) -> 0 | K22: S3_AUX_100DCH002+ | L22: =VLOOKUP(K22,'CH assign'!A:B,2,0) -> #N/A | M22: =VLOOKUP(L22,Etch_Length_From_Layout!A:B,2,0) -> #N/A | N22: =F22+H22+J22+M22 -> #N/A | O22: =IF(ABS(N22-N23)<1,"PASS","FAIL") -> #N/A
C23: 20 | D23: AUXCHN | E23: S3_AUXCH- | F23: =VLOOKUP(E23,Etch_Length_From_Layout!A:B,2,0) -> 1261.97 | G23: S3_1AUX- | H23: =VLOOKUP(G23,Etch_Length_From_Layout!A:B,2,0) -> 0 | I23: S3_2AUX- | J23: =VLOOKUP(I23,Etch_Length_From_Layout!A:B,2,0) -> 0 | K23: S3_AUX_100DCH002- | L23: =VLOOKUP(K23,'CH assign'!A:B,2,0) -> #N/A | M23: =VLOOKUP(L23,Etch_Length_From_Layout!A:B,2,0) -> #N/A | N23: =F23+H23+J23+M23 -> #N/A
B24: SITE4 | C24: 21 | D24: AUXCHP | E24: S4_AUXCH+ | F24: =VLOOKUP(E24,Etch_Length_From_Layout!A:B,2,0) -> 1270.93 | G24: S4_1AUX+ | H24: =VLOOKUP(G24,Etch_Length_From_Layout!A:B,2,0) -> 0 | I24: S4_2AUX+ | J24: =VLOOKUP(I24,Etch_Length_From_Layout!A:B,2,0) -> 0 | K24: S4_AUX_100DCH002+ | L24: =VLOOKUP(K24,'CH assign'!A:B,2,0) -> #N/A | M24: =VLOOKUP(L24,Etch_Length_From_Layout!A:B,2,0) -> #N/A | N24: =F24+H24+J24+M24 -> #N/A | O24: =IF(ABS(N24-N25)<1,"PASS","FAIL") -> #N/A
C25: 20 | D25: AUXCHN | E25: S4_AUXCH- | F25: =VLOOKUP(E25,Etch_Length_From_Layout!A:B,2,0) -> 1261.97 | G25: S4_1AUX- | H25: =VLOOKUP(G25,Etch_Length_From_Layout!A:B,2,0) -> 0 | I25: S4_2AUX- | J25: =VLOOKUP(I25,Etch_Length_From_Layout!A:B,2,0) -> 0 | K25: S4_AUX_100DCH002- | L25: =VLOOKUP(K25,'CH assign'!A:B,2,0) -> #N/A | M25: =VLOOKUP(L25,Etch_Length_From_Layout!A:B,2,0) -> #N/A | N25: =F25+H25+J25+M25 -> #N/A
M26: MAX | N26: =MAX(N18:N25) -> #N/A
M27: min | N27: =MIN(N18:N25) -> #N/A
M28: MAX-min | N28: =N26-N27 -> #N/A
M29: Result | N29: =IF(N28<=10,"PASS", "FAIL") -> #N/A

Sheet Flash
B1: DUT-> U1 flash等長誤差1 mil；4 Site等長
B2: SITE | C2: Pin number | D2: Pin name | E2: DUT->RLY | F2: Length1 (mils) | G2: RLY->RLY | H2: Length2 (mils) | I2: RLY->0 ohm | J2: Length3 (mils) | K2: RLY->U1 | L2: Length4 (mils) | M2: Total length (mils)
B3: Site1 | C3: 43 | D3: SPI_CSN | E3: S1_SPI_CSN | F3: =VLOOKUP(E3,Etch_Length_From_Layout!A:B,2,0) -> 1018.74 | G3: S1_1SPI_CSN | H3: =VLOOKUP(G3,Etch_Length_From_Layout!A:B,2,0) -> 0 | K3: S1_SPI_1_CSN | L3: =VLOOKUP(K3,Etch_Length_From_Layout!A:B,2,0) -> 0 | M3: =F3+H3+J3+L3 -> 1018.74
C4: 42 | D4: SPI_SCK | E4: S1_SPI_SCK | F4: =VLOOKUP(E4,Etch_Length_From_Layout!A:B,2,0) -> 996.97 | G4: S1_1SPI_SCK | H4: =VLOOKUP(G4,Etch_Length_From_Layout!A:B,2,0) -> 0 | K4: S1_SPI_1_SCK | L4: =VLOOKUP(K4,Etch_Length_From_Layout!A:B,2,0) -> 0 | M4: =F4+H4+J4+L4 -> 996.97
C5: 44 | D5: SPI_SDI | E5: S1_SPI_SDI | F5: =VLOOKUP(E5,Etch_Length_From_Layout!A:B,2,0) -> 1082.53 | G5: S1_1SPI_SDI | H5: =VLOOKUP(G5,Etch_Length_From_Layout!A:B,2,0) -> 0 | I5: S1_SPI_1_SDI | J5: =VLOOKUP(I5,Etch_Length_From_Layout!A:B,2,0) -> 0 | K5: S1_SPI_11_SDI | L5: =VLOOKUP(K5,Etch_Length_From_Layout!A:B,2,0) -> 0 | M5: =F5+H5+J5+L5 -> 1082.53
C6: 41 | D6: SPI_SDO | E6: S1_SPI_SDO | F6: =VLOOKUP(E6,Etch_Length_From_Layout!A:B,2,0) -> 1145.37 | G6: S1_1SPI_SDO | H6: =VLOOKUP(G6,Etch_Length_From_Layout!A:B,2,0) -> 0 | I6: S1_SPI_1_SDO | J6: =VLOOKUP(I6,Etch_Length_From_Layout!A:B,2,0) -> 0 | K6: S1_SPI_11_SDO | L6: =VLOOKUP(K6,Etch_Length_From_Layout!A:B,2,0) -> 0 | M6: =F6+H6+J6+L6 -> 1145.37
B7: Site2 | C7: 43 | D7: SPI_CSN | E7: S2_SPI_CSN | F7: =VLOOKUP(E7,Etch_Length_From_Layout!A:B,2,0) -> 1018.74 | G7: S2_1SPI_CSN | H7: =VLOOKUP(G7,Etch_Length_From_Layout!A:B,2,0) -> 0 | K7: S2_SPI_1_CSN | L7: =VLOOKUP(K7,Etch_Length_From_Layout!A:B,2,0) -> 0 | M7: =F7+H7+J7+L7 -> 1018.74
C8: 42 | D8: SPI_SCK | E8: S2_SPI_SCK | F8: =VLOOKUP(E8,Etch_Length_From_Layout!A:B,2,0) -> 996.97 | G8: S2_1SPI_SCK | H8: =VLOOKUP(G8,Etch_Length_From_Layout!A:B,2,0) -> 0 | K8: S2_SPI_1_SCK | L8: =VLOOKUP(K8,Etch_Length_From_Layout!A:B,2,0) -> 0 | M8: =F8+H8+J8+L8 -> 996.97
C9: 44 | D9: SPI_SDI | E9: S2_SPI_SDI | F9: =VLOOKUP(E9,Etch_Length_From_Layout!A:B,2,0) -> 1344.39 | G9: S2_1SPI_SDI | H9: =VLOOKUP(G9,Etch_Length_From_Layout!A:B,2,0) -> 0 | I9: S2_SPI_1_SDI | J9: =VLOOKUP(I9,Etch_Length_From_Layout!A:B,2,0) -> 0 | K9: S2_SPI_11_SDI | L9: =VLOOKUP(K9,Etch_Length_From_Layout!A:B,2,0) -> 0 | M9: =F9+H9+J9+L9 -> 1344.39
C10: 41 | D10: SPI_SDO | E10: S2_SPI_SDO | F10: =VLOOKUP(E10,Etch_Length_From_Layout!A:B,2,0) -> 1455.19 | G10: S2_1SPI_SDO | H10: =VLOOKUP(G10,Etch_Length_From_Layout!A:B,2,0) -> 0 | I10: S2_SPI_1_SDO | J10: =VLOOKUP(I10,Etch_Length_From_Layout!A:B,2,0) -> 0 | K10: S2_SPI_11_SDO | L10: =VLOOKUP(K10,Etch_Length_From_Layout!A:B,2,0) -> 0 | M10: =F10+H10+J10+L10 -> 1455.19
B11: Site3 | C11: 43 | D11: SPI_CSN | E11: S3_SPI_CSN | F11: =VLOOKUP(E11,Etch_Length_From_Layout!A:B,2,0) -> 1018.74 | G11: S3_1SPI_CSN | H11: =VLOOKUP(G11,Etch_Length_From_Layout!A:B,2,0) -> 0 | K11: S3_SPI_1_CSN | L11: =VLOOKUP(K11,Etch_Length_From_Layout!A:B,2,0) -> 0 | M11: =F11+H11+J11+L11 -> 1018.74
C12: 42 | D12: SPI_SCK | E12: S3_SPI_SCK | F12: =VLOOKUP(E12,Etch_Length_From_Layout!A:B,2,0) -> 996.97 | G12: S3_1SPI_SCK | H12: =VLOOKUP(G12,Etch_Length_From_Layout!A:B,2,0) -> 0 | K12: S3_SPI_1_SCK | L12: =VLOOKUP(K12,Etch_Length_From_Layout!A:B,2,0) -> 0 | M12: =F12+H12+J12+L12 -> 996.97
C13: 44 | D13: SPI_SDI | E13: S3_SPI_SDI | F13: =VLOOKUP(E13,Etch_Length_From_Layout!A:B,2,0) -> 1344.39 | G13: S3_1SPI_SDI | H13: =VLOOKUP(G13,Etch_Length_From_Layout!A:B,2,0) -> 0 | I13: S3_SPI_1_SDI | J13: =VLOOKUP(I13,Etch_Length_From_Layout!A:B,2,0) -> 0 | K13: S3_SPI_11_SDI | L13: =VLOOKUP(K13,Etch_Length_From_Layout!A:B,2,0) -> 0 | M13: =F13+H13+J13+L13 -> 1344.39
C14: 41 | D14: SPI_SDO | E14: S3_SPI_SDO | F14: =VLOOKUP(E14,Etch_Length_From_Layout!A:B,2,0) -> 1455.19 | G14: S3_1SPI_SDO | H14: =VLOOKUP(G14,Etch_Length_From_Layout!A:B,2,0) -> 0 | I14: S3_SPI_1_SDO | J14: =VLOOKUP(I14,Etch_Length_From_Layout!A:B,2,0) -> 0 | K14: S3_SPI_11_SDO | L14: =VLOOKUP(K14,Etch_Length_From_Layout!A:B,2,0) -> 0 | M14: =F14+H14+J14+L14 -> 1455.19
B15: Site4 | C15: 43 | D15: SPI_CSN | E15: S4_SPI_CSN | F15: =VLOOKUP(E15,Etch_Length_From_Layout!A:B,2,0) -> 1018.74 | G15: S4_1SPI_CSN | H15: =VLOOKUP(G15,Etch_Length_From_Layout!A:B,2,0) -> 0 | K15: S4_SPI_1_CSN | L15: =VLOOKUP(K15,Etch_Length_From_Layout!A:B,2,0) -> 0 | M15: =F15+H15+J15+L15 -> 1018.74
C16: 42 | D16: SPI_SCK | E16: S4_SPI_SCK | F16: =VLOOKUP(E16,Etch_Length_From_Layout!A:B,2,0) -> 996.97 | G16: S4_1SPI_SCK | H16: =VLOOKUP(G16,Etch_Length_From_Layout!A:B,2,0) -> 0 | K16: S4_SPI_1_SCK | L16: =VLOOKUP(K16,Etch_Length_From_Layout!A:B,2,0) -> 0 | M16: =F16+H16+J16+L16 -> 996.97
C17: 44 | D17: SPI_SDI | E17: S4_SPI_SDI | F17: =VLOOKUP(E17,Etch_Length_From_Layout!A:B,2,0) -> 147.48 | G17: S4_1SPI_SDI | H17: =VLOOKUP(G17,Etch_Length_From_Layout!A:B,2,0) -> 0 | I17: S4_SPI_1_SDI | J17: =VLOOKUP(I17,Etch_Length_From_Layout!A:B,2,0) -> 0 | K17: S4_SPI_11_SDI | L17: =VLOOKUP(K17,Etch_Length_From_Layout!A:B,2,0) -> 0 | M17: =F17+H17+J17+L17 -> 147.48
C18: 41 | D18: SPI_SDO | E18: S4_SPI_SDO | F18: =VLOOKUP(E18,Etch_Length_From_Layout!A:B,2,0) -> 1455.19 | G18: S4_1SPI_SDO | H18: =VLOOKUP(G18,Etch_Length_From_Layout!A:B,2,0) -> 0 | I18: S4_SPI_1_SDO | J18: =VLOOKUP(I18,Etch_Length_From_Layout!A:B,2,0) -> 0 | K18: S4_SPI_11_SDO | L18: =VLOOKUP(K18,Etch_Length_From_Layout!A:B,2,0) -> 0 | M18: =F18+H18+J18+L18 -> 1455.19
L19: MAX | M19: =MAX(M3:M18) -> 1455.19
L20: min | M20: =MIN(M3:M18) -> 147.48
L21: MAX-min | M21: =M19-M20 -> 1307.71
L22: Result | M22: =IF(M21<=1,"PASS", "FAIL") -> FAIL
B24: DUT-> U2 flash等長誤差1 mil；4 Site等長
B25: SITE | C25: Pin number | D25: Pin name | E25: DUT->RLY | F25: Length1 (mils) | G25: RLY->RLY | H25: Length2 (mils) | I25: RLY->0 ohm | J25: Length3 (mils) | K25: RLY->U2 | L25: Length4 (mils) | M25: Total length (mils)
B26: Site1 | C26: 43 | D26: SPI_CSN | E26: S1_SPI_CSN | F26: =VLOOKUP(E26,Etch_Length_From_Layout!A:B,2,0) -> 1018.74 | G26: S1_1SPI_CSN | H26: =VLOOKUP(G26,Etch_Length_From_Layout!A:B,2,0) -> 0 | K26: S1_SPI_2_CSN | L26: =VLOOKUP(K26,Etch_Length_From_Layout!A:B,2,0) -> 0 | M26: =F26+H26+J26+L26 -> 1018.74
C27: 42 | D27: SPI_SCK | E27: S1_SPI_SCK | F27: =VLOOKUP(E27,Etch_Length_From_Layout!A:B,2,0) -> 996.97 | G27: S1_1SPI_SCK | H27: =VLOOKUP(G27,Etch_Length_From_Layout!A:B,2,0) -> 0 | K27: S1_SPI_2_SCK | L27: =VLOOKUP(K27,Etch_Length_From_Layout!A:B,2,0) -> 0 | M27: =F27+H27+J27+L27 -> 996.97
C28: 44 | D28: SPI_SDI | E28: S1_SPI_SDI | F28: =VLOOKUP(E28,Etch_Length_From_Layout!A:B,2,0) -> 1082.53 | G28: S1_1SPI_SDI | H28: =VLOOKUP(G28,Etch_Length_From_Layout!A:B,2,0) -> 0 | I28: S1_SPI_2_SDI | J28: =VLOOKUP(I28,Etch_Length_From_Layout!A:B,2,0) -> 0 | K28: S1_SPI_22_SDI | L28: =VLOOKUP(K28,Etch_Length_From_Layout!A:B,2,0) -> 0 | M28: =F28+H28+J28+L28 -> 1082.53
C29: 41 | D29: SPI_SDO | E29: S1_SPI_SDO | F29: =VLOOKUP(E29,Etch_Length_From_Layout!A:B,2,0) -> 1145.37 | G29: S1_1SPI_SDO | H29: =VLOOKUP(G29,Etch_Length_From_Layout!A:B,2,0) -> 0 | I29: S1_SPI_2_SDO | J29: =VLOOKUP(I29,Etch_Length_From_Layout!A:B,2,0) -> 0 | K29: S1_SPI_22_SDO | L29: =VLOOKUP(K29,Etch_Length_From_Layout!A:B,2,0) -> 0 | M29: =F29+H29+J29+L29 -> 1145.37
B30: Site2 | C30: 43 | D30: SPI_CSN | E30: S2_SPI_CSN | F30: =VLOOKUP(E30,Etch_Length_From_Layout!A:B,2,0) -> 1018.74 | G30: S2_1SPI_CSN | H30: =VLOOKUP(G30,Etch_Length_From_Layout!A:B,2,0) -> 0 | K30: S2_SPI_2_CSN | L30: =VLOOKUP(K30,Etch_Length_From_Layout!A:B,2,0) -> 0 | M30: =F30+H30+J30+L30 -> 1018.74
C31: 42 | D31: SPI_SCK | E31: S2_SPI_SCK | F31: =VLOOKUP(E31,Etch_Length_From_Layout!A:B,2,0) -> 996.97 | G31: S2_1SPI_SCK | H31: =VLOOKUP(G31,Etch_Length_From_Layout!A:B,2,0) -> 0 | K31: S2_SPI_2_SCK | L31: =VLOOKUP(K31,Etch_Length_From_Layout!A:B,2,0) -> 0 | M31: =F31+H31+J31+L31 -> 996.97
C32: 44 | D32: SPI_SDI | E32: S2_SPI_SDI | F32: =VLOOKUP(E32,Etch_Length_From_Layout!A:B,2,0) -> 1344.39 | G32: S2_1SPI_SDI | H32: =VLOOKUP(G32,Etch_Length_From_Layout!A:B,2,0) -> 0 | I32: S2_SPI_2_SDI | J32: =VLOOKUP(I32,Etch_Length_From_Layout!A:B,2,0) -> 0 | K32: S2_SPI_22_SDI | L32: =VLOOKUP(K32,Etch_Length_From_Layout!A:B,2,0) -> 0 | M32: =F32+H32+J32+L32 -> 1344.39
C33: 41 | D33: SPI_SDO | E33: S2_SPI_SDO | F33: =VLOOKUP(E33,Etch_Length_From_Layout!A:B,2,0) -> 1455.19 | G33: S2_1SPI_SDO | H33: =VLOOKUP(G33,Etch_Length_From_Layout!A:B,2,0) -> 0 | I33: S2_SPI_2_SDO | J33: =VLOOKUP(I33,Etch_Length_From_Layout!A:B,2,0) -> 0 | K33: S2_SPI_22_SDO | L33: =VLOOKUP(K33,Etch_Length_From_Layout!A:B,2,0) -> 0 | M33: =F33+H33+J33+L33 -> 1455.19
B34: Site3 | C34: 43 | D34: SPI_CSN | E34: S3_SPI_CSN | F34: =VLOOKUP(E34,Etch_Length_From_Layout!A:B,2,0) -> 1018.74 | G34: S3_1SPI_CSN | H34: =VLOOKUP(G34,Etch_Length_From_Layout!A:B,2,0) -> 0 | K34: S3_SPI_2_CSN | L34: =VLOOKUP(K34,Etch_Length_From_Layout!A:B,2,0) -> 0 | M34: =F34+H34+J34+L34 -> 1018.74
C35: 42 | D35: SPI_SCK | E35: S3_SPI_SCK | F35: =VLOOKUP(E35,Etch_Length_From_Layout!A:B,2,0) -> 996.97 | G35: S3_1SPI_SCK | H35: =VLOOKUP(G35,Etch_Length_From_Layout!A:B,2,0) -> 0 | K35: S3_SPI_2_SCK | L35: =VLOOKUP(K35,Etch_Length_From_Layout!A:B,2,0) -> 0 | M35: =F35+H35+J35+L35 -> 996.97
C36: 44 | D36: SPI_SDI | E36: S3_SPI_SDI | F36: =VLOOKUP(E36,Etch_Length_From_Layout!A:B,2,0) -> 1344.39 | G36: S3_1SPI_SDI | H36: =VLOOKUP(G36,Etch_Length_From_Layout!A:B,2,0) -> 0 | I36: S3_SPI_2_SDI | J36: =VLOOKUP(I36,Etch_Length_From_Layout!A:B,2,0) -> 0 | K36: S3_SPI_22_SDI | L36: =VLOOKUP(K36,Etch_Length_From_Layout!A:B,2,0) -> 0 | M36: =F36+H36+J36+L36 -> 1344.39
C37: 41 | D37: SPI_SDO | E37: S3_SPI_SDO | F37: =VLOOKUP(E37,Etch_Length_From_Layout!A:B,2,0) -> 1455.19 | G37: S3_1SPI_SDO | H37: =VLOOKUP(G37,Etch_Length_From_Layout!A:B,2,0) -> 0 | I37: S3_SPI_2_SDO | J37: =VLOOKUP(I37,Etch_Length_From_Layout!A:B,2,0) -> 0 | K37: S3_SPI_22_SDO | L37: =VLOOKUP(K37,Etch_Length_From_Layout!A:B,2,0) -> 0 | M37: =F37+H37+J37+L37 -> 1455.19
B38: Site4 | C38: 43 | D38: SPI_CSN | E38: S4_SPI_CSN | F38: =VLOOKUP(E38,Etch_Length_From_Layout!A:B,2,0) -> 1018.74 | G38: S4_1SPI_CSN | H38: =VLOOKUP(G38,Etch_Length_From_Layout!A:B,2,0) -> 0 | K38: S4_SPI_2_CSN | L38: =VLOOKUP(K38,Etch_Length_From_Layout!A:B,2,0) -> 0 | M38: =F38+H38+J38+L38 -> 1018.74
C39: 42 | D39: SPI_SCK | E39: S4_SPI_SCK | F39: =VLOOKUP(E39,Etch_Length_From_Layout!A:B,2,0) -> 996.97 | G39: S4_1SPI_SCK | H39: =VLOOKUP(G39,Etch_Length_From_Layout!A:B,2,0) -> 0 | K39: S4_SPI_2_SCK | L39: =VLOOKUP(K39,Etch_Length_From_Layout!A:B,2,0) -> 0 | M39: =F39+H39+J39+L39 -> 996.97
C40: 44 | D40: SPI_SDI | E40: S4_SPI_SDI | F40: =VLOOKUP(E40,Etch_Length_From_Layout!A:B,2,0) -> 147.48 | G40: S4_1SPI_SDI | H40: =VLOOKUP(G40,Etch_Length_From_Layout!A:B,2,0) -> 0 | I40: S4_SPI_2_SDI | J40: =VLOOKUP(I40,Etch_Length_From_Layout!A:B,2,0) -> 0 | K40: S4_SPI_22_SDI | L40: =VLOOKUP(K40,Etch_Length_From_Layout!A:B,2,0) -> 0 | M40: =F40+H40+J40+L40 -> 147.48
C41: 41 | D41: SPI_SDO | E41: S4_SPI_SDO | F41: =VLOOKUP(E41,Etch_Length_From_Layout!A:B,2,0) -> 1455.19 | G41: S4_1SPI_SDO | H41: =VLOOKUP(G41,Etch_Length_From_Layout!A:B,2,0) -> 0 | I41: S4_SPI_2_SDO | J41: =VLOOKUP(I41,Etch_Length_From_Layout!A:B,2,0) -> 0 | K41: S4_SPI_22_SDO | L41: =VLOOKUP(K41,Etch_Length_From_Layout!A:B,2,0) -> 0 | M41: =F41+H41+J41+L41 -> 1455.19
...

Sheet Scan
B1: 等長誤差1 mil；4 Site等長
B2: SITE | C2: Pin number | D2: Pin name | E2: DUT->RLY | F2: Length1 (mils) | G2: RLY->Channel | H2: Channel | I2: Length2 (mils) | J2: Total length (mils)
B3: SITE1 | C3: 48 | D3: FAIL_FLAG_O | G3: S1_SCAN_DCH008 | H3: =VLOOKUP(G3,'CH assign'!A:B,2,0) -> #N/A | I3: =VLOOKUP(H3,Etch_Length_From_Layout!A:B,2,0) -> #N/A | J3: =F3+I3 -> #N/A
C4: 52 | D4: LED_SPI_BLANK_A | G4: S1_SCAN_DCH012 | H4: =VLOOKUP(G4,'CH assign'!A:B,2,0) -> #N/A | I4: =VLOOKUP(H4,Etch_Length_From_Layout!A:B,2,0) -> #N/A | J4: =F4+I4 -> #N/A
C5: 53 | D5: LED_SPI_GSCLK_A | G5: S1_SCAN_DCH013 | H5: =VLOOKUP(G5,'CH assign'!A:B,2,0) -> #N/A | I5: =VLOOKUP(H5,Etch_Length_From_Layout!A:B,2,0) -> #N/A | J5: =F5+I5 -> #N/A
C6: 56 | D6: LED_SPI_XLAT_A | G6: S1_SCAN_DCH016 | H6: =VLOOKUP(G6,'CH assign'!A:B,2,0) -> #N/A | I6: =VLOOKUP(H6,Etch_Length_From_Layout!A:B,2,0) -> #N/A | J6: =F6+I6 -> #N/A
C7: 57 | D7: LED_SPI_BLANK_B | G7: S1_SCAN_DCH017 | H7: =VLOOKUP(G7,'CH assign'!A:B,2,0) -> #N/A | I7: =VLOOKUP(H7,Etch_Length_From_Layout!A:B,2,0) -> #N/A | J7: =F7+I7 -> #N/A
C8: 58 | D8: LED_SPI_GSCLK_B | G8: S1_SCAN_DCH018 | H8: =VLOOKUP(G8,'CH assign'!A:B,2,0) -> #N/A | I8: =VLOOKUP(H8,Etch_Length_From_Layout!A:B,2,0) -> #N/A | J8: =F8+I8 -> #N/A
C9: 59 | D9: LED_SPI_SIN_B | G9: S1_SCAN_DCH019 | H9: =VLOOKUP(G9,'CH assign'!A:B,2,0) -> #N/A | I9: =VLOOKUP(H9,Etch_Length_From_Layout!A:B,2,0) -> #N/A | J9: =F9+I9 -> #N/A
C10: 60 | D10: LED_SPI_SCLK_B | G10: S1_SCAN_DCH020 | H10: =VLOOKUP(G10,'CH assign'!A:B,2,0) -> #N/A | I10: =VLOOKUP(H10,Etch_Length_From_Layout!A:B,2,0) -> #N/A | J10: =F10+I10 -> #N/A
C11: 61 | D11: LED_SPI_XLAT_B | G11: S1_SCAN_DCH021 | H11: =VLOOKUP(G11,'CH assign'!A:B,2,0) -> #N/A | I11: =VLOOKUP(H11,Etch_Length_From_Layout!A:B,2,0) -> #N/A | J11: =F11+I11 -> #N/A
C12: 67 | D12: OSD_SPI_SCK_I2CCLK | G12: S1_SCAN_DCH024 | H12: =VLOOKUP(G12,'CH assign'!A:B,2,0) -> #N/A | I12: =VLOOKUP(H12,Etch_Length_From_Layout!A:B,2,0) -> #N/A | J12: =F12+I12 -> #N/A
C13: 68 | D13: OSD_SPI_SDI_I2CDAT | G13: S1_SCAN_DCH025 | H13: =VLOOKUP(G13,'CH assign'!A:B,2,0) -> #N/A | I13: =VLOOKUP(H13,Etch_Length_From_Layout!A:B,2,0) -> #N/A | J13: =F13+I13 -> #N/A
C14: 69 | D14: OSD_SPI_CSN | G14: S1_SCAN_DCH026 | H14: =VLOOKUP(G14,'CH assign'!A:B,2,0) -> #N/A | I14: =VLOOKUP(H14,Etch_Length_From_Layout!A:B,2,0) -> #N/A | J14: =F14+I14 -> #N/A
C15: 149 | D15: OE2 | G15: S1_SCAN_DCH031 | H15: =VLOOKUP(G15,'CH assign'!A:B,2,0) -> #N/A | I15: =VLOOKUP(H15,Etch_Length_From_Layout!A:B,2,0) -> #N/A | J15: =F15+I15 -> #N/A
... C18: 152 | D18: CLK7 | G18: S1_SCAN_DCH034 | H18: =VLOOKUP(G18,'CH assign'!A:B,2,0) -> #N/A | I18: =VLOOKUP(H18,Etch_Length_From_Layout!A:B,2,0) -> #N/A | J18: =F18+I18 -> #N/A
C19: 43 | D19: SPI_CSN | E19: S1_SPI_CSN | F19: =VLOOKUP(E19,Etch_Length_From_Layout!A:B,2,0) -> 1018.74 | G19: S1_SCAN_DCH051 | H19: =VLOOKUP(G19,'CH assign'!A:B,2,0) -> #N/A | I19: =VLOOKUP(H19,Etch_Length_From_Layout!A:B,2,0) -> #N/A | J19: =F19+I19 -> #N/A
C20: 42 | D20: SPI_SCK | E20: S1_SPI_SCK | F20: =VLOOKUP(E20,Etch_Length_From_Layout!A:B,2,0) -> 996.97 | G20: S1_SCAN_DCH050 | H20: =VLOOKUP(G20,'CH assign'!A:B,2,0) -> #N/A | I20: =VLOOKUP(H20,Etch_Length_From_Layout!A:B,2,0) -> #N/A | J20: =F20+I20 -> #N/A
C21: 44 | D21: SPI_SDI | E21: S1_SPI_SDI | F21: =VLOOKUP(E21,Etch_Length_From_Layout!A:B,2,0) -> 1082.53 | G21: S1_SCAN_DCH053 | H21: =VLOOKUP(G21,'CH assign'!A:B,2,0) -> #N/A | I21: =VLOOKUP(H21,Etch_Length_From_Layout!A:B,2,0) -> #N/A | J21: =F21+I21 -> #N/A
C22: 41 | D22: SPI_SDO | E22: S1_SPI_SDO | F22: =VLOOKUP(E22,Etch_Length_From_Layout!A:B,2,0) -> 1145.37 | G22: S1_SCAN_DCH052 | H22: =VLOOKUP(G22,'CH assign'!A:B,2,0) -> #N/A | I22: =VLOOKUP(H22,Etch_Length_From_Layout!A:B,2,0) -> #N/A | J22: =F22+I22 -> #N/A
B23: SITE2 | C23: 48 | D23: FAIL_FLAG_O | G23: S2_SCAN_DCH008 | H23: =VLOOKUP(G23,'CH assign'!A:B,2,0) -> #N/A | I23: =VLOOKUP(H23,Etch_Length_From_Layout!A:B,2,0) -> #N/A | J23: =F23+I23 -> #N/A
C24: 52 | D24: LED_SPI_BLANK_A | G24: S2_SCAN_DCH012 | H24: =VLOOKUP(G24,'CH assign'!A:B,2,0) -> #N/A | I24: =VLOOKUP(H24,Etch_Length_From_Layout!A:B,2,0) -> #N/A | J24: =F24+I24 -> #N/A
C25: 53 | D25: LED_SPI_GSCLK_A | G25: S2_SCAN_DCH013 | H25: =VLOOKUP(G25,'CH assign'!A:B,2,0) -> #N/A | I25: =VLOOKUP(H25,Etch_Length_From_Layout!A:B,2,0) -> #N/A | J25: =F25+I25 -> #N/A
C26: 56 | D26: LED_SPI_XLAT_A | G26: S2_SCAN_DCH016 | H26: =VLOOKUP(G26,'CH assign'!A:B,2,0) -> #N/A | I26: =VLOOKUP(H26,Etch_Length_From_Layout!A:B,2,0) -> #N/A | J26: =F26+I26 -> #N/A
C27: 57 | D27: LED_SPI_BLANK_B | G27: S2_SCAN_DCH017 | H27: =VLOOKUP(G27,'CH assign'!A:B,2,0) -> #N/A | I27: =VLOOKUP(H27,Etch_Length_From_Layout!A:B,2,0) -> #N/A | J27: =F27+I27 -> #N/A
C28: 58 | D28: LED_SPI_GSCLK_B | G28: S2_SCAN_DCH018 | H28: =VLOOKUP(G28,'CH assign'!A:B,2,0) -> #N/A | I28: =VLOOKUP(H28,Etch_Length_From_Layout!A:B,2,0) -> #N/A | J28: =F28+I28 -> #N/A
C29: 59 | D29: LED_SPI_SIN_B | G29: S2_SCAN_DCH019 | H29: =VLOOKUP(G29,'CH assign'!A:B,2,0) -> #N/A | I29: =VLOOKUP(H29,Etch_Length_From_Layout!A:B,2,0) -> #N/A | J29: =F29+I29 -> #N/A
C30: 60 | D30: LED_SPI_SCLK_B | G30: S2_SCAN_DCH020 | H30: =VLOOKUP(G30,'CH assign'!A:B,2,0) -> #N/A | I30: =VLOOKUP(H30,Etch_Length_From_Layout!A:B,2,0) -> #N/A | J30: =F30+I30 -> #N/A
C31: 61 | D31: LED_SPI_XLAT_B | G31: S2_SCAN_DCH021 | H31: =VLOOKUP(G31,'CH assign'!A:B,2,0) -> #N/A | I31: =VLOOKUP(H31,Etch_Length_From_Layout!A:B,2,0) -> #N/A | J31: =F31+I31 -> #N/A
C32: 67 | D32: OSD_SPI_SCK_I2CCLK | G32: S2_SCAN_DCH024 | H32: =VLOOKUP(G32,'CH assign'!A:B,2,0) -> #N/A | I32: =VLOOKUP(H32,Etch_Length_From_Layout!A:B,2,0) -> #N/A | J32: =F32+I32 -> #N/A
C33: 68 | D33: OSD_SPI_SDI_I2CDAT | G33: S2_SCAN_DCH025 | H33: =VLOOKUP(G33,'CH assign'!A:B,2,0) -> #N/A | I33: =VLOOKUP(H33,Etch_Length_From_Layout!A:B,2,0) -> #N/A | J33: =F33+I33 -> #N/A
C34: 69 | D34: OSD_SPI_CSN | G34: S2_SCAN_DCH026 | H34: =VLOOKUP(G34,'CH assign'!A:B,2,0) -> #N/A | I34: =VLOOKUP(H34,Etch_Length_From_Layout!A:B,2,0) -> #N/A | J34: =F34+I34 -> #N/A
C35: 149 | D35: OE2 | G35: S2_SCAN_DCH031 | H35: =VLOOKUP(G35,'CH assign'!A:B,2,0) -> #N/A | I35: =VLOOKUP(H35,Etch_Length_From_Layout!A:B,2,0) -> #N/A | J35: =F35+I35 -> #N/A
... C38: 152 | D38: CLK7 | G38: S2_SCAN_DCH034 | H38: =VLOOKUP(G38,'CH assign'!A:B,2,0) -> #N/A | I38: =VLOOKUP(H38,Etch_Length_From_Layout!A:B,2,0) -> #N/A | J38: =F38+I38 -> #N/A
C39: 43 | D39: SPI_CSN | E39: S2_SPI_CSN | F39: =VLOOKUP(E39,Etch_Length_From_Layout!A:B,2,0) -> 1018.74 | G39: S2_SCAN_DCH051 | H39: =VLOOKUP(G39,'CH assign'!A:B,2,0) -> #N/A | I39: =VLOOKUP(H39,Etch_Length_From_Layout!A:B,2,0) -> #N/A | J39: =F39+I39 -> #N/A
C40: 42 | D40: SPI_SCK | E40: S2_SPI_SCK | F40: =VLOOKUP(E40,Etch_Length_From_Layout!A:B,2,0) -> 996.97 | G40: S2_SCAN_DCH050 | H40: =VLOOKUP(G40,'CH assign'!A:B,2,0) -> #N/A | I40: =VLOOKUP(H40,Etch_Length_From_Layout!A:B,2,0) -> #N/A | J40: =F40+I40 -> #N/A
C41: 44 | D41: SPI_SDI | E41: S2_SPI_SDI | F41: =VLOOKUP(E41,Etch_Length_From_Layout!A:B,2,0) -> 1344.39 | G41: S2_SCAN_DCH053 | H41: =VLOOKUP(G41,'CH assign'!A:B,2,0) -> #N/A | I41: =VLOOKUP(H41,Etch_Length_From_Layout!A:B,2,0) -> #N/A | J41: =F41+I41 -> #N/A
C42: 41 | D42: SPI_SDO | E42: S2_SPI_SDO | F42: =VLOOKUP(E42,Etch_Length_From_Layout!A:B,2,0) -> 1455.19 | G42: S2_SCAN_DCH052 | H42: =VLOOKUP(G42,'CH assign'!A:B,2,0) -> #N/A | I42: =VLOOKUP(H42,Etch_Length_From_Layout!A:B,2,0) -> #N/A | J42: =F42+I42 -> #N/A
B43: SITE3 | C43: 48 | D43: FAIL_FLAG_O | G43: S3_SCAN_DCH008 | H43: =VLOOKUP(G43,'CH assign'!A:B,2,0) -> #N/A | I43: =VLOOKUP(H43,Etch_Length_From_Layout!A:B,2,0) -> #N/A | J43: =F43+I43 -> #N/A
C44: 52 | D44: LED_SPI_BLANK_A | G44: S3_SCAN_DCH012 | H44: =VLOOKUP(G44,'CH assign'!A:B,2,0) -> #N/A | I44: =VLOOKUP(H44,Etch_Length_From_Layout!A:B,2,0) -> #N/A | J44: =F44+I44 -> #N/A
...

Sheet CH assign
A1: S1_Rx_85Dch004- | B1: D32116
A2: S1_Rx_85Dch004+ | B2: D32114
A3: S1_Rx_85Dch003- | B3: D32112
A4: S1_Rx_85Dch003+ | B4: D32110
A5: S1_Rx_85Dch002- | B5: D32108
A6: S1_Rx_85Dch002+ | B6: D32106
A7: S1_Rx_85Dch001- | B7: D32104
A8: S1_Rx_85Dch001+ | B8: D32102
A9: S3_Rx_85Dch004- | B9: D31716
A10: S3_Rx_85Dch004+ | B10: D31714
A11: S3_Rx_85Dch003- | B11: D31712
A12: S3_Rx_85Dch003+ | B12: D31710
... A344: S3_3Tx_100Dch003+ | B344: D11901

Sheet Etch_Length_From_Layout
A1: Design Name D:/iTest/homeoffice/Test Hardware/980HX-8880F5-KBG-A10/8880F5-0817_PLACEMENT/8880F5-0823_13.brd
A2: Date Sun Aug 23 22:16:00 2026
A3: Net Name | B3: Etch Length (mils) | C3: Manhattan Length (mils) | D3: Percent Manhattan (mils)
A4: D10202 | B4: 32822.29 | C4: 4737.79 | D4: 692.78
A5: D10204 | B5: 32822.02 | C5: 4780.5 | D5: 686.58
A6: D10206 | B6: 32822.12 | C6: 5117.77 | D6: 641.34
A7: D10208 | B7: 32822.3 | C7: 5212 | D7: 629.74
A8: D10210 | B8: 32822.43 | C8: 5406.28 | D8: 607.12
A9: D10212 | B9: 32822.25 | C9: 5532.01 | D9: 593.32
A10: D10213 | B10: 32822.49 | C10: 7355.22 | D10: 446.25
A11: D10214 | B11: 32822.06 | C11: 5774.78 | D11: 568.37
A12: D10215 | B12: 32822.04 | C12: 7631.73 | D12: 430.07
A13: D10216 | B13: 32822.4 | C13: 5900.51 | D13: 556.26
A14: D10301 | B14: 32822.07 | C14: 10461.6 | D14: 313.74
A15: D10303 | B15: 32822.43 | C15: 10306.61 | D15: 318.46
... A1049: UT1_UW15 | B1049: 0 | C1049: 1122.5 | D1049: 0
